# SkyCastle
# Author: Arrrg
# From: Minecraft Forums
# Updated to MC 1.9: 21 Apr 2016

biomesToSpawnIn=deep ocean

weight=1

uniqueMinDistance=6000

emplanks_into_distance=-54
acceptable_target_blocks=water
dimensions=44,30,30
allowable_overhang=9001
max_leveling=0
leveling_buffer=0
preserve_water=0
preserve_lava=0
preserve_plants=0

rule1=0,100,preserveBlock
rule2=0,100,grass
rule3=0,100,dirt
rule4=0,100,cobblestone
rule5=0,100,planks
rule6=0,100,glowstone
rule7=0,100,wheat-1,wheat-2,wheat-3,wheat-4,wheat-5,wheat-6,wheat-7
rule8=0,100,flowing_water
rule9=0,100,stone
rule10=0,100,flowing_lava
rule11=0,100,farmland

# Note: "Sand & gravel" trap unlikely to work in MC 1.9.  May drop upon spawning.
rule12=7,100,sand
rule13=7,100,gravel

rule14=0,100,coal_ore
rule15=0,100,MobSpawner:Skeleton
rule16=0,100,MobSpawner:Zombie
rule17=0,100,coal_block,emerald_block,coal_block
rule18=0,100,iron_block
rule19=0,100,brick_block
rule20=0,100,glass
rule21=0,100,ladder-5
rule22=0,100,ladder-4
rule23=0,100,ladder-3
rule24=0,100,ladder-2
rule25=0,100,stone_slab-3
rule26=0,100,fence
rule27=0,100,yellow_flower,red_flower,brown_mushroom,red_mushroom,red_flower-1,tallgrass-2,brown_mushroom,red_mushroom,pumpkin-4
rule28=0,100,snow_layer
rule29=0,100,stone_stairs-1
rule30=0,100,stone_stairs-0

layer
1,1,1,1,1,1,1,1,1,1,1,1,1,1,1,1,1,1,1,1,1,1,1,1,1,1,1,1,1,1
1,1,1,1,1,1,1,1,1,1,1,1,1,1,1,1,1,1,1,1,1,1,1,1,1,1,1,1,1,1
1,1,1,1,1,1,1,1,1,1,1,1,1,1,1,1,1,1,1,1,1,1,1,1,1,1,1,1,1,1
1,1,1,1,1,1,1,1,1,1,1,1,1,1,1,1,1,1,1,1,1,1,1,1,1,1,1,1,1,1
1,1,1,1,1,1,1,0,0,0,0,0,0,0,0,0,0,0,0,0,0,0,0,1,1,1,1,1,1,1
1,1,1,1,1,1,1,1,1,1,1,0,0,0,0,0,0,0,0,1,1,1,1,1,1,1,1,1,1,1
1,1,1,1,1,1,1,1,1,1,1,1,1,1,1,1,1,1,1,1,1,1,1,1,1,1,1,1,1,1
1,1,1,1,1,1,1,1,1,1,1,1,1,1,1,1,1,1,1,1,1,1,1,1,1,1,1,1,1,1
1,1,1,1,1,1,1,1,1,1,1,1,1,1,1,1,1,1,1,1,1,1,1,1,1,1,1,1,1,1
1,1,1,1,1,1,1,1,1,1,1,1,1,1,1,1,1,1,1,1,9,1,1,1,1,1,1,1,1,1
1,1,1,1,1,1,1,1,1,1,1,1,1,1,1,1,1,1,1,1,1,1,1,1,1,1,1,1,1,1
1,1,1,1,1,1,1,1,1,1,1,1,1,1,1,1,1,1,1,1,1,1,1,1,1,1,1,1,1,1
1,1,1,1,1,1,1,1,1,1,1,1,1,1,1,1,1,1,1,1,1,1,1,1,1,1,1,1,1,1
1,1,1,1,1,1,1,1,1,1,1,1,1,1,9,9,1,1,1,1,1,1,1,1,1,1,1,1,1,1
1,1,1,1,1,1,1,1,1,1,1,1,1,9,0,0,9,1,1,1,1,1,1,1,1,1,1,1,1,1
1,1,1,1,1,1,1,1,1,1,1,1,1,9,0,0,9,1,1,1,1,1,1,1,1,1,1,1,1,1
1,1,1,1,1,1,1,1,1,1,1,1,1,1,9,9,1,1,1,1,1,1,1,1,1,1,1,1,1,1
1,1,1,1,1,1,1,1,1,1,1,1,1,1,1,1,1,1,1,1,1,1,1,1,1,1,1,1,1,1
1,1,1,1,1,1,1,1,1,1,1,1,1,1,1,1,1,1,1,1,1,1,1,1,1,1,1,1,1,1
1,1,1,1,1,1,1,1,1,1,1,1,1,1,1,1,1,1,1,1,1,1,1,1,1,1,1,1,1,1
1,1,1,1,1,1,1,1,1,1,1,1,1,1,1,1,1,1,1,1,1,1,1,1,1,1,1,1,1,1
1,1,1,1,1,1,1,1,1,1,1,1,1,1,1,1,1,1,1,1,1,1,1,1,1,1,1,1,1,1
1,1,1,1,1,1,1,1,1,1,1,1,1,1,1,1,1,1,1,1,1,1,1,1,1,1,1,1,1,1
1,1,1,1,1,1,1,1,1,1,1,1,1,1,1,1,1,1,1,1,1,1,1,1,1,1,1,1,1,1
1,1,1,1,1,1,1,1,1,1,1,1,1,1,1,1,1,1,1,1,1,1,1,1,1,1,1,1,1,1
1,1,1,1,1,1,1,1,1,1,1,1,1,1,1,1,1,1,1,1,1,1,1,1,1,1,1,1,1,1
1,1,1,1,1,1,1,1,1,1,1,1,1,1,1,1,1,1,1,1,1,1,1,1,1,1,1,1,1,1
1,1,1,1,1,1,1,1,1,1,1,1,1,1,1,1,1,1,1,1,1,1,1,1,1,1,1,1,1,1
1,1,1,1,1,1,1,1,1,1,1,1,1,1,1,1,1,1,1,1,1,1,1,1,1,1,1,1,1,1
1,1,1,1,1,1,1,1,1,1,1,1,1,1,1,1,1,1,1,1,1,1,1,1,1,1,1,1,1,1
endlayer

layer
1,1,1,1,1,1,1,1,1,1,1,0,0,0,0,0,0,0,0,1,1,1,1,1,1,1,1,1,1,1
1,1,1,1,1,1,1,1,1,1,1,0,0,0,0,0,0,0,0,1,1,1,1,1,1,1,1,1,1,1
1,1,1,1,1,1,1,1,1,1,1,0,0,0,0,0,0,0,0,1,1,1,1,1,1,1,1,1,1,1
1,1,1,1,1,1,1,1,1,1,1,0,0,0,0,0,0,0,0,1,1,1,1,1,1,1,1,1,1,1
1,1,1,1,9,1,1,0,0,0,0,0,0,0,0,0,0,0,0,0,0,0,0,1,1,9,1,1,1,1
1,1,1,1,1,1,1,1,1,1,1,0,0,0,0,0,0,0,0,1,1,1,1,1,1,1,1,1,1,1
1,1,1,1,1,1,1,1,1,1,1,1,1,1,1,1,1,1,1,1,1,1,1,1,1,1,1,1,1,1
1,1,1,1,1,1,1,1,1,1,1,1,1,1,1,1,1,1,1,1,1,1,1,1,1,1,1,1,1,1
1,1,1,1,1,1,1,1,1,1,1,1,1,1,1,1,1,1,1,1,1,1,1,1,1,1,1,1,1,1
1,1,1,1,1,1,1,1,1,1,1,1,1,1,1,1,1,1,1,1,9,1,1,1,1,1,1,1,1,1
1,1,1,1,1,1,1,1,1,1,1,1,1,1,1,1,1,1,1,1,1,1,1,1,1,1,1,1,1,1
1,1,1,1,1,1,1,1,1,1,1,1,1,1,1,1,1,1,1,1,1,1,1,1,1,1,1,1,1,1
1,1,1,1,1,1,1,1,1,1,1,1,1,9,9,9,9,1,1,1,1,1,1,1,1,1,1,1,1,1
1,1,1,1,1,1,1,1,1,1,1,1,9,9,9,9,9,9,1,1,1,1,1,1,1,1,1,1,1,1
1,1,1,1,1,1,1,1,1,1,1,1,9,9,0,0,9,9,1,1,1,1,1,1,1,1,1,1,1,1
1,1,1,1,1,1,1,1,1,1,1,1,9,9,0,0,9,9,1,1,1,1,1,1,1,1,1,1,1,1
1,1,1,1,1,1,1,1,1,1,1,1,9,9,9,9,9,9,1,1,1,1,1,1,1,1,1,1,1,1
1,1,1,1,1,1,1,1,1,1,1,1,1,9,9,9,9,1,1,1,1,1,1,1,1,1,1,1,1,1
1,1,1,1,1,1,1,1,1,1,1,1,1,1,1,1,1,1,1,1,1,1,1,1,1,1,1,1,1,1
1,1,1,1,1,1,1,1,1,1,1,1,1,1,1,1,1,1,1,1,1,1,1,1,1,1,1,1,1,1
1,1,1,1,1,1,1,1,1,1,1,1,1,1,1,1,1,1,1,1,1,1,1,1,1,1,1,1,1,1
1,1,1,1,1,1,1,1,1,1,1,1,1,1,1,1,1,1,1,1,1,1,1,1,1,1,1,1,1,1
1,1,1,1,1,1,1,1,1,1,1,1,1,1,1,1,1,1,1,1,1,1,1,1,1,1,1,1,1,1
1,1,1,1,1,1,1,1,1,1,1,1,1,1,1,1,1,1,1,1,1,1,1,1,1,1,1,1,1,1
1,1,1,1,1,1,1,1,1,1,1,1,1,1,1,1,1,1,1,1,1,1,1,1,1,1,1,1,1,1
1,1,1,1,9,1,1,1,1,1,1,1,1,1,1,1,1,1,1,1,1,1,1,1,1,9,1,1,1,1
1,1,1,1,1,1,1,1,1,1,1,1,1,1,1,1,1,1,1,1,1,1,1,1,1,1,1,1,1,1
1,1,1,1,1,1,1,1,1,1,1,1,1,1,1,1,1,1,1,1,1,1,1,1,1,1,1,1,1,1
1,1,1,1,1,1,1,1,1,1,1,1,1,1,1,1,1,1,1,1,1,1,1,1,1,1,1,1,1,1
1,1,1,1,1,1,1,1,1,1,1,1,1,1,1,1,1,1,1,1,1,1,1,1,1,1,1,1,1,1
endlayer

layer
1,1,1,1,1,1,1,1,1,1,1,0,0,0,0,0,0,0,0,1,1,1,1,1,1,1,1,1,1,1
1,1,1,1,1,1,1,1,1,1,1,0,0,0,0,0,0,0,0,1,1,1,1,1,1,1,1,1,1,1
1,1,1,1,1,1,1,1,1,1,1,0,0,0,0,0,0,0,0,1,1,1,1,1,1,1,1,1,1,1
1,1,1,1,1,1,1,1,1,1,1,0,0,0,0,0,0,0,0,1,1,1,1,1,1,1,1,1,1,1
1,1,1,1,9,1,1,0,0,0,0,0,0,0,0,0,0,0,0,0,0,0,0,1,1,9,1,1,1,1
1,1,1,1,1,1,1,1,1,1,1,1,1,1,1,1,1,1,1,1,1,1,1,1,1,1,1,1,1,1
1,1,1,1,1,1,1,1,1,1,1,1,1,1,1,1,1,1,1,1,1,1,1,1,1,1,1,1,1,1
1,1,1,1,1,1,1,1,1,1,1,1,1,1,1,1,1,1,1,1,1,1,1,1,1,1,1,1,1,1
1,1,1,1,1,1,1,1,1,1,1,1,1,1,1,1,1,1,1,1,9,1,1,1,1,1,1,1,1,1
1,1,1,1,1,1,1,1,1,1,1,1,1,1,1,1,1,1,1,9,9,9,1,1,1,1,1,1,1,1
1,1,1,1,1,1,1,1,1,1,1,1,1,1,1,1,1,1,1,1,9,1,1,1,1,1,1,1,1,1
1,1,1,1,1,1,1,1,1,1,1,1,1,1,1,1,1,1,1,1,1,1,1,1,1,1,1,1,1,1
1,1,1,1,1,1,1,1,1,1,1,1,1,9,9,9,9,1,1,1,1,1,1,1,1,1,1,1,1,1
1,1,1,1,1,1,1,1,1,1,1,1,9,9,9,9,9,9,1,1,1,1,1,1,1,1,1,1,1,1
1,1,1,1,1,1,1,1,1,1,1,1,9,9,0,0,9,9,1,1,1,1,1,1,1,1,1,1,1,1
1,1,1,1,1,1,1,1,1,1,1,1,9,9,0,0,9,9,1,1,1,1,1,1,1,1,1,1,1,1
1,1,1,1,1,1,1,1,1,1,1,1,9,9,9,9,9,9,1,1,1,1,1,1,1,1,1,1,1,1
1,1,1,1,1,1,1,1,1,1,1,1,1,9,9,9,9,1,1,1,1,1,1,1,1,1,1,1,1,1
1,1,1,1,1,1,1,1,1,1,1,1,1,1,1,1,1,1,1,1,1,1,1,1,1,1,1,1,1,1
1,1,1,1,1,1,1,1,1,1,1,1,1,1,1,1,1,1,1,1,1,1,1,1,1,1,1,1,1,1
1,1,1,1,1,1,1,1,1,1,1,1,1,1,1,1,1,1,1,1,1,1,1,1,1,1,1,1,1,1
1,1,1,1,1,1,1,1,1,1,1,1,1,1,1,1,1,1,1,1,1,1,1,1,1,1,1,1,1,1
1,1,1,1,1,1,1,1,1,1,1,1,1,1,1,1,1,1,1,1,1,1,1,1,1,1,1,1,1,1
1,1,1,1,1,1,1,1,1,1,1,1,1,1,1,1,1,1,1,1,1,1,1,1,1,1,1,1,1,1
1,1,1,1,1,1,1,1,1,1,1,1,1,1,1,1,1,1,1,1,1,1,1,1,1,1,1,1,1,1
1,1,1,1,9,1,1,1,1,1,1,1,1,1,1,1,1,1,1,1,1,1,1,1,1,9,1,1,1,1
1,1,1,1,1,1,1,1,1,1,1,1,1,1,1,1,1,1,1,1,1,1,1,1,1,1,1,1,1,1
1,1,1,1,1,1,1,1,1,1,1,1,1,1,1,1,1,1,1,1,1,1,1,1,1,1,1,1,1,1
1,1,1,1,1,1,1,1,1,1,1,1,1,1,1,1,1,1,1,1,1,1,1,1,1,1,1,1,1,1
1,1,1,1,1,1,1,1,1,1,1,1,1,1,1,1,1,1,1,1,1,1,1,1,1,1,1,1,1,1
endlayer

layer
1,1,1,1,1,1,1,1,1,1,1,1,1,1,1,1,1,1,1,1,1,1,1,1,1,1,1,1,1,1
1,1,1,1,1,1,1,1,1,1,1,1,1,1,1,1,1,1,1,1,1,1,1,1,1,1,1,1,1,1
1,1,1,1,1,1,1,1,1,1,1,1,1,1,1,1,1,1,1,1,1,1,1,1,1,1,1,1,1,1
1,1,1,1,9,1,1,1,1,1,1,1,1,1,1,1,1,1,1,1,1,1,1,1,1,9,1,1,1,1
1,1,1,9,9,9,1,0,0,0,0,0,0,0,0,0,0,0,0,0,0,0,0,1,9,9,9,1,1,1
1,1,1,1,9,1,1,1,1,1,1,0,0,0,0,0,0,0,0,1,1,1,1,1,1,9,1,1,1,1
1,1,1,1,1,1,1,1,1,1,1,1,1,1,1,1,1,1,1,1,1,1,1,1,1,1,1,1,1,1
1,1,1,1,1,1,1,1,1,1,1,1,1,1,1,1,1,1,1,1,1,1,1,1,1,1,1,1,1,1
1,1,1,1,1,1,1,1,1,1,1,1,1,1,1,1,1,1,1,1,9,1,1,1,1,1,1,1,1,1
1,1,1,1,1,1,1,1,1,1,1,1,1,1,1,1,1,1,1,9,9,9,1,1,1,1,1,1,1,1
1,1,1,1,1,1,1,1,1,1,1,1,1,1,1,1,1,1,1,1,9,1,1,1,1,1,1,1,1,1
1,1,1,1,1,1,1,1,1,1,1,1,9,9,9,9,9,9,1,1,1,1,1,1,1,1,1,1,1,1
1,1,1,1,1,1,1,1,1,1,1,9,9,9,9,9,9,9,9,1,1,1,1,1,1,1,1,1,1,1
1,1,1,1,1,1,1,1,1,1,1,9,9,9,9,9,9,9,9,1,1,1,1,1,1,1,1,1,1,1
1,1,1,1,1,1,1,1,1,1,1,9,9,9,0,0,9,9,9,1,1,1,1,1,1,1,1,1,1,1
1,1,1,1,1,1,1,1,1,1,1,9,9,9,0,0,9,9,9,1,1,1,1,1,1,1,1,1,1,1
1,1,1,1,1,1,1,1,1,1,1,9,9,9,9,9,9,9,9,1,1,1,1,1,1,1,1,1,1,1
1,1,1,1,1,1,1,1,1,1,1,9,9,9,9,9,9,9,9,1,1,1,1,1,1,1,1,1,1,1
1,1,1,1,1,1,1,1,1,1,1,1,9,9,9,9,9,9,1,1,1,1,1,1,1,1,1,1,1,1
1,1,1,1,1,1,1,1,1,1,1,1,1,1,1,1,1,1,1,1,1,1,1,1,1,1,1,1,1,1
1,1,1,1,1,1,1,1,1,1,1,1,1,1,1,1,1,1,1,1,1,1,1,1,1,1,1,1,1,1
1,1,1,1,1,1,1,1,1,1,1,1,1,1,1,1,1,1,1,1,1,1,1,1,1,1,1,1,1,1
1,1,1,1,1,1,1,1,1,1,1,1,1,1,1,1,1,1,1,1,1,1,1,1,1,1,1,1,1,1
1,1,1,1,1,1,1,1,1,1,1,1,1,1,1,1,1,1,1,1,1,1,1,1,1,1,1,1,1,1
1,1,1,1,9,1,1,1,1,1,1,1,1,1,1,1,1,1,1,1,1,1,1,1,1,9,1,1,1,1
1,1,1,9,9,9,1,1,1,1,1,1,1,1,1,1,1,1,1,1,1,1,1,1,9,9,9,1,1,1
1,1,1,1,9,1,1,1,1,1,1,1,1,1,1,1,1,1,1,1,1,1,1,1,1,9,1,1,1,1
1,1,1,1,1,1,1,1,1,1,1,1,1,1,1,1,1,1,1,1,1,1,1,1,1,1,1,1,1,1
1,1,1,1,1,1,1,1,1,1,1,1,1,1,1,1,1,1,1,1,1,1,1,1,1,1,1,1,1,1
1,1,1,1,1,1,1,1,1,1,1,1,1,1,1,1,1,1,1,1,1,1,1,1,1,1,1,1,1,1
endlayer

layer
1,1,1,1,1,1,1,1,1,1,1,0,0,0,0,0,0,0,0,1,1,1,1,1,1,1,1,1,1,1
1,1,1,1,1,1,1,1,1,1,1,0,0,0,0,0,0,0,0,1,1,1,1,1,1,1,1,1,1,1
1,1,1,1,1,1,1,1,1,1,1,0,0,0,0,0,0,0,0,1,1,1,1,1,1,1,1,1,1,1
1,1,1,9,9,9,1,1,1,1,1,0,0,0,0,0,0,0,0,1,1,1,1,1,9,9,9,1,1,1
1,1,1,9,9,9,1,0,0,0,0,0,0,0,0,0,0,0,0,0,0,0,0,1,9,9,9,1,1,1
1,1,1,9,9,9,1,1,1,1,1,0,0,0,0,0,0,0,0,1,1,1,1,1,9,9,9,1,1,1
1,1,1,1,1,1,1,1,1,1,1,1,1,1,1,1,1,1,1,1,1,1,1,1,1,1,1,1,1,1
1,1,1,1,1,1,1,1,1,1,1,1,1,1,1,1,1,1,1,1,1,1,1,1,1,1,1,1,1,1
1,1,1,1,1,1,1,1,1,1,1,1,1,1,1,1,1,1,1,9,9,9,1,1,1,1,1,1,1,1
1,1,1,1,1,1,1,1,1,1,1,1,1,1,1,1,1,1,1,9,9,9,1,1,1,1,1,1,1,1
1,1,1,1,1,1,1,1,1,1,1,1,1,1,1,1,1,1,1,9,9,9,1,1,1,1,1,1,1,1
1,1,1,1,1,1,1,1,1,1,1,1,9,9,9,9,9,9,1,1,1,1,1,1,1,1,1,1,1,1
1,1,1,1,1,1,1,1,1,1,1,9,9,9,9,9,9,9,9,1,1,1,1,1,1,1,1,1,1,1
1,1,1,1,1,1,1,1,1,1,1,9,9,9,9,9,9,9,9,1,1,1,1,1,1,1,1,1,1,1
1,1,1,1,1,1,1,1,1,1,1,9,9,9,0,0,9,9,9,1,1,1,1,1,1,1,1,1,1,1
1,1,1,1,1,1,1,1,1,1,1,9,9,9,0,0,9,9,9,1,1,1,1,1,1,1,1,1,1,1
1,1,1,1,1,1,1,1,1,1,1,9,9,9,9,9,9,9,9,1,1,1,1,1,1,1,1,1,1,1
1,1,1,1,1,1,1,1,1,1,1,9,9,9,9,9,9,9,9,1,1,1,1,1,1,1,1,1,1,1
1,1,1,1,1,1,1,1,1,1,1,1,9,9,9,9,9,9,1,1,1,1,1,1,1,1,1,1,1,1
1,1,1,1,1,1,1,1,1,1,1,1,1,1,1,1,1,1,1,1,1,1,1,1,1,1,1,1,1,1
1,1,1,1,1,1,1,1,1,1,1,1,1,1,1,1,1,1,1,1,1,1,1,1,1,1,1,1,1,1
1,1,1,1,1,1,1,1,1,1,1,1,1,1,1,1,1,1,1,1,1,1,1,1,1,1,1,1,1,1
1,1,1,1,1,1,1,1,1,1,1,1,1,1,1,1,1,1,1,1,1,1,1,1,1,1,1,1,1,1
1,1,1,1,1,1,1,1,1,1,1,1,1,1,1,1,1,1,1,1,1,1,1,1,1,1,1,1,1,1
1,1,1,9,9,9,1,1,1,1,1,1,1,1,1,1,1,1,1,1,1,1,1,1,9,9,9,1,1,1
1,1,1,9,9,9,1,1,1,1,1,1,1,1,1,1,1,1,1,1,1,1,1,1,9,9,9,1,1,1
1,1,1,9,9,9,1,1,1,1,1,1,1,1,1,1,1,1,1,1,1,1,1,1,9,9,9,1,1,1
1,1,1,1,1,1,1,1,1,1,1,1,1,1,1,1,1,1,1,1,1,1,1,1,1,1,1,1,1,1
1,1,1,1,1,1,1,1,1,1,1,1,1,1,1,1,1,1,1,1,1,1,1,1,1,1,1,1,1,1
1,1,1,1,1,1,1,1,1,1,1,1,1,1,1,1,1,1,1,1,1,1,1,1,1,1,1,1,1,1
endlayer

layer
1,1,1,1,1,1,1,1,1,1,1,0,0,0,0,0,0,0,0,1,1,1,1,1,1,1,1,1,1,1
1,1,1,1,1,1,1,1,1,1,1,0,0,0,0,0,0,0,0,1,1,1,1,1,1,1,1,1,1,1
1,1,1,9,9,9,1,1,1,1,1,0,0,0,0,0,0,0,0,1,1,1,1,1,9,9,9,1,1,1
1,1,9,9,9,9,9,1,1,1,1,0,0,0,0,0,0,0,0,1,1,1,1,9,9,9,9,9,1,1
1,1,9,9,9,9,9,0,0,0,0,0,0,0,0,0,0,0,0,0,0,0,0,9,9,9,9,9,1,1
1,1,9,9,9,9,9,1,1,1,1,0,0,0,0,0,0,0,0,1,1,1,1,9,9,9,9,9,1,1
1,1,1,9,9,9,1,1,1,1,1,1,1,1,1,1,1,1,1,1,1,1,1,1,9,9,9,1,1,1
1,1,1,1,1,1,1,1,1,1,1,1,1,1,1,1,1,1,1,9,9,9,1,1,1,1,1,1,1,1
1,1,1,1,1,1,1,1,1,1,1,1,1,1,1,1,1,1,9,9,9,9,9,1,1,1,1,1,1,1
1,1,1,1,1,1,1,1,1,1,1,1,1,1,1,1,1,1,9,9,9,9,9,1,1,1,1,1,1,1
1,1,1,1,1,1,1,1,1,1,1,1,9,9,9,9,9,9,9,9,9,9,9,1,1,1,1,1,1,1
1,1,1,1,1,1,1,1,1,1,1,9,9,9,9,9,9,9,9,9,9,9,1,1,1,1,1,1,1,1
1,1,1,1,1,1,1,1,1,1,9,9,9,9,9,9,9,9,9,9,1,1,1,1,1,1,1,1,1,1
1,1,1,1,1,1,1,1,1,1,9,9,9,9,9,9,9,9,9,9,1,1,1,1,1,1,1,1,1,1
1,1,1,1,1,1,1,1,1,1,9,9,9,9,0,0,9,9,9,9,1,1,1,1,1,1,1,1,1,1
1,1,1,1,1,1,1,1,1,1,9,9,9,9,0,0,9,9,9,9,1,1,1,1,1,1,1,1,1,1
1,1,1,1,1,1,1,1,1,1,9,9,9,9,9,9,9,9,9,9,1,1,1,1,1,1,1,1,1,1
1,1,1,1,1,1,1,1,1,1,9,9,9,9,9,9,9,9,9,9,1,1,1,1,1,1,1,1,1,1
1,1,1,1,1,1,1,1,1,1,1,9,9,9,9,9,9,9,9,1,1,1,1,1,1,1,1,1,1,1
1,1,1,1,1,1,1,1,1,1,1,1,9,9,9,9,9,9,1,1,1,1,1,1,1,1,1,1,1,1
1,1,1,1,1,1,1,1,1,1,1,1,1,1,1,1,1,1,1,1,1,1,1,1,1,1,1,1,1,1
1,1,1,1,1,1,1,1,1,1,1,1,1,1,1,1,1,1,1,1,1,1,1,1,1,1,1,1,1,1
1,1,1,1,1,1,1,1,1,1,1,1,1,1,1,1,1,1,1,1,1,1,1,1,1,1,1,1,1,1
1,1,1,9,9,9,1,1,1,1,1,1,1,1,1,1,1,1,1,1,1,1,1,1,9,9,9,1,1,1
1,1,9,9,9,9,9,1,1,1,1,1,1,1,1,1,1,1,1,1,1,1,1,9,9,9,9,9,1,1
1,1,9,9,9,9,9,1,1,1,1,1,1,1,1,1,1,1,1,1,1,1,1,9,9,9,9,9,1,1
1,1,9,9,9,9,9,1,1,1,1,1,1,1,1,1,1,1,1,1,1,1,1,9,9,9,9,9,1,1
1,1,1,9,9,9,1,1,1,1,1,1,1,1,1,1,1,1,1,1,1,1,1,1,9,9,9,1,1,1
1,1,1,1,1,1,1,1,1,1,1,1,1,1,1,1,1,1,1,1,1,1,1,1,1,1,1,1,1,1
1,1,1,1,1,1,1,1,1,1,1,1,1,1,1,1,1,1,1,1,1,1,1,1,1,1,1,1,1,1
endlayer

layer
1,1,1,1,1,1,1,1,1,1,1,0,0,0,0,0,0,0,0,1,1,1,1,1,1,1,1,1,1,1
1,1,1,1,1,1,1,1,1,1,1,0,0,0,0,0,0,0,0,1,1,1,1,1,1,1,1,1,1,1
1,1,1,9,9,9,1,1,1,1,1,0,0,0,0,0,0,0,0,1,1,1,1,1,9,9,9,1,1,1
1,1,9,9,9,9,9,1,1,1,1,0,0,0,0,0,0,0,0,1,1,1,1,9,9,9,9,9,1,1
1,1,9,9,9,9,9,0,0,0,0,0,0,9,0,0,9,0,0,0,0,0,0,9,9,9,9,9,1,1
1,1,9,9,9,9,9,1,1,1,1,0,0,0,0,0,0,0,0,1,1,1,1,9,9,9,9,9,1,1
1,1,1,9,9,9,1,1,1,1,1,1,1,1,1,1,1,1,1,1,1,1,1,1,9,9,9,1,1,1
1,1,1,1,1,1,1,1,1,1,1,1,1,1,1,1,1,1,1,9,9,9,1,1,1,1,1,1,1,1
1,1,1,1,1,1,1,1,1,1,1,1,1,1,1,1,1,1,9,9,9,9,9,1,1,1,1,1,1,1
1,1,1,1,1,1,1,1,1,1,0,0,9,9,9,9,9,9,9,9,9,9,9,1,1,1,1,1,1,1
1,1,1,1,1,1,1,1,1,1,0,9,9,9,9,9,9,9,0,9,9,9,9,1,1,1,1,1,1,1
1,1,1,1,1,1,1,1,1,1,9,9,9,9,9,9,9,9,9,9,9,9,1,1,1,1,1,1,1,1
1,1,1,1,1,1,1,1,1,1,9,9,9,9,9,9,9,9,9,9,1,1,1,1,1,1,1,1,1,1
1,1,1,1,1,1,1,1,1,1,9,9,9,9,9,9,9,9,9,9,1,1,1,1,1,1,1,1,1,1
1,1,1,1,1,1,1,1,1,1,9,9,9,9,0,0,9,9,9,9,1,1,1,1,1,1,1,1,1,1
1,1,1,1,1,1,1,1,1,1,9,9,9,9,0,0,9,9,9,9,1,1,1,1,1,1,1,1,1,1
1,1,1,1,1,1,1,1,1,1,9,9,9,9,9,9,9,9,9,9,1,1,1,1,1,1,1,1,1,1
1,1,1,1,1,1,1,1,1,1,9,9,9,9,9,9,9,9,9,9,1,1,1,1,1,1,1,1,1,1
1,1,1,1,1,1,1,1,1,1,1,9,9,9,9,9,9,9,9,1,1,1,1,1,1,1,1,1,1,1
1,1,1,1,1,1,1,1,1,1,1,1,9,9,9,9,9,9,1,1,1,1,1,1,1,1,1,1,1,1
1,1,1,1,1,1,1,1,1,1,1,1,1,1,1,1,1,1,1,1,1,1,1,1,1,1,1,1,1,1
1,1,1,1,1,1,1,1,1,1,1,1,1,1,1,1,1,1,1,1,1,1,1,1,1,1,1,1,1,1
1,1,1,1,1,1,1,1,1,1,1,1,1,1,1,1,1,1,1,1,1,1,1,1,1,1,1,1,1,1
1,1,1,9,9,9,1,1,1,1,1,1,1,1,1,1,1,1,1,1,1,1,1,1,9,9,9,1,1,1
1,1,9,9,9,9,9,1,1,1,1,1,1,1,1,1,1,1,1,1,1,1,1,9,9,9,9,9,1,1
1,1,9,9,9,9,9,1,1,1,1,1,1,1,1,1,1,1,1,1,1,1,1,9,9,9,9,9,1,1
1,1,9,9,9,9,9,1,1,1,1,1,1,1,1,1,1,1,1,1,1,1,1,9,9,9,9,9,1,1
1,1,1,9,9,9,1,1,1,1,1,1,1,1,1,1,1,1,1,1,1,1,1,1,9,9,9,1,1,1
1,1,1,1,1,1,1,1,1,1,1,1,1,1,1,1,1,1,1,1,1,1,1,1,1,1,1,1,1,1
1,1,1,1,1,1,1,1,1,1,1,1,1,1,1,1,1,1,1,1,1,1,1,1,1,1,1,1,1,1
endlayer

layer
1,1,1,1,1,1,1,1,1,1,1,0,0,0,0,0,0,0,0,1,1,1,1,1,1,1,1,1,1,1
1,1,1,9,9,9,1,1,1,1,1,0,0,0,0,0,0,0,0,1,1,1,1,1,9,9,9,1,1,1
1,1,9,9,9,9,9,1,1,1,1,0,0,0,0,0,0,0,0,1,1,1,1,9,9,9,9,9,1,1
1,9,9,9,9,9,9,9,1,1,1,0,0,0,0,0,0,0,0,1,1,1,9,9,9,9,9,9,9,1
1,9,9,9,9,9,9,9,0,0,0,0,0,9,0,0,9,0,0,0,0,0,9,9,9,9,9,9,9,1
1,9,9,9,9,9,9,9,0,0,0,0,0,0,0,0,0,0,0,0,0,0,9,9,9,9,9,9,9,1
1,1,9,9,9,9,9,1,1,1,1,1,1,1,1,1,1,1,1,1,1,1,1,9,9,9,9,9,1,1
1,1,1,9,9,9,1,1,1,1,1,1,1,1,1,1,1,1,1,9,9,9,1,1,9,9,9,1,1,1
1,1,1,1,1,1,1,1,1,1,1,1,1,1,1,1,1,1,9,4,4,4,9,1,1,1,1,1,1,1
1,1,1,1,1,1,1,1,1,1,1,9,9,9,9,9,9,9,4,4,4,4,9,1,1,1,1,1,1,1
1,1,1,1,1,1,1,1,1,1,9,0,0,0,9,9,0,0,0,0,4,4,9,1,1,1,1,1,1,1
1,1,1,1,1,1,1,1,1,9,0,0,0,0,0,0,0,0,0,0,9,9,1,1,1,1,1,1,1,1
1,1,1,1,1,1,1,1,1,9,0,0,0,0,0,0,0,0,0,0,9,1,1,1,1,1,1,1,1,1
1,1,1,1,1,1,1,1,1,9,0,0,0,0,0,0,0,0,0,0,9,1,1,1,1,1,1,1,1,1
1,1,1,1,1,1,1,1,1,9,0,0,0,0,0,0,0,0,0,0,9,1,1,1,1,1,1,1,1,1
1,1,1,1,1,1,1,1,1,9,0,0,0,0,0,0,0,0,0,0,9,1,1,1,1,1,1,1,1,1
1,1,1,1,1,1,1,1,1,9,9,9,9,9,9,9,9,9,9,9,9,1,1,1,1,1,1,1,1,1
1,1,1,1,1,1,1,1,1,9,9,9,9,9,9,9,9,9,9,9,9,1,1,1,1,1,1,1,1,1
1,1,1,1,1,1,1,1,1,1,9,9,9,9,9,9,9,9,9,9,1,1,1,1,1,1,1,1,1,1
1,1,1,1,1,1,1,1,1,1,1,9,9,9,9,9,9,9,9,1,1,1,1,1,1,1,1,1,1,1
1,1,1,1,1,1,1,1,1,1,1,1,9,9,9,9,9,9,1,1,1,1,1,1,1,1,1,1,1,1
1,1,1,1,1,1,1,1,1,1,1,1,1,1,1,1,1,1,1,1,1,1,1,1,1,1,1,1,1,1
1,1,1,9,9,9,1,1,1,1,1,1,1,1,1,1,1,1,1,1,1,1,1,1,9,9,9,1,1,1
1,1,9,9,9,9,9,1,1,1,1,1,1,1,1,1,1,1,1,1,1,1,1,9,9,9,9,9,1,1
1,9,9,9,9,9,9,9,1,1,1,1,1,1,1,1,1,1,1,1,1,1,9,9,9,9,9,9,9,1
1,9,9,9,9,9,9,9,1,1,1,1,1,1,1,1,1,1,1,1,1,1,9,9,9,9,9,9,9,1
1,9,9,9,9,9,9,9,1,1,1,1,1,1,1,1,1,1,1,1,1,1,9,9,9,9,9,9,9,1
1,1,9,9,9,9,9,1,1,1,1,1,1,1,1,1,1,1,1,1,1,1,1,9,9,9,9,9,1,1
1,1,1,9,9,9,1,1,1,1,1,1,1,1,1,1,1,1,1,1,1,1,1,1,9,9,9,1,1,1
1,1,1,1,1,1,1,1,1,1,1,1,1,1,1,1,1,1,1,1,1,1,1,1,1,1,1,1,1,1
endlayer

layer
1,1,1,1,1,1,1,1,1,1,1,0,0,0,0,0,0,0,0,1,1,1,1,1,1,1,1,1,1,1
1,1,9,9,9,9,9,1,1,1,1,0,0,0,0,0,0,0,0,1,1,1,1,9,9,9,9,9,1,1
1,9,9,9,9,9,9,9,1,1,1,0,0,0,0,0,0,0,0,1,1,1,9,9,9,9,9,9,9,1
1,9,9,9,9,9,9,9,1,1,1,0,0,9,9,9,9,0,0,1,1,1,9,9,9,9,9,9,9,1
1,9,9,9,9,9,9,9,0,0,0,0,9,0,9,9,0,9,0,0,0,0,9,9,9,9,9,9,9,1
1,9,9,9,9,9,9,9,0,0,0,0,0,9,9,9,9,0,0,0,0,0,9,9,9,9,9,9,9,1
1,9,9,9,9,9,9,9,1,1,1,1,1,1,1,1,1,1,1,9,9,9,9,9,9,9,9,9,9,1
1,1,9,9,9,9,9,1,1,1,1,1,1,1,1,1,1,1,9,12,12,12,9,9,9,9,9,9,1,1
1,1,1,1,1,1,1,1,1,1,1,9,9,9,9,9,9,9,12,15,18,17,24,9,1,1,1,1,1,1
1,1,1,1,1,1,1,1,1,1,9,0,0,0,9,9,0,0,0,0,0,18,12,9,1,1,1,1,1,1
1,1,1,1,1,1,1,1,1,9,0,0,0,0,0,0,0,0,0,0,0,16,12,9,1,1,1,1,1,1
1,1,1,1,1,1,1,1,9,9,0,0,0,0,0,0,0,0,0,0,12,12,9,1,1,1,1,1,1,1
1,1,1,1,1,1,1,1,9,9,0,0,0,0,0,0,0,0,0,0,9,9,1,1,1,1,1,1,1,1
1,1,1,1,1,1,1,1,9,9,0,0,0,0,0,0,0,0,0,0,9,9,1,1,1,1,1,1,1,1
1,1,1,1,1,1,1,1,9,9,0,0,0,0,0,0,0,0,0,0,9,9,1,1,1,1,1,1,1,1
1,1,1,1,1,1,1,1,9,9,0,0,0,0,0,0,0,0,0,0,9,9,1,1,1,1,1,1,1,1
1,1,1,1,1,1,1,1,9,9,9,9,9,9,9,9,9,9,9,9,9,9,1,1,1,1,1,1,1,1
1,1,1,1,1,1,1,1,9,9,9,9,9,9,9,9,9,9,9,9,9,9,1,1,1,1,1,1,1,1
1,1,1,1,1,1,1,1,1,9,9,9,9,9,9,9,9,9,9,9,9,1,1,1,1,1,1,1,1,1
1,1,1,1,1,1,1,1,1,1,9,9,9,9,9,9,9,9,9,9,1,1,1,1,1,1,1,1,1,1
1,1,1,1,1,1,1,1,1,1,1,9,9,9,9,9,9,9,9,1,1,1,1,1,1,1,1,1,1,1
1,1,1,1,1,1,1,1,1,1,1,1,9,9,9,9,9,9,1,1,1,1,1,1,1,1,1,1,1,1
1,1,9,9,9,9,9,1,1,1,1,1,1,1,1,1,1,1,1,1,1,1,1,9,9,9,9,9,1,1
1,9,9,9,9,9,9,9,1,1,1,1,1,1,1,1,1,1,1,1,1,1,9,9,9,9,9,9,9,1
1,9,9,9,9,9,9,9,1,1,1,1,1,1,1,1,1,1,1,1,1,1,9,9,9,9,9,9,9,1
1,9,9,9,9,9,9,9,1,1,1,1,1,1,1,1,1,1,1,1,1,1,9,9,9,9,9,9,9,1
1,9,9,9,9,9,9,9,1,1,1,1,1,1,1,1,1,1,1,1,1,1,9,9,9,9,9,9,9,1
1,9,9,9,9,9,9,9,1,1,1,1,1,1,1,1,1,1,1,1,1,1,9,9,9,9,9,9,9,1
1,1,9,9,9,9,9,1,1,1,1,1,1,1,1,1,1,1,1,1,1,1,1,9,9,9,9,9,1,1
1,1,1,1,1,1,1,1,1,1,1,1,1,1,1,1,1,1,1,1,1,1,1,1,1,1,1,1,1,1
endlayer

layer
1,1,9,9,9,9,9,1,1,1,1,0,0,0,0,0,0,0,0,1,1,1,1,9,9,9,9,9,1,1
1,9,9,9,9,9,9,9,1,1,1,0,0,0,0,0,0,0,0,1,1,1,9,9,9,9,9,9,9,1
9,9,9,9,9,9,9,9,9,1,1,0,9,9,9,9,9,9,0,1,1,9,9,9,9,9,9,9,9,9
9,9,9,9,9,9,9,9,9,1,1,9,9,9,9,9,9,9,9,1,1,9,9,9,9,9,9,9,9,9
9,9,9,9,9,9,9,9,0,0,0,28,28,0,0,0,0,28,28,0,0,0,9,9,9,9,9,9,9,9
9,9,9,9,9,9,9,9,9,9,9,9,9,8,9,9,8,9,9,9,9,9,9,9,9,9,9,9,9,9
9,9,9,9,9,9,9,9,9,9,9,9,9,9,9,9,9,9,9,9,9,9,9,9,9,9,9,9,9,9
1,9,9,9,9,9,9,9,9,9,9,9,9,9,9,9,9,9,9,12,12,12,9,9,9,9,9,9,9,1
1,1,9,9,9,9,9,9,9,9,9,9,9,9,9,9,9,9,12,0,0,0,12,9,9,9,9,9,1,1
1,1,1,1,1,9,9,9,9,9,9,0,0,0,9,9,0,0,0,0,0,0,12,9,1,1,1,1,1,1
1,1,1,1,1,1,9,9,9,9,0,0,0,0,0,0,0,0,0,0,0,0,12,9,1,1,1,1,1,1
1,1,1,1,1,1,9,9,9,9,0,0,0,0,0,0,0,0,0,0,12,12,9,9,1,1,1,1,1,1
1,1,1,1,1,1,9,9,9,9,0,0,0,0,0,0,0,0,0,0,9,9,9,9,1,1,1,1,1,1
1,1,1,1,1,1,9,9,9,9,0,0,0,0,0,0,0,0,0,0,9,9,9,9,1,1,1,1,1,1
1,1,1,1,1,1,9,9,9,9,0,0,0,0,0,0,0,0,0,0,9,9,9,9,1,1,1,1,1,1
1,1,1,1,1,1,9,9,9,9,0,0,0,0,0,0,0,0,0,0,9,9,9,9,1,1,1,1,1,1
1,1,1,1,1,1,9,9,9,9,9,9,9,9,9,9,9,9,9,9,9,9,9,9,1,1,1,1,1,1
1,1,1,1,1,1,9,9,9,9,9,9,9,9,9,9,9,9,9,9,9,9,9,9,1,1,1,1,1,1
1,1,1,1,1,1,1,9,9,9,9,9,9,9,9,9,9,9,9,9,9,9,9,1,1,1,1,1,1,1
1,1,1,1,1,1,1,9,9,9,9,9,9,9,9,9,9,9,9,9,9,9,9,1,1,1,1,1,1,1
1,1,1,1,1,1,1,1,9,9,9,9,9,9,9,9,9,9,9,9,9,9,1,1,1,1,1,1,1,1
1,1,9,9,9,9,9,1,1,9,9,9,9,9,9,9,9,9,9,9,9,1,1,9,9,9,9,9,1,1
1,9,9,9,9,9,9,9,1,1,9,9,9,9,9,9,9,9,9,9,1,1,9,9,9,9,9,9,9,1
9,9,9,9,9,9,9,9,9,1,1,1,9,9,9,9,9,9,1,1,1,9,9,9,9,9,9,9,9,9
9,9,9,9,9,9,9,9,9,1,1,1,1,1,1,1,1,1,1,1,1,9,9,9,9,9,9,9,9,9
9,9,9,9,9,9,9,9,9,1,1,1,1,1,1,1,1,1,1,1,1,9,9,9,9,9,9,9,9,9
9,9,9,9,9,9,9,9,9,1,1,1,1,1,1,1,1,1,1,1,1,9,9,9,9,9,9,9,9,9
9,9,9,9,9,9,9,9,9,1,1,1,1,1,1,1,1,1,1,1,1,9,9,9,9,9,9,9,9,9
1,9,9,9,9,9,9,9,1,1,1,1,1,1,1,1,1,1,1,1,1,1,9,9,9,9,9,9,9,1
1,1,9,9,9,9,9,1,1,1,1,1,1,1,1,1,1,1,1,1,1,1,1,9,9,9,9,9,1,1
endlayer

layer
1,1,9,9,9,9,9,9,1,1,1,0,0,0,0,0,0,0,0,1,1,1,9,9,9,9,9,9,1,1
1,9,9,9,9,9,9,9,9,1,1,0,0,0,0,0,0,0,0,1,1,9,9,9,9,9,9,9,9,1
9,9,9,9,9,9,9,9,9,9,1,0,0,0,0,0,0,0,0,1,9,9,9,9,9,9,9,9,9,9
9,9,9,9,9,9,9,9,9,9,9,9,9,9,9,9,9,9,9,9,9,9,9,9,9,9,9,9,9,9
9,9,9,9,9,9,9,9,0,0,23,13,13,0,0,0,0,13,13,24,0,0,9,9,9,9,9,9,9,9
9,9,9,9,9,9,9,9,9,9,9,9,9,9,9,9,9,9,9,9,9,9,9,9,9,9,9,9,9,9
9,9,9,9,9,9,9,9,9,9,9,9,9,9,9,9,9,9,9,9,9,9,9,9,9,9,9,9,9,9
9,9,9,9,9,9,9,9,9,9,9,9,9,9,9,9,9,9,9,12,12,12,9,9,9,9,9,9,9,9
1,9,9,9,9,9,9,9,9,9,9,9,9,9,9,9,9,9,12,0,0,23,12,9,9,9,9,9,9,1
1,1,9,9,9,9,9,9,9,9,9,0,0,0,9,9,0,0,0,0,0,0,12,9,9,9,9,9,1,1
1,1,1,9,9,9,9,9,9,9,0,0,0,0,0,0,0,0,0,0,0,0,12,9,9,9,9,1,1,1
1,1,1,1,9,9,9,9,9,9,0,0,0,0,0,0,0,0,0,0,12,12,9,9,9,9,1,1,1,1
1,1,1,1,1,9,9,9,9,9,0,0,0,0,0,0,0,0,0,0,9,9,9,9,9,1,1,1,1,1
1,1,1,1,1,9,9,9,9,9,0,0,0,0,0,0,0,0,0,0,9,9,9,9,9,1,1,1,1,1
1,1,1,1,1,9,9,9,9,9,0,0,0,0,0,0,0,0,0,0,9,9,9,9,9,1,1,1,1,1
1,1,1,1,1,9,9,9,9,9,0,0,0,0,0,0,0,0,0,0,9,9,9,9,9,1,1,1,1,1
1,1,1,1,1,9,9,9,9,9,9,9,9,9,9,9,9,9,9,9,9,9,9,9,9,1,1,1,1,1
1,1,1,1,1,9,9,9,9,9,9,9,9,9,9,9,9,9,9,9,9,9,9,9,9,1,1,1,1,1
1,1,1,1,9,9,9,9,9,9,9,9,9,9,9,9,9,9,9,9,9,9,9,9,9,9,1,1,1,1
1,1,1,9,9,9,9,9,9,9,9,9,9,9,9,9,9,9,9,9,9,9,9,9,9,9,9,1,1,1
1,1,9,9,9,9,9,9,9,9,9,9,9,9,9,9,9,9,9,9,9,9,9,9,9,9,9,9,1,1
1,9,9,9,9,9,9,9,9,9,9,9,9,9,9,9,9,9,9,9,9,9,9,9,9,9,9,9,9,1
9,9,9,9,9,9,9,9,9,9,9,9,9,9,9,9,9,9,9,9,9,9,9,9,9,9,9,9,9,9
9,9,9,9,9,9,9,9,9,9,9,9,9,9,9,9,9,9,9,9,9,9,9,9,9,9,9,9,9,9
9,9,9,9,9,9,9,9,9,9,9,9,9,9,9,9,9,9,9,9,9,9,9,9,9,9,9,9,9,9
9,9,9,9,9,9,9,9,9,9,9,9,1,1,1,1,1,1,9,9,9,9,9,9,9,9,9,9,9,9
9,9,9,9,9,9,9,9,9,9,9,1,1,1,1,1,1,1,1,9,9,9,9,9,9,9,9,9,9,9
9,9,9,9,9,9,9,9,9,9,1,1,1,1,1,1,1,1,1,1,9,9,9,9,9,9,9,9,9,9
1,9,9,9,9,9,9,9,9,1,1,1,1,1,1,1,1,1,1,1,1,9,9,9,9,9,9,9,9,1
1,1,9,9,9,9,9,9,1,1,1,1,1,1,1,1,1,1,1,1,1,1,1,9,9,9,9,9,1,1
endlayer

layer
1,1,3,3,3,3,3,3,1,1,1,1,1,1,1,1,1,1,1,1,1,1,3,3,3,3,3,3,1,1
1,3,3,3,3,3,3,3,3,1,1,1,1,3,3,3,3,1,1,1,1,3,3,3,3,3,3,3,3,1
3,3,3,3,3,3,3,3,3,3,1,3,3,3,3,3,3,3,3,1,3,3,3,3,3,3,3,3,3,3
3,3,3,3,3,3,3,3,3,3,3,3,3,3,3,3,3,3,3,3,3,3,3,3,3,3,3,3,3,3
3,3,3,3,3,3,3,3,0,23,13,13,0,0,0,0,0,0,13,13,24,0,3,3,3,3,3,3,3,3
3,3,3,3,3,3,3,3,3,3,3,3,3,3,3,3,3,3,3,3,3,3,3,3,3,3,3,3,3,3
3,3,3,3,3,3,3,3,3,3,3,3,3,3,3,3,3,3,3,3,3,3,3,3,3,3,3,3,3,3
3,3,3,3,3,3,3,3,3,3,3,3,3,3,3,3,3,3,3,12,12,12,3,3,3,3,3,3,3,3
1,3,3,3,3,3,3,3,3,3,3,3,3,3,3,3,3,3,12,0,23,12,12,3,3,3,3,3,3,1
1,1,3,3,3,3,3,3,3,3,3,0,0,0,3,3,0,0,0,0,0,21,12,3,3,3,3,3,1,1
1,1,1,3,3,3,3,3,3,3,0,0,0,0,0,0,0,0,0,0,0,0,12,3,3,3,3,1,1,1
1,1,1,3,3,3,3,3,3,3,0,0,0,0,0,0,0,0,0,0,12,12,3,3,3,3,3,1,1,1
1,1,1,3,3,3,3,3,3,3,0,0,0,0,0,0,0,0,0,0,3,3,3,3,3,3,3,1,1,1
1,1,3,3,3,3,3,3,3,3,0,0,0,0,0,0,0,0,0,0,3,3,3,3,3,3,3,3,1,1
1,1,3,3,3,3,3,3,3,3,0,0,0,0,0,0,0,0,0,0,3,3,3,3,3,3,3,3,1,1
1,1,3,3,3,3,3,3,3,3,0,0,0,0,0,0,0,0,0,0,3,3,3,3,3,3,3,3,1,1
1,1,3,3,3,3,3,3,3,3,3,3,3,3,3,3,3,3,3,3,3,3,3,3,3,3,3,3,1,1
1,1,1,3,3,3,3,3,3,3,3,3,3,3,3,3,3,3,3,3,3,3,3,3,3,3,3,1,1,1
1,1,1,3,3,3,3,3,3,3,3,3,3,3,3,3,3,3,3,3,3,3,3,3,3,3,3,1,1,1
1,1,1,3,3,3,3,3,3,3,3,3,3,3,3,3,3,3,3,3,3,3,3,3,3,3,3,1,1,1
1,1,3,3,3,3,3,3,3,3,3,3,3,3,3,3,3,3,3,3,3,3,3,3,3,3,3,3,1,1
1,3,3,3,3,3,3,3,3,3,3,3,3,3,3,3,3,3,3,3,3,3,3,3,3,3,3,3,3,1
3,3,3,3,3,3,3,3,3,3,3,3,3,3,3,3,3,3,3,3,3,3,3,3,3,3,3,3,3,3
3,3,3,3,3,3,3,3,3,3,3,3,3,3,3,3,3,3,3,3,3,3,3,3,3,3,3,3,3,3
3,3,3,3,3,3,3,3,3,3,3,3,3,3,3,3,3,3,3,3,3,3,3,3,3,3,3,3,3,3
3,3,3,3,3,3,3,3,3,3,3,3,3,3,3,3,3,3,3,3,3,3,3,3,3,3,3,3,3,3
3,3,3,3,3,3,3,3,3,3,3,3,3,3,3,3,3,3,3,3,3,3,3,3,3,3,3,3,3,3
3,3,3,3,3,3,3,3,3,3,1,1,1,3,3,3,3,1,1,1,3,3,3,3,3,3,3,3,3,3
1,3,3,3,3,3,3,3,3,1,1,1,1,1,1,1,1,1,1,1,1,3,3,3,3,3,3,3,3,1
1,1,3,3,3,3,3,3,1,1,1,1,1,1,1,1,1,1,1,1,1,1,3,3,3,3,3,3,1,1
endlayer

layer
1,1,3,3,3,3,3,3,1,1,1,1,1,1,1,1,1,1,1,1,1,1,3,3,3,3,3,3,1,1
1,3,3,3,3,3,3,3,3,1,1,1,1,3,3,3,3,1,1,1,1,3,3,3,3,3,3,3,3,1
3,3,3,3,3,3,3,3,3,3,3,3,3,3,3,3,3,3,3,3,3,3,3,3,3,3,3,3,3,3
3,3,3,3,3,3,3,3,3,3,3,3,3,3,3,3,3,3,3,3,3,3,3,3,3,3,3,3,3,3
3,3,3,3,3,3,3,3,23,13,13,13,0,0,0,0,0,0,13,13,13,24,3,3,3,3,3,3,3,3
3,3,3,3,3,3,3,3,3,3,3,3,3,3,3,3,3,3,3,3,3,3,3,3,3,3,3,3,3,3
3,3,3,3,3,3,3,3,3,3,3,3,3,3,3,3,3,3,3,3,3,3,3,3,3,3,3,3,3,3
3,3,3,3,3,3,3,3,3,3,3,3,3,3,3,3,3,3,3,12,12,12,3,3,3,3,3,3,3,3
1,3,3,3,3,3,3,3,3,3,3,3,3,3,3,3,3,3,12,23,12,12,12,3,3,3,3,3,3,1
1,1,3,3,3,3,3,3,3,3,3,28,28,28,3,3,28,28,28,28,23,12,12,3,3,3,3,3,1,1
1,1,3,3,3,3,3,3,3,3,28,28,28,28,28,28,28,28,28,28,0,21,12,3,3,3,3,3,1,1
1,1,3,3,3,3,3,3,3,3,28,28,28,28,28,28,28,28,28,28,12,12,3,3,3,3,3,3,1,1
1,3,3,3,3,3,3,3,3,3,28,28,28,28,28,28,28,28,28,28,3,3,3,3,3,3,3,3,1,1
1,3,3,3,3,3,3,3,3,3,28,28,28,28,28,28,28,28,28,28,3,3,3,3,3,3,3,3,3,1
1,3,3,3,3,3,3,3,3,3,28,28,28,28,28,28,28,28,28,28,3,3,3,3,3,3,3,3,3,1
1,3,3,3,3,3,3,3,3,3,28,28,28,28,28,28,28,28,28,28,3,3,3,3,3,3,3,3,3,1
1,3,3,3,3,3,3,3,3,3,3,3,3,3,3,3,3,3,3,3,3,3,3,3,3,3,3,3,3,1
1,1,3,3,3,3,3,3,3,3,3,3,3,3,3,3,3,3,3,3,3,3,3,3,3,3,3,3,1,1
1,1,3,3,3,3,3,3,3,3,3,3,3,3,3,3,3,3,3,3,3,3,3,3,3,3,3,3,1,1
1,1,3,3,3,3,3,3,3,3,3,3,3,3,3,3,3,3,3,3,3,3,3,3,3,3,3,3,1,1
1,1,3,3,3,3,3,3,3,3,3,3,3,3,3,3,3,3,3,3,3,3,3,3,3,3,3,3,1,1
1,3,3,3,3,3,3,3,3,3,3,3,3,3,3,3,3,3,3,3,3,3,3,3,3,3,3,3,3,1
3,3,3,3,3,3,3,3,3,3,3,3,3,3,3,3,3,3,3,3,3,3,3,3,3,3,3,3,3,3
3,3,3,3,3,3,3,3,3,3,3,3,3,3,3,3,3,3,3,3,3,3,3,3,3,3,3,3,3,3
3,3,3,3,3,3,3,3,3,3,3,3,3,3,3,3,3,3,3,3,3,3,3,3,3,3,3,3,3,3
3,3,3,3,3,3,3,3,3,3,3,3,3,3,3,3,3,3,3,3,3,3,3,3,3,3,3,3,3,3
3,3,3,3,3,3,3,3,3,3,3,3,3,3,3,3,3,3,3,3,3,3,3,3,3,3,3,3,3,3
3,3,3,3,3,3,3,3,3,3,3,3,3,3,3,3,3,3,3,3,3,3,3,3,3,3,3,3,3,3
1,3,3,3,3,3,3,3,3,1,1,1,1,3,3,3,3,1,1,1,1,3,3,3,3,3,3,3,3,1
1,1,3,3,3,3,3,3,1,1,1,1,1,1,1,1,1,1,1,1,1,1,3,3,3,3,3,3,1,1
endlayer

layer
1,1,2,2,2,2,2,2,1,1,1,1,2,2,2,2,2,2,1,1,1,1,2,2,2,2,2,2,1,1
1,2,2,4,4,4,2,2,2,1,1,2,2,2,2,2,2,2,2,1,1,2,2,2,4,4,4,2,2,1
2,2,4,4,4,4,4,2,2,2,2,2,2,2,2,2,2,2,2,2,2,2,2,4,4,4,4,4,2,2
2,4,4,4,4,4,4,4,4,4,4,4,4,4,4,4,4,4,4,4,4,4,4,4,4,4,4,4,4,2
2,4,4,4,4,4,4,4,13,13,13,13,0,0,0,0,0,0,13,13,13,13,4,4,4,4,4,4,4,2
2,4,4,4,4,4,4,4,4,4,4,4,4,4,4,4,4,4,4,4,4,4,4,4,4,4,4,4,4,2
2,2,4,4,4,4,4,2,2,2,2,2,2,2,2,2,2,2,2,2,2,2,2,4,4,4,4,4,2,2
2,2,2,4,4,4,2,2,2,2,2,2,2,2,2,2,2,2,2,4,4,4,2,2,4,4,4,2,2,2
1,2,2,4,4,4,2,2,4,4,4,4,4,4,4,4,4,4,4,12,8,8,4,2,4,4,4,2,2,1
1,1,2,4,4,4,2,2,4,4,4,13,12,0,4,4,0,13,12,4,12,8,4,2,4,4,4,2,1,1
1,1,2,4,4,4,2,2,4,4,13,12,13,12,0,0,13,12,13,12,4,12,4,2,4,4,4,2,1,1
1,2,2,4,4,4,2,2,4,4,12,13,12,13,12,13,12,13,12,13,4,4,2,2,4,4,4,2,2,1
2,2,2,4,4,4,2,2,4,4,13,12,13,12,13,12,13,12,13,12,4,2,2,2,4,4,4,2,2,2
2,2,2,4,4,4,2,2,4,4,12,13,12,13,12,13,12,13,12,13,4,2,2,2,4,4,4,2,2,2
2,2,2,4,4,4,2,2,4,4,13,12,13,12,13,12,13,12,13,12,4,2,2,2,4,4,4,2,2,2
2,2,2,4,4,4,4,4,4,4,12,13,12,13,12,13,12,13,12,13,4,4,4,4,4,4,4,2,2,2
2,2,2,4,4,4,2,2,2,4,4,4,4,4,4,4,4,4,4,4,4,2,2,2,4,4,4,2,2,2
2,2,2,4,4,4,11,11,11,11,11,11,11,2,4,4,2,11,11,11,11,11,11,11,4,4,4,2,2,2
1,2,2,4,4,4,11,11,11,11,11,11,11,2,4,4,2,11,11,11,11,11,11,11,4,4,4,2,2,1
1,1,2,4,4,4,11,11,11,11,11,11,11,2,4,4,2,11,11,11,11,11,11,11,4,4,4,2,1,1
1,1,2,4,4,4,11,11,11,8,11,11,11,2,4,4,2,11,11,11,8,11,11,11,4,4,4,2,1,1
1,2,2,4,4,4,11,11,11,11,11,11,11,2,4,4,2,11,11,11,11,11,11,11,4,4,4,2,2,1
2,2,2,4,4,4,11,11,11,11,11,11,11,2,4,4,2,11,11,11,11,11,11,11,4,4,4,2,2,2
2,2,4,4,4,4,4,11,11,11,11,11,11,2,4,4,2,11,11,11,11,11,11,4,4,4,4,4,2,2
2,4,4,4,4,4,4,4,4,4,4,4,4,4,4,4,4,4,4,4,4,4,4,4,4,4,4,4,4,2
2,4,4,4,4,4,4,4,4,4,4,4,4,4,4,4,4,4,4,4,4,4,4,4,4,4,4,4,4,2
2,4,4,4,4,4,4,4,4,4,4,4,4,4,4,4,4,4,4,4,4,4,4,4,4,4,4,4,4,2
2,2,4,4,4,4,4,2,2,2,2,2,2,2,4,4,2,2,2,2,2,2,2,4,4,4,4,4,2,2
1,2,2,4,4,4,2,2,2,2,2,2,2,2,4,4,2,2,2,2,2,2,2,2,4,4,4,2,2,1
1,1,2,2,2,2,2,2,1,1,1,1,2,2,8,8,2,2,1,1,1,1,2,2,2,2,2,2,1,1
endlayer

layer
1,1,1,1,1,1,1,1,1,1,1,1,1,1,1,1,1,1,1,1,1,1,1,1,1,1,1,1,1,1
1,1,1,4,4,4,1,1,1,1,1,1,1,1,1,1,1,1,1,1,1,1,1,1,4,4,4,1,1,1
1,1,4,0,0,0,4,1,1,1,1,1,1,1,1,1,1,1,1,1,1,1,1,4,0,0,0,4,1,1
1,4,0,0,0,0,0,4,4,4,4,4,4,4,4,4,4,4,4,4,4,4,4,0,0,0,0,0,4,1
1,4,0,0,0,0,0,0,0,0,0,0,14,0,0,0,0,14,0,0,0,0,0,0,0,0,0,0,4,1
1,4,0,0,0,0,0,4,4,4,4,4,4,4,4,4,4,4,4,4,4,4,4,0,0,0,0,0,4,1
1,1,4,0,0,0,4,0,0,1,1,1,1,1,1,1,1,1,1,27,27,27,27,4,0,0,0,4,1,1
1,1,1,4,0,4,27,27,0,1,1,1,1,1,1,1,1,1,1,12,12,12,27,27,4,0,4,1,1,1
1,1,1,4,0,4,27,27,0,19,19,19,19,19,19,19,19,19,19,12,8,8,12,27,4,0,4,1,1,1
1,1,1,4,0,4,27,27,0,19,19,0,0,14,8,8,14,0,0,19,12,8,12,27,4,0,4,1,1,1
1,1,1,4,0,4,27,27,0,19,0,0,0,14,14,14,14,0,0,0,19,12,12,27,4,0,4,1,1,1
1,1,1,4,0,4,27,27,0,19,0,0,0,0,0,0,0,0,0,0,19,12,1,1,4,0,4,1,1,1
1,1,1,4,0,4,27,27,0,19,0,0,0,0,0,0,0,0,0,0,19,1,1,1,4,0,4,1,1,1
1,1,1,4,0,4,27,27,0,19,0,0,0,0,0,0,0,0,0,0,19,1,1,1,4,0,4,1,1,1
1,1,1,4,0,4,27,27,0,19,29,0,0,0,0,0,0,0,0,0,19,1,1,1,4,0,4,1,1,1
1,1,1,4,0,0,0,0,0,0,0,0,0,0,0,0,0,0,0,0,0,0,0,0,0,0,4,1,1,1
1,1,1,4,0,4,26,26,0,19,19,19,19,4,0,0,4,19,19,19,19,0,26,26,4,0,4,1,1,1
1,1,1,4,0,4,7,7,7,7,7,7,7,26,0,0,26,7,7,7,7,7,7,7,4,0,4,1,1,1
1,1,1,4,0,4,7,7,7,7,7,7,7,26,0,0,26,7,7,7,7,7,7,7,4,0,4,1,1,1
1,1,1,4,0,4,7,7,7,7,7,7,7,26,0,0,26,7,7,7,7,7,7,7,4,0,4,1,1,1
1,1,1,4,0,4,7,7,7,25,7,7,7,26,0,0,26,7,7,7,25,7,7,7,4,0,4,1,1,1
1,1,1,4,0,4,7,7,7,7,7,7,7,26,0,0,26,7,7,7,7,7,7,7,4,0,4,1,1,1
1,1,1,4,0,4,7,7,7,7,7,7,7,26,0,0,26,7,7,7,7,7,7,7,4,0,4,1,1,1
1,1,4,0,0,0,4,7,7,7,7,7,7,26,0,0,26,7,7,7,7,7,7,4,0,0,0,4,1,1
1,4,0,0,0,0,0,4,4,4,4,4,4,4,0,0,4,4,4,4,4,4,4,0,0,0,0,0,4,1
1,4,0,0,0,0,0,0,0,0,0,0,23,4,0,0,4,24,0,0,0,0,0,0,0,0,0,0,4,1
1,4,0,0,0,0,0,4,4,4,4,4,4,4,0,0,4,4,4,4,4,4,4,0,0,0,0,0,4,1
1,1,4,0,0,0,4,1,1,1,1,1,26,4,0,0,4,26,1,1,1,1,1,4,0,0,0,4,1,1
1,1,1,4,4,4,1,1,1,1,1,1,1,1,0,0,1,1,1,1,1,1,1,1,4,4,4,1,1,1
1,1,1,1,1,1,1,1,1,1,1,1,1,1,0,0,1,1,1,1,1,1,1,1,1,1,1,1,1,1
endlayer

layer
1,1,1,1,1,1,1,1,1,1,1,1,1,1,1,1,1,1,1,1,1,1,1,1,1,1,1,1,1,1
1,1,1,4,4,4,1,1,1,1,1,1,1,1,1,1,1,1,1,1,1,1,1,1,4,4,4,1,1,1
1,1,4,0,0,0,4,1,1,1,1,1,1,1,1,1,1,1,1,1,1,1,1,4,0,0,0,4,1,1
1,4,0,0,0,0,0,4,4,4,4,4,4,4,4,4,4,4,4,4,4,4,4,0,0,0,0,0,4,1
1,4,0,0,0,0,0,0,0,0,0,0,14,24,0,0,23,14,0,0,0,0,0,0,0,0,0,0,4,1
1,4,0,0,0,0,0,4,4,4,4,4,4,4,4,4,4,4,4,4,4,4,4,0,0,0,0,0,4,1
1,1,4,0,0,0,4,1,1,1,1,1,1,1,1,1,1,1,1,1,1,1,1,4,0,0,0,4,1,1
1,1,1,4,0,4,1,1,1,1,1,1,1,1,1,1,1,1,1,12,12,12,1,1,4,0,4,1,1,1
1,1,1,4,0,4,1,1,1,19,19,19,19,19,19,19,19,19,19,12,8,8,12,1,4,0,4,1,1,1
1,1,1,4,0,4,1,1,1,19,19,0,0,14,14,14,14,0,0,19,12,8,12,1,4,0,4,1,1,1
1,1,1,4,0,4,1,1,1,19,0,0,0,14,25,25,14,0,0,0,19,12,12,1,4,0,4,1,1,1
1,1,1,4,0,4,1,1,1,19,0,0,0,0,0,0,0,0,0,0,19,12,1,1,4,0,4,1,1,1
1,1,1,4,0,4,1,1,1,19,0,0,0,0,0,0,0,0,0,0,19,1,1,1,4,0,4,1,1,1
1,1,1,4,0,4,1,1,1,19,29,0,0,0,0,0,0,0,0,0,19,1,1,1,4,0,4,1,1,1
1,1,1,4,0,4,1,1,1,19,0,0,0,0,0,0,0,0,0,0,19,1,1,1,4,0,4,1,1,1
1,1,1,4,0,0,0,0,0,0,0,0,0,0,0,0,0,0,0,0,0,0,0,0,0,0,4,1,1,1
1,1,1,4,0,4,1,1,1,19,19,19,19,4,0,0,4,19,19,19,19,1,1,1,4,0,4,1,1,1
1,1,1,4,0,4,1,1,1,1,1,1,1,26,0,0,26,1,1,1,1,1,1,1,4,0,4,1,1,1
1,1,1,4,0,4,1,1,1,1,1,1,1,1,0,0,1,1,1,1,1,1,1,1,4,0,4,1,1,1
1,1,1,4,0,4,1,1,1,1,1,1,1,1,0,0,1,1,1,1,1,1,1,1,4,0,4,1,1,1
1,1,1,4,0,4,1,1,1,0,1,1,1,1,0,0,1,1,1,1,0,1,1,1,4,0,4,1,1,1
1,1,1,4,0,4,1,1,1,1,1,1,1,1,0,0,1,1,1,1,1,1,1,1,4,0,4,1,1,1
1,1,1,4,0,4,1,1,1,1,1,1,1,1,0,0,1,1,1,1,1,1,1,1,4,0,4,1,1,1
1,1,4,0,0,0,4,1,1,1,1,1,1,1,0,0,1,1,1,1,1,1,1,4,0,0,0,4,1,1
1,4,0,0,0,0,0,4,4,4,4,4,4,4,0,0,4,4,4,4,4,4,4,0,0,0,0,0,4,1
1,4,0,0,0,0,0,0,0,0,0,0,23,4,0,0,4,24,0,0,0,0,0,0,0,0,0,0,4,1
1,4,0,0,0,0,0,4,4,4,4,4,4,4,0,0,4,4,4,4,4,4,4,0,0,0,0,0,4,1
1,1,4,0,0,0,4,1,1,1,1,1,26,4,0,0,4,26,1,1,1,1,1,4,0,0,0,4,1,1
1,1,1,4,4,4,1,1,1,1,1,1,1,1,0,0,1,1,1,1,1,1,1,1,4,4,4,1,1,1
1,1,1,1,1,1,1,1,1,1,1,1,1,1,0,0,1,1,1,1,1,1,1,1,1,1,1,1,1,1
endlayer

layer
1,1,1,1,1,1,1,1,1,1,1,1,1,1,1,1,1,1,1,1,1,1,1,1,1,1,1,1,1,1
1,1,1,4,4,4,1,1,1,1,1,1,1,1,1,1,1,1,1,1,1,1,1,1,4,4,4,1,1,1
1,1,4,0,0,0,4,1,1,1,1,1,1,1,1,1,1,1,1,1,1,1,1,4,0,0,0,4,1,1
1,4,0,0,0,0,0,4,4,4,4,4,4,4,4,4,4,4,4,4,4,4,4,0,0,0,0,0,4,1
1,4,0,0,16,0,0,0,0,0,0,0,0,13,0,0,13,0,0,0,0,0,0,0,0,16,0,0,4,1
1,4,0,0,0,0,0,4,4,4,4,4,4,4,4,4,4,4,4,4,4,4,4,0,0,0,0,0,4,1
1,1,4,0,0,0,4,1,1,1,1,1,1,1,1,1,1,1,1,1,1,1,1,4,0,0,0,4,1,1
1,1,1,4,0,4,1,1,1,1,1,1,1,1,1,1,1,1,1,12,12,12,1,1,4,0,4,1,1,1
1,1,1,4,0,4,1,1,1,19,19,19,19,19,19,19,19,19,19,12,8,8,12,1,4,0,4,1,1,1
1,1,1,4,0,4,1,1,1,19,19,0,0,25,14,14,25,0,0,19,12,8,12,1,4,0,4,1,1,1
1,1,1,4,0,4,1,1,1,19,0,0,0,25,0,0,25,0,0,0,19,12,12,1,4,0,4,1,1,1
1,1,1,4,0,4,1,1,1,19,0,0,0,0,0,0,0,0,0,0,19,12,1,1,4,0,4,1,1,1
1,1,1,4,0,4,1,1,1,19,29,0,0,0,0,0,0,0,0,0,19,1,1,1,4,0,4,1,1,1
1,1,1,4,0,4,1,1,1,19,0,0,0,0,0,0,0,0,0,0,19,1,1,1,4,0,4,1,1,1
1,1,1,4,0,4,1,1,30,19,0,0,0,0,0,0,0,0,0,0,19,30,1,1,4,0,4,1,1,1
1,1,1,4,0,4,0,0,4,19,0,0,0,0,0,0,0,0,0,0,19,4,0,0,4,0,4,1,1,1
1,1,1,4,0,4,1,1,29,19,19,20,19,4,0,0,4,19,20,19,19,29,1,1,4,0,4,1,1,1
1,1,1,4,0,4,1,1,1,1,1,1,1,26,0,0,26,1,1,1,1,1,1,1,4,0,4,1,1,1
1,1,1,4,0,4,1,1,1,1,1,1,1,1,0,0,1,1,1,1,1,1,1,1,4,0,4,1,1,1
1,1,1,4,0,4,1,1,1,1,1,1,1,1,0,0,1,1,1,1,1,1,1,1,4,0,4,1,1,1
1,1,1,4,0,4,1,1,1,0,1,1,1,1,0,0,1,1,1,1,0,1,1,1,4,0,4,1,1,1
1,1,1,4,0,4,1,1,1,1,1,1,1,1,0,0,1,1,1,1,1,1,1,1,4,0,4,1,1,1
1,1,1,4,0,4,1,1,1,1,1,1,1,1,0,0,1,1,1,1,1,1,1,1,4,0,4,1,1,1
1,1,4,0,0,0,4,1,1,1,1,1,1,1,0,0,1,1,1,1,1,1,1,4,0,0,0,4,1,1
1,4,0,0,0,0,0,4,4,4,4,4,4,4,0,0,4,4,4,4,4,4,4,0,0,0,0,0,4,1
1,4,0,0,15,0,0,0,0,0,0,0,23,4,0,0,4,24,0,0,0,0,0,0,0,15,0,0,4,1
1,4,0,0,0,0,0,4,4,4,4,4,4,4,0,0,4,4,4,4,4,4,4,0,0,0,0,0,4,1
1,1,4,0,0,0,4,1,1,1,1,1,26,4,0,0,4,26,1,1,1,1,1,4,0,0,0,4,1,1
1,1,1,4,4,4,1,1,1,1,1,1,1,1,0,0,1,1,1,1,1,1,1,1,4,4,4,1,1,1
1,1,1,1,1,1,1,1,1,1,1,1,1,1,0,0,1,1,1,1,1,1,1,1,1,1,1,1,1,1
endlayer

layer
1,1,1,1,1,1,1,1,1,1,1,1,1,1,1,1,1,1,1,1,1,1,1,1,1,1,1,1,1,1
1,1,1,4,4,4,1,1,1,1,1,1,1,1,1,1,1,1,1,1,1,1,1,1,4,4,4,1,1,1
1,1,4,4,4,4,4,1,1,1,1,1,1,1,1,1,1,1,1,1,1,1,1,4,4,4,4,4,1,1
1,4,4,4,4,4,4,4,4,4,4,4,4,4,4,4,4,4,4,4,4,4,4,4,4,4,4,4,4,1
1,4,4,4,4,4,4,4,4,4,4,4,4,4,4,4,4,4,4,4,4,4,4,4,4,4,4,4,4,1
1,4,4,4,4,4,4,4,4,4,4,4,4,4,4,4,4,4,4,4,4,4,4,4,4,4,4,4,4,1
1,1,4,4,4,4,4,1,1,1,1,1,1,1,1,1,1,1,1,1,1,1,1,4,4,4,4,4,1,1
1,1,1,4,4,4,1,1,1,1,1,1,1,1,1,1,1,1,1,12,12,12,1,1,4,4,4,1,1,1
1,1,1,4,4,4,1,1,1,19,19,19,19,19,19,19,19,19,19,12,8,8,12,1,4,4,4,1,1,1
1,1,1,4,4,4,1,1,1,19,19,0,0,0,25,25,0,0,0,19,12,8,12,1,4,4,4,1,1,1
1,1,1,4,4,4,1,1,1,19,0,0,0,0,0,0,0,0,0,0,19,12,12,1,4,4,4,1,1,1
1,1,1,4,4,4,1,1,1,19,29,0,0,0,0,0,0,0,0,0,19,12,1,1,4,4,4,1,1,1
1,1,1,4,4,4,1,1,1,19,0,0,0,0,0,0,0,0,0,0,19,1,1,1,4,4,4,1,1,1
1,1,1,4,4,4,1,1,1,19,0,0,0,0,0,0,0,0,0,0,19,1,1,1,4,4,4,1,1,1
1,1,1,4,4,4,1,1,1,19,0,0,0,0,0,0,0,0,0,0,19,1,1,1,4,4,4,1,1,1
1,1,1,4,4,4,0,0,25,19,0,0,0,0,0,0,0,0,0,0,19,25,0,0,4,4,4,1,1,1
1,1,1,4,4,4,1,1,1,19,20,20,20,4,0,0,4,20,20,20,19,1,1,1,4,4,4,1,1,1
1,1,1,4,4,4,1,1,1,1,1,1,1,26,0,0,26,1,1,1,1,1,1,1,4,4,4,1,1,1
1,1,1,4,4,4,1,1,1,1,1,1,1,1,0,0,1,1,1,1,1,1,1,1,4,4,4,1,1,1
1,1,1,4,4,4,1,1,1,1,1,1,1,1,0,0,1,1,1,1,1,1,1,1,4,4,4,1,1,1
1,1,1,4,4,4,1,1,1,0,1,1,1,1,0,0,1,1,1,1,0,1,1,1,4,4,4,1,1,1
1,1,1,4,4,4,1,1,1,1,1,1,1,1,0,0,1,1,1,1,1,1,1,1,4,4,4,1,1,1
1,1,1,4,4,4,1,1,1,1,1,1,1,1,0,0,1,1,1,1,1,1,1,1,4,4,4,1,1,1
1,1,4,4,4,4,4,1,1,1,1,1,1,1,0,0,1,1,1,1,1,1,1,4,4,4,4,4,1,1
1,4,4,4,4,4,4,4,4,4,4,4,4,4,0,0,4,4,4,4,4,4,4,4,4,4,4,4,4,1
1,4,4,4,4,4,4,4,4,4,4,4,23,4,0,0,4,24,4,4,4,4,4,4,4,4,4,4,4,1
1,4,4,4,4,4,4,4,4,4,4,4,4,4,0,0,4,4,4,4,4,4,4,4,4,4,4,4,4,1
1,1,4,4,4,4,4,1,1,1,1,1,26,4,0,0,4,26,1,1,1,1,1,4,4,4,4,4,1,1
1,1,1,4,4,4,1,1,1,1,1,1,1,1,0,0,1,1,1,1,1,1,1,1,4,4,4,1,1,1
1,1,1,1,1,1,1,1,1,1,1,1,1,1,0,0,1,1,1,1,1,1,1,1,1,1,1,1,1,1
endlayer

layer
1,1,1,1,1,1,1,1,1,1,1,1,1,1,1,1,1,1,1,1,1,1,1,1,1,1,1,1,1,1
1,1,1,4,4,4,1,1,1,1,1,1,1,1,1,1,1,1,1,1,1,1,1,1,4,4,4,1,1,1
1,1,4,0,0,0,4,1,1,1,1,1,1,1,0,0,1,1,1,1,1,1,1,4,0,0,0,4,1,1
1,4,0,0,0,0,0,4,4,0,4,0,4,0,4,4,0,4,0,4,0,4,4,0,0,0,0,0,4,1
1,4,0,0,0,0,0,0,0,0,0,0,0,0,0,0,0,0,0,0,0,0,0,0,0,0,0,0,4,1
1,4,0,0,0,0,0,4,1,1,1,1,1,1,0,0,1,1,1,1,1,1,4,0,0,0,0,0,4,1
1,1,4,0,0,0,4,1,1,1,1,1,1,1,1,1,1,1,1,1,1,1,1,4,0,0,0,4,1,1
1,1,1,4,0,4,1,1,1,1,1,1,1,1,1,1,1,1,1,12,12,12,1,1,4,0,4,1,1,1
1,1,1,4,0,1,1,1,1,19,19,19,19,19,19,19,19,19,19,8,8,8,12,1,1,0,4,1,1,1
1,1,1,0,0,1,1,1,1,19,19,0,0,0,0,0,0,0,0,19,8,8,12,1,1,0,0,1,1,1
1,1,1,4,0,1,1,1,1,19,29,0,0,0,0,0,0,0,0,0,19,8,12,1,1,0,4,1,1,1
1,1,1,0,0,1,1,1,1,19,0,0,0,0,0,0,0,0,0,0,19,12,1,1,1,0,0,1,1,1
1,1,1,4,0,1,1,1,1,19,0,0,0,0,0,0,0,0,0,0,19,1,1,1,1,0,4,1,1,1
1,1,1,0,0,1,1,1,1,19,0,0,0,0,0,0,0,0,0,0,19,1,1,1,1,0,0,1,1,1
1,1,1,4,0,1,1,1,1,19,0,0,0,0,0,0,0,0,0,0,19,1,1,1,1,0,4,1,1,1
1,1,1,4,0,0,0,0,0,19,0,0,0,0,0,0,0,0,0,0,19,0,0,0,1,0,4,1,1,1
1,1,1,0,0,1,1,1,1,19,19,20,19,4,4,4,4,19,20,19,19,1,1,1,1,0,0,1,1,1
1,1,1,4,0,1,1,1,1,1,1,1,1,4,4,4,4,1,1,1,1,1,1,1,1,0,4,1,1,1
1,1,1,0,0,1,1,1,1,1,1,1,1,1,0,0,1,1,1,1,1,1,1,1,1,0,0,1,1,1
1,1,1,4,0,1,1,1,1,1,1,1,1,1,0,0,1,1,1,1,1,1,1,1,1,0,4,1,1,1
1,1,1,0,0,1,1,1,1,0,1,1,1,1,0,0,1,1,1,1,0,1,1,1,1,0,0,1,1,1
1,1,1,4,0,1,1,1,1,1,1,1,1,1,0,0,1,1,1,1,1,1,1,1,1,0,4,1,1,1
1,1,1,4,0,4,1,1,1,1,1,1,1,1,0,0,1,1,1,1,1,1,1,1,4,0,4,1,1,1
1,1,4,0,0,0,4,1,1,1,1,1,1,1,1,1,1,1,1,1,1,1,1,4,0,0,0,4,1,1
1,4,0,0,0,0,0,4,1,1,1,1,4,4,4,4,4,4,1,1,1,1,4,0,0,0,0,0,4,1
1,4,0,0,0,0,0,0,0,0,0,0,23,4,4,4,4,24,0,0,0,0,0,0,0,0,0,0,4,1
1,4,0,0,0,0,0,4,0,4,0,4,4,4,4,4,4,4,4,0,4,0,4,0,0,0,0,0,4,1
1,1,4,0,0,0,4,1,1,1,1,1,4,4,4,4,4,4,1,1,1,1,1,4,0,0,0,4,1,1
1,1,1,4,4,4,1,1,1,1,1,1,1,1,0,0,1,1,1,1,1,1,1,1,4,4,4,1,1,1
1,1,1,1,1,1,1,1,1,1,1,1,1,1,0,0,1,1,1,1,1,1,1,1,1,1,1,1,1,1
endlayer

layer
1,1,1,1,1,1,1,1,1,1,1,1,1,1,1,1,1,1,1,1,1,1,1,1,1,1,1,1,1,1
1,1,1,4,20,4,1,1,1,1,1,1,1,1,1,1,1,1,1,1,1,1,1,1,4,20,4,1,1,1
1,1,4,0,0,0,4,1,1,1,1,1,1,1,0,0,1,1,1,1,1,1,1,4,0,0,0,4,1,1
1,4,0,0,0,0,0,4,1,1,1,1,1,1,0,0,1,1,1,1,1,1,4,0,0,0,0,0,4,1
1,20,0,0,0,0,0,0,0,0,0,0,0,0,0,0,0,0,0,0,0,0,0,0,0,0,0,0,20,1
1,4,0,0,0,0,0,4,1,1,1,1,1,1,0,0,1,1,1,1,1,1,4,0,0,0,0,0,4,1
1,1,4,0,0,0,4,1,1,1,1,1,1,1,1,1,1,1,1,1,1,1,1,4,0,0,0,4,1,1
1,1,1,4,0,4,1,1,1,1,1,1,1,1,1,1,1,1,1,12,12,12,1,1,4,0,4,1,1,1
1,1,1,1,0,1,1,1,1,19,19,19,19,19,19,19,19,19,19,19,19,19,12,1,1,0,1,1,1,1
1,1,1,1,0,1,1,1,1,19,29,19,19,19,19,19,19,19,19,19,19,19,12,1,1,0,1,1,1,1
1,1,1,1,0,1,1,1,1,19,0,19,19,19,19,19,19,19,19,19,19,19,12,1,1,0,1,1,1,1
1,1,1,1,0,1,1,1,1,19,0,19,19,19,19,19,19,19,19,19,19,12,1,1,1,0,1,1,1,1
1,1,1,1,0,1,1,1,1,19,0,19,19,19,19,19,19,19,19,19,19,1,1,1,1,0,1,1,1,1
1,1,1,1,0,1,1,1,1,19,0,19,19,19,19,19,19,19,19,19,19,1,1,1,1,0,1,1,1,1
1,1,1,1,0,1,1,1,1,19,0,19,19,19,19,19,19,19,19,19,19,1,1,1,1,0,1,1,1,1
1,1,1,0,0,0,0,0,0,19,0,19,19,19,19,19,19,19,19,19,19,0,0,0,0,0,0,1,1,1
1,1,1,1,0,1,1,1,1,19,19,19,19,19,19,19,19,19,19,19,19,1,1,1,1,0,1,1,1,1
1,1,1,1,0,1,1,1,1,1,1,1,1,1,25,25,1,1,1,1,1,1,1,1,1,0,1,1,1,1
1,1,1,1,0,1,1,1,1,1,1,1,1,1,0,0,1,1,1,1,1,1,1,1,1,0,1,1,1,1
1,1,1,1,0,1,1,1,1,1,1,1,1,1,0,0,1,1,1,1,1,1,1,1,1,0,1,1,1,1
1,1,1,1,0,1,1,1,1,0,1,1,1,1,0,0,1,1,1,1,0,1,1,1,1,0,1,1,1,1
1,1,1,1,0,1,1,1,1,1,1,1,1,1,0,0,1,1,1,1,1,1,1,1,1,0,1,1,1,1
1,1,1,4,0,4,1,1,1,1,1,1,1,1,0,0,1,1,1,1,1,1,1,1,4,0,4,1,1,1
1,1,4,0,0,0,4,1,1,1,1,1,4,20,20,20,20,4,1,1,1,1,1,4,0,0,0,4,1,1
1,4,0,0,0,0,0,4,1,1,1,1,4,0,0,0,0,4,1,1,1,1,4,0,0,0,0,0,4,1
1,20,0,0,0,0,0,0,0,0,0,0,0,0,0,0,0,0,0,0,0,0,0,0,0,0,0,0,20,1
1,4,0,0,0,0,0,4,1,1,1,1,4,0,0,0,0,4,1,1,1,1,4,0,0,0,0,0,4,1
1,1,4,0,0,0,4,1,1,1,1,1,4,0,0,0,0,4,1,1,1,1,1,4,0,0,0,4,1,1
1,1,1,4,20,4,1,1,1,1,1,1,4,20,20,20,20,4,1,1,1,1,1,1,4,20,4,1,1,1
1,1,1,1,1,1,1,1,1,1,1,1,1,1,0,0,1,1,1,1,1,1,1,1,1,1,1,1,1,1
endlayer

layer
1,1,1,1,1,1,1,1,1,1,1,1,1,1,1,1,1,1,1,1,1,1,1,1,1,1,1,1,1,1
1,1,1,4,4,4,1,1,1,1,1,1,1,1,1,1,1,1,1,1,1,1,1,1,4,4,4,1,1,1
1,1,4,0,0,0,4,1,1,1,1,1,1,1,0,0,1,1,1,1,1,1,1,4,0,0,0,4,1,1
1,4,0,0,0,0,0,4,1,1,1,1,1,1,0,0,1,1,1,1,1,1,4,0,0,0,0,0,4,1
1,4,0,0,0,0,0,4,0,0,0,0,0,0,0,0,0,0,0,0,0,0,4,0,0,0,0,0,4,1
1,4,0,0,0,0,0,4,1,1,1,1,1,1,0,0,1,1,1,1,1,1,4,0,0,0,0,0,4,1
1,1,4,0,0,0,4,1,1,1,1,1,1,1,1,1,1,1,1,1,1,1,1,4,0,0,0,4,1,1
1,1,1,4,4,4,1,1,1,1,1,1,1,1,1,1,1,1,1,12,12,12,1,1,4,4,4,1,1,1
1,1,1,1,1,1,1,1,1,19,19,19,19,19,4,4,19,19,19,0,0,23,12,1,1,1,1,1,1,1
1,1,1,1,1,1,1,1,1,19,0,0,0,0,0,0,0,0,0,0,0,0,12,1,1,1,1,1,1,1
1,1,1,1,1,1,1,1,1,19,0,0,0,0,0,0,0,0,0,0,0,0,12,1,1,1,1,1,1,1
1,1,1,1,1,1,1,1,1,19,0,0,0,0,0,0,0,0,0,0,19,12,1,1,1,1,1,1,1,1
1,1,1,1,1,1,1,1,1,19,0,0,0,0,0,0,0,0,0,0,19,1,1,1,1,1,1,1,1,1
1,1,1,1,1,1,1,1,1,19,0,0,0,0,0,0,0,0,0,0,19,1,1,1,1,1,1,1,1,1
1,1,1,1,1,1,1,1,1,19,0,0,0,0,0,0,0,0,0,0,19,1,1,1,1,1,1,1,1,1
1,1,1,0,0,0,0,0,0,19,0,0,0,0,0,0,0,0,0,0,19,0,0,0,0,0,0,1,1,1
1,1,1,1,1,1,1,1,1,19,19,19,19,19,4,4,19,19,19,19,19,1,1,1,1,1,1,1,1,1
1,1,1,1,1,1,1,1,1,1,1,1,1,1,0,0,1,1,1,1,1,1,1,1,1,1,1,1,1,1
1,1,1,1,1,1,1,1,1,1,1,1,1,1,0,0,1,1,1,1,1,1,1,1,1,1,1,1,1,1
1,1,1,1,1,1,1,1,1,1,1,1,1,1,0,0,1,1,1,1,1,1,1,1,1,1,1,1,1,1
1,1,1,1,1,1,1,1,1,0,1,1,1,1,0,0,1,1,1,1,0,1,1,1,1,1,1,1,1,1
1,1,1,1,1,1,1,1,1,1,1,1,1,1,0,0,1,1,1,1,1,1,1,1,1,1,1,1,1,1
1,1,1,4,4,4,1,1,1,1,1,1,1,1,0,0,1,1,1,1,1,1,1,1,4,4,4,1,1,1
1,1,4,0,0,0,4,1,1,1,1,1,4,20,20,20,20,4,1,1,1,1,1,4,0,0,0,4,1,1
1,4,0,0,0,0,0,4,1,1,1,1,4,0,0,0,0,4,1,1,1,1,4,0,0,0,0,0,4,1
1,4,0,0,0,0,0,4,1,1,1,1,0,0,0,0,0,0,1,1,1,1,4,0,0,0,0,0,4,1
1,4,0,0,0,0,0,4,1,1,1,1,4,0,0,0,0,4,1,1,1,1,4,0,0,0,0,0,4,1
1,1,4,0,0,0,4,1,1,1,1,1,4,0,0,0,0,4,1,1,1,1,1,4,0,0,0,4,1,1
1,1,1,4,4,4,1,1,1,1,1,1,4,20,20,20,20,4,1,1,1,1,1,1,4,4,4,1,1,1
1,1,1,1,1,1,1,1,1,1,1,1,1,1,0,0,1,1,1,1,1,1,1,1,1,1,1,1,1,1
endlayer

layer
1,1,1,5,5,5,1,1,1,1,1,1,1,1,1,1,1,1,1,1,1,1,1,1,5,5,5,1,1,1
1,1,5,5,5,5,5,1,1,1,1,1,1,1,1,1,1,1,1,1,1,1,1,5,5,5,5,5,1,1
1,5,5,0,0,0,5,5,1,1,1,1,1,1,0,0,1,1,1,1,1,1,5,5,0,0,0,5,5,1
5,5,0,0,0,0,0,5,5,1,1,1,1,1,0,0,1,1,1,1,1,5,5,0,0,0,0,0,5,5
5,5,0,0,0,0,0,5,5,0,0,0,0,0,0,0,0,0,0,0,0,5,5,0,0,0,0,0,5,5
5,5,0,0,0,0,0,5,5,1,1,1,1,1,0,0,1,1,1,1,1,5,5,0,0,0,0,0,5,5
1,5,5,0,0,0,5,5,1,1,1,1,1,1,1,1,1,1,1,1,1,1,5,5,0,0,0,5,5,1
1,1,5,5,5,5,5,1,5,1,1,1,1,1,1,1,1,1,1,12,12,12,1,5,5,5,5,5,1,1
1,1,1,5,5,5,1,1,5,19,19,19,19,4,20,20,4,19,19,0,0,23,12,1,5,5,5,1,1,1
1,1,1,1,1,1,1,1,5,19,0,0,0,0,0,0,0,0,0,0,0,0,12,1,1,1,1,1,1,1
1,1,1,1,1,1,1,1,5,19,0,0,0,0,0,0,0,0,0,0,0,0,12,1,1,1,1,1,1,1
1,1,1,1,1,1,1,1,5,19,0,0,0,0,0,0,0,0,0,0,19,12,1,1,1,1,1,1,1,1
1,1,1,1,1,1,1,1,5,19,0,0,0,0,0,0,0,0,0,0,19,5,1,1,1,1,1,1,1,1
1,1,1,1,1,1,1,1,5,19,0,0,0,0,0,0,0,0,0,0,19,5,1,1,1,1,1,1,1,1
1,1,1,1,1,1,1,1,5,19,0,0,0,0,0,0,0,0,0,0,19,5,1,1,1,1,1,1,1,1
1,1,1,0,0,0,0,0,5,19,0,0,0,0,0,0,0,0,0,0,19,5,0,0,0,0,0,1,1,1
1,1,1,1,1,1,1,1,5,19,19,19,19,4,20,20,4,19,19,19,19,5,1,1,1,1,1,1,1,1
1,1,1,1,1,1,1,1,5,1,1,1,1,1,0,0,1,1,1,1,1,5,1,1,1,1,1,1,1,1
1,1,1,1,1,1,1,1,1,1,1,1,1,1,0,0,1,1,1,1,1,1,1,1,1,1,1,1,1,1
1,1,1,1,1,1,1,1,1,1,1,1,1,1,0,0,1,1,1,1,1,1,1,1,1,1,1,1,1,1
1,1,1,1,1,1,1,1,1,0,1,1,1,1,0,0,1,1,1,1,0,1,1,1,1,1,1,1,1,1
1,1,1,5,5,5,1,1,1,1,1,1,1,1,0,0,1,1,1,1,1,1,1,1,5,5,5,1,1,1
1,1,5,5,5,5,5,1,1,1,1,25,4,1,0,0,1,4,25,1,1,1,1,5,5,5,5,5,1,1
1,5,5,0,0,0,5,5,1,1,1,25,4,4,4,4,4,4,25,1,1,1,5,5,0,0,0,5,5,1
5,5,0,0,0,0,0,5,5,1,1,25,4,0,0,0,0,4,25,1,1,5,5,0,0,0,0,0,5,5
5,5,0,0,0,0,0,5,5,1,1,25,4,1,0,0,1,4,25,1,1,5,5,0,0,0,0,0,5,5
5,5,0,0,0,0,0,5,5,1,1,25,4,0,0,0,0,4,25,1,1,5,5,0,0,0,0,0,5,5
1,5,5,0,0,0,5,5,1,1,1,25,4,0,0,0,0,4,25,1,1,1,5,5,0,0,0,5,5,1
1,1,5,5,5,5,5,1,1,1,1,25,4,4,4,4,4,4,25,1,1,1,1,5,5,5,5,5,1,1
1,1,1,5,5,5,1,1,1,1,1,25,4,1,0,0,1,4,25,1,1,1,1,1,5,5,5,1,1,1
endlayer

layer
1,1,1,1,1,1,1,1,1,1,1,1,1,1,1,1,1,1,1,1,1,1,1,1,1,1,1,1,1,1
1,1,1,5,5,5,1,1,1,1,1,1,1,1,1,1,1,1,1,1,1,1,1,1,5,5,5,1,1,1
1,1,5,0,0,0,5,1,1,1,1,1,1,1,0,0,1,1,1,1,1,1,1,5,0,0,0,5,1,1
1,5,0,0,0,0,0,5,1,1,1,1,1,1,0,0,1,1,1,1,1,1,5,0,0,0,0,0,5,1
1,5,0,0,0,0,0,5,1,0,0,0,0,0,0,0,0,0,0,0,0,0,5,0,0,0,0,0,5,1
1,5,0,0,0,0,0,5,1,1,1,1,1,1,0,0,1,1,1,1,1,1,5,0,0,0,0,0,5,1
1,1,5,0,0,0,5,1,1,1,1,1,1,1,1,1,1,1,1,1,1,1,1,5,0,0,0,5,1,1
1,1,1,5,5,5,1,1,1,5,1,1,1,1,1,1,1,1,1,12,12,12,1,1,5,5,5,1,1,1
1,1,1,1,1,1,1,1,1,5,19,19,4,4,20,20,4,4,19,0,0,23,12,1,1,1,1,1,1,1
1,1,1,1,1,1,1,1,1,5,0,0,0,0,0,0,0,0,0,0,0,0,12,1,1,1,1,1,1,1
1,1,1,1,1,1,1,1,1,5,0,0,0,0,0,0,0,0,0,0,0,0,12,1,1,1,1,1,1,1
1,1,1,1,1,1,1,1,1,5,0,0,0,0,0,0,0,0,0,0,5,12,1,1,1,1,1,1,1,1
1,1,1,1,1,1,1,1,1,5,0,0,0,0,0,0,0,0,0,0,5,1,1,1,1,1,1,1,1,1
1,1,1,1,1,1,1,1,1,5,0,0,0,0,0,0,0,0,0,0,5,1,1,1,1,1,1,1,1,1
1,1,1,1,1,1,1,1,1,5,0,0,0,0,0,0,0,0,0,0,5,1,1,1,1,1,1,1,1,1
1,1,1,0,0,0,0,0,0,5,0,0,0,0,0,0,0,0,0,0,5,0,0,0,0,0,0,1,1,1
1,1,1,1,1,1,1,1,1,5,19,19,4,4,20,20,4,4,19,19,5,1,1,1,1,1,1,1,1,1
1,1,1,1,1,1,1,1,1,5,1,1,1,1,0,0,1,1,1,1,5,1,1,1,1,1,1,1,1,1
1,1,1,1,1,1,1,1,1,1,1,1,1,1,0,0,1,1,1,1,1,1,1,1,1,1,1,1,1,1
1,1,1,1,1,1,1,1,1,1,1,1,1,1,0,0,1,1,1,1,1,1,1,1,1,1,1,1,1,1
1,1,1,1,1,1,1,1,1,0,1,1,1,1,0,0,1,1,1,1,0,1,1,1,1,1,1,1,1,1
1,1,1,1,1,1,1,1,1,1,1,1,1,1,0,0,1,1,1,1,1,1,1,1,1,1,1,1,1,1
1,1,1,5,5,5,1,1,1,1,1,1,1,25,4,4,25,1,1,1,1,1,1,1,5,5,5,1,1,1
1,1,5,0,0,0,5,1,1,1,1,1,1,25,4,4,25,1,1,1,1,1,1,5,0,0,0,5,1,1
1,5,0,0,0,0,0,5,1,1,1,1,1,25,4,4,25,1,1,1,1,1,5,0,0,0,0,0,5,1
1,5,0,0,0,0,0,5,1,1,1,1,1,25,4,4,25,1,1,1,1,1,5,0,0,0,0,0,5,1
1,5,0,0,0,0,0,5,1,1,1,1,1,25,4,4,25,1,1,1,1,1,5,0,0,0,0,0,5,1
1,1,5,0,0,0,5,1,1,1,1,1,1,25,4,4,25,1,1,1,1,1,1,5,0,0,0,5,1,1
1,1,1,5,5,5,1,1,1,1,1,1,1,25,4,4,25,1,1,1,1,1,1,1,5,5,5,1,1,1
1,1,1,1,1,1,1,1,1,1,1,1,1,25,4,4,25,1,1,1,1,1,1,1,1,1,1,1,1,1
endlayer

layer
1,1,1,1,1,1,1,1,1,1,1,1,1,1,1,1,1,1,1,1,1,1,1,1,1,1,1,1,1,1
1,1,1,5,5,5,1,1,1,1,1,1,1,1,1,1,1,1,1,1,1,1,1,1,5,5,5,1,1,1
1,1,5,0,0,0,5,1,1,1,1,1,1,1,0,0,1,1,1,1,1,1,1,5,0,0,0,5,1,1
1,5,0,0,0,0,0,5,1,1,1,1,1,1,0,0,1,1,1,1,1,1,5,0,0,0,0,0,5,1
1,5,0,0,0,0,0,5,1,0,0,0,0,0,0,0,0,0,0,0,0,0,5,0,0,0,0,0,5,1
1,5,0,0,0,0,0,5,1,1,1,1,1,1,0,0,1,1,1,1,1,1,5,0,0,0,0,0,5,1
1,1,5,0,0,0,5,1,1,1,1,1,1,1,1,1,1,1,1,1,1,1,1,5,0,0,0,5,1,1
1,1,1,5,5,5,1,1,1,1,5,1,1,1,1,1,1,1,1,12,12,12,1,1,5,5,5,1,1,1
1,1,1,1,1,1,1,1,1,1,5,4,20,20,20,20,20,20,4,0,0,23,12,1,1,1,1,1,1,1
1,1,1,1,1,1,1,1,1,1,5,0,0,0,0,0,0,0,0,0,0,0,12,1,1,1,1,1,1,1
1,1,1,1,1,1,1,1,1,1,5,0,0,0,0,0,0,0,0,0,0,0,12,1,1,1,1,1,1,1
1,1,1,1,1,1,1,1,1,1,5,0,0,0,0,0,0,0,0,5,12,12,1,1,1,1,1,1,1,1
1,1,1,1,1,1,1,1,1,1,5,0,0,0,0,0,0,0,0,5,1,1,1,1,1,1,1,1,1,1
1,1,1,1,1,1,1,1,1,1,5,0,0,0,0,0,0,0,0,5,1,1,1,1,1,1,1,1,1,1
1,1,1,1,1,1,1,1,1,1,5,0,0,0,0,0,0,0,0,5,1,1,1,1,1,1,1,1,1,1
1,1,1,0,0,0,0,0,0,1,5,0,0,0,0,0,0,0,0,5,1,0,0,0,0,0,0,1,1,1
1,1,1,1,1,1,1,1,1,1,5,4,20,20,20,20,20,20,4,5,1,1,1,1,1,1,1,1,1,1
1,1,1,1,1,1,1,1,1,1,5,1,1,1,0,0,1,1,1,5,1,1,1,1,1,1,1,1,1,1
1,1,1,1,1,1,1,1,1,1,1,1,1,1,0,0,1,1,1,1,1,1,1,1,1,1,1,1,1,1
1,1,1,1,1,1,1,1,1,1,1,1,1,1,0,0,1,1,1,1,1,1,1,1,1,1,1,1,1,1
1,1,1,1,1,1,1,1,1,0,1,1,1,1,0,0,1,1,1,1,0,1,1,1,1,1,1,1,1,1
1,1,1,1,1,1,1,1,1,1,1,1,1,1,0,0,1,1,1,1,1,1,1,1,1,1,1,1,1,1
1,1,1,5,5,5,1,1,1,1,1,1,1,1,1,1,1,1,1,1,1,1,1,1,5,5,5,1,1,1
1,1,5,0,0,0,5,1,1,1,1,1,1,1,1,1,1,1,1,1,1,1,1,5,0,0,0,5,1,1
1,5,0,0,0,0,0,5,1,1,1,1,1,1,1,1,1,1,1,1,1,1,5,0,0,0,0,0,5,1
1,5,0,0,0,0,0,5,1,1,1,1,1,1,1,1,1,1,1,1,1,1,5,0,0,0,0,0,5,1
1,5,0,0,0,0,0,5,1,1,1,1,1,1,1,1,1,1,1,1,1,1,5,0,0,0,0,0,5,1
1,1,5,0,0,0,5,1,1,1,1,1,1,1,1,1,1,1,1,1,1,1,1,5,0,0,0,5,1,1
1,1,1,5,5,5,1,1,1,1,1,1,1,1,1,1,1,1,1,1,1,1,1,1,5,5,5,1,1,1
1,1,1,1,1,1,1,1,1,1,1,1,1,1,1,1,1,1,1,1,1,1,1,1,1,1,1,1,1,1
endlayer

layer
1,1,1,1,1,1,1,1,1,1,1,1,1,1,1,1,1,1,1,1,1,1,1,1,1,1,1,1,1,1
1,1,1,1,1,1,1,1,1,1,1,1,1,1,1,1,1,1,1,1,1,1,1,1,1,1,1,1,1,1
1,1,1,5,5,5,1,1,1,1,1,1,1,1,0,0,1,1,1,1,1,1,1,1,5,5,5,1,1,1
1,1,5,0,0,0,5,1,1,1,1,1,1,1,0,0,1,1,1,1,1,1,1,5,0,0,0,5,1,1
1,1,5,0,0,0,5,1,1,0,0,0,0,0,0,0,0,0,0,0,0,0,1,5,0,0,0,5,1,1
1,1,5,0,0,0,5,1,1,1,1,1,1,1,0,0,1,1,1,1,1,1,1,5,0,0,0,5,1,1
1,1,1,5,5,5,1,1,1,1,1,1,1,1,1,1,1,1,1,1,1,1,1,1,5,5,5,1,1,1
1,1,1,1,1,1,1,1,1,1,5,1,1,1,1,1,1,1,1,12,12,12,1,1,1,1,1,1,1,1
1,1,1,1,1,1,1,1,1,1,5,4,20,20,20,20,20,20,4,0,0,23,12,1,1,1,1,1,1,1
1,1,1,1,1,1,1,1,1,1,5,0,0,0,0,0,0,0,0,0,0,0,12,1,1,1,1,1,1,1
1,1,1,1,1,1,1,1,1,1,5,0,0,0,0,0,0,0,0,0,0,0,12,1,1,1,1,1,1,1
1,1,1,1,1,1,1,1,1,1,5,0,0,0,0,0,0,0,0,5,12,12,1,1,1,1,1,1,1,1
1,1,1,1,1,1,1,1,1,1,5,0,0,0,0,0,0,0,0,5,1,1,1,1,1,1,1,1,1,1
1,1,1,1,1,1,1,1,1,1,5,0,0,0,0,0,0,0,0,5,1,1,1,1,1,1,1,1,1,1
1,1,1,1,1,1,1,1,1,1,5,0,0,0,0,0,0,0,0,5,1,1,1,1,1,1,1,1,1,1
1,1,1,0,0,0,0,0,0,1,5,0,0,0,0,0,0,0,0,5,1,0,0,0,0,0,0,1,1,1
1,1,1,1,1,1,1,1,1,1,5,4,20,20,20,20,20,20,4,5,1,1,1,1,1,1,1,1,1,1
1,1,1,1,1,1,1,1,1,1,5,1,1,1,0,0,1,1,1,5,1,1,1,1,1,1,1,1,1,1
1,1,1,1,1,1,1,1,1,1,1,1,1,1,0,0,1,1,1,1,1,1,1,1,1,1,1,1,1,1
1,1,1,1,1,1,1,1,1,1,1,1,1,1,0,0,1,1,1,1,1,1,1,1,1,1,1,1,1,1
1,1,1,1,1,1,1,1,1,0,1,1,1,1,0,0,1,1,1,1,0,1,1,1,1,1,1,1,1,1
1,1,1,1,1,1,1,1,1,1,1,1,1,1,0,0,1,1,1,1,1,1,1,1,1,1,1,1,1,1
1,1,1,1,1,1,1,1,1,1,1,1,1,1,1,1,1,1,1,1,1,1,1,1,1,1,1,1,1,1
1,1,1,5,5,5,1,1,1,1,1,1,1,1,1,1,1,1,1,1,1,1,1,1,5,5,5,1,1,1
1,1,5,0,0,0,5,1,1,1,1,1,1,1,1,1,1,1,1,1,1,1,1,5,0,0,0,5,1,1
1,1,5,0,0,0,5,1,1,1,1,1,1,1,1,1,1,1,1,1,1,1,1,5,0,0,0,5,1,1
1,1,5,0,0,0,5,1,1,1,1,1,1,1,1,1,1,1,1,1,1,1,1,5,0,0,0,5,1,1
1,1,1,5,5,5,1,1,1,1,1,1,1,1,1,1,1,1,1,1,1,1,1,1,5,5,5,1,1,1
1,1,1,1,1,1,1,1,1,1,1,1,1,1,1,1,1,1,1,1,1,1,1,1,1,1,1,1,1,1
1,1,1,1,1,1,1,1,1,1,1,1,1,1,1,1,1,1,1,1,1,1,1,1,1,1,1,1,1,1
endlayer

layer
1,1,1,1,1,1,1,1,1,1,1,1,1,1,1,1,1,1,1,1,1,1,1,1,1,1,1,1,1,1
1,1,1,1,1,1,1,1,1,1,1,1,1,1,1,1,1,1,1,1,1,1,1,1,1,1,1,1,1,1
1,1,1,5,5,5,1,1,1,1,1,1,1,1,0,0,1,1,1,1,1,1,1,1,5,5,5,1,1,1
1,1,5,0,0,0,5,1,1,1,1,1,1,1,0,0,1,1,1,1,1,1,1,5,0,0,0,5,1,1
1,1,5,0,0,0,5,1,1,0,0,0,0,0,0,0,0,0,0,0,0,0,1,5,0,0,0,5,1,1
1,1,5,0,0,0,5,1,1,1,1,1,1,1,0,0,1,1,1,1,1,1,1,5,0,0,0,5,1,1
1,1,1,5,5,5,1,1,1,1,1,1,1,1,1,1,1,1,1,1,1,1,1,1,5,5,5,1,1,1
1,1,1,1,1,1,1,1,1,1,1,5,1,1,1,1,1,1,5,12,12,12,1,1,1,1,1,1,1,1
1,1,1,1,1,1,1,1,1,1,1,5,4,4,20,20,4,4,5,0,0,23,12,1,1,1,1,1,1,1
1,1,1,1,1,1,1,1,1,1,1,5,0,0,0,0,0,0,5,0,0,0,12,1,1,1,1,1,1,1
1,1,1,1,1,1,1,1,1,1,1,5,0,0,0,0,0,0,5,0,0,0,12,1,1,1,1,1,1,1
1,1,1,1,1,1,1,1,1,1,1,5,0,0,0,0,0,0,5,12,12,12,1,1,1,1,1,1,1,1
1,1,1,1,1,1,1,1,1,1,1,5,0,0,0,0,0,0,5,1,1,1,1,1,1,1,1,1,1,1
1,1,1,1,1,1,1,1,1,1,1,5,0,0,0,0,0,0,5,1,1,1,1,1,1,1,1,1,1,1
1,1,1,1,1,1,1,1,1,1,1,5,0,0,0,0,0,0,5,1,1,1,1,1,1,1,1,1,1,1
1,1,1,0,0,0,0,0,0,1,1,5,0,0,0,0,0,0,5,1,1,0,0,0,0,0,0,1,1,1
1,1,1,1,1,1,1,1,1,1,1,5,4,4,20,20,4,4,5,1,1,1,1,1,1,1,1,1,1,1
1,1,1,1,1,1,1,1,1,1,1,5,1,1,0,0,1,1,5,1,1,1,1,1,1,1,1,1,1,1
1,1,1,1,1,1,1,1,1,1,1,1,1,1,0,0,1,1,1,1,1,1,1,1,1,1,1,1,1,1
1,1,1,1,1,1,1,1,1,1,1,1,1,1,0,0,1,1,1,1,1,1,1,1,1,1,1,1,1,1
1,1,1,1,1,1,1,1,1,0,1,1,1,1,0,0,1,1,1,1,0,1,1,1,1,1,1,1,1,1
1,1,1,1,1,1,1,1,1,1,1,1,1,1,0,0,1,1,1,1,1,1,1,1,1,1,1,1,1,1
1,1,1,1,1,1,1,1,1,1,1,1,1,1,1,1,1,1,1,1,1,1,1,1,1,1,1,1,1,1
1,1,1,5,5,5,1,1,1,1,1,1,1,1,1,1,1,1,1,1,1,1,1,1,5,5,5,1,1,1
1,1,5,0,0,0,5,1,1,1,1,1,1,1,1,1,1,1,1,1,1,1,1,5,0,0,0,5,1,1
1,1,5,0,0,0,5,1,1,1,1,1,1,1,1,1,1,1,1,1,1,1,1,5,0,0,0,5,1,1
1,1,5,0,0,0,5,1,1,1,1,1,1,1,1,1,1,1,1,1,1,1,1,5,0,0,0,5,1,1
1,1,1,5,5,5,1,1,1,1,1,1,1,1,1,1,1,1,1,1,1,1,1,1,5,5,5,1,1,1
1,1,1,1,1,1,1,1,1,1,1,1,1,1,1,1,1,1,1,1,1,1,1,1,1,1,1,1,1,1
1,1,1,1,1,1,1,1,1,1,1,1,1,1,1,1,1,1,1,1,1,1,1,1,1,1,1,1,1,1
endlayer

layer
1,1,1,1,1,1,1,1,1,1,1,1,1,1,1,1,1,1,1,1,1,1,1,1,1,1,1,1,1,1
1,1,1,1,1,1,1,1,1,1,1,1,1,1,1,1,1,1,1,1,1,1,1,1,1,1,1,1,1,1
1,1,1,1,1,1,1,1,1,1,1,1,1,1,0,0,1,1,1,1,1,1,1,1,1,1,1,1,1,1
1,1,1,5,5,5,1,1,1,1,1,1,1,1,0,0,1,1,1,1,1,1,1,1,5,5,5,1,1,1
1,1,1,5,0,5,1,1,1,0,0,0,0,0,0,0,0,0,0,0,0,0,1,1,5,0,5,1,1,1
1,1,1,5,5,5,1,1,1,1,1,1,1,1,0,0,1,1,1,1,1,1,1,1,5,5,5,1,1,1
1,1,1,1,1,1,1,1,1,1,1,1,1,1,1,1,1,1,1,1,1,1,1,1,1,1,1,1,1,1
1,1,1,1,1,1,1,1,1,1,1,5,1,1,1,1,1,1,5,12,12,12,1,1,1,1,1,1,1,1
1,1,1,1,1,1,1,1,1,1,1,5,19,4,20,20,4,19,5,0,0,23,12,1,1,1,1,1,1,1
1,1,1,1,1,1,1,1,1,1,1,5,0,0,0,0,0,0,5,0,0,0,12,1,1,1,1,1,1,1
1,1,1,1,1,1,1,1,1,1,1,5,0,0,0,0,0,0,5,0,0,0,12,1,1,1,1,1,1,1
1,1,1,1,1,1,1,1,1,1,1,5,0,0,0,0,0,0,5,12,12,12,1,1,1,1,1,1,1,1
1,1,1,1,1,1,1,1,1,1,1,5,0,0,0,0,0,0,5,1,1,1,1,1,1,1,1,1,1,1
1,1,1,1,1,1,1,1,1,1,1,5,0,0,0,0,0,0,5,1,1,1,1,1,1,1,1,1,1,1
1,1,1,1,1,1,1,1,1,1,1,5,0,0,0,0,0,0,5,1,1,1,1,1,1,1,1,1,1,1
1,1,1,0,0,0,0,0,0,1,1,5,0,0,0,0,0,0,5,1,1,0,0,0,0,0,0,1,1,1
1,1,1,1,1,1,1,1,1,1,1,5,19,4,20,20,4,19,5,1,1,1,1,1,1,1,1,1,1,1
1,1,1,1,1,1,1,1,1,1,1,5,0,0,0,0,0,0,5,1,1,1,1,1,1,1,1,1,1,1
1,1,1,1,1,1,1,1,1,1,1,1,1,1,0,0,1,1,1,1,1,1,1,1,1,1,1,1,1,1
1,1,1,1,1,1,1,1,1,1,1,1,1,1,0,0,1,1,1,1,1,1,1,1,1,1,1,1,1,1
1,1,1,1,1,1,1,1,1,0,1,1,1,1,0,0,1,1,1,1,0,1,1,1,1,1,1,1,1,1
1,1,1,1,1,1,1,1,1,1,1,1,1,1,0,0,1,1,1,1,1,1,1,1,1,1,1,1,1,1
1,1,1,1,1,1,1,1,1,1,1,1,1,1,0,0,1,1,1,1,1,1,1,1,1,1,1,1,1,1
1,1,1,1,1,1,1,1,1,1,1,1,1,1,0,0,1,1,1,1,1,1,1,1,1,1,1,1,1,1
1,1,1,5,5,5,1,1,1,1,1,1,1,1,0,0,1,1,1,1,1,1,1,1,5,5,5,1,1,1
1,1,1,5,0,5,1,1,1,1,1,1,1,1,0,0,1,1,1,1,1,1,1,1,5,0,5,1,1,1
1,1,1,5,5,5,1,1,1,1,1,1,1,1,0,0,1,1,1,1,1,1,1,1,5,5,5,1,1,1
1,1,1,1,1,1,1,1,1,1,1,1,1,1,0,0,1,1,1,1,1,1,1,1,1,1,1,1,1,1
1,1,1,1,1,1,1,1,1,1,1,1,1,1,0,0,1,1,1,1,1,1,1,1,1,1,1,1,1,1
1,1,1,1,1,1,1,1,1,1,1,1,1,1,0,0,1,1,1,1,1,1,1,1,1,1,1,1,1,1
endlayer

layer
0,0,0,0,0,0,0,0,0,0,0,0,0,0,0,0,0,0,0,0,0,0,0,0,0,0,0,0,0,0
0,0,0,0,0,0,0,0,0,0,0,0,0,0,0,0,0,0,0,0,0,0,0,0,0,0,0,0,0,0
0,0,0,0,0,0,0,0,0,0,0,0,0,0,0,0,0,0,0,0,0,0,0,0,0,0,0,0,0,0
0,0,0,5,5,5,0,0,0,0,0,0,0,0,0,0,0,0,0,0,0,0,0,0,5,5,5,0,0,0
0,0,0,5,0,5,0,0,0,0,0,0,0,0,0,0,0,0,0,0,0,0,0,0,5,0,5,0,0,0
0,0,0,5,5,5,0,0,0,0,0,0,0,0,0,0,0,0,0,0,0,0,0,0,5,5,5,0,0,0
0,0,0,0,0,0,0,0,0,0,0,0,0,0,0,0,0,0,0,0,0,0,0,0,0,0,0,0,0,0
0,0,0,0,0,0,0,0,0,0,0,0,5,1,1,1,1,5,1,12,12,12,1,0,0,0,0,0,0,0
0,0,0,0,0,0,0,0,0,0,0,0,5,19,4,4,19,5,12,0,0,23,12,0,0,0,0,0,0,0
0,0,0,0,0,0,0,0,0,0,0,0,5,0,0,0,0,5,12,0,0,0,12,0,0,0,0,0,0,0
0,0,0,0,0,0,0,0,0,0,0,0,5,0,0,0,0,5,12,0,0,0,12,0,0,0,0,0,0,0
0,0,0,0,0,0,0,0,0,0,0,0,5,0,0,0,0,5,1,12,12,12,1,0,0,0,0,0,0,0
0,0,0,0,0,0,0,0,0,0,0,0,5,0,0,0,0,5,0,0,0,0,0,0,0,0,0,0,0,0
0,0,0,0,0,0,0,0,0,0,0,0,5,0,0,0,0,5,0,0,0,0,0,0,0,0,0,0,0,0
0,0,0,0,0,0,0,0,0,0,0,0,5,0,0,0,0,5,0,0,0,0,0,0,0,0,0,0,0,0
0,0,0,0,0,0,0,0,0,0,0,0,5,0,0,0,0,5,0,0,0,0,0,0,0,0,0,0,0,0
0,0,0,0,0,0,0,0,0,0,0,0,5,19,4,4,19,5,0,0,0,0,0,0,0,0,0,0,0,0
0,0,0,0,0,0,0,0,0,0,0,0,5,0,0,0,0,5,0,0,0,0,0,0,0,0,0,0,0,0
0,0,0,0,0,0,0,0,0,0,0,0,0,0,0,0,0,0,0,0,0,0,0,0,0,0,0,0,0,0
0,0,0,0,0,0,0,0,0,0,0,0,0,0,0,0,0,0,0,0,0,0,0,0,0,0,0,0,0,0
0,0,0,0,0,0,0,0,0,0,0,0,0,0,0,0,0,0,0,0,0,0,0,0,0,0,0,0,0,0
0,0,0,0,0,0,0,0,0,0,0,0,0,0,0,0,0,0,0,0,0,0,0,0,0,0,0,0,0,0
0,0,0,0,0,0,0,0,0,0,0,0,0,0,0,0,0,0,0,0,0,0,0,0,0,0,0,0,0,0
0,0,0,0,0,0,0,0,0,0,0,0,0,0,0,0,0,0,0,0,0,0,0,0,0,0,0,0,0,0
0,0,0,5,5,5,0,0,0,0,0,0,0,0,0,0,0,0,0,0,0,0,0,0,5,5,5,0,0,0
0,0,0,5,0,5,0,0,0,0,0,0,0,0,0,0,0,0,0,0,0,0,0,0,5,0,5,0,0,0
0,0,0,5,5,5,0,0,0,0,0,0,0,0,0,0,0,0,0,0,0,0,0,0,5,5,5,0,0,0
0,0,0,0,0,0,0,0,0,0,0,0,0,0,0,0,0,0,0,0,0,0,0,0,0,0,0,0,0,0
0,0,0,0,0,0,0,0,0,0,0,0,0,0,0,0,0,0,0,0,0,0,0,0,0,0,0,0,0,0
0,0,0,0,0,0,0,0,0,0,0,0,0,0,0,0,0,0,0,0,0,0,0,0,0,0,0,0,0,0
endlayer

layer
0,0,0,0,0,0,0,0,0,0,0,0,0,0,0,0,0,0,0,0,0,0,0,0,0,0,0,0,0,0
0,0,0,0,0,0,0,0,0,0,0,0,0,0,0,0,0,0,0,0,0,0,0,0,0,0,0,0,0,0
0,0,0,0,0,0,0,0,0,0,0,0,0,0,0,0,0,0,0,0,0,0,0,0,0,0,0,0,0,0
0,0,0,0,5,0,0,0,0,0,0,0,0,0,0,0,0,0,0,0,0,0,0,0,0,5,0,0,0,0
0,0,0,5,0,5,0,0,0,0,0,0,0,0,0,0,0,0,0,0,0,0,0,0,5,0,5,0,0,0
0,0,0,0,5,0,0,0,0,0,0,0,0,0,0,0,0,0,0,0,0,0,0,0,0,5,0,0,0,0
0,0,0,0,0,0,0,0,0,0,0,0,0,0,0,0,0,0,0,0,0,0,0,0,0,0,0,0,0,0
0,0,0,0,0,0,0,0,0,0,0,0,5,1,1,1,1,5,1,12,12,12,1,0,0,0,0,0,0,0
0,0,0,0,0,0,0,0,0,0,0,0,5,19,19,19,19,5,12,0,0,23,12,0,0,0,0,0,0,0
0,0,0,0,0,0,0,0,0,0,0,0,5,0,0,0,0,5,12,0,0,0,12,0,0,0,0,0,0,0
0,0,0,0,0,0,0,0,0,0,0,0,5,0,0,0,0,5,12,0,0,0,12,0,0,0,0,0,0,0
0,0,0,0,0,0,0,0,0,0,0,0,5,0,0,0,0,5,1,12,12,12,1,0,0,0,0,0,0,0
0,0,0,0,0,0,0,0,0,0,0,0,5,0,0,0,0,5,0,0,0,0,0,0,0,0,0,0,0,0
0,0,0,0,0,0,0,0,0,0,0,0,5,0,0,0,0,5,0,0,0,0,0,0,0,0,0,0,0,0
0,0,0,0,0,0,0,0,0,0,0,0,5,0,0,0,0,5,0,0,0,0,0,0,0,0,0,0,0,0
0,0,0,0,0,0,0,0,0,0,0,0,5,0,0,0,0,5,0,0,0,0,0,0,0,0,0,0,0,0
0,0,0,0,0,0,0,0,0,0,0,0,5,19,19,19,19,5,0,0,0,0,0,0,0,0,0,0,0,0
0,0,0,0,0,0,0,0,0,0,0,0,5,0,0,0,0,5,0,0,0,0,0,0,0,0,0,0,0,0
0,0,0,0,0,0,0,0,0,0,0,0,0,0,0,0,0,0,0,0,0,0,0,0,0,0,0,0,0,0
0,0,0,0,0,0,0,0,0,0,0,0,0,0,0,0,0,0,0,0,0,0,0,0,0,0,0,0,0,0
0,0,0,0,0,0,0,0,0,0,0,0,0,0,0,0,0,0,0,0,0,0,0,0,0,0,0,0,0,0
0,0,0,0,0,0,0,0,0,0,0,0,0,0,0,0,0,0,0,0,0,0,0,0,0,0,0,0,0,0
0,0,0,0,0,0,0,0,0,0,0,0,0,0,0,0,0,0,0,0,0,0,0,0,0,0,0,0,0,0
0,0,0,0,0,0,0,0,0,0,0,0,0,0,0,0,0,0,0,0,0,0,0,0,0,0,0,0,0,0
0,0,0,0,5,0,0,0,0,0,0,0,0,0,0,0,0,0,0,0,0,0,0,0,0,5,0,0,0,0
0,0,0,5,0,5,0,0,0,0,0,0,0,0,0,0,0,0,0,0,0,0,0,0,5,0,5,0,0,0
0,0,0,0,5,0,0,0,0,0,0,0,0,0,0,0,0,0,0,0,0,0,0,0,0,5,0,0,0,0
0,0,0,0,0,0,0,0,0,0,0,0,0,0,0,0,0,0,0,0,0,0,0,0,0,0,0,0,0,0
0,0,0,0,0,0,0,0,0,0,0,0,0,0,0,0,0,0,0,0,0,0,0,0,0,0,0,0,0,0
0,0,0,0,0,0,0,0,0,0,0,0,0,0,0,0,0,0,0,0,0,0,0,0,0,0,0,0,0,0
endlayer

layer
0,0,0,0,0,0,0,0,0,0,0,0,0,0,0,0,0,0,0,0,0,0,0,0,0,0,0,0,0,0
0,0,0,0,0,0,0,0,0,0,0,0,0,0,0,0,0,0,0,0,0,0,0,0,0,0,0,0,0,0
0,0,0,0,0,0,0,0,0,0,0,0,0,0,0,0,0,0,0,0,0,0,0,0,0,0,0,0,0,0
0,0,0,0,5,0,0,0,0,0,0,0,0,0,0,0,0,0,0,0,0,0,0,0,0,5,0,0,0,0
0,0,0,5,0,5,0,0,0,0,0,0,0,0,0,0,0,0,0,0,0,0,0,0,5,0,5,0,0,0
0,0,0,0,5,0,0,0,0,0,0,0,0,0,0,0,0,0,0,0,0,0,0,0,0,5,0,0,0,0
0,0,0,0,0,0,0,0,0,0,0,0,0,0,0,0,0,0,0,0,0,0,0,0,0,0,0,0,0,0
0,0,0,0,0,0,0,0,0,0,0,0,0,5,1,1,5,0,0,12,12,12,0,0,0,0,0,0,0,0
0,0,0,0,0,0,0,0,0,0,0,0,0,5,19,19,5,0,12,0,0,23,12,0,0,0,0,0,0,0
0,0,0,0,0,0,0,0,0,0,0,0,0,5,0,0,5,0,12,0,0,0,12,0,0,0,0,0,0,0
0,0,0,0,0,0,0,0,0,0,0,0,0,5,0,0,5,0,12,0,0,0,12,0,0,0,0,0,0,0
0,0,0,0,0,0,0,0,0,0,0,0,0,5,0,0,5,0,0,12,12,12,0,0,0,0,0,0,0,0
0,0,0,0,0,0,0,0,0,0,0,0,0,5,0,0,5,0,0,0,0,0,0,0,0,0,0,0,0,0
0,0,0,0,0,0,0,0,0,0,0,0,0,5,0,0,5,0,0,0,0,0,0,0,0,0,0,0,0,0
0,0,0,0,0,0,0,0,0,0,0,0,0,5,0,0,5,0,0,0,0,0,0,0,0,0,0,0,0,0
0,0,0,0,0,0,0,0,0,0,0,0,0,5,0,0,5,0,0,0,0,0,0,0,0,0,0,0,0,0
0,0,0,0,0,0,0,0,0,0,0,0,0,5,19,19,5,0,0,0,0,0,0,0,0,0,0,0,0,0
0,0,0,0,0,0,0,0,0,0,0,0,0,5,0,0,5,0,0,0,0,0,0,0,0,0,0,0,0,0
0,0,0,0,0,0,0,0,0,0,0,0,0,0,0,0,0,0,0,0,0,0,0,0,0,0,0,0,0,0
0,0,0,0,0,0,0,0,0,0,0,0,0,0,0,0,0,0,0,0,0,0,0,0,0,0,0,0,0,0
0,0,0,0,0,0,0,0,0,0,0,0,0,0,0,0,0,0,0,0,0,0,0,0,0,0,0,0,0,0
0,0,0,0,0,0,0,0,0,0,0,0,0,0,0,0,0,0,0,0,0,0,0,0,0,0,0,0,0,0
0,0,0,0,0,0,0,0,0,0,0,0,0,0,0,0,0,0,0,0,0,0,0,0,0,0,0,0,0,0
0,0,0,0,0,0,0,0,0,0,0,0,0,0,0,0,0,0,0,0,0,0,0,0,0,0,0,0,0,0
0,0,0,0,5,0,0,0,0,0,0,0,0,0,0,0,0,0,0,0,0,0,0,0,0,5,0,0,0,0
0,0,0,5,0,5,0,0,0,0,0,0,0,0,0,0,0,0,0,0,0,0,0,0,5,0,5,0,0,0
0,0,0,0,5,0,0,0,0,0,0,0,0,0,0,0,0,0,0,0,0,0,0,0,0,5,0,0,0,0
0,0,0,0,0,0,0,0,0,0,0,0,0,0,0,0,0,0,0,0,0,0,0,0,0,0,0,0,0,0
0,0,0,0,0,0,0,0,0,0,0,0,0,0,0,0,0,0,0,0,0,0,0,0,0,0,0,0,0,0
0,0,0,0,0,0,0,0,0,0,0,0,0,0,0,0,0,0,0,0,0,0,0,0,0,0,0,0,0,0
endlayer

layer
0,0,0,0,0,0,0,0,0,0,0,0,0,0,0,0,0,0,0,0,0,0,0,0,0,0,0,0,0,0
0,0,0,0,0,0,0,0,0,0,0,0,0,0,0,0,0,0,0,0,0,0,0,0,0,0,0,0,0,0
0,0,0,0,0,0,0,0,0,0,0,0,0,0,0,0,0,0,0,0,0,0,0,0,0,0,0,0,0,0
0,0,0,0,0,0,0,0,0,0,0,0,0,0,0,0,0,0,0,0,0,0,0,0,0,0,0,0,0,0
0,0,0,0,5,0,0,0,0,0,0,0,0,0,0,0,0,0,0,0,0,0,0,0,0,5,0,0,0,0
0,0,0,0,0,0,0,0,0,0,0,0,0,0,0,0,0,0,0,0,0,0,0,0,0,0,0,0,0,0
0,0,0,0,0,0,0,0,0,0,0,0,0,0,0,0,0,0,0,4,4,4,0,0,0,0,0,0,0,0
0,0,0,0,0,0,0,0,0,0,0,0,0,5,1,1,5,0,4,12,4,12,4,0,0,0,0,0,0,0
0,0,0,0,0,0,0,0,0,0,0,0,0,5,19,19,5,4,12,4,4,23,12,4,0,0,0,0,0,0
0,0,0,0,0,0,0,0,0,0,0,0,0,5,0,0,5,4,4,4,4,4,4,4,0,0,0,0,0,0
0,0,0,0,0,0,0,0,0,0,0,0,0,5,0,0,5,4,12,4,4,4,12,4,0,0,0,0,0,0
0,0,0,0,0,0,0,0,0,0,0,0,0,5,0,0,5,0,4,12,4,12,4,0,0,0,0,0,0,0
0,0,0,0,0,0,0,0,0,0,0,0,0,5,0,0,5,0,0,4,4,4,0,0,0,0,0,0,0,0
0,0,0,0,0,0,0,0,0,0,0,0,0,5,0,0,5,0,0,0,0,0,0,0,0,0,0,0,0,0
0,0,0,0,0,0,0,0,0,0,0,0,0,5,0,0,5,0,0,0,0,0,0,0,0,0,0,0,0,0
0,0,0,0,0,0,0,0,0,0,0,0,0,5,0,0,5,0,0,0,0,0,0,0,0,0,0,0,0,0
0,0,0,0,0,0,0,0,0,0,0,0,0,5,19,19,5,0,0,0,0,0,0,0,0,0,0,0,0,0
0,0,0,0,0,0,0,0,0,0,0,0,0,5,0,0,5,0,0,0,0,0,0,0,0,0,0,0,0,0
0,0,0,0,0,0,0,0,0,0,0,0,0,0,0,0,0,0,0,0,0,0,0,0,0,0,0,0,0,0
0,0,0,0,0,0,0,0,0,0,0,0,0,0,0,0,0,0,0,0,0,0,0,0,0,0,0,0,0,0
0,0,0,0,0,0,0,0,0,0,0,0,0,0,0,0,0,0,0,0,0,0,0,0,0,0,0,0,0,0
0,0,0,0,0,0,0,0,0,0,0,0,0,0,0,0,0,0,0,0,0,0,0,0,0,0,0,0,0,0
0,0,0,0,0,0,0,0,0,0,0,0,0,0,0,0,0,0,0,0,0,0,0,0,0,0,0,0,0,0
0,0,0,0,0,0,0,0,0,0,0,0,0,0,0,0,0,0,0,0,0,0,0,0,0,0,0,0,0,0
0,0,0,0,0,0,0,0,0,0,0,0,0,0,0,0,0,0,0,0,0,0,0,0,0,0,0,0,0,0
0,0,0,0,5,0,0,0,0,0,0,0,0,0,0,0,0,0,0,0,0,0,0,0,0,5,0,0,0,0
0,0,0,0,0,0,0,0,0,0,0,0,0,0,0,0,0,0,0,0,0,0,0,0,0,0,0,0,0,0
0,0,0,0,0,0,0,0,0,0,0,0,0,0,0,0,0,0,0,0,0,0,0,0,0,0,0,0,0,0
0,0,0,0,0,0,0,0,0,0,0,0,0,0,0,0,0,0,0,0,0,0,0,0,0,0,0,0,0,0
0,0,0,0,0,0,0,0,0,0,0,0,0,0,0,0,0,0,0,0,0,0,0,0,0,0,0,0,0,0
endlayer

layer
0,0,0,0,0,0,0,0,0,0,0,0,0,0,0,0,0,0,0,0,0,0,0,0,0,0,0,0,0,0
0,0,0,0,0,0,0,0,0,0,0,0,0,0,0,0,0,0,0,0,0,0,0,0,0,0,0,0,0,0
0,0,0,0,0,0,0,0,0,0,0,0,0,0,0,0,0,0,0,0,0,0,0,0,0,0,0,0,0,0
0,0,0,0,0,0,0,0,0,0,0,0,0,0,0,0,0,0,0,0,0,0,0,0,0,0,0,0,0,0
0,0,0,0,5,0,0,0,0,0,0,0,0,0,0,0,0,0,0,0,0,0,0,0,0,5,0,0,0,0
0,0,0,0,0,0,0,0,0,0,0,0,0,0,0,0,0,0,0,0,0,0,0,0,0,0,0,0,0,0
0,0,0,0,0,0,0,0,0,0,0,0,0,0,0,0,0,0,0,0,0,0,0,0,0,0,0,0,0,0
0,0,0,0,0,0,0,0,0,0,0,0,0,0,5,5,0,0,0,12,0,12,0,0,0,0,0,0,0,0
0,0,0,0,0,0,0,0,0,0,0,0,0,0,5,5,0,0,12,0,0,0,12,0,0,0,0,0,0,0
0,0,0,0,0,0,0,0,0,0,0,0,0,0,5,5,0,0,0,0,0,0,0,0,0,0,0,0,0,0
0,0,0,0,0,0,0,0,0,0,0,0,0,0,5,5,0,0,12,0,0,0,12,0,0,0,0,0,0,0
0,0,0,0,0,0,0,0,0,0,0,0,0,0,5,5,0,0,0,12,0,12,0,0,0,0,0,0,0,0
0,0,0,0,0,0,0,0,0,0,0,0,0,0,5,5,0,0,0,0,0,0,0,0,0,0,0,0,0,0
0,0,0,0,0,0,0,0,0,0,0,0,0,0,5,5,0,0,0,0,0,0,0,0,0,0,0,0,0,0
0,0,0,0,0,0,0,0,0,0,0,0,0,0,5,5,0,0,0,0,0,0,0,0,0,0,0,0,0,0
0,0,0,0,0,0,0,0,0,0,0,0,0,0,5,5,0,0,0,0,0,0,0,0,0,0,0,0,0,0
0,0,0,0,0,0,0,0,0,0,0,0,0,0,5,5,0,0,0,0,0,0,0,0,0,0,0,0,0,0
0,0,0,0,0,0,0,0,0,0,0,0,0,0,5,5,0,0,0,0,0,0,0,0,0,0,0,0,0,0
0,0,0,0,0,0,0,0,0,0,0,0,0,0,0,0,0,0,0,0,0,0,0,0,0,0,0,0,0,0
0,0,0,0,0,0,0,0,0,0,0,0,0,0,0,0,0,0,0,0,0,0,0,0,0,0,0,0,0,0
0,0,0,0,0,0,0,0,0,0,0,0,0,0,0,0,0,0,0,0,0,0,0,0,0,0,0,0,0,0
0,0,0,0,0,0,0,0,0,0,0,0,0,0,0,0,0,0,0,0,0,0,0,0,0,0,0,0,0,0
0,0,0,0,0,0,0,0,0,0,0,0,0,0,0,0,0,0,0,0,0,0,0,0,0,0,0,0,0,0
0,0,0,0,0,0,0,0,0,0,0,0,0,0,0,0,0,0,0,0,0,0,0,0,0,0,0,0,0,0
0,0,0,0,0,0,0,0,0,0,0,0,0,0,0,0,0,0,0,0,0,0,0,0,0,0,0,0,0,0
0,0,0,0,5,0,0,0,0,0,0,0,0,0,0,0,0,0,0,0,0,0,0,0,0,5,0,0,0,0
0,0,0,0,0,0,0,0,0,0,0,0,0,0,0,0,0,0,0,0,0,0,0,0,0,0,0,0,0,0
0,0,0,0,0,0,0,0,0,0,0,0,0,0,0,0,0,0,0,0,0,0,0,0,0,0,0,0,0,0
0,0,0,0,0,0,0,0,0,0,0,0,0,0,0,0,0,0,0,0,0,0,0,0,0,0,0,0,0,0
0,0,0,0,0,0,0,0,0,0,0,0,0,0,0,0,0,0,0,0,0,0,0,0,0,0,0,0,0,0
endlayer

layer
0,0,0,0,0,0,0,0,0,0,0,0,0,0,0,0,0,0,0,0,0,0,0,0,0,0,0,0,0,0
0,0,0,0,0,0,0,0,0,0,0,0,0,0,0,0,0,0,0,0,0,0,0,0,0,0,0,0,0,0
0,0,0,0,0,0,0,0,0,0,0,0,0,0,0,0,0,0,0,0,0,0,0,0,0,0,0,0,0,0
0,0,0,0,0,0,0,0,0,0,0,0,0,0,0,0,0,0,0,0,0,0,0,0,0,0,0,0,0,0
0,0,0,0,26,0,0,0,0,0,0,0,0,0,0,0,0,0,0,0,0,0,0,0,0,26,0,0,0,0
0,0,0,0,0,0,0,0,0,0,0,0,0,0,0,0,0,0,0,0,0,0,0,0,0,0,0,0,0,0
0,0,0,0,0,0,0,0,0,0,0,0,0,0,0,0,0,0,0,0,0,0,0,0,0,0,0,0,0,0
0,0,0,0,0,0,0,0,0,0,0,0,0,0,0,0,0,0,0,12,0,12,0,0,0,0,0,0,0,0
0,0,0,0,0,0,0,0,0,0,0,0,0,0,0,0,0,0,12,0,0,0,12,0,0,0,0,0,0,0
0,0,0,0,0,0,0,0,0,0,0,0,0,0,0,0,0,0,0,0,6,0,0,0,0,0,0,0,0,0
0,0,0,0,0,0,0,0,0,0,0,0,0,0,0,0,0,0,12,0,0,0,12,0,0,0,0,0,0,0
0,0,0,0,0,0,0,0,0,0,0,0,0,0,0,0,0,0,0,12,0,12,0,0,0,0,0,0,0,0
0,0,0,0,0,0,0,0,0,0,0,0,0,0,0,0,0,0,0,0,0,0,0,0,0,0,0,0,0,0
0,0,0,0,0,0,0,0,0,0,0,0,0,0,0,0,0,0,0,0,0,0,0,0,0,0,0,0,0,0
0,0,0,0,0,0,0,0,0,0,0,0,0,0,0,0,0,0,0,0,0,0,0,0,0,0,0,0,0,0
0,0,0,0,0,0,0,0,0,0,0,0,0,0,0,0,0,0,0,0,0,0,0,0,0,0,0,0,0,0
0,0,0,0,0,0,0,0,0,0,0,0,0,0,0,0,0,0,0,0,0,0,0,0,0,0,0,0,0,0
0,0,0,0,0,0,0,0,0,0,0,0,0,0,0,0,0,0,0,0,0,0,0,0,0,0,0,0,0,0
0,0,0,0,0,0,0,0,0,0,0,0,0,0,0,0,0,0,0,0,0,0,0,0,0,0,0,0,0,0
0,0,0,0,0,0,0,0,0,0,0,0,0,0,0,0,0,0,0,0,0,0,0,0,0,0,0,0,0,0
0,0,0,0,0,0,0,0,0,0,0,0,0,0,0,0,0,0,0,0,0,0,0,0,0,0,0,0,0,0
0,0,0,0,0,0,0,0,0,0,0,0,0,0,0,0,0,0,0,0,0,0,0,0,0,0,0,0,0,0
0,0,0,0,0,0,0,0,0,0,0,0,0,0,0,0,0,0,0,0,0,0,0,0,0,0,0,0,0,0
0,0,0,0,0,0,0,0,0,0,0,0,0,0,0,0,0,0,0,0,0,0,0,0,0,0,0,0,0,0
0,0,0,0,0,0,0,0,0,0,0,0,0,0,0,0,0,0,0,0,0,0,0,0,0,0,0,0,0,0
0,0,0,0,26,0,0,0,0,0,0,0,0,0,0,0,0,0,0,0,0,0,0,0,0,26,0,0,0,0
0,0,0,0,0,0,0,0,0,0,0,0,0,0,0,0,0,0,0,0,0,0,0,0,0,0,0,0,0,0
0,0,0,0,0,0,0,0,0,0,0,0,0,0,0,0,0,0,0,0,0,0,0,0,0,0,0,0,0,0
0,0,0,0,0,0,0,0,0,0,0,0,0,0,0,0,0,0,0,0,0,0,0,0,0,0,0,0,0,0
0,0,0,0,0,0,0,0,0,0,0,0,0,0,0,0,0,0,0,0,0,0,0,0,0,0,0,0,0,0
endlayer

layer
0,0,0,0,0,0,0,0,0,0,0,0,0,0,0,0,0,0,0,0,0,0,0,0,0,0,0,0,0,0
0,0,0,0,0,0,0,0,0,0,0,0,0,0,0,0,0,0,0,0,0,0,0,0,0,0,0,0,0,0
0,0,0,0,0,0,0,0,0,0,0,0,0,0,0,0,0,0,0,0,0,0,0,0,0,0,0,0,0,0
0,0,0,0,0,0,0,0,0,0,0,0,0,0,0,0,0,0,0,0,0,0,0,0,0,0,0,0,0,0
0,0,0,0,26,0,0,0,0,0,0,0,0,0,0,0,0,0,0,0,0,0,0,0,0,26,0,0,0,0
0,0,0,0,0,0,0,0,0,0,0,0,0,0,0,0,0,0,0,0,0,0,0,0,0,0,0,0,0,0
0,0,0,0,0,0,0,0,0,0,0,0,0,0,0,0,0,0,0,0,0,0,0,0,0,0,0,0,0,0
0,0,0,0,0,0,0,0,0,0,0,0,0,0,0,0,0,0,0,12,0,12,0,0,0,0,0,0,0,0
0,0,0,0,0,0,0,0,0,0,0,0,0,0,0,0,0,0,12,0,22,0,12,0,0,0,0,0,0,0
0,0,0,0,0,0,0,0,0,0,0,0,0,0,0,0,0,0,0,23,12,24,0,0,0,0,0,0,0,0
0,0,0,0,0,0,0,0,0,0,0,0,0,0,0,0,0,0,12,0,21,0,12,0,0,0,0,0,0,0
0,0,0,0,0,0,0,0,0,0,0,0,0,0,0,0,0,0,0,12,0,12,0,0,0,0,0,0,0,0
0,0,0,0,0,0,0,0,0,0,0,0,0,0,0,0,0,0,0,0,0,0,0,0,0,0,0,0,0,0
0,0,0,0,0,0,0,0,0,0,0,0,0,0,0,0,0,0,0,0,0,0,0,0,0,0,0,0,0,0
0,0,0,0,0,0,0,0,0,0,0,0,0,0,0,0,0,0,0,0,0,0,0,0,0,0,0,0,0,0
0,0,0,0,0,0,0,0,0,0,0,0,0,0,0,0,0,0,0,0,0,0,0,0,0,0,0,0,0,0
0,0,0,0,0,0,0,0,0,0,0,0,0,0,0,0,0,0,0,0,0,0,0,0,0,0,0,0,0,0
0,0,0,0,0,0,0,0,0,0,0,0,0,0,0,0,0,0,0,0,0,0,0,0,0,0,0,0,0,0
0,0,0,0,0,0,0,0,0,0,0,0,0,0,0,0,0,0,0,0,0,0,0,0,0,0,0,0,0,0
0,0,0,0,0,0,0,0,0,0,0,0,0,0,0,0,0,0,0,0,0,0,0,0,0,0,0,0,0,0
0,0,0,0,0,0,0,0,0,0,0,0,0,0,0,0,0,0,0,0,0,0,0,0,0,0,0,0,0,0
0,0,0,0,0,0,0,0,0,0,0,0,0,0,0,0,0,0,0,0,0,0,0,0,0,0,0,0,0,0
0,0,0,0,0,0,0,0,0,0,0,0,0,0,0,0,0,0,0,0,0,0,0,0,0,0,0,0,0,0
0,0,0,0,0,0,0,0,0,0,0,0,0,0,0,0,0,0,0,0,0,0,0,0,0,0,0,0,0,0
0,0,0,0,0,0,0,0,0,0,0,0,0,0,0,0,0,0,0,0,0,0,0,0,0,0,0,0,0,0
0,0,0,0,26,0,0,0,0,0,0,0,0,0,0,0,0,0,0,0,0,0,0,0,0,26,0,0,0,0
0,0,0,0,0,0,0,0,0,0,0,0,0,0,0,0,0,0,0,0,0,0,0,0,0,0,0,0,0,0
0,0,0,0,0,0,0,0,0,0,0,0,0,0,0,0,0,0,0,0,0,0,0,0,0,0,0,0,0,0
0,0,0,0,0,0,0,0,0,0,0,0,0,0,0,0,0,0,0,0,0,0,0,0,0,0,0,0,0,0
0,0,0,0,0,0,0,0,0,0,0,0,0,0,0,0,0,0,0,0,0,0,0,0,0,0,0,0,0,0
endlayer

layer
0,0,0,0,0,0,0,0,0,0,0,0,0,0,0,0,0,0,0,0,0,0,0,0,0,0,0,0,0,0
0,0,0,0,0,0,0,0,0,0,0,0,0,0,0,0,0,0,0,0,0,0,0,0,0,0,0,0,0,0
0,0,0,0,0,0,0,0,0,0,0,0,0,0,0,0,0,0,0,0,0,0,0,0,0,0,0,0,0,0
0,0,0,0,0,0,0,0,0,0,0,0,0,0,0,0,0,0,0,0,0,0,0,0,0,0,0,0,0,0
0,0,0,0,26,0,0,0,0,0,0,0,0,0,0,0,0,0,0,0,0,0,0,0,0,26,0,0,0,0
0,0,0,0,0,0,0,0,0,0,0,0,0,0,0,0,0,0,0,0,0,0,0,0,0,0,0,0,0,0
0,0,0,0,0,0,0,0,0,0,0,0,0,0,0,0,0,0,5,5,5,5,5,0,0,0,0,0,0,0
0,0,0,0,0,0,0,0,0,0,0,0,0,0,0,0,0,5,5,12,22,12,5,5,0,0,0,0,0,0
0,0,0,0,0,0,0,0,0,0,0,0,0,0,0,0,0,5,12,23,12,22,12,5,0,0,0,0,0,0
0,0,0,0,0,0,0,0,0,0,0,0,0,0,0,0,0,5,23,12,12,12,24,5,0,0,0,0,0,0
0,0,0,0,0,0,0,0,0,0,0,0,0,0,0,0,0,5,12,21,12,24,12,5,0,0,0,0,0,0
0,0,0,0,0,0,0,0,0,0,0,0,0,0,0,0,0,5,5,12,21,12,5,5,0,0,0,0,0,0
0,0,0,0,0,0,0,0,0,0,0,0,0,0,0,0,0,0,5,5,5,5,5,0,0,0,0,0,0,0
0,0,0,0,0,0,0,0,0,0,0,0,0,0,0,0,0,0,0,0,0,0,0,0,0,0,0,0,0,0
0,0,0,0,0,0,0,0,0,0,0,0,0,0,0,0,0,0,0,0,0,0,0,0,0,0,0,0,0,0
0,0,0,0,0,0,0,0,0,0,0,0,0,0,0,0,0,0,0,0,0,0,0,0,0,0,0,0,0,0
0,0,0,0,0,0,0,0,0,0,0,0,0,0,0,0,0,0,0,0,0,0,0,0,0,0,0,0,0,0
0,0,0,0,0,0,0,0,0,0,0,0,0,0,0,0,0,0,0,0,0,0,0,0,0,0,0,0,0,0
0,0,0,0,0,0,0,0,0,0,0,0,0,0,0,0,0,0,0,0,0,0,0,0,0,0,0,0,0,0
0,0,0,0,0,0,0,0,0,0,0,0,0,0,0,0,0,0,0,0,0,0,0,0,0,0,0,0,0,0
0,0,0,0,0,0,0,0,0,0,0,0,0,0,0,0,0,0,0,0,0,0,0,0,0,0,0,0,0,0
0,0,0,0,0,0,0,0,0,0,0,0,0,0,0,0,0,0,0,0,0,0,0,0,0,0,0,0,0,0
0,0,0,0,0,0,0,0,0,0,0,0,0,0,0,0,0,0,0,0,0,0,0,0,0,0,0,0,0,0
0,0,0,0,0,0,0,0,0,0,0,0,0,0,0,0,0,0,0,0,0,0,0,0,0,0,0,0,0,0
0,0,0,0,0,0,0,0,0,0,0,0,0,0,0,0,0,0,0,0,0,0,0,0,0,0,0,0,0,0
0,0,0,0,26,0,0,0,0,0,0,0,0,0,0,0,0,0,0,0,0,0,0,0,0,26,0,0,0,0
0,0,0,0,0,0,0,0,0,0,0,0,0,0,0,0,0,0,0,0,0,0,0,0,0,0,0,0,0,0
0,0,0,0,0,0,0,0,0,0,0,0,0,0,0,0,0,0,0,0,0,0,0,0,0,0,0,0,0,0
0,0,0,0,0,0,0,0,0,0,0,0,0,0,0,0,0,0,0,0,0,0,0,0,0,0,0,0,0,0
0,0,0,0,0,0,0,0,0,0,0,0,0,0,0,0,0,0,0,0,0,0,0,0,0,0,0,0,0,0
endlayer

layer
0,0,0,0,0,0,0,0,0,0,0,0,0,0,0,0,0,0,0,0,0,0,0,0,0,0,0,0,0,0
0,0,0,0,0,0,0,0,0,0,0,0,0,0,0,0,0,0,0,0,0,0,0,0,0,0,0,0,0,0
0,0,0,0,0,0,0,0,0,0,0,0,0,0,0,0,0,0,0,0,0,0,0,0,0,0,0,0,0,0
0,0,0,0,0,0,0,0,0,0,0,0,0,0,0,0,0,0,0,0,0,0,0,0,0,0,0,0,0,0
0,0,0,0,0,0,0,0,0,0,0,0,0,0,0,0,0,0,0,0,0,0,0,0,0,0,0,0,0,0
0,0,0,0,0,0,0,0,0,0,0,0,0,0,0,0,0,0,0,0,0,0,0,0,0,0,0,0,0,0
0,0,0,0,0,0,0,0,0,0,0,0,0,0,0,0,0,0,0,5,5,5,0,0,0,0,0,0,0,0
0,0,0,0,0,0,0,0,0,0,0,0,0,0,0,0,0,0,5,12,12,12,5,0,0,0,0,0,0,0
0,0,0,0,0,0,0,0,0,0,0,0,0,0,0,0,0,5,12,12,8,12,12,5,0,0,0,0,0,0
0,0,0,0,0,0,0,0,0,0,0,0,0,0,0,0,0,5,12,8,8,8,12,5,0,0,0,0,0,0
0,0,0,0,0,0,0,0,0,0,0,0,0,0,0,0,0,5,12,12,8,12,12,5,0,0,0,0,0,0
0,0,0,0,0,0,0,0,0,0,0,0,0,0,0,0,0,0,5,12,12,12,5,0,0,0,0,0,0,0
0,0,0,0,0,0,0,0,0,0,0,0,0,0,0,0,0,0,0,5,5,5,0,0,0,0,0,0,0,0
0,0,0,0,0,0,0,0,0,0,0,0,0,0,0,0,0,0,0,0,0,0,0,0,0,0,0,0,0,0
0,0,0,0,0,0,0,0,0,0,0,0,0,0,0,0,0,0,0,0,0,0,0,0,0,0,0,0,0,0
0,0,0,0,0,0,0,0,0,0,0,0,0,0,0,0,0,0,0,0,0,0,0,0,0,0,0,0,0,0
0,0,0,0,0,0,0,0,0,0,0,0,0,0,0,0,0,0,0,0,0,0,0,0,0,0,0,0,0,0
0,0,0,0,0,0,0,0,0,0,0,0,0,0,0,0,0,0,0,0,0,0,0,0,0,0,0,0,0,0
0,0,0,0,0,0,0,0,0,0,0,0,0,0,0,0,0,0,0,0,0,0,0,0,0,0,0,0,0,0
0,0,0,0,0,0,0,0,0,0,0,0,0,0,0,0,0,0,0,0,0,0,0,0,0,0,0,0,0,0
0,0,0,0,0,0,0,0,0,0,0,0,0,0,0,0,0,0,0,0,0,0,0,0,0,0,0,0,0,0
0,0,0,0,0,0,0,0,0,0,0,0,0,0,0,0,0,0,0,0,0,0,0,0,0,0,0,0,0,0
0,0,0,0,0,0,0,0,0,0,0,0,0,0,0,0,0,0,0,0,0,0,0,0,0,0,0,0,0,0
0,0,0,0,0,0,0,0,0,0,0,0,0,0,0,0,0,0,0,0,0,0,0,0,0,0,0,0,0,0
0,0,0,0,0,0,0,0,0,0,0,0,0,0,0,0,0,0,0,0,0,0,0,0,0,0,0,0,0,0
0,0,0,0,0,0,0,0,0,0,0,0,0,0,0,0,0,0,0,0,0,0,0,0,0,0,0,0,0,0
0,0,0,0,0,0,0,0,0,0,0,0,0,0,0,0,0,0,0,0,0,0,0,0,0,0,0,0,0,0
0,0,0,0,0,0,0,0,0,0,0,0,0,0,0,0,0,0,0,0,0,0,0,0,0,0,0,0,0,0
0,0,0,0,0,0,0,0,0,0,0,0,0,0,0,0,0,0,0,0,0,0,0,0,0,0,0,0,0,0
0,0,0,0,0,0,0,0,0,0,0,0,0,0,0,0,0,0,0,0,0,0,0,0,0,0,0,0,0,0
endlayer

layer
0,0,0,0,0,0,0,0,0,0,0,0,0,0,0,0,0,0,0,0,0,0,0,0,0,0,0,0,0,0
0,0,0,0,0,0,0,0,0,0,0,0,0,0,0,0,0,0,0,0,0,0,0,0,0,0,0,0,0,0
0,0,0,0,0,0,0,0,0,0,0,0,0,0,0,0,0,0,0,0,0,0,0,0,0,0,0,0,0,0
0,0,0,0,0,0,0,0,0,0,0,0,0,0,0,0,0,0,0,0,0,0,0,0,0,0,0,0,0,0
0,0,0,0,0,0,0,0,0,0,0,0,0,0,0,0,0,0,0,0,0,0,0,0,0,0,0,0,0,0
0,0,0,0,0,0,0,0,0,0,0,0,0,0,0,0,0,0,0,0,0,0,0,0,0,0,0,0,0,0
0,0,0,0,0,0,0,0,0,0,0,0,0,0,0,0,0,0,0,0,5,0,0,0,0,0,0,0,0,0
0,0,0,0,0,0,0,0,0,0,0,0,0,0,0,0,0,0,0,5,12,5,0,0,0,0,0,0,0,0
0,0,0,0,0,0,0,0,0,0,0,0,0,0,0,0,0,0,5,8,5,8,5,0,0,0,0,0,0,0
0,0,0,0,0,0,0,0,0,0,0,0,0,0,0,0,0,5,12,5,5,5,12,5,0,0,0,0,0,0
0,0,0,0,0,0,0,0,0,0,0,0,0,0,0,0,0,0,5,8,5,8,5,0,0,0,0,0,0,0
0,0,0,0,0,0,0,0,0,0,0,0,0,0,0,0,0,0,0,5,12,5,0,0,0,0,0,0,0,0
0,0,0,0,0,0,0,0,0,0,0,0,0,0,0,0,0,0,0,0,5,0,0,0,0,0,0,0,0,0
0,0,0,0,0,0,0,0,0,0,0,0,0,0,0,0,0,0,0,0,0,0,0,0,0,0,0,0,0,0
0,0,0,0,0,0,0,0,0,0,0,0,0,0,0,0,0,0,0,0,0,0,0,0,0,0,0,0,0,0
0,0,0,0,0,0,0,0,0,0,0,0,0,0,0,0,0,0,0,0,0,0,0,0,0,0,0,0,0,0
0,0,0,0,0,0,0,0,0,0,0,0,0,0,0,0,0,0,0,0,0,0,0,0,0,0,0,0,0,0
0,0,0,0,0,0,0,0,0,0,0,0,0,0,0,0,0,0,0,0,0,0,0,0,0,0,0,0,0,0
0,0,0,0,0,0,0,0,0,0,0,0,0,0,0,0,0,0,0,0,0,0,0,0,0,0,0,0,0,0
0,0,0,0,0,0,0,0,0,0,0,0,0,0,0,0,0,0,0,0,0,0,0,0,0,0,0,0,0,0
0,0,0,0,0,0,0,0,0,0,0,0,0,0,0,0,0,0,0,0,0,0,0,0,0,0,0,0,0,0
0,0,0,0,0,0,0,0,0,0,0,0,0,0,0,0,0,0,0,0,0,0,0,0,0,0,0,0,0,0
0,0,0,0,0,0,0,0,0,0,0,0,0,0,0,0,0,0,0,0,0,0,0,0,0,0,0,0,0,0
0,0,0,0,0,0,0,0,0,0,0,0,0,0,0,0,0,0,0,0,0,0,0,0,0,0,0,0,0,0
0,0,0,0,0,0,0,0,0,0,0,0,0,0,0,0,0,0,0,0,0,0,0,0,0,0,0,0,0,0
0,0,0,0,0,0,0,0,0,0,0,0,0,0,0,0,0,0,0,0,0,0,0,0,0,0,0,0,0,0
0,0,0,0,0,0,0,0,0,0,0,0,0,0,0,0,0,0,0,0,0,0,0,0,0,0,0,0,0,0
0,0,0,0,0,0,0,0,0,0,0,0,0,0,0,0,0,0,0,0,0,0,0,0,0,0,0,0,0,0
0,0,0,0,0,0,0,0,0,0,0,0,0,0,0,0,0,0,0,0,0,0,0,0,0,0,0,0,0,0
0,0,0,0,0,0,0,0,0,0,0,0,0,0,0,0,0,0,0,0,0,0,0,0,0,0,0,0,0,0
endlayer

layer
0,0,0,0,0,0,0,0,0,0,0,0,0,0,0,0,0,0,0,0,0,0,0,0,0,0,0,0,0,0
0,0,0,0,0,0,0,0,0,0,0,0,0,0,0,0,0,0,0,0,0,0,0,0,0,0,0,0,0,0
0,0,0,0,0,0,0,0,0,0,0,0,0,0,0,0,0,0,0,0,0,0,0,0,0,0,0,0,0,0
0,0,0,0,0,0,0,0,0,0,0,0,0,0,0,0,0,0,0,0,0,0,0,0,0,0,0,0,0,0
0,0,0,0,0,0,0,0,0,0,0,0,0,0,0,0,0,0,0,0,0,0,0,0,0,0,0,0,0,0
0,0,0,0,0,0,0,0,0,0,0,0,0,0,0,0,0,0,0,0,0,0,0,0,0,0,0,0,0,0
0,0,0,0,0,0,0,0,0,0,0,0,0,0,0,0,0,0,0,0,5,0,0,0,0,0,0,0,0,0
0,0,0,0,0,0,0,0,0,0,0,0,0,0,0,0,0,0,0,5,12,5,0,0,0,0,0,0,0,0
0,0,0,0,0,0,0,0,0,0,0,0,0,0,0,0,0,0,5,5,5,5,5,0,0,0,0,0,0,0
0,0,0,0,0,0,0,0,0,0,0,0,0,0,0,0,0,5,12,5,5,5,12,5,0,0,0,0,0,0
0,0,0,0,0,0,0,0,0,0,0,0,0,0,0,0,0,0,5,5,5,5,5,0,0,0,0,0,0,0
0,0,0,0,0,0,0,0,0,0,0,0,0,0,0,0,0,0,0,5,12,5,0,0,0,0,0,0,0,0
0,0,0,0,0,0,0,0,0,0,0,0,0,0,0,0,0,0,0,0,5,0,0,0,0,0,0,0,0,0
0,0,0,0,0,0,0,0,0,0,0,0,0,0,0,0,0,0,0,0,0,0,0,0,0,0,0,0,0,0
0,0,0,0,0,0,0,0,0,0,0,0,0,0,0,0,0,0,0,0,0,0,0,0,0,0,0,0,0,0
0,0,0,0,0,0,0,0,0,0,0,0,0,0,0,0,0,0,0,0,0,0,0,0,0,0,0,0,0,0
0,0,0,0,0,0,0,0,0,0,0,0,0,0,0,0,0,0,0,0,0,0,0,0,0,0,0,0,0,0
0,0,0,0,0,0,0,0,0,0,0,0,0,0,0,0,0,0,0,0,0,0,0,0,0,0,0,0,0,0
0,0,0,0,0,0,0,0,0,0,0,0,0,0,0,0,0,0,0,0,0,0,0,0,0,0,0,0,0,0
0,0,0,0,0,0,0,0,0,0,0,0,0,0,0,0,0,0,0,0,0,0,0,0,0,0,0,0,0,0
0,0,0,0,0,0,0,0,0,0,0,0,0,0,0,0,0,0,0,0,0,0,0,0,0,0,0,0,0,0
0,0,0,0,0,0,0,0,0,0,0,0,0,0,0,0,0,0,0,0,0,0,0,0,0,0,0,0,0,0
0,0,0,0,0,0,0,0,0,0,0,0,0,0,0,0,0,0,0,0,0,0,0,0,0,0,0,0,0,0
0,0,0,0,0,0,0,0,0,0,0,0,0,0,0,0,0,0,0,0,0,0,0,0,0,0,0,0,0,0
0,0,0,0,0,0,0,0,0,0,0,0,0,0,0,0,0,0,0,0,0,0,0,0,0,0,0,0,0,0
0,0,0,0,0,0,0,0,0,0,0,0,0,0,0,0,0,0,0,0,0,0,0,0,0,0,0,0,0,0
0,0,0,0,0,0,0,0,0,0,0,0,0,0,0,0,0,0,0,0,0,0,0,0,0,0,0,0,0,0
0,0,0,0,0,0,0,0,0,0,0,0,0,0,0,0,0,0,0,0,0,0,0,0,0,0,0,0,0,0
0,0,0,0,0,0,0,0,0,0,0,0,0,0,0,0,0,0,0,0,0,0,0,0,0,0,0,0,0,0
0,0,0,0,0,0,0,0,0,0,0,0,0,0,0,0,0,0,0,0,0,0,0,0,0,0,0,0,0,0
endlayer

layer
0,0,0,0,0,0,0,0,0,0,0,0,0,0,0,0,0,0,0,0,0,0,0,0,0,0,0,0,0,0
0,0,0,0,0,0,0,0,0,0,0,0,0,0,0,0,0,0,0,0,0,0,0,0,0,0,0,0,0,0
0,0,0,0,0,0,0,0,0,0,0,0,0,0,0,0,0,0,0,0,0,0,0,0,0,0,0,0,0,0
0,0,0,0,0,0,0,0,0,0,0,0,0,0,0,0,0,0,0,0,0,0,0,0,0,0,0,0,0,0
0,0,0,0,0,0,0,0,0,0,0,0,0,0,0,0,0,0,0,0,0,0,0,0,0,0,0,0,0,0
0,0,0,0,0,0,0,0,0,0,0,0,0,0,0,0,0,0,0,0,0,0,0,0,0,0,0,0,0,0
0,0,0,0,0,0,0,0,0,0,0,0,0,0,0,0,0,0,0,0,0,0,0,0,0,0,0,0,0,0
0,0,0,0,0,0,0,0,0,0,0,0,0,0,0,0,0,0,0,0,12,0,0,0,0,0,0,0,0,0
0,0,0,0,0,0,0,0,0,0,0,0,0,0,0,0,0,0,0,5,5,5,0,0,0,0,0,0,0,0
0,0,0,0,0,0,0,0,0,0,0,0,0,0,0,0,0,0,12,5,5,5,12,0,0,0,0,0,0,0
0,0,0,0,0,0,0,0,0,0,0,0,0,0,0,0,0,0,0,5,5,5,0,0,0,0,0,0,0,0
0,0,0,0,0,0,0,0,0,0,0,0,0,0,0,0,0,0,0,0,12,0,0,0,0,0,0,0,0,0
0,0,0,0,0,0,0,0,0,0,0,0,0,0,0,0,0,0,0,0,0,0,0,0,0,0,0,0,0,0
0,0,0,0,0,0,0,0,0,0,0,0,0,0,0,0,0,0,0,0,0,0,0,0,0,0,0,0,0,0
0,0,0,0,0,0,0,0,0,0,0,0,0,0,0,0,0,0,0,0,0,0,0,0,0,0,0,0,0,0
0,0,0,0,0,0,0,0,0,0,0,0,0,0,0,0,0,0,0,0,0,0,0,0,0,0,0,0,0,0
0,0,0,0,0,0,0,0,0,0,0,0,0,0,0,0,0,0,0,0,0,0,0,0,0,0,0,0,0,0
0,0,0,0,0,0,0,0,0,0,0,0,0,0,0,0,0,0,0,0,0,0,0,0,0,0,0,0,0,0
0,0,0,0,0,0,0,0,0,0,0,0,0,0,0,0,0,0,0,0,0,0,0,0,0,0,0,0,0,0
0,0,0,0,0,0,0,0,0,0,0,0,0,0,0,0,0,0,0,0,0,0,0,0,0,0,0,0,0,0
0,0,0,0,0,0,0,0,0,0,0,0,0,0,0,0,0,0,0,0,0,0,0,0,0,0,0,0,0,0
0,0,0,0,0,0,0,0,0,0,0,0,0,0,0,0,0,0,0,0,0,0,0,0,0,0,0,0,0,0
0,0,0,0,0,0,0,0,0,0,0,0,0,0,0,0,0,0,0,0,0,0,0,0,0,0,0,0,0,0
0,0,0,0,0,0,0,0,0,0,0,0,0,0,0,0,0,0,0,0,0,0,0,0,0,0,0,0,0,0
0,0,0,0,0,0,0,0,0,0,0,0,0,0,0,0,0,0,0,0,0,0,0,0,0,0,0,0,0,0
0,0,0,0,0,0,0,0,0,0,0,0,0,0,0,0,0,0,0,0,0,0,0,0,0,0,0,0,0,0
0,0,0,0,0,0,0,0,0,0,0,0,0,0,0,0,0,0,0,0,0,0,0,0,0,0,0,0,0,0
0,0,0,0,0,0,0,0,0,0,0,0,0,0,0,0,0,0,0,0,0,0,0,0,0,0,0,0,0,0
0,0,0,0,0,0,0,0,0,0,0,0,0,0,0,0,0,0,0,0,0,0,0,0,0,0,0,0,0,0
0,0,0,0,0,0,0,0,0,0,0,0,0,0,0,0,0,0,0,0,0,0,0,0,0,0,0,0,0,0
endlayer

layer
0,0,0,0,0,0,0,0,0,0,0,0,0,0,0,0,0,0,0,0,0,0,0,0,0,0,0,0,0,0
0,0,0,0,0,0,0,0,0,0,0,0,0,0,0,0,0,0,0,0,0,0,0,0,0,0,0,0,0,0
0,0,0,0,0,0,0,0,0,0,0,0,0,0,0,0,0,0,0,0,0,0,0,0,0,0,0,0,0,0
0,0,0,0,0,0,0,0,0,0,0,0,0,0,0,0,0,0,0,0,0,0,0,0,0,0,0,0,0,0
0,0,0,0,0,0,0,0,0,0,0,0,0,0,0,0,0,0,0,0,0,0,0,0,0,0,0,0,0,0
0,0,0,0,0,0,0,0,0,0,0,0,0,0,0,0,0,0,0,0,0,0,0,0,0,0,0,0,0,0
0,0,0,0,0,0,0,0,0,0,0,0,0,0,0,0,0,0,0,0,0,0,0,0,0,0,0,0,0,0
0,0,0,0,0,0,0,0,0,0,0,0,0,0,0,0,0,0,0,0,12,0,0,0,0,0,0,0,0,0
0,0,0,0,0,0,0,0,0,0,0,0,0,0,0,0,0,0,0,5,5,5,0,0,0,0,0,0,0,0
0,0,0,0,0,0,0,0,0,0,0,0,0,0,0,0,0,0,12,5,5,5,12,0,0,0,0,0,0,0
0,0,0,0,0,0,0,0,0,0,0,0,0,0,0,0,0,0,0,5,5,5,0,0,0,0,0,0,0,0
0,0,0,0,0,0,0,0,0,0,0,0,0,0,0,0,0,0,0,0,12,0,0,0,0,0,0,0,0,0
0,0,0,0,0,0,0,0,0,0,0,0,0,0,0,0,0,0,0,0,0,0,0,0,0,0,0,0,0,0
0,0,0,0,0,0,0,0,0,0,0,0,0,0,0,0,0,0,0,0,0,0,0,0,0,0,0,0,0,0
0,0,0,0,0,0,0,0,0,0,0,0,0,0,0,0,0,0,0,0,0,0,0,0,0,0,0,0,0,0
0,0,0,0,0,0,0,0,0,0,0,0,0,0,0,0,0,0,0,0,0,0,0,0,0,0,0,0,0,0
0,0,0,0,0,0,0,0,0,0,0,0,0,0,0,0,0,0,0,0,0,0,0,0,0,0,0,0,0,0
0,0,0,0,0,0,0,0,0,0,0,0,0,0,0,0,0,0,0,0,0,0,0,0,0,0,0,0,0,0
0,0,0,0,0,0,0,0,0,0,0,0,0,0,0,0,0,0,0,0,0,0,0,0,0,0,0,0,0,0
0,0,0,0,0,0,0,0,0,0,0,0,0,0,0,0,0,0,0,0,0,0,0,0,0,0,0,0,0,0
0,0,0,0,0,0,0,0,0,0,0,0,0,0,0,0,0,0,0,0,0,0,0,0,0,0,0,0,0,0
0,0,0,0,0,0,0,0,0,0,0,0,0,0,0,0,0,0,0,0,0,0,0,0,0,0,0,0,0,0
0,0,0,0,0,0,0,0,0,0,0,0,0,0,0,0,0,0,0,0,0,0,0,0,0,0,0,0,0,0
0,0,0,0,0,0,0,0,0,0,0,0,0,0,0,0,0,0,0,0,0,0,0,0,0,0,0,0,0,0
0,0,0,0,0,0,0,0,0,0,0,0,0,0,0,0,0,0,0,0,0,0,0,0,0,0,0,0,0,0
0,0,0,0,0,0,0,0,0,0,0,0,0,0,0,0,0,0,0,0,0,0,0,0,0,0,0,0,0,0
0,0,0,0,0,0,0,0,0,0,0,0,0,0,0,0,0,0,0,0,0,0,0,0,0,0,0,0,0,0
0,0,0,0,0,0,0,0,0,0,0,0,0,0,0,0,0,0,0,0,0,0,0,0,0,0,0,0,0,0
0,0,0,0,0,0,0,0,0,0,0,0,0,0,0,0,0,0,0,0,0,0,0,0,0,0,0,0,0,0
0,0,0,0,0,0,0,0,0,0,0,0,0,0,0,0,0,0,0,0,0,0,0,0,0,0,0,0,0,0
endlayer

layer
0,0,0,0,0,0,0,0,0,0,0,0,0,0,0,0,0,0,0,0,0,0,0,0,0,0,0,0,0,0
0,0,0,0,0,0,0,0,0,0,0,0,0,0,0,0,0,0,0,0,0,0,0,0,0,0,0,0,0,0
0,0,0,0,0,0,0,0,0,0,0,0,0,0,0,0,0,0,0,0,0,0,0,0,0,0,0,0,0,0
0,0,0,0,0,0,0,0,0,0,0,0,0,0,0,0,0,0,0,0,0,0,0,0,0,0,0,0,0,0
0,0,0,0,0,0,0,0,0,0,0,0,0,0,0,0,0,0,0,0,0,0,0,0,0,0,0,0,0,0
0,0,0,0,0,0,0,0,0,0,0,0,0,0,0,0,0,0,0,0,0,0,0,0,0,0,0,0,0,0
0,0,0,0,0,0,0,0,0,0,0,0,0,0,0,0,0,0,0,0,0,0,0,0,0,0,0,0,0,0
0,0,0,0,0,0,0,0,0,0,0,0,0,0,0,0,0,0,0,0,0,0,0,0,0,0,0,0,0,0
0,0,0,0,0,0,0,0,0,0,0,0,0,0,0,0,0,0,0,0,5,0,0,0,0,0,0,0,0,0
0,0,0,0,0,0,0,0,0,0,0,0,0,0,0,0,0,0,0,5,5,5,0,0,0,0,0,0,0,0
0,0,0,0,0,0,0,0,0,0,0,0,0,0,0,0,0,0,0,0,5,0,0,0,0,0,0,0,0,0
0,0,0,0,0,0,0,0,0,0,0,0,0,0,0,0,0,0,0,0,0,0,0,0,0,0,0,0,0,0
0,0,0,0,0,0,0,0,0,0,0,0,0,0,0,0,0,0,0,0,0,0,0,0,0,0,0,0,0,0
0,0,0,0,0,0,0,0,0,0,0,0,0,0,0,0,0,0,0,0,0,0,0,0,0,0,0,0,0,0
0,0,0,0,0,0,0,0,0,0,0,0,0,0,0,0,0,0,0,0,0,0,0,0,0,0,0,0,0,0
0,0,0,0,0,0,0,0,0,0,0,0,0,0,0,0,0,0,0,0,0,0,0,0,0,0,0,0,0,0
0,0,0,0,0,0,0,0,0,0,0,0,0,0,0,0,0,0,0,0,0,0,0,0,0,0,0,0,0,0
0,0,0,0,0,0,0,0,0,0,0,0,0,0,0,0,0,0,0,0,0,0,0,0,0,0,0,0,0,0
0,0,0,0,0,0,0,0,0,0,0,0,0,0,0,0,0,0,0,0,0,0,0,0,0,0,0,0,0,0
0,0,0,0,0,0,0,0,0,0,0,0,0,0,0,0,0,0,0,0,0,0,0,0,0,0,0,0,0,0
0,0,0,0,0,0,0,0,0,0,0,0,0,0,0,0,0,0,0,0,0,0,0,0,0,0,0,0,0,0
0,0,0,0,0,0,0,0,0,0,0,0,0,0,0,0,0,0,0,0,0,0,0,0,0,0,0,0,0,0
0,0,0,0,0,0,0,0,0,0,0,0,0,0,0,0,0,0,0,0,0,0,0,0,0,0,0,0,0,0
0,0,0,0,0,0,0,0,0,0,0,0,0,0,0,0,0,0,0,0,0,0,0,0,0,0,0,0,0,0
0,0,0,0,0,0,0,0,0,0,0,0,0,0,0,0,0,0,0,0,0,0,0,0,0,0,0,0,0,0
0,0,0,0,0,0,0,0,0,0,0,0,0,0,0,0,0,0,0,0,0,0,0,0,0,0,0,0,0,0
0,0,0,0,0,0,0,0,0,0,0,0,0,0,0,0,0,0,0,0,0,0,0,0,0,0,0,0,0,0
0,0,0,0,0,0,0,0,0,0,0,0,0,0,0,0,0,0,0,0,0,0,0,0,0,0,0,0,0,0
0,0,0,0,0,0,0,0,0,0,0,0,0,0,0,0,0,0,0,0,0,0,0,0,0,0,0,0,0,0
0,0,0,0,0,0,0,0,0,0,0,0,0,0,0,0,0,0,0,0,0,0,0,0,0,0,0,0,0,0
endlayer

layer
0,0,0,0,0,0,0,0,0,0,0,0,0,0,0,0,0,0,0,0,0,0,0,0,0,0,0,0,0,0
0,0,0,0,0,0,0,0,0,0,0,0,0,0,0,0,0,0,0,0,0,0,0,0,0,0,0,0,0,0
0,0,0,0,0,0,0,0,0,0,0,0,0,0,0,0,0,0,0,0,0,0,0,0,0,0,0,0,0,0
0,0,0,0,0,0,0,0,0,0,0,0,0,0,0,0,0,0,0,0,0,0,0,0,0,0,0,0,0,0
0,0,0,0,0,0,0,0,0,0,0,0,0,0,0,0,0,0,0,0,0,0,0,0,0,0,0,0,0,0
0,0,0,0,0,0,0,0,0,0,0,0,0,0,0,0,0,0,0,0,0,0,0,0,0,0,0,0,0,0
0,0,0,0,0,0,0,0,0,0,0,0,0,0,0,0,0,0,0,0,0,0,0,0,0,0,0,0,0,0
0,0,0,0,0,0,0,0,0,0,0,0,0,0,0,0,0,0,0,0,0,0,0,0,0,0,0,0,0,0
0,0,0,0,0,0,0,0,0,0,0,0,0,0,0,0,0,0,0,0,5,0,0,0,0,0,0,0,0,0
0,0,0,0,0,0,0,0,0,0,0,0,0,0,0,0,0,0,0,5,5,5,0,0,0,0,0,0,0,0
0,0,0,0,0,0,0,0,0,0,0,0,0,0,0,0,0,0,0,0,5,0,0,0,0,0,0,0,0,0
0,0,0,0,0,0,0,0,0,0,0,0,0,0,0,0,0,0,0,0,0,0,0,0,0,0,0,0,0,0
0,0,0,0,0,0,0,0,0,0,0,0,0,0,0,0,0,0,0,0,0,0,0,0,0,0,0,0,0,0
0,0,0,0,0,0,0,0,0,0,0,0,0,0,0,0,0,0,0,0,0,0,0,0,0,0,0,0,0,0
0,0,0,0,0,0,0,0,0,0,0,0,0,0,0,0,0,0,0,0,0,0,0,0,0,0,0,0,0,0
0,0,0,0,0,0,0,0,0,0,0,0,0,0,0,0,0,0,0,0,0,0,0,0,0,0,0,0,0,0
0,0,0,0,0,0,0,0,0,0,0,0,0,0,0,0,0,0,0,0,0,0,0,0,0,0,0,0,0,0
0,0,0,0,0,0,0,0,0,0,0,0,0,0,0,0,0,0,0,0,0,0,0,0,0,0,0,0,0,0
0,0,0,0,0,0,0,0,0,0,0,0,0,0,0,0,0,0,0,0,0,0,0,0,0,0,0,0,0,0
0,0,0,0,0,0,0,0,0,0,0,0,0,0,0,0,0,0,0,0,0,0,0,0,0,0,0,0,0,0
0,0,0,0,0,0,0,0,0,0,0,0,0,0,0,0,0,0,0,0,0,0,0,0,0,0,0,0,0,0
0,0,0,0,0,0,0,0,0,0,0,0,0,0,0,0,0,0,0,0,0,0,0,0,0,0,0,0,0,0
0,0,0,0,0,0,0,0,0,0,0,0,0,0,0,0,0,0,0,0,0,0,0,0,0,0,0,0,0,0
0,0,0,0,0,0,0,0,0,0,0,0,0,0,0,0,0,0,0,0,0,0,0,0,0,0,0,0,0,0
0,0,0,0,0,0,0,0,0,0,0,0,0,0,0,0,0,0,0,0,0,0,0,0,0,0,0,0,0,0
0,0,0,0,0,0,0,0,0,0,0,0,0,0,0,0,0,0,0,0,0,0,0,0,0,0,0,0,0,0
0,0,0,0,0,0,0,0,0,0,0,0,0,0,0,0,0,0,0,0,0,0,0,0,0,0,0,0,0,0
0,0,0,0,0,0,0,0,0,0,0,0,0,0,0,0,0,0,0,0,0,0,0,0,0,0,0,0,0,0
0,0,0,0,0,0,0,0,0,0,0,0,0,0,0,0,0,0,0,0,0,0,0,0,0,0,0,0,0,0
0,0,0,0,0,0,0,0,0,0,0,0,0,0,0,0,0,0,0,0,0,0,0,0,0,0,0,0,0,0
endlayer

layer
0,0,0,0,0,0,0,0,0,0,0,0,0,0,0,0,0,0,0,0,0,0,0,0,0,0,0,0,0,0
0,0,0,0,0,0,0,0,0,0,0,0,0,0,0,0,0,0,0,0,0,0,0,0,0,0,0,0,0,0
0,0,0,0,0,0,0,0,0,0,0,0,0,0,0,0,0,0,0,0,0,0,0,0,0,0,0,0,0,0
0,0,0,0,0,0,0,0,0,0,0,0,0,0,0,0,0,0,0,0,0,0,0,0,0,0,0,0,0,0
0,0,0,0,0,0,0,0,0,0,0,0,0,0,0,0,0,0,0,0,0,0,0,0,0,0,0,0,0,0
0,0,0,0,0,0,0,0,0,0,0,0,0,0,0,0,0,0,0,0,0,0,0,0,0,0,0,0,0,0
0,0,0,0,0,0,0,0,0,0,0,0,0,0,0,0,0,0,0,0,0,0,0,0,0,0,0,0,0,0
0,0,0,0,0,0,0,0,0,0,0,0,0,0,0,0,0,0,0,0,0,0,0,0,0,0,0,0,0,0
0,0,0,0,0,0,0,0,0,0,0,0,0,0,0,0,0,0,0,0,0,0,0,0,0,0,0,0,0,0
0,0,0,0,0,0,0,0,0,0,0,0,0,0,0,0,0,0,0,0,5,0,0,0,0,0,0,0,0,0
0,0,0,0,0,0,0,0,0,0,0,0,0,0,0,0,0,0,0,0,0,0,0,0,0,0,0,0,0,0
0,0,0,0,0,0,0,0,0,0,0,0,0,0,0,0,0,0,0,0,0,0,0,0,0,0,0,0,0,0
0,0,0,0,0,0,0,0,0,0,0,0,0,0,0,0,0,0,0,0,0,0,0,0,0,0,0,0,0,0
0,0,0,0,0,0,0,0,0,0,0,0,0,0,0,0,0,0,0,0,0,0,0,0,0,0,0,0,0,0
0,0,0,0,0,0,0,0,0,0,0,0,0,0,0,0,0,0,0,0,0,0,0,0,0,0,0,0,0,0
0,0,0,0,0,0,0,0,0,0,0,0,0,0,0,0,0,0,0,0,0,0,0,0,0,0,0,0,0,0
0,0,0,0,0,0,0,0,0,0,0,0,0,0,0,0,0,0,0,0,0,0,0,0,0,0,0,0,0,0
0,0,0,0,0,0,0,0,0,0,0,0,0,0,0,0,0,0,0,0,0,0,0,0,0,0,0,0,0,0
0,0,0,0,0,0,0,0,0,0,0,0,0,0,0,0,0,0,0,0,0,0,0,0,0,0,0,0,0,0
0,0,0,0,0,0,0,0,0,0,0,0,0,0,0,0,0,0,0,0,0,0,0,0,0,0,0,0,0,0
0,0,0,0,0,0,0,0,0,0,0,0,0,0,0,0,0,0,0,0,0,0,0,0,0,0,0,0,0,0
0,0,0,0,0,0,0,0,0,0,0,0,0,0,0,0,0,0,0,0,0,0,0,0,0,0,0,0,0,0
0,0,0,0,0,0,0,0,0,0,0,0,0,0,0,0,0,0,0,0,0,0,0,0,0,0,0,0,0,0
0,0,0,0,0,0,0,0,0,0,0,0,0,0,0,0,0,0,0,0,0,0,0,0,0,0,0,0,0,0
0,0,0,0,0,0,0,0,0,0,0,0,0,0,0,0,0,0,0,0,0,0,0,0,0,0,0,0,0,0
0,0,0,0,0,0,0,0,0,0,0,0,0,0,0,0,0,0,0,0,0,0,0,0,0,0,0,0,0,0
0,0,0,0,0,0,0,0,0,0,0,0,0,0,0,0,0,0,0,0,0,0,0,0,0,0,0,0,0,0
0,0,0,0,0,0,0,0,0,0,0,0,0,0,0,0,0,0,0,0,0,0,0,0,0,0,0,0,0,0
0,0,0,0,0,0,0,0,0,0,0,0,0,0,0,0,0,0,0,0,0,0,0,0,0,0,0,0,0,0
0,0,0,0,0,0,0,0,0,0,0,0,0,0,0,0,0,0,0,0,0,0,0,0,0,0,0,0,0,0
endlayer

layer
0,0,0,0,0,0,0,0,0,0,0,0,0,0,0,0,0,0,0,0,0,0,0,0,0,0,0,0,0,0
0,0,0,0,0,0,0,0,0,0,0,0,0,0,0,0,0,0,0,0,0,0,0,0,0,0,0,0,0,0
0,0,0,0,0,0,0,0,0,0,0,0,0,0,0,0,0,0,0,0,0,0,0,0,0,0,0,0,0,0
0,0,0,0,0,0,0,0,0,0,0,0,0,0,0,0,0,0,0,0,0,0,0,0,0,0,0,0,0,0
0,0,0,0,0,0,0,0,0,0,0,0,0,0,0,0,0,0,0,0,0,0,0,0,0,0,0,0,0,0
0,0,0,0,0,0,0,0,0,0,0,0,0,0,0,0,0,0,0,0,0,0,0,0,0,0,0,0,0,0
0,0,0,0,0,0,0,0,0,0,0,0,0,0,0,0,0,0,0,0,0,0,0,0,0,0,0,0,0,0
0,0,0,0,0,0,0,0,0,0,0,0,0,0,0,0,0,0,0,0,0,0,0,0,0,0,0,0,0,0
0,0,0,0,0,0,0,0,0,0,0,0,0,0,0,0,0,0,0,0,0,0,0,0,0,0,0,0,0,0
0,0,0,0,0,0,0,0,0,0,0,0,0,0,0,0,0,0,0,0,5,0,0,0,0,0,0,0,0,0
0,0,0,0,0,0,0,0,0,0,0,0,0,0,0,0,0,0,0,0,0,0,0,0,0,0,0,0,0,0
0,0,0,0,0,0,0,0,0,0,0,0,0,0,0,0,0,0,0,0,0,0,0,0,0,0,0,0,0,0
0,0,0,0,0,0,0,0,0,0,0,0,0,0,0,0,0,0,0,0,0,0,0,0,0,0,0,0,0,0
0,0,0,0,0,0,0,0,0,0,0,0,0,0,0,0,0,0,0,0,0,0,0,0,0,0,0,0,0,0
0,0,0,0,0,0,0,0,0,0,0,0,0,0,0,0,0,0,0,0,0,0,0,0,0,0,0,0,0,0
0,0,0,0,0,0,0,0,0,0,0,0,0,0,0,0,0,0,0,0,0,0,0,0,0,0,0,0,0,0
0,0,0,0,0,0,0,0,0,0,0,0,0,0,0,0,0,0,0,0,0,0,0,0,0,0,0,0,0,0
0,0,0,0,0,0,0,0,0,0,0,0,0,0,0,0,0,0,0,0,0,0,0,0,0,0,0,0,0,0
0,0,0,0,0,0,0,0,0,0,0,0,0,0,0,0,0,0,0,0,0,0,0,0,0,0,0,0,0,0
0,0,0,0,0,0,0,0,0,0,0,0,0,0,0,0,0,0,0,0,0,0,0,0,0,0,0,0,0,0
0,0,0,0,0,0,0,0,0,0,0,0,0,0,0,0,0,0,0,0,0,0,0,0,0,0,0,0,0,0
0,0,0,0,0,0,0,0,0,0,0,0,0,0,0,0,0,0,0,0,0,0,0,0,0,0,0,0,0,0
0,0,0,0,0,0,0,0,0,0,0,0,0,0,0,0,0,0,0,0,0,0,0,0,0,0,0,0,0,0
0,0,0,0,0,0,0,0,0,0,0,0,0,0,0,0,0,0,0,0,0,0,0,0,0,0,0,0,0,0
0,0,0,0,0,0,0,0,0,0,0,0,0,0,0,0,0,0,0,0,0,0,0,0,0,0,0,0,0,0
0,0,0,0,0,0,0,0,0,0,0,0,0,0,0,0,0,0,0,0,0,0,0,0,0,0,0,0,0,0
0,0,0,0,0,0,0,0,0,0,0,0,0,0,0,0,0,0,0,0,0,0,0,0,0,0,0,0,0,0
0,0,0,0,0,0,0,0,0,0,0,0,0,0,0,0,0,0,0,0,0,0,0,0,0,0,0,0,0,0
0,0,0,0,0,0,0,0,0,0,0,0,0,0,0,0,0,0,0,0,0,0,0,0,0,0,0,0,0,0
0,0,0,0,0,0,0,0,0,0,0,0,0,0,0,0,0,0,0,0,0,0,0,0,0,0,0,0,0,0
endlayer
