biomesToSpawnIn=hell,boneyard,phantasmagoric inferno,corrupted sands,bloody heap,nether,sludgepit,undergarden
weight=1
emplanks_into_distance=96
unacceptable_target_blocks=Natura:Cloud
dimensions=96,12,12
allowable_overhang=0
max_cut_in=96
cut_in_buffer=0
max_leveling=0
leveling_buffer=0
preserve_water=0
preserve_lava=1
preserve_plants=0


rule1=0,100,brick_block,brick_block,brick_block,brick_block,brick_block,brick_block,brick_block,brick_block,brick_block,air
rule2=0,0,wool-14
rule3=0,100,brick_block,brick_block,brick_block,air
rule4=2,100,brick_block_fence,brick_block_fence,brick_block_fence,air


layer
1,1,1,1,1,1,1,1,1,1,1,1
1,1,1,1,1,1,1,1,1,1,1,1
1,1,1,1,1,1,1,1,1,1,1,1
1,1,1,1,1,1,1,1,1,1,1,1
1,1,1,1,1,1,1,1,1,1,1,1
1,1,1,1,1,1,1,1,1,1,1,1
1,1,1,1,1,1,1,1,1,1,1,1
1,1,1,1,1,1,1,1,1,1,1,1
1,1,1,1,1,1,1,1,1,1,1,1
1,1,1,1,1,1,1,1,1,1,1,1
1,1,1,1,1,1,1,1,1,1,1,1
1,1,1,1,1,1,1,1,1,1,1,1
endlayer

layer
1,1,1,1,1,1,1,1,1,1,1,1
1,1,1,1,1,1,1,1,1,1,1,1
1,1,1,1,1,1,1,1,1,1,1,1
1,1,1,1,1,1,1,1,1,1,1,1
1,1,1,1,1,1,1,1,1,1,1,1
1,1,1,1,1,1,1,1,1,1,1,1
1,1,1,1,1,1,1,1,1,1,1,1
1,1,1,1,1,1,1,1,1,1,1,1
1,1,1,1,1,1,1,1,1,1,1,1
1,1,1,1,1,1,1,1,1,1,1,1
1,1,1,1,1,1,1,1,1,1,1,1
1,1,1,1,1,1,1,1,1,1,1,1
endlayer

layer
1,1,1,1,1,1,1,1,1,1,1,1
1,1,1,1,1,1,1,1,1,1,1,1
1,1,1,1,1,1,1,1,1,1,1,1
1,1,1,1,1,1,1,1,1,1,1,1
1,1,1,1,1,1,1,1,1,1,1,1
1,1,1,1,1,1,1,1,1,1,1,1
1,1,1,1,1,1,1,1,1,1,1,1
1,1,1,1,1,1,1,1,1,1,1,1
1,1,1,1,1,1,1,1,1,1,1,1
1,1,1,1,1,1,1,1,1,1,1,1
1,1,1,1,1,1,1,1,1,1,1,1
1,1,1,1,1,1,1,1,1,1,1,1
endlayer

layer
1,1,1,1,1,1,1,1,1,1,1,1
1,1,1,1,1,1,1,1,1,1,1,1
1,1,1,1,1,1,1,1,1,1,1,1
1,1,1,1,1,1,1,1,1,1,1,1
1,1,1,1,1,1,1,1,1,1,1,1
1,1,1,1,1,1,1,1,1,1,1,1
1,1,1,1,1,1,1,1,1,1,1,1
1,1,1,1,1,1,1,1,1,1,1,1
1,1,1,1,1,1,1,1,1,1,1,1
1,1,1,1,1,1,1,1,1,1,1,1
1,1,1,1,1,1,1,1,1,1,1,1
1,1,1,1,1,1,1,1,1,1,1,1
endlayer

layer
2,2,2,2,1,1,1,1,2,2,2,2
2,2,1,1,3,3,3,3,1,1,2,2
2,1,3,3,3,3,3,3,3,3,1,2
2,1,3,3,3,3,3,3,3,3,1,2
1,3,3,3,3,3,3,3,3,3,3,1
1,3,3,3,3,3,3,3,3,3,3,1
1,3,3,3,3,3,3,3,3,3,3,1
1,3,3,3,3,3,3,3,3,3,3,1
2,1,3,3,3,3,3,3,3,3,1,2
2,1,3,3,3,3,3,3,3,3,1,2
2,2,1,1,3,3,3,3,1,1,2,2
2,2,2,2,1,1,1,1,2,2,2,2
endlayer

layer
2,2,2,2,1,1,1,1,2,2,2,2
2,2,1,1,0,0,0,0,1,1,2,2
2,1,0,0,0,0,0,0,0,0,1,2
2,1,0,0,0,0,0,0,0,0,1,2
1,0,0,0,0,0,0,0,0,0,0,1
1,0,0,0,0,0,0,0,0,0,0,1
1,0,0,0,0,0,0,0,0,0,0,1
1,0,0,0,0,0,0,0,0,0,0,1
2,1,0,0,0,0,0,0,0,0,1,2
2,1,0,0,0,0,0,0,0,0,1,2
2,2,1,1,0,0,0,0,1,1,2,2
2,2,2,2,1,1,1,1,2,2,2,2
endlayer

layer
2,2,2,2,1,4,4,1,2,2,2,2
2,2,1,1,0,0,0,0,1,1,2,2
2,1,0,0,0,0,0,0,0,0,1,2
2,1,0,0,0,0,0,0,0,0,1,2
1,0,0,0,0,0,0,0,0,0,0,1
4,0,0,0,0,0,0,0,0,0,0,4
4,0,0,0,0,0,0,0,0,0,0,4
1,0,0,0,0,0,0,0,0,0,0,1
2,1,0,0,0,0,0,0,0,0,1,2
2,1,0,0,0,0,0,0,0,0,1,2
2,2,1,1,0,0,0,0,1,1,2,2
2,2,2,2,1,4,4,1,2,2,2,2
endlayer

layer
2,2,2,2,1,4,4,1,2,2,2,2
2,2,1,1,0,0,0,0,1,1,2,2
2,1,0,0,0,0,0,0,0,0,1,2
2,1,0,0,0,0,0,0,0,0,1,2
1,0,0,0,0,0,0,0,0,0,0,1
4,0,0,0,0,0,0,0,0,0,0,4
4,0,0,0,0,0,0,0,0,0,0,4
1,0,0,0,0,0,0,0,0,0,0,1
2,1,0,0,0,0,0,0,0,0,1,2
2,1,0,0,0,0,0,0,0,0,1,2
2,2,1,1,0,0,0,0,1,1,2,2
2,2,2,2,1,4,4,1,2,2,2,2
endlayer

layer
2,2,2,2,1,4,4,1,2,2,2,2
2,2,1,1,0,0,0,0,1,1,2,2
2,1,0,0,0,0,0,0,0,0,1,2
2,1,0,0,0,0,0,0,0,0,1,2
1,0,0,0,0,0,0,0,0,0,0,1
4,0,0,0,0,0,0,0,0,0,0,4
4,0,0,0,0,0,0,0,0,0,0,4
1,0,0,0,0,0,0,0,0,0,0,1
2,1,0,0,0,0,0,0,0,0,1,2
2,1,0,0,0,0,0,0,0,0,1,2
2,2,1,1,0,0,0,0,1,1,2,2
2,2,2,2,1,4,4,1,2,2,2,2
endlayer

layer
2,2,2,2,1,4,4,1,2,2,2,2
2,2,1,1,0,0,0,0,1,1,2,2
2,1,0,0,0,0,0,0,0,0,1,2
2,1,0,0,0,0,0,0,0,0,1,2
1,0,0,0,0,0,0,0,0,0,0,1
4,0,0,0,0,0,0,0,0,0,0,4
4,0,0,0,0,0,0,0,0,0,0,4
1,0,0,0,0,0,0,0,0,0,0,1
2,1,0,0,0,0,0,0,0,0,1,2
2,1,0,0,0,0,0,0,0,0,1,2
2,2,1,1,0,0,0,0,1,1,2,2
2,2,2,2,1,4,4,1,2,2,2,2
endlayer

layer
2,2,2,2,1,1,1,1,2,2,2,2
2,2,1,1,0,0,0,0,1,1,2,2
2,1,0,0,0,0,0,0,0,0,1,2
2,1,0,0,0,0,0,0,0,0,1,2
1,0,0,0,0,0,0,0,0,0,0,1
1,0,0,0,0,0,0,0,0,0,0,1
1,0,0,0,0,0,0,0,0,0,0,1
1,0,0,0,0,0,0,0,0,0,0,1
2,1,0,0,0,0,0,0,0,0,1,2
2,1,0,0,0,0,0,0,0,0,1,2
2,2,1,1,0,0,0,0,1,1,2,2
2,2,2,2,1,1,1,1,2,2,2,2
endlayer

layer
2,2,2,2,1,1,1,1,2,2,2,2
2,2,1,1,3,3,3,3,1,1,2,2
2,1,3,3,3,3,3,3,3,3,1,2
2,1,3,3,3,3,3,3,3,3,1,2
1,3,3,3,3,3,3,3,3,3,3,1
1,3,3,3,3,3,3,3,3,3,3,1
1,3,3,3,3,3,3,3,3,3,3,1
1,3,3,3,3,3,3,3,3,3,3,1
2,1,3,3,3,3,3,3,3,3,1,2
2,1,3,3,3,3,3,3,3,3,1,2
2,2,1,1,3,3,3,3,1,1,2,2
2,2,2,2,1,1,1,1,2,2,2,2
endlayer

layer
2,2,2,2,1,1,1,1,2,2,2,2
2,2,1,1,0,0,0,0,1,1,2,2
2,1,0,0,0,0,0,0,0,0,1,2
2,1,0,0,0,0,0,0,0,0,1,2
1,0,0,0,0,0,0,0,0,0,0,1
1,0,0,0,0,0,0,0,0,0,0,1
1,0,0,0,0,0,0,0,0,0,0,1
1,0,0,0,0,0,0,0,0,0,0,1
2,1,0,0,0,0,0,0,0,0,1,2
2,1,0,0,0,0,0,0,0,0,1,2
2,2,1,1,0,0,0,0,1,1,2,2
2,2,2,2,1,1,1,1,2,2,2,2
endlayer

layer
2,2,2,2,1,4,4,1,2,2,2,2
2,2,1,1,0,0,0,0,1,1,2,2
2,1,0,0,0,0,0,0,0,0,1,2
2,1,0,0,0,0,0,0,0,0,1,2
1,0,0,0,0,0,0,0,0,0,0,1
4,0,0,0,0,0,0,0,0,0,0,4
4,0,0,0,0,0,0,0,0,0,0,4
1,0,0,0,0,0,0,0,0,0,0,1
2,1,0,0,0,0,0,0,0,0,1,2
2,1,0,0,0,0,0,0,0,0,1,2
2,2,1,1,0,0,0,0,1,1,2,2
2,2,2,2,1,4,4,1,2,2,2,2
endlayer

layer
2,2,2,2,1,4,4,1,2,2,2,2
2,2,1,1,0,0,0,0,1,1,2,2
2,1,0,0,0,0,0,0,0,0,1,2
2,1,0,0,0,0,0,0,0,0,1,2
1,0,0,0,0,0,0,0,0,0,0,1
4,0,0,0,0,0,0,0,0,0,0,4
4,0,0,0,0,0,0,0,0,0,0,4
1,0,0,0,0,0,0,0,0,0,0,1
2,1,0,0,0,0,0,0,0,0,1,2
2,1,0,0,0,0,0,0,0,0,1,2
2,2,1,1,0,0,0,0,1,1,2,2
2,2,2,2,1,4,4,1,2,2,2,2
endlayer

layer
2,2,2,2,1,4,4,1,2,2,2,2
2,2,1,1,0,0,0,0,1,1,2,2
2,1,0,0,0,0,0,0,0,0,1,2
2,1,0,0,0,0,0,0,0,0,1,2
1,0,0,0,0,0,0,0,0,0,0,1
4,0,0,0,0,0,0,0,0,0,0,4
4,0,0,0,0,0,0,0,0,0,0,4
1,0,0,0,0,0,0,0,0,0,0,1
2,1,0,0,0,0,0,0,0,0,1,2
2,1,0,0,0,0,0,0,0,0,1,2
2,2,1,1,0,0,0,0,1,1,2,2
2,2,2,2,1,4,4,1,2,2,2,2
endlayer

layer
2,2,2,2,1,4,4,1,2,2,2,2
2,2,1,1,0,0,0,0,1,1,2,2
2,1,0,0,0,0,0,0,0,0,1,2
2,1,0,0,0,0,0,0,0,0,1,2
1,0,0,0,0,0,0,0,0,0,0,1
4,0,0,0,0,0,0,0,0,0,0,4
4,0,0,0,0,0,0,0,0,0,0,4
1,0,0,0,0,0,0,0,0,0,0,1
2,1,0,0,0,0,0,0,0,0,1,2
2,1,0,0,0,0,0,0,0,0,1,2
2,2,1,1,0,0,0,0,1,1,2,2
2,2,2,2,1,4,4,1,2,2,2,2
endlayer

layer
2,2,2,2,1,1,1,1,2,2,2,2
2,2,1,1,0,0,0,0,1,1,2,2
2,1,0,0,0,0,0,0,0,0,1,2
2,1,0,0,0,0,0,0,0,0,1,2
1,0,0,0,0,0,0,0,0,0,0,1
1,0,0,0,0,0,0,0,0,0,0,1
1,0,0,0,0,0,0,0,0,0,0,1
1,0,0,0,0,0,0,0,0,0,0,1
2,1,0,0,0,0,0,0,0,0,1,2
2,1,0,0,0,0,0,0,0,0,1,2
2,2,1,1,0,0,0,0,1,1,2,2
2,2,2,2,1,1,1,1,2,2,2,2
endlayer

layer
2,2,2,2,1,1,1,1,2,2,2,2
2,2,1,1,3,3,3,3,1,1,2,2
2,1,3,3,3,3,3,3,3,3,1,2
2,1,3,3,3,3,3,3,3,3,1,2
1,3,3,3,3,3,3,3,3,3,3,1
1,3,3,3,3,3,3,3,3,3,3,1
1,3,3,3,3,3,3,3,3,3,3,1
1,3,3,3,3,3,3,3,3,3,3,1
2,1,3,3,3,3,3,3,3,3,1,2
2,1,3,3,3,3,3,3,3,3,1,2
2,2,1,1,3,3,3,3,1,1,2,2
2,2,2,2,1,1,1,1,2,2,2,2
endlayer

layer
2,2,2,2,1,1,1,1,2,2,2,2
2,2,1,1,0,0,0,0,1,1,2,2
2,1,0,0,0,0,0,0,0,0,1,2
2,1,0,0,0,0,0,0,0,0,1,2
1,0,0,0,0,0,0,0,0,0,0,1
1,0,0,0,0,0,0,0,0,0,0,1
1,0,0,0,0,0,0,0,0,0,0,1
1,0,0,0,0,0,0,0,0,0,0,1
2,1,0,0,0,0,0,0,0,0,1,2
2,1,0,0,0,0,0,0,0,0,1,2
2,2,1,1,0,0,0,0,1,1,2,2
2,2,2,2,1,1,1,1,2,2,2,2
endlayer

layer
2,2,2,2,1,4,4,1,2,2,2,2
2,2,1,1,0,0,0,0,1,1,2,2
2,1,0,0,0,0,0,0,0,0,1,2
2,1,0,0,0,0,0,0,0,0,1,2
1,0,0,0,0,0,0,0,0,0,0,1
4,0,0,0,0,0,0,0,0,0,0,4
4,0,0,0,0,0,0,0,0,0,0,4
1,0,0,0,0,0,0,0,0,0,0,1
2,1,0,0,0,0,0,0,0,0,1,2
2,1,0,0,0,0,0,0,0,0,1,2
2,2,1,1,0,0,0,0,1,1,2,2
2,2,2,2,1,4,4,1,2,2,2,2
endlayer

layer
2,2,2,2,1,4,4,1,2,2,2,2
2,2,1,1,0,0,0,0,1,1,2,2
2,1,0,0,0,0,0,0,0,0,1,2
2,1,0,0,0,0,0,0,0,0,1,2
1,0,0,0,0,0,0,0,0,0,0,1
4,0,0,0,0,0,0,0,0,0,0,4
4,0,0,0,0,0,0,0,0,0,0,4
1,0,0,0,0,0,0,0,0,0,0,1
2,1,0,0,0,0,0,0,0,0,1,2
2,1,0,0,0,0,0,0,0,0,1,2
2,2,1,1,0,0,0,0,1,1,2,2
2,2,2,2,1,4,4,1,2,2,2,2
endlayer

layer
2,2,2,2,1,4,4,1,2,2,2,2
2,2,1,1,0,0,0,0,1,1,2,2
2,1,0,0,0,0,0,0,0,0,1,2
2,1,0,0,0,0,0,0,0,0,1,2
1,0,0,0,0,0,0,0,0,0,0,1
4,0,0,0,0,0,0,0,0,0,0,4
4,0,0,0,0,0,0,0,0,0,0,4
1,0,0,0,0,0,0,0,0,0,0,1
2,1,0,0,0,0,0,0,0,0,1,2
2,1,0,0,0,0,0,0,0,0,1,2
2,2,1,1,0,0,0,0,1,1,2,2
2,2,2,2,1,4,4,1,2,2,2,2
endlayer

layer
2,2,2,2,1,4,4,1,2,2,2,2
2,2,1,1,0,0,0,0,1,1,2,2
2,1,0,0,0,0,0,0,0,0,1,2
2,1,0,0,0,0,0,0,0,0,1,2
1,0,0,0,0,0,0,0,0,0,0,1
4,0,0,0,0,0,0,0,0,0,0,4
4,0,0,0,0,0,0,0,0,0,0,4
1,0,0,0,0,0,0,0,0,0,0,1
2,1,0,0,0,0,0,0,0,0,1,2
2,1,0,0,0,0,0,0,0,0,1,2
2,2,1,1,0,0,0,0,1,1,2,2
2,2,2,2,1,4,4,1,2,2,2,2
endlayer

layer
2,2,2,2,1,1,1,1,2,2,2,2
2,2,1,1,0,0,0,0,1,1,2,2
2,1,0,0,0,0,0,0,0,0,1,2
2,1,0,0,0,0,0,0,0,0,1,2
1,0,0,0,0,0,0,0,0,0,0,1
1,0,0,0,0,0,0,0,0,0,0,1
1,0,0,0,0,0,0,0,0,0,0,1
1,0,0,0,0,0,0,0,0,0,0,1
2,1,0,0,0,0,0,0,0,0,1,2
2,1,0,0,0,0,0,0,0,0,1,2
2,2,1,1,0,0,0,0,1,1,2,2
2,2,2,2,1,1,1,1,2,2,2,2
endlayer

layer
2,2,2,2,1,1,1,1,2,2,2,2
2,2,1,1,3,3,3,3,1,1,2,2
2,1,3,3,3,3,3,3,3,3,1,2
2,1,3,3,3,3,3,3,3,3,1,2
1,3,3,3,3,3,3,3,3,3,3,1
1,3,3,3,3,3,3,3,3,3,3,1
1,3,3,3,3,3,3,3,3,3,3,1
1,3,3,3,3,3,3,3,3,3,3,1
2,1,3,3,3,3,3,3,3,3,1,2
2,1,3,3,3,3,3,3,3,3,1,2
2,2,1,1,3,3,3,3,1,1,2,2
2,2,2,2,1,1,1,1,2,2,2,2
endlayer

layer
2,2,2,2,1,1,1,1,2,2,2,2
2,2,1,1,0,0,0,0,1,1,2,2
2,1,0,0,0,0,0,0,0,0,1,2
2,1,0,0,0,0,0,0,0,0,1,2
1,0,0,0,0,0,0,0,0,0,0,1
1,0,0,0,0,0,0,0,0,0,0,1
1,0,0,0,0,0,0,0,0,0,0,1
1,0,0,0,0,0,0,0,0,0,0,1
2,1,0,0,0,0,0,0,0,0,1,2
2,1,0,0,0,0,0,0,0,0,1,2
2,2,1,1,0,0,0,0,1,1,2,2
2,2,2,2,1,1,1,1,2,2,2,2
endlayer

layer
2,2,2,2,1,4,4,1,2,2,2,2
2,2,1,1,0,0,0,0,1,1,2,2
2,1,0,0,0,0,0,0,0,0,1,2
2,1,0,0,0,0,0,0,0,0,1,2
1,0,0,0,0,0,0,0,0,0,0,1
4,0,0,0,0,0,0,0,0,0,0,4
4,0,0,0,0,0,0,0,0,0,0,4
1,0,0,0,0,0,0,0,0,0,0,1
2,1,0,0,0,0,0,0,0,0,1,2
2,1,0,0,0,0,0,0,0,0,1,2
2,2,1,1,0,0,0,0,1,1,2,2
2,2,2,2,1,4,4,1,2,2,2,2
endlayer

layer
2,2,2,2,1,4,4,1,2,2,2,2
2,2,1,1,0,0,0,0,1,1,2,2
2,1,0,0,0,0,0,0,0,0,1,2
2,1,0,0,0,0,0,0,0,0,1,2
1,0,0,0,0,0,0,0,0,0,0,1
4,0,0,0,0,0,0,0,0,0,0,4
4,0,0,0,0,0,0,0,0,0,0,4
1,0,0,0,0,0,0,0,0,0,0,1
2,1,0,0,0,0,0,0,0,0,1,2
2,1,0,0,0,0,0,0,0,0,1,2
2,2,1,1,0,0,0,0,1,1,2,2
2,2,2,2,1,4,4,1,2,2,2,2
endlayer

layer
2,2,2,2,1,4,4,1,2,2,2,2
2,2,1,1,0,0,0,0,1,1,2,2
2,1,0,0,0,0,0,0,0,0,1,2
2,1,0,0,0,0,0,0,0,0,1,2
1,0,0,0,0,0,0,0,0,0,0,1
4,0,0,0,0,0,0,0,0,0,0,4
4,0,0,0,0,0,0,0,0,0,0,4
1,0,0,0,0,0,0,0,0,0,0,1
2,1,0,0,0,0,0,0,0,0,1,2
2,1,0,0,0,0,0,0,0,0,1,2
2,2,1,1,0,0,0,0,1,1,2,2
2,2,2,2,1,4,4,1,2,2,2,2
endlayer

layer
2,2,2,2,1,4,4,1,2,2,2,2
2,2,1,1,0,0,0,0,1,1,2,2
2,1,0,0,0,0,0,0,0,0,1,2
2,1,0,0,0,0,0,0,0,0,1,2
1,0,0,0,0,0,0,0,0,0,0,1
4,0,0,0,0,0,0,0,0,0,0,4
4,0,0,0,0,0,0,0,0,0,0,4
1,0,0,0,0,0,0,0,0,0,0,1
2,1,0,0,0,0,0,0,0,0,1,2
2,1,0,0,0,0,0,0,0,0,1,2
2,2,1,1,0,0,0,0,1,1,2,2
2,2,2,2,1,4,4,1,2,2,2,2
endlayer

layer
2,2,2,2,1,1,1,1,2,2,2,2
2,2,1,1,0,0,0,0,1,1,2,2
2,1,0,0,0,0,0,0,0,0,1,2
2,1,0,0,0,0,0,0,0,0,1,2
1,0,0,0,0,0,0,0,0,0,0,1
1,0,0,0,0,0,0,0,0,0,0,1
1,0,0,0,0,0,0,0,0,0,0,1
1,0,0,0,0,0,0,0,0,0,0,1
2,1,0,0,0,0,0,0,0,0,1,2
2,1,0,0,0,0,0,0,0,0,1,2
2,2,1,1,0,0,0,0,1,1,2,2
2,2,2,2,1,1,1,1,2,2,2,2
endlayer

layer
2,2,2,2,1,1,1,1,2,2,2,2
2,2,1,1,3,3,3,3,1,1,2,2
2,1,3,3,3,3,3,3,3,3,1,2
2,1,3,3,3,3,3,3,3,3,1,2
1,3,3,3,3,3,3,3,3,3,3,1
1,3,3,3,3,3,3,3,3,3,3,1
1,3,3,3,3,3,3,3,3,3,3,1
1,3,3,3,3,3,3,3,3,3,3,1
2,1,3,3,3,3,3,3,3,3,1,2
2,1,3,3,3,3,3,3,3,3,1,2
2,2,1,1,3,3,3,3,1,1,2,2
2,2,2,2,1,1,1,1,2,2,2,2
endlayer

layer
2,2,2,2,1,1,1,1,2,2,2,2
2,2,1,1,0,0,0,0,1,1,2,2
2,1,0,0,0,0,0,0,0,0,1,2
2,1,0,0,0,0,0,0,0,0,1,2
1,0,0,0,0,0,0,0,0,0,0,1
1,0,0,0,0,0,0,0,0,0,0,1
1,0,0,0,0,0,0,0,0,0,0,1
1,0,0,0,0,0,0,0,0,0,0,1
2,1,0,0,0,0,0,0,0,0,1,2
2,1,0,0,0,0,0,0,0,0,1,2
2,2,1,1,0,0,0,0,1,1,2,2
2,2,2,2,1,1,1,1,2,2,2,2
endlayer

layer
2,2,2,2,1,4,4,1,2,2,2,2
2,2,1,1,0,0,0,0,1,1,2,2
2,1,0,0,0,0,0,0,0,0,1,2
2,1,0,0,0,0,0,0,0,0,1,2
1,0,0,0,0,0,0,0,0,0,0,1
4,0,0,0,0,0,0,0,0,0,0,4
4,0,0,0,0,0,0,0,0,0,0,4
1,0,0,0,0,0,0,0,0,0,0,1
2,1,0,0,0,0,0,0,0,0,1,2
2,1,0,0,0,0,0,0,0,0,1,2
2,2,1,1,0,0,0,0,1,1,2,2
2,2,2,2,1,4,4,1,2,2,2,2
endlayer

layer
2,2,2,2,1,4,4,1,2,2,2,2
2,2,1,1,0,0,0,0,1,1,2,2
2,1,0,0,0,0,0,0,0,0,1,2
2,1,0,0,0,0,0,0,0,0,1,2
1,0,0,0,0,0,0,0,0,0,0,1
4,0,0,0,0,0,0,0,0,0,0,4
4,0,0,0,0,0,0,0,0,0,0,4
1,0,0,0,0,0,0,0,0,0,0,1
2,1,0,0,0,0,0,0,0,0,1,2
2,1,0,0,0,0,0,0,0,0,1,2
2,2,1,1,0,0,0,0,1,1,2,2
2,2,2,2,1,4,4,1,2,2,2,2
endlayer

layer
2,2,2,2,1,4,4,1,2,2,2,2
2,2,1,1,0,0,0,0,1,1,2,2
2,1,0,0,0,0,0,0,0,0,1,2
2,1,0,0,0,0,0,0,0,0,1,2
1,0,0,0,0,0,0,0,0,0,0,1
4,0,0,0,0,0,0,0,0,0,0,4
4,0,0,0,0,0,0,0,0,0,0,4
1,0,0,0,0,0,0,0,0,0,0,1
2,1,0,0,0,0,0,0,0,0,1,2
2,1,0,0,0,0,0,0,0,0,1,2
2,2,1,1,0,0,0,0,1,1,2,2
2,2,2,2,1,4,4,1,2,2,2,2
endlayer

layer
2,2,2,2,1,4,4,1,2,2,2,2
2,2,1,1,0,0,0,0,1,1,2,2
2,1,0,0,0,0,0,0,0,0,1,2
2,1,0,0,0,0,0,0,0,0,1,2
1,0,0,0,0,0,0,0,0,0,0,1
4,0,0,0,0,0,0,0,0,0,0,4
4,0,0,0,0,0,0,0,0,0,0,4
1,0,0,0,0,0,0,0,0,0,0,1
2,1,0,0,0,0,0,0,0,0,1,2
2,1,0,0,0,0,0,0,0,0,1,2
2,2,1,1,0,0,0,0,1,1,2,2
2,2,2,2,1,4,4,1,2,2,2,2
endlayer

layer
2,2,2,2,1,1,1,1,2,2,2,2
2,2,1,1,0,0,0,0,1,1,2,2
2,1,0,0,0,0,0,0,0,0,1,2
2,1,0,0,0,0,0,0,0,0,1,2
1,0,0,0,0,0,0,0,0,0,0,1
1,0,0,0,0,0,0,0,0,0,0,1
1,0,0,0,0,0,0,0,0,0,0,1
1,0,0,0,0,0,0,0,0,0,0,1
2,1,0,0,0,0,0,0,0,0,1,2
2,1,0,0,0,0,0,0,0,0,1,2
2,2,1,1,0,0,0,0,1,1,2,2
2,2,2,2,1,1,1,1,2,2,2,2
endlayer

layer
2,2,2,2,1,1,1,1,2,2,2,2
2,2,1,1,3,3,3,3,1,1,2,2
2,1,3,3,3,3,3,3,3,3,1,2
2,1,3,3,3,3,3,3,3,3,1,2
1,3,3,3,3,3,3,3,3,3,3,1
1,3,3,3,3,3,3,3,3,3,3,1
1,3,3,3,3,3,3,3,3,3,3,1
1,3,3,3,3,3,3,3,3,3,3,1
2,1,3,3,3,3,3,3,3,3,1,2
2,1,3,3,3,3,3,3,3,3,1,2
2,2,1,1,3,3,3,3,1,1,2,2
2,2,2,2,1,1,1,1,2,2,2,2
endlayer

layer
2,2,2,2,1,1,1,1,2,2,2,2
2,2,1,1,0,0,0,0,1,1,2,2
2,1,0,0,0,0,0,0,0,0,1,2
2,1,0,0,0,0,0,0,0,0,1,2
1,0,0,0,0,0,0,0,0,0,0,1
1,0,0,0,0,0,0,0,0,0,0,1
1,0,0,0,0,0,0,0,0,0,0,1
1,0,0,0,0,0,0,0,0,0,0,1
2,1,0,0,0,0,0,0,0,0,1,2
2,1,0,0,0,0,0,0,0,0,1,2
2,2,1,1,0,0,0,0,1,1,2,2
2,2,2,2,1,1,1,1,2,2,2,2
endlayer

layer
2,2,2,2,1,4,4,1,2,2,2,2
2,2,1,1,0,0,0,0,1,1,2,2
2,1,0,0,0,0,0,0,0,0,1,2
2,1,0,0,0,0,0,0,0,0,1,2
1,0,0,0,0,0,0,0,0,0,0,1
4,0,0,0,0,0,0,0,0,0,0,4
4,0,0,0,0,0,0,0,0,0,0,4
1,0,0,0,0,0,0,0,0,0,0,1
2,1,0,0,0,0,0,0,0,0,1,2
2,1,0,0,0,0,0,0,0,0,1,2
2,2,1,1,0,0,0,0,1,1,2,2
2,2,2,2,1,4,4,1,2,2,2,2
endlayer

layer
2,2,2,2,1,4,4,1,2,2,2,2
2,2,1,1,0,0,0,0,1,1,2,2
2,1,0,0,0,0,0,0,0,0,1,2
2,1,0,0,0,0,0,0,0,0,1,2
1,0,0,0,0,0,0,0,0,0,0,1
4,0,0,0,0,0,0,0,0,0,0,4
4,0,0,0,0,0,0,0,0,0,0,4
1,0,0,0,0,0,0,0,0,0,0,1
2,1,0,0,0,0,0,0,0,0,1,2
2,1,0,0,0,0,0,0,0,0,1,2
2,2,1,1,0,0,0,0,1,1,2,2
2,2,2,2,1,4,4,1,2,2,2,2
endlayer

layer
2,2,2,2,1,4,4,1,2,2,2,2
2,2,1,1,0,0,0,0,1,1,2,2
2,1,0,0,0,0,0,0,0,0,1,2
2,1,0,0,0,0,0,0,0,0,1,2
1,0,0,0,0,0,0,0,0,0,0,1
4,0,0,0,0,0,0,0,0,0,0,4
4,0,0,0,0,0,0,0,0,0,0,4
1,0,0,0,0,0,0,0,0,0,0,1
2,1,0,0,0,0,0,0,0,0,1,2
2,1,0,0,0,0,0,0,0,0,1,2
2,2,1,1,0,0,0,0,1,1,2,2
2,2,2,2,1,4,4,1,2,2,2,2
endlayer

layer
2,2,2,2,1,4,4,1,2,2,2,2
2,2,1,1,0,0,0,0,1,1,2,2
2,1,0,0,0,0,0,0,0,0,1,2
2,1,0,0,0,0,0,0,0,0,1,2
1,0,0,0,0,0,0,0,0,0,0,1
4,0,0,0,0,0,0,0,0,0,0,4
4,0,0,0,0,0,0,0,0,0,0,4
1,0,0,0,0,0,0,0,0,0,0,1
2,1,0,0,0,0,0,0,0,0,1,2
2,1,0,0,0,0,0,0,0,0,1,2
2,2,1,1,0,0,0,0,1,1,2,2
2,2,2,2,1,4,4,1,2,2,2,2
endlayer

layer
2,2,2,2,1,1,1,1,2,2,2,2
2,2,1,1,0,0,0,0,1,1,2,2
2,1,0,0,0,0,0,0,0,0,1,2
2,1,0,0,0,0,0,0,0,0,1,2
1,0,0,0,0,0,0,0,0,0,0,1
1,0,0,0,0,0,0,0,0,0,0,1
1,0,0,0,0,0,0,0,0,0,0,1
1,0,0,0,0,0,0,0,0,0,0,1
2,1,0,0,0,0,0,0,0,0,1,2
2,1,0,0,0,0,0,0,0,0,1,2
2,2,1,1,0,0,0,0,1,1,2,2
2,2,2,2,1,1,1,1,2,2,2,2
endlayer

layer
2,2,2,2,1,1,1,1,2,2,2,2
2,2,1,1,3,3,3,3,1,1,2,2
2,1,3,3,3,3,3,3,3,3,1,2
2,1,3,3,3,3,3,3,3,3,1,2
1,3,3,3,3,3,3,3,3,3,3,1
1,3,3,3,3,3,3,3,3,3,3,1
1,3,3,3,3,3,3,3,3,3,3,1
1,3,3,3,3,3,3,3,3,3,3,1
2,1,3,3,3,3,3,3,3,3,1,2
2,1,3,3,3,3,3,3,3,3,1,2
2,2,1,1,3,3,3,3,1,1,2,2
2,2,2,2,1,1,1,1,2,2,2,2
endlayer

layer
2,2,2,2,1,1,1,1,2,2,2,2
2,2,1,1,0,0,0,0,1,1,2,2
2,1,0,0,0,0,0,0,0,0,1,2
2,1,0,0,0,0,0,0,0,0,1,2
1,0,0,0,0,0,0,0,0,0,0,1
1,0,0,0,0,0,0,0,0,0,0,1
1,0,0,0,0,0,0,0,0,0,0,1
1,0,0,0,0,0,0,0,0,0,0,1
2,1,0,0,0,0,0,0,0,0,1,2
2,1,0,0,0,0,0,0,0,0,1,2
2,2,1,1,0,0,0,0,1,1,2,2
2,2,2,2,1,1,1,1,2,2,2,2
endlayer

layer
2,2,2,2,1,4,4,1,2,2,2,2
2,2,1,1,0,0,0,0,1,1,2,2
2,1,0,0,0,0,0,0,0,0,1,2
2,1,0,0,0,0,0,0,0,0,1,2
1,0,0,0,0,0,0,0,0,0,0,1
4,0,0,0,0,0,0,0,0,0,0,4
4,0,0,0,0,0,0,0,0,0,0,4
1,0,0,0,0,0,0,0,0,0,0,1
2,1,0,0,0,0,0,0,0,0,1,2
2,1,0,0,0,0,0,0,0,0,1,2
2,2,1,1,0,0,0,0,1,1,2,2
2,2,2,2,1,4,4,1,2,2,2,2
endlayer

layer
2,2,2,2,1,4,4,1,2,2,2,2
2,2,1,1,0,0,0,0,1,1,2,2
2,1,0,0,0,0,0,0,0,0,1,2
2,1,0,0,0,0,0,0,0,0,1,2
1,0,0,0,0,0,0,0,0,0,0,1
4,0,0,0,0,0,0,0,0,0,0,4
4,0,0,0,0,0,0,0,0,0,0,4
1,0,0,0,0,0,0,0,0,0,0,1
2,1,0,0,0,0,0,0,0,0,1,2
2,1,0,0,0,0,0,0,0,0,1,2
2,2,1,1,0,0,0,0,1,1,2,2
2,2,2,2,1,4,4,1,2,2,2,2
endlayer

layer
2,2,2,2,1,4,4,1,2,2,2,2
2,2,1,1,0,0,0,0,1,1,2,2
2,1,0,0,0,0,0,0,0,0,1,2
2,1,0,0,0,0,0,0,0,0,1,2
1,0,0,0,0,0,0,0,0,0,0,1
4,0,0,0,0,0,0,0,0,0,0,4
4,0,0,0,0,0,0,0,0,0,0,4
1,0,0,0,0,0,0,0,0,0,0,1
2,1,0,0,0,0,0,0,0,0,1,2
2,1,0,0,0,0,0,0,0,0,1,2
2,2,1,1,0,0,0,0,1,1,2,2
2,2,2,2,1,4,4,1,2,2,2,2
endlayer

layer
2,2,2,2,1,4,4,1,2,2,2,2
2,2,1,1,0,0,0,0,1,1,2,2
2,1,0,0,0,0,0,0,0,0,1,2
2,1,0,0,0,0,0,0,0,0,1,2
1,0,0,0,0,0,0,0,0,0,0,1
4,0,0,0,0,0,0,0,0,0,0,4
4,0,0,0,0,0,0,0,0,0,0,4
1,0,0,0,0,0,0,0,0,0,0,1
2,1,0,0,0,0,0,0,0,0,1,2
2,1,0,0,0,0,0,0,0,0,1,2
2,2,1,1,0,0,0,0,1,1,2,2
2,2,2,2,1,4,4,1,2,2,2,2
endlayer

layer
2,2,2,2,1,1,1,1,2,2,2,2
2,2,1,1,0,0,0,0,1,1,2,2
2,1,0,0,0,0,0,0,0,0,1,2
2,1,0,0,0,0,0,0,0,0,1,2
1,0,0,0,0,0,0,0,0,0,0,1
1,0,0,0,0,0,0,0,0,0,0,1
1,0,0,0,0,0,0,0,0,0,0,1
1,0,0,0,0,0,0,0,0,0,0,1
2,1,0,0,0,0,0,0,0,0,1,2
2,1,0,0,0,0,0,0,0,0,1,2
2,2,1,1,0,0,0,0,1,1,2,2
2,2,2,2,1,1,1,1,2,2,2,2
endlayer

layer
2,2,2,2,1,1,1,1,2,2,2,2
2,2,1,1,3,3,3,3,1,1,2,2
2,1,3,3,3,3,3,3,3,3,1,2
2,1,3,3,3,3,3,3,3,3,1,2
1,3,3,3,3,3,3,3,3,3,3,1
1,3,3,3,3,3,3,3,3,3,3,1
1,3,3,3,3,3,3,3,3,3,3,1
1,3,3,3,3,3,3,3,3,3,3,1
2,1,3,3,3,3,3,3,3,3,1,2
2,1,3,3,3,3,3,3,3,3,1,2
2,2,1,1,3,3,3,3,1,1,2,2
2,2,2,2,1,1,1,1,2,2,2,2
endlayer

layer
2,2,2,2,1,1,1,1,2,2,2,2
2,2,1,1,0,0,0,0,1,1,2,2
2,1,0,0,0,0,0,0,0,0,1,2
2,1,0,0,0,0,0,0,0,0,1,2
1,0,0,0,0,0,0,0,0,0,0,1
1,0,0,0,0,0,0,0,0,0,0,1
1,0,0,0,0,0,0,0,0,0,0,1
1,0,0,0,0,0,0,0,0,0,0,1
2,1,0,0,0,0,0,0,0,0,1,2
2,1,0,0,0,0,0,0,0,0,1,2
2,2,1,1,0,0,0,0,1,1,2,2
2,2,2,2,1,1,1,1,2,2,2,2
endlayer

layer
2,2,2,2,1,4,4,1,2,2,2,2
2,2,1,1,0,0,0,0,1,1,2,2
2,1,0,0,0,0,0,0,0,0,1,2
2,1,0,0,0,0,0,0,0,0,1,2
1,0,0,0,0,0,0,0,0,0,0,1
4,0,0,0,0,0,0,0,0,0,0,4
4,0,0,0,0,0,0,0,0,0,0,4
1,0,0,0,0,0,0,0,0,0,0,1
2,1,0,0,0,0,0,0,0,0,1,2
2,1,0,0,0,0,0,0,0,0,1,2
2,2,1,1,0,0,0,0,1,1,2,2
2,2,2,2,1,4,4,1,2,2,2,2
endlayer

layer
2,2,2,2,1,4,4,1,2,2,2,2
2,2,1,1,0,0,0,0,1,1,2,2
2,1,0,0,0,0,0,0,0,0,1,2
2,1,0,0,0,0,0,0,0,0,1,2
1,0,0,0,0,0,0,0,0,0,0,1
4,0,0,0,0,0,0,0,0,0,0,4
4,0,0,0,0,0,0,0,0,0,0,4
1,0,0,0,0,0,0,0,0,0,0,1
2,1,0,0,0,0,0,0,0,0,1,2
2,1,0,0,0,0,0,0,0,0,1,2
2,2,1,1,0,0,0,0,1,1,2,2
2,2,2,2,1,4,4,1,2,2,2,2
endlayer

layer
2,2,2,2,1,4,4,1,2,2,2,2
2,2,1,1,0,0,0,0,1,1,2,2
2,1,0,0,0,0,0,0,0,0,1,2
2,1,0,0,0,0,0,0,0,0,1,2
1,0,0,0,0,0,0,0,0,0,0,1
4,0,0,0,0,0,0,0,0,0,0,4
4,0,0,0,0,0,0,0,0,0,0,4
1,0,0,0,0,0,0,0,0,0,0,1
2,1,0,0,0,0,0,0,0,0,1,2
2,1,0,0,0,0,0,0,0,0,1,2
2,2,1,1,0,0,0,0,1,1,2,2
2,2,2,2,1,4,4,1,2,2,2,2
endlayer

layer
2,2,2,2,1,4,4,1,2,2,2,2
2,2,1,1,0,0,0,0,1,1,2,2
2,1,0,0,0,0,0,0,0,0,1,2
2,1,0,0,0,0,0,0,0,0,1,2
1,0,0,0,0,0,0,0,0,0,0,1
4,0,0,0,0,0,0,0,0,0,0,4
4,0,0,0,0,0,0,0,0,0,0,4
1,0,0,0,0,0,0,0,0,0,0,1
2,1,0,0,0,0,0,0,0,0,1,2
2,1,0,0,0,0,0,0,0,0,1,2
2,2,1,1,0,0,0,0,1,1,2,2
2,2,2,2,1,4,4,1,2,2,2,2
endlayer

layer
2,2,2,2,1,1,1,1,2,2,2,2
2,2,1,1,0,0,0,0,1,1,2,2
2,1,0,0,0,0,0,0,0,0,1,2
2,1,0,0,0,0,0,0,0,0,1,2
1,0,0,0,0,0,0,0,0,0,0,1
1,0,0,0,0,0,0,0,0,0,0,1
1,0,0,0,0,0,0,0,0,0,0,1
1,0,0,0,0,0,0,0,0,0,0,1
2,1,0,0,0,0,0,0,0,0,1,2
2,1,0,0,0,0,0,0,0,0,1,2
2,2,1,1,0,0,0,0,1,1,2,2
2,2,2,2,1,1,1,1,2,2,2,2
endlayer

layer
2,2,2,2,1,1,1,1,2,2,2,2
2,2,1,1,3,3,3,3,1,1,2,2
2,1,3,3,3,3,3,3,3,3,1,2
2,1,3,3,3,3,3,3,3,3,1,2
1,3,3,3,3,3,3,3,3,3,3,1
1,3,3,3,3,3,3,3,3,3,3,1
1,3,3,3,3,3,3,3,3,3,3,1
1,3,3,3,3,3,3,3,3,3,3,1
2,1,3,3,3,3,3,3,3,3,1,2
2,1,3,3,3,3,3,3,3,3,1,2
2,2,1,1,3,3,3,3,1,1,2,2
2,2,2,2,1,1,1,1,2,2,2,2
endlayer

layer
2,2,2,2,1,1,1,1,2,2,2,2
2,2,1,1,0,0,0,0,1,1,2,2
2,1,0,0,0,0,0,0,0,0,1,2
2,1,0,0,0,0,0,0,0,0,1,2
1,0,0,0,0,0,0,0,0,0,0,1
1,0,0,0,0,0,0,0,0,0,0,1
1,0,0,0,0,0,0,0,0,0,0,1
1,0,0,0,0,0,0,0,0,0,0,1
2,1,0,0,0,0,0,0,0,0,1,2
2,1,0,0,0,0,0,0,0,0,1,2
2,2,1,1,0,0,0,0,1,1,2,2
2,2,2,2,1,1,1,1,2,2,2,2
endlayer

layer
2,2,2,2,1,4,4,1,2,2,2,2
2,2,1,1,0,0,0,0,1,1,2,2
2,1,0,0,0,0,0,0,0,0,1,2
2,1,0,0,0,0,0,0,0,0,1,2
1,0,0,0,0,0,0,0,0,0,0,1
4,0,0,0,0,0,0,0,0,0,0,4
4,0,0,0,0,0,0,0,0,0,0,4
1,0,0,0,0,0,0,0,0,0,0,1
2,1,0,0,0,0,0,0,0,0,1,2
2,1,0,0,0,0,0,0,0,0,1,2
2,2,1,1,0,0,0,0,1,1,2,2
2,2,2,2,1,4,4,1,2,2,2,2
endlayer

layer
2,2,2,2,1,4,4,1,2,2,2,2
2,2,1,1,0,0,0,0,1,1,2,2
2,1,0,0,0,0,0,0,0,0,1,2
2,1,0,0,0,0,0,0,0,0,1,2
1,0,0,0,0,0,0,0,0,0,0,1
4,0,0,0,0,0,0,0,0,0,0,4
4,0,0,0,0,0,0,0,0,0,0,4
1,0,0,0,0,0,0,0,0,0,0,1
2,1,0,0,0,0,0,0,0,0,1,2
2,1,0,0,0,0,0,0,0,0,1,2
2,2,1,1,0,0,0,0,1,1,2,2
2,2,2,2,1,4,4,1,2,2,2,2
endlayer

layer
2,2,2,2,1,4,4,1,2,2,2,2
2,2,1,1,0,0,0,0,1,1,2,2
2,1,0,0,0,0,0,0,0,0,1,2
2,1,0,0,0,0,0,0,0,0,1,2
1,0,0,0,0,0,0,0,0,0,0,1
4,0,0,0,0,0,0,0,0,0,0,4
4,0,0,0,0,0,0,0,0,0,0,4
1,0,0,0,0,0,0,0,0,0,0,1
2,1,0,0,0,0,0,0,0,0,1,2
2,1,0,0,0,0,0,0,0,0,1,2
2,2,1,1,0,0,0,0,1,1,2,2
2,2,2,2,1,4,4,1,2,2,2,2
endlayer

layer
2,2,2,2,1,4,4,1,2,2,2,2
2,2,1,1,0,0,0,0,1,1,2,2
2,1,0,0,0,0,0,0,0,0,1,2
2,1,0,0,0,0,0,0,0,0,1,2
1,0,0,0,0,0,0,0,0,0,0,1
4,0,0,0,0,0,0,0,0,0,0,4
4,0,0,0,0,0,0,0,0,0,0,4
1,0,0,0,0,0,0,0,0,0,0,1
2,1,0,0,0,0,0,0,0,0,1,2
2,1,0,0,0,0,0,0,0,0,1,2
2,2,1,1,0,0,0,0,1,1,2,2
2,2,2,2,1,4,4,1,2,2,2,2
endlayer

layer
2,2,2,2,1,1,1,1,2,2,2,2
2,2,1,1,0,0,0,0,1,1,2,2
2,1,0,0,0,0,0,0,0,0,1,2
2,1,0,0,0,0,0,0,0,0,1,2
1,0,0,0,0,0,0,0,0,0,0,1
1,0,0,0,0,0,0,0,0,0,0,1
1,0,0,0,0,0,0,0,0,0,0,1
1,0,0,0,0,0,0,0,0,0,0,1
2,1,0,0,0,0,0,0,0,0,1,2
2,1,0,0,0,0,0,0,0,0,1,2
2,2,1,1,0,0,0,0,1,1,2,2
2,2,2,2,1,1,1,1,2,2,2,2
endlayer

layer
2,2,2,2,1,1,1,1,2,2,2,2
2,2,1,1,3,3,3,3,1,1,2,2
2,1,3,3,3,3,3,3,3,3,1,2
2,1,3,3,3,3,3,3,3,3,1,2
1,3,3,3,3,3,3,3,3,3,3,1
1,3,3,3,3,3,3,3,3,3,3,1
1,3,3,3,3,3,3,3,3,3,3,1
1,3,3,3,3,3,3,3,3,3,3,1
2,1,3,3,3,3,3,3,3,3,1,2
2,1,3,3,3,3,3,3,3,3,1,2
2,2,1,1,3,3,3,3,1,1,2,2
2,2,2,2,1,1,1,1,2,2,2,2
endlayer

layer
2,2,2,2,1,1,1,1,2,2,2,2
2,2,1,1,0,0,0,0,1,1,2,2
2,1,0,0,0,0,0,0,0,0,1,2
2,1,0,0,0,0,0,0,0,0,1,2
1,0,0,0,0,0,0,0,0,0,0,1
1,0,0,0,0,0,0,0,0,0,0,1
1,0,0,0,0,0,0,0,0,0,0,1
1,0,0,0,0,0,0,0,0,0,0,1
2,1,0,0,0,0,0,0,0,0,1,2
2,1,0,0,0,0,0,0,0,0,1,2
2,2,1,1,0,0,0,0,1,1,2,2
2,2,2,2,1,1,1,1,2,2,2,2
endlayer

layer
2,2,2,2,1,4,4,1,2,2,2,2
2,2,1,1,0,0,0,0,1,1,2,2
2,1,0,0,0,0,0,0,0,0,1,2
2,1,0,0,0,0,0,0,0,0,1,2
1,0,0,0,0,0,0,0,0,0,0,1
4,0,0,0,0,0,0,0,0,0,0,4
4,0,0,0,0,0,0,0,0,0,0,4
1,0,0,0,0,0,0,0,0,0,0,1
2,1,0,0,0,0,0,0,0,0,1,2
2,1,0,0,0,0,0,0,0,0,1,2
2,2,1,1,0,0,0,0,1,1,2,2
2,2,2,2,1,4,4,1,2,2,2,2
endlayer

layer
2,2,2,2,1,4,4,1,2,2,2,2
2,2,1,1,0,0,0,0,1,1,2,2
2,1,0,0,0,0,0,0,0,0,1,2
2,1,0,0,0,0,0,0,0,0,1,2
1,0,0,0,0,0,0,0,0,0,0,1
4,0,0,0,0,0,0,0,0,0,0,4
4,0,0,0,0,0,0,0,0,0,0,4
1,0,0,0,0,0,0,0,0,0,0,1
2,1,0,0,0,0,0,0,0,0,1,2
2,1,0,0,0,0,0,0,0,0,1,2
2,2,1,1,0,0,0,0,1,1,2,2
2,2,2,2,1,4,4,1,2,2,2,2
endlayer

layer
2,2,2,2,1,4,4,1,2,2,2,2
2,2,1,1,0,0,0,0,1,1,2,2
2,1,0,0,0,0,0,0,0,0,1,2
2,1,0,0,0,0,0,0,0,0,1,2
1,0,0,0,0,0,0,0,0,0,0,1
4,0,0,0,0,0,0,0,0,0,0,4
4,0,0,0,0,0,0,0,0,0,0,4
1,0,0,0,0,0,0,0,0,0,0,1
2,1,0,0,0,0,0,0,0,0,1,2
2,1,0,0,0,0,0,0,0,0,1,2
2,2,1,1,0,0,0,0,1,1,2,2
2,2,2,2,1,4,4,1,2,2,2,2
endlayer

layer
2,2,2,2,1,4,4,1,2,2,2,2
2,2,1,1,0,0,0,0,1,1,2,2
2,1,0,0,0,0,0,0,0,0,1,2
2,1,0,0,0,0,0,0,0,0,1,2
1,0,0,0,0,0,0,0,0,0,0,1
4,0,0,0,0,0,0,0,0,0,0,4
4,0,0,0,0,0,0,0,0,0,0,4
1,0,0,0,0,0,0,0,0,0,0,1
2,1,0,0,0,0,0,0,0,0,1,2
2,1,0,0,0,0,0,0,0,0,1,2
2,2,1,1,0,0,0,0,1,1,2,2
2,2,2,2,1,4,4,1,2,2,2,2
endlayer

layer
2,2,2,2,1,1,1,1,2,2,2,2
2,2,1,1,0,0,0,0,1,1,2,2
2,1,0,0,0,0,0,0,0,0,1,2
2,1,0,0,0,0,0,0,0,0,1,2
1,0,0,0,0,0,0,0,0,0,0,1
1,0,0,0,0,0,0,0,0,0,0,1
1,0,0,0,0,0,0,0,0,0,0,1
1,0,0,0,0,0,0,0,0,0,0,1
2,1,0,0,0,0,0,0,0,0,1,2
2,1,0,0,0,0,0,0,0,0,1,2
2,2,1,1,0,0,0,0,1,1,2,2
2,2,2,2,1,1,1,1,2,2,2,2
endlayer

layer
2,2,2,2,1,1,1,1,2,2,2,2
2,2,1,1,3,3,3,3,1,1,2,2
2,1,3,3,3,3,3,3,3,3,1,2
2,1,3,3,3,3,3,3,3,3,1,2
1,3,3,3,3,3,3,3,3,3,3,1
1,3,3,3,3,3,3,3,3,3,3,1
1,3,3,3,3,3,3,3,3,3,3,1
1,3,3,3,3,3,3,3,3,3,3,1
2,1,3,3,3,3,3,3,3,3,1,2
2,1,3,3,3,3,3,3,3,3,1,2
2,2,1,1,3,3,3,3,1,1,2,2
2,2,2,2,1,1,1,1,2,2,2,2
endlayer

layer
2,2,2,2,1,1,1,1,2,2,2,2
2,2,1,1,0,0,0,0,1,1,2,2
2,1,0,0,0,0,0,0,0,0,1,2
2,1,0,0,0,0,0,0,0,0,1,2
1,0,0,0,0,0,0,0,0,0,0,1
1,0,0,0,0,0,0,0,0,0,0,1
1,0,0,0,0,0,0,0,0,0,0,1
1,0,0,0,0,0,0,0,0,0,0,1
2,1,0,0,0,0,0,0,0,0,1,2
2,1,0,0,0,0,0,0,0,0,1,2
2,2,1,1,0,0,0,0,1,1,2,2
2,2,2,2,1,1,1,1,2,2,2,2
endlayer

layer
2,2,2,2,1,4,4,1,2,2,2,2
2,2,1,1,0,0,0,0,1,1,2,2
2,1,0,0,0,0,0,0,0,0,1,2
2,1,0,0,0,0,0,0,0,0,1,2
1,0,0,0,0,0,0,0,0,0,0,1
4,0,0,0,0,0,0,0,0,0,0,4
4,0,0,0,0,0,0,0,0,0,0,4
1,0,0,0,0,0,0,0,0,0,0,1
2,1,0,0,0,0,0,0,0,0,1,2
2,1,0,0,0,0,0,0,0,0,1,2
2,2,1,1,0,0,0,0,1,1,2,2
2,2,2,2,1,4,4,1,2,2,2,2
endlayer

layer
2,2,2,2,1,4,4,1,2,2,2,2
2,2,1,1,0,0,0,0,1,1,2,2
2,1,0,0,0,0,0,0,0,0,1,2
2,1,0,0,0,0,0,0,0,0,1,2
1,0,0,0,0,0,0,0,0,0,0,1
4,0,0,0,0,0,0,0,0,0,0,4
4,0,0,0,0,0,0,0,0,0,0,4
1,0,0,0,0,0,0,0,0,0,0,1
2,1,0,0,0,0,0,0,0,0,1,2
2,1,0,0,0,0,0,0,0,0,1,2
2,2,1,1,0,0,0,0,1,1,2,2
2,2,2,2,1,4,4,1,2,2,2,2
endlayer

layer
2,2,2,2,1,4,4,1,2,2,2,2
2,2,1,1,0,0,0,0,1,1,2,2
2,1,0,0,0,0,0,0,0,0,1,2
2,1,0,0,0,0,0,0,0,0,1,2
1,0,0,0,0,0,0,0,0,0,0,1
4,0,0,0,0,0,0,0,0,0,0,4
4,0,0,0,0,0,0,0,0,0,0,4
1,0,0,0,0,0,0,0,0,0,0,1
2,1,0,0,0,0,0,0,0,0,1,2
2,1,0,0,0,0,0,0,0,0,1,2
2,2,1,1,0,0,0,0,1,1,2,2
2,2,2,2,1,4,4,1,2,2,2,2
endlayer

layer
2,2,2,2,1,4,4,1,2,2,2,2
2,2,1,1,0,0,0,0,1,1,2,2
2,1,0,0,0,0,0,0,0,0,1,2
2,1,0,0,0,0,0,0,0,0,1,2
1,0,0,0,0,0,0,0,0,0,0,1
4,0,0,0,0,0,0,0,0,0,0,4
4,0,0,0,0,0,0,0,0,0,0,4
1,0,0,0,0,0,0,0,0,0,0,1
2,1,0,0,0,0,0,0,0,0,1,2
2,1,0,0,0,0,0,0,0,0,1,2
2,2,1,1,0,0,0,0,1,1,2,2
2,2,2,2,1,4,4,1,2,2,2,2
endlayer

layer
2,2,2,2,1,1,1,1,2,2,2,2
2,2,1,1,0,0,0,0,1,1,2,2
2,1,0,0,0,0,0,0,0,0,1,2
2,1,0,0,0,0,0,0,0,0,1,2
1,0,0,0,0,0,0,0,0,0,0,1
1,0,0,0,0,0,0,0,0,0,0,1
1,0,0,0,0,0,0,0,0,0,0,1
1,0,0,0,0,0,0,0,0,0,0,1
2,1,0,0,0,0,0,0,0,0,1,2
2,1,0,0,0,0,0,0,0,0,1,2
2,2,1,1,0,0,0,0,1,1,2,2
2,2,2,2,1,1,1,1,2,2,2,2
endlayer

layer
2,2,2,2,1,1,1,1,2,2,2,2
2,2,1,1,3,3,3,3,1,1,2,2
2,1,3,3,3,3,3,3,3,3,1,2
2,1,3,3,3,3,3,3,3,3,1,2
1,3,3,3,3,3,3,3,3,3,3,1
1,3,3,3,3,3,3,3,3,3,3,1
1,3,3,3,3,3,3,3,3,3,3,1
1,3,3,3,3,3,3,3,3,3,3,1
2,1,3,3,3,3,3,3,3,3,1,2
2,1,3,3,3,3,3,3,3,3,1,2
2,2,1,1,3,3,3,3,1,1,2,2
2,2,2,2,1,1,1,1,2,2,2,2
endlayer

layer
2,2,2,2,1,1,1,1,2,2,2,2
2,2,1,1,0,0,0,0,1,1,2,2
2,1,0,0,0,0,0,0,0,0,1,2
2,1,0,0,0,0,0,0,0,0,1,2
1,0,0,0,0,0,0,0,0,0,0,1
1,0,0,0,0,0,0,0,0,0,0,1
1,0,0,0,0,0,0,0,0,0,0,1
1,0,0,0,0,0,0,0,0,0,0,1
2,1,0,0,0,0,0,0,0,0,1,2
2,1,0,0,0,0,0,0,0,0,1,2
2,2,1,1,0,0,0,0,1,1,2,2
2,2,2,2,1,1,1,1,2,2,2,2
endlayer

layer
2,2,2,2,1,4,4,1,2,2,2,2
2,2,1,1,0,0,0,0,1,1,2,2
2,1,0,0,0,0,0,0,0,0,1,2
2,1,0,0,0,0,0,0,0,0,1,2
1,0,0,0,0,0,0,0,0,0,0,1
4,0,0,0,0,0,0,0,0,0,0,4
4,0,0,0,0,0,0,0,0,0,0,4
1,0,0,0,0,0,0,0,0,0,0,1
2,1,0,0,0,0,0,0,0,0,1,2
2,1,0,0,0,0,0,0,0,0,1,2
2,2,1,1,0,0,0,0,1,1,2,2
2,2,2,2,1,4,4,1,2,2,2,2
endlayer

layer
2,2,2,2,1,4,4,1,2,2,2,2
2,2,1,1,0,0,0,0,1,1,2,2
2,1,0,0,0,0,0,0,0,0,1,2
2,1,0,0,0,0,0,0,0,0,1,2
1,0,0,0,0,0,0,0,0,0,0,1
4,0,0,0,0,0,0,0,0,0,0,4
4,0,0,0,0,0,0,0,0,0,0,4
1,0,0,0,0,0,0,0,0,0,0,1
2,1,0,0,0,0,0,0,0,0,1,2
2,1,0,0,0,0,0,0,0,0,1,2
2,2,1,1,0,0,0,0,1,1,2,2
2,2,2,2,1,4,4,1,2,2,2,2
endlayer

layer
2,2,2,2,1,4,4,1,2,2,2,2
2,2,1,1,0,0,0,0,1,1,2,2
2,1,0,0,0,0,0,0,0,0,1,2
2,1,0,0,0,0,0,0,0,0,1,2
1,0,0,0,0,0,0,0,0,0,0,1
4,0,0,0,0,0,0,0,0,0,0,4
4,0,0,0,0,0,0,0,0,0,0,4
1,0,0,0,0,0,0,0,0,0,0,1
2,1,0,0,0,0,0,0,0,0,1,2
2,1,0,0,0,0,0,0,0,0,1,2
2,2,1,1,0,0,0,0,1,1,2,2
2,2,2,2,1,4,4,1,2,2,2,2
endlayer

layer
2,2,2,2,1,4,4,1,2,2,2,2
2,2,1,1,0,0,0,0,1,1,2,2
2,1,0,0,0,0,0,0,0,0,1,2
2,1,0,0,0,0,0,0,0,0,1,2
1,0,0,0,0,0,0,0,0,0,0,1
4,0,0,0,0,0,0,0,0,0,0,4
4,0,0,0,0,0,0,0,0,0,0,4
1,0,0,0,0,0,0,0,0,0,0,1
2,1,0,0,0,0,0,0,0,0,1,2
2,1,0,0,0,0,0,0,0,0,1,2
2,2,1,1,0,0,0,0,1,1,2,2
2,2,2,2,1,4,4,1,2,2,2,2
endlayer

layer
2,2,2,2,1,1,1,1,2,2,2,2
2,2,1,1,0,0,0,0,1,1,2,2
2,1,0,0,0,0,0,0,0,0,1,2
2,1,0,0,0,0,0,0,0,0,1,2
1,0,0,0,0,0,0,0,0,0,0,1
1,0,0,0,0,0,0,0,0,0,0,1
1,0,0,0,0,0,0,0,0,0,0,1
1,0,0,0,0,0,0,0,0,0,0,1
2,1,0,0,0,0,0,0,0,0,1,2
2,1,0,0,0,0,0,0,0,0,1,2
2,2,1,1,0,0,0,0,1,1,2,2
2,2,2,2,1,1,1,1,2,2,2,2
endlayer

layer
2,2,2,2,1,1,1,1,2,2,2,2
2,2,1,1,3,3,3,3,1,1,2,2
2,1,3,3,3,3,3,3,3,3,1,2
2,1,3,3,3,3,3,3,3,3,1,2
1,3,3,3,3,3,3,3,3,3,3,1
1,3,3,3,3,3,3,3,3,3,3,1
1,3,3,3,3,3,3,3,3,3,3,1
1,3,3,3,3,3,3,3,3,3,3,1
2,1,3,3,3,3,3,3,3,3,1,2
2,1,3,3,3,3,3,3,3,3,1,2
2,2,1,1,3,3,3,3,1,1,2,2
2,2,2,2,1,1,1,1,2,2,2,2
endlayer

layer
2,2,2,2,1,1,1,1,2,2,2,2
2,2,1,1,0,0,0,0,1,1,2,2
2,1,0,0,0,0,0,0,0,0,1,2
2,1,0,0,0,0,0,0,0,0,1,2
1,0,0,0,0,0,0,0,0,0,0,1
1,0,0,0,0,0,0,0,0,0,0,1
1,0,0,0,0,0,0,0,0,0,0,1
1,0,0,0,0,0,0,0,0,0,0,1
2,1,0,0,0,0,0,0,0,0,1,2
2,1,0,0,0,0,0,0,0,0,1,2
2,2,1,1,0,0,0,0,1,1,2,2
2,2,2,2,1,1,1,1,2,2,2,2
endlayer

layer
2,2,2,2,1,4,4,1,2,2,2,2
2,2,1,1,0,0,0,0,1,1,2,2
2,1,0,0,0,0,0,0,0,0,1,2
2,1,0,0,0,0,0,0,0,0,1,2
1,0,0,0,0,0,0,0,0,0,0,1
4,0,0,0,0,0,0,0,0,0,0,4
4,0,0,0,0,0,0,0,0,0,0,4
1,0,0,0,0,0,0,0,0,0,0,1
2,1,0,0,0,0,0,0,0,0,1,2
2,1,0,0,0,0,0,0,0,0,1,2
2,2,1,1,0,0,0,0,1,1,2,2
2,2,2,2,1,4,4,1,2,2,2,2
endlayer

layer
2,2,2,2,1,4,4,1,2,2,2,2
2,2,1,1,0,0,0,0,1,1,2,2
2,1,0,0,0,0,0,0,0,0,1,2
2,1,0,0,0,0,0,0,0,0,1,2
1,0,0,0,0,0,0,0,0,0,0,1
4,0,0,0,0,0,0,0,0,0,0,4
4,0,0,0,0,0,0,0,0,0,0,4
1,0,0,0,0,0,0,0,0,0,0,1
2,1,0,0,0,0,0,0,0,0,1,2
2,1,0,0,0,0,0,0,0,0,1,2
2,2,1,1,0,0,0,0,1,1,2,2
2,2,2,2,1,4,4,1,2,2,2,2
endlayer

layer
2,2,2,2,1,4,4,1,2,2,2,2
2,2,1,1,0,0,0,0,1,1,2,2
2,1,0,0,0,0,0,0,0,0,1,2
2,1,0,0,0,0,0,0,0,0,1,2
1,0,0,0,0,0,0,0,0,0,0,1
4,0,0,0,0,0,0,0,0,0,0,4
4,0,0,0,0,0,0,0,0,0,0,4
1,0,0,0,0,0,0,0,0,0,0,1
2,1,0,0,0,0,0,0,0,0,1,2
2,1,0,0,0,0,0,0,0,0,1,2
2,2,1,1,0,0,0,0,1,1,2,2
2,2,2,2,1,4,4,1,2,2,2,2
endlayer

layer
2,2,2,2,1,4,4,1,2,2,2,2
2,2,1,1,0,0,0,0,1,1,2,2
2,1,0,0,0,0,0,0,0,0,1,2
2,1,0,0,0,0,0,0,0,0,1,2
1,0,0,0,0,0,0,0,0,0,0,1
4,0,0,0,0,0,0,0,0,0,0,4
4,0,0,0,0,0,0,0,0,0,0,4
1,0,0,0,0,0,0,0,0,0,0,1
2,1,0,0,0,0,0,0,0,0,1,2
2,1,0,0,0,0,0,0,0,0,1,2
2,2,1,1,0,0,0,0,1,1,2,2
2,2,2,2,1,4,4,1,2,2,2,2
endlayer

layer
2,2,2,2,1,1,1,1,2,2,2,2
2,2,1,1,0,0,0,0,1,1,2,2
2,1,0,0,0,0,0,0,0,0,1,2
2,1,0,0,0,0,0,0,0,0,1,2
1,0,0,0,0,0,0,0,0,0,0,1
1,0,0,0,0,0,0,0,0,0,0,1
1,0,0,0,0,0,0,0,0,0,0,1
1,0,0,0,0,0,0,0,0,0,0,1
2,1,0,0,0,0,0,0,0,0,1,2
2,1,0,0,0,0,0,0,0,0,1,2
2,2,1,1,0,0,0,0,1,1,2,2
2,2,2,2,1,1,1,1,2,2,2,2
endlayer

layer
2,2,2,2,1,1,1,1,2,2,2,2
2,2,1,1,3,3,3,3,1,1,2,2
2,1,3,3,3,3,3,3,3,3,1,2
2,1,3,3,3,3,3,3,3,3,1,2
1,3,3,3,3,3,3,3,3,3,3,1
1,3,3,3,3,3,3,3,3,3,3,1
1,3,3,3,3,3,3,3,3,3,3,1
1,3,3,3,3,3,3,3,3,3,3,1
2,1,3,3,3,3,3,3,3,3,1,2
2,1,3,3,3,3,3,3,3,3,1,2
2,2,1,1,3,3,3,3,1,1,2,2
2,2,2,2,1,1,1,1,2,2,2,2
endlayer

