# Author: RoofFiddler
# From: Minecraft Forums
# Last Updated 13 Jul 2017

weight=2
emplanks_into_distance=0

unacceptable_target_blocks=flowing_water,water,flowing_lava,lava,cloud,Natura:Cloud,red_mushroom_block,brown_mushroom_block,planks,cobblestone,ice,end_stone,stone,brick_block,glowstone,bedrock,quartz_ore,iron_bars,nether_fence,slime_congealed,slime_dirt,slime_grass,ash_block,flesh

dimensions=7,9,15
allowable_overhang=0
max_leveling=2
leveling_buffer=0
preserve_water=0
preserve_lava=0
preserve_plants=1

rule1=0,100,air,cobblestone,mossy_cobblestone
rule2=0,100,cobblestone,mossy_cobblestone
rule3=1,80,cobblestone,mossy_cobblestone
rule4=1,75,cobblestone,mossy_cobblestone
rule5=2,75,cobblestone,mossy_cobblestone
rule6=2,50,cobblestone,mossy_cobblestone

layer
1,1,1,1,1,1,1,1,1,1,1,1,1,1,1
1,1,1,1,1,1,1,1,1,1,1,1,1,1,1
1,1,1,1,1,1,1,1,1,1,1,1,1,1,1
1,1,1,1,1,1,1,1,1,1,1,1,1,1,1
1,1,1,1,1,1,1,1,1,1,1,1,1,1,1
1,1,1,1,1,1,1,1,1,1,1,1,1,1,1
1,1,1,1,1,1,1,1,1,1,1,1,1,1,1
1,1,1,1,1,1,1,1,1,1,1,1,1,1,1
1,1,1,1,1,1,1,1,1,1,1,1,1,1,1
endlayer

layer
0,3,0,0,0,0,0,3,0,0,0,0,0,3,0
3,2,3,0,0,0,3,2,3,0,0,0,3,2,3
0,3,0,0,0,0,0,3,0,0,0,0,0,3,0
0,0,0,0,0,0,0,0,0,0,0,0,0,0,0
0,0,0,0,0,0,0,0,0,0,0,0,0,0,0
0,0,0,0,0,0,0,0,0,0,0,0,0,0,0
0,3,0,0,0,0,0,3,0,0,0,0,0,3,0
3,2,3,0,0,0,3,2,3,0,0,0,3,2,3
0,3,0,0,0,0,0,3,0,0,0,0,0,3,0
endlayer

layer
0,0,0,0,0,0,0,0,0,0,0,0,0,0,0
0,3,0,0,0,0,0,3,0,0,0,0,0,3,0
0,0,0,0,0,0,0,0,0,0,0,0,0,0,0
0,0,0,0,0,0,0,0,0,0,0,0,0,0,0
0,0,0,0,0,0,0,0,0,0,0,0,0,0,0
0,0,0,0,0,0,0,0,0,0,0,0,0,0,0
0,0,0,0,0,0,0,0,0,0,0,0,0,0,0
0,3,0,0,0,0,0,3,0,0,0,0,0,3,0
0,0,0,0,0,0,0,0,0,0,0,0,0,0,0
endlayer

layer
0,0,0,0,0,0,0,0,0,0,0,0,0,0,0
0,3,0,0,0,0,0,3,0,0,0,0,0,3,0
0,0,0,0,0,0,0,0,0,0,0,0,0,0,0
0,0,0,0,0,0,0,0,0,0,0,0,0,0,0
0,0,0,0,0,0,0,0,0,0,0,0,0,0,0
0,0,0,0,0,0,0,0,0,0,0,0,0,0,0
0,0,0,0,0,0,0,0,0,0,0,0,0,0,0
0,3,0,0,0,0,0,3,0,0,0,0,0,3,0
0,0,0,0,0,0,0,0,0,0,0,0,0,0,0
endlayer

layer
0,0,0,0,0,0,0,0,0,0,0,0,0,0,0
5,3,5,0,0,0,5,3,5,0,0,0,5,3,5
0,5,0,0,0,0,0,5,0,0,0,0,0,5,0
0,0,0,0,0,0,0,0,0,0,0,0,0,0,0
0,0,0,0,0,0,0,0,0,0,0,0,0,0,0
0,0,0,0,0,0,0,0,0,0,0,0,0,0,0
0,5,0,0,0,0,0,5,0,0,0,0,0,5,0
5,3,5,0,0,0,5,3,5,0,0,0,5,3,5
0,0,0,0,0,0,0,0,0,0,0,0,0,0,0
endlayer

layer
0,0,0,0,0,0,0,0,0,0,0,0,0,0,0
4,0,4,5,0,5,4,0,4,5,0,5,4,0,4
0,4,0,0,0,0,0,4,0,0,0,0,0,4,0
0,5,0,0,0,0,0,5,0,0,0,0,0,5,0
0,0,0,0,0,0,0,0,0,0,0,0,0,0,0
0,5,0,0,0,0,0,5,0,0,0,0,0,5,0
0,4,0,0,0,0,0,4,0,0,0,0,0,4,0
4,0,4,5,0,5,4,0,4,5,0,5,4,0,4
0,0,0,0,0,0,0,4,0,0,0,0,0,0,0
endlayer

layer
0,0,0,0,0,0,0,0,0,0,0,0,0,0,0
0,0,0,4,6,4,0,0,0,4,6,4,0,0,0
0,0,0,0,0,0,0,0,0,0,0,0,0,0,0
0,4,0,0,0,0,0,4,0,0,0,0,0,4,0
0,6,0,0,0,0,0,6,0,0,0,0,0,6,0
0,4,0,0,0,0,0,4,0,0,0,0,0,4,0
0,0,0,0,0,0,0,0,0,0,0,0,0,0,0
0,0,0,4,6,4,0,0,0,4,6,4,0,0,0
0,0,0,0,0,0,0,0,0,0,0,0,0,0,0
endlayer