weight=30
dimensionsToSpawnIn=overworld
embed_into_distance=6
random_height_offset=0,0
unacceptable_target_blocks=flowing_water,water,flowing_lava,lava,ice,packed_ice,stained_hardened_clay-9,brick_block,double_stone_slab,stonebrick,red_sandstone,red_nether_brick,red_mushroom_block,brown_mushroom_block,planks,cobblestone,end_stone,obsidian,purpur_block,iron_bars,purpur_slab,purpur_pillar,netherrack,soul_sand,quartz_ore,stained_glass,glass
dimensions=190,31,41
allowable_overhang=0
max_leveling=4
leveling_buffer=-1
preventRotation=0
preserve_water=0
preserve_lava=0
preserve_plants=0
uniqueMinDistance=300000
spawnMinDistance=15000
spawnMaxDistance=0

rule1=0,100,preserveBlock
rule2=0,100,chisel:concrete_gray-7
rule3=0,100,air
rule4=0,100,chisel:concrete_black-7
rule5=0,100,minecraft:iron_bars-0
rule6=0,100,chisel:glassdyedcyan-3
rule7=0,100,minecraft:sea_lantern-0
rule8=0,100,chisel:glasspanedyedcyan-3
rule9=0,100,ChestGenHook:chests/woodland_mansion:1-3,ChestGenHook:chests/nether_bridge:9-3,ChestGenHook:chests/stronghold_library:9-3,ChestGenHook:chests/stronghold_crossing:9-3,ChestGenHook:chests/stronghold_corridor:9-3
rule10=0,100,air,air,air
rule11=0,100,air,air,air
rule12=0,100,ChestGenHook:chests/village_blacksmith:9-5,ChestGenHook:chests/nether_bridge:9-5,ChestGenHook:chests/stronghold_library:9-5,ChestGenHook:chests/stronghold_crossing:9-5,ChestGenHook:chests/stronghold_corridor:9-5
rule13=0,100,air
rule14=0,100,chisel:factory-2
rule15=0,100,ChestGenHook:chests/woodland_mansion:9-4,ChestGenHook:chests/nether_bridge:9-4,ChestGenHook:chests/stronghold_library:9-4,ChestGenHook:chests/stronghold_crossing:9-4,ChestGenHook:chests/stronghold_corridor:9-4
rule16=0,100,ChestGenHook:chests/woodland_mansion:9-2,ChestGenHook:chests/nether_bridge:9-2,ChestGenHook:chests/stronghold_library:9-2,ChestGenHook:chests/stronghold_crossing:9-2,ChestGenHook:chests/stronghold_corridor:9-2
rule17=0,100,air
rule18=0,100,air,air,air
rule19=0,100,air
rule20=0,100,minecraft:lava-0
rule21=0,100,chisel:glassdyedcyan-3
rule22=0,100,minecraft:stone_slab-8
rule23=0,100,minecraft:stone_slab-0
rule24=0,100,air
rule25=0,100,chisel:glasspanedyedcyan-3
rule26=0,100,chisel:energizedvoidstone-7
rule27=0,100,chisel:laboratory-4
rule28=0,100,chisel:laboratory-4
rule29=0,100,chisel:laboratory-4
rule30=0,100,chisel:factory1-2
rule31=0,100,minecraft:cobblestone_wall-0
rule32=0,100,air
rule33=0,100,air
rule34=0,100,air
rule35=0,100,minecraft:double_stone_slab-0
rule36=0,100,air

layer
1,1,1,1,1,1,1,1,1,1,1,1,1,1,1,1,1,1,1,1,1,1,2,2,2,2,2,2,2,2,2,1,1,1,1,1,1,1,1,1,1
1,1,1,1,1,1,1,1,1,1,1,1,1,1,1,1,1,1,1,1,1,1,2,2,2,2,2,2,2,2,2,2,2,1,1,1,1,1,1,1,1
1,1,1,1,1,1,1,1,1,1,1,1,1,1,1,1,1,1,1,1,1,1,2,2,2,2,2,2,2,2,2,2,2,2,1,1,1,1,1,1,1
1,1,1,1,1,1,1,1,1,1,1,1,1,1,1,1,1,1,1,1,1,2,2,2,2,2,2,2,2,2,2,2,2,2,2,1,1,1,1,1,1
1,1,1,1,1,1,1,1,1,1,1,1,1,1,1,1,1,1,1,1,2,2,2,2,2,2,2,2,2,2,2,2,2,2,2,2,1,1,1,1,1
1,1,1,1,1,1,1,1,1,2,1,1,1,1,1,1,1,1,1,2,2,2,2,2,2,2,2,2,2,2,2,2,2,2,2,2,2,1,1,1,1
1,1,1,1,1,1,1,1,2,2,1,1,1,1,1,1,1,1,2,2,2,2,2,2,2,2,2,2,2,2,2,2,2,2,2,2,2,2,1,1,1
1,1,1,1,1,1,1,2,2,2,1,1,1,1,1,1,1,2,2,2,2,2,2,2,2,2,2,2,2,2,2,2,2,2,2,2,2,2,1,1,1
1,1,1,1,1,1,2,1,1,2,1,1,1,1,1,1,2,2,2,2,2,2,2,2,2,2,2,2,2,2,2,2,2,2,2,2,2,1,1,1,1
1,1,1,1,1,2,1,1,2,1,1,1,1,1,1,2,2,2,2,2,2,2,2,2,2,2,2,2,2,2,2,2,2,2,2,2,2,1,1,1,1
1,1,1,1,2,1,1,2,1,1,1,1,1,1,2,2,2,2,2,2,2,2,2,2,2,2,2,2,2,2,2,2,2,2,2,2,2,2,1,1,1
1,1,1,2,1,1,2,1,1,1,1,1,1,2,2,2,2,2,2,2,2,2,2,2,2,2,2,2,2,2,2,2,2,2,2,2,2,2,1,1,1
1,1,2,1,1,2,1,1,1,1,1,1,2,2,2,2,2,2,2,2,2,2,2,2,2,2,2,2,2,2,2,2,2,2,2,2,2,1,1,1,1
1,2,1,1,2,1,1,1,1,1,1,2,2,2,2,2,2,2,2,2,2,2,2,2,2,2,2,2,2,2,2,2,2,2,2,2,2,1,1,1,1
2,2,2,2,1,1,1,1,1,1,2,2,2,2,2,2,2,2,2,2,2,2,2,2,2,2,2,2,2,2,2,2,2,2,2,2,2,2,1,1,1
1,1,1,2,1,1,1,1,1,2,2,2,2,2,2,2,2,2,2,2,2,2,2,2,2,2,2,2,2,2,2,2,2,2,2,2,2,2,1,1,1
1,1,1,2,1,1,1,1,2,2,2,2,2,2,2,2,2,2,2,2,2,2,2,2,2,2,2,2,2,2,2,2,2,2,2,2,2,1,1,1,1
1,1,1,2,1,1,1,2,2,2,2,2,2,2,2,2,2,2,2,2,2,2,2,2,2,2,2,2,2,2,2,2,2,2,2,2,2,1,1,1,1
1,1,1,2,1,1,2,2,2,2,2,2,2,2,2,2,2,2,2,2,2,2,2,2,2,2,2,2,2,2,2,2,2,2,2,2,2,2,2,2,2
1,1,1,2,2,2,2,2,2,2,2,2,2,2,2,2,2,2,2,2,2,2,2,2,2,2,2,2,2,2,2,2,2,2,2,2,2,2,2,2,2
1,1,1,2,2,2,2,2,2,2,2,2,2,2,2,2,2,2,2,2,2,2,2,2,2,2,2,2,2,2,2,2,2,2,2,2,2,2,2,2,2
1,1,1,1,2,2,2,2,2,2,2,2,2,2,2,2,2,2,2,2,2,2,2,2,2,2,2,2,2,2,2,2,2,2,2,2,2,2,2,2,2
1,1,1,1,1,2,2,2,2,2,2,2,2,2,2,2,2,2,2,2,2,2,2,2,2,2,2,2,2,2,2,2,2,2,2,2,2,2,2,2,1
1,1,1,1,1,1,2,2,2,2,2,2,2,2,2,2,2,2,2,2,2,2,2,2,2,2,2,2,2,2,2,2,2,2,2,2,2,2,2,1,1
1,1,1,1,1,1,1,2,2,2,2,2,2,2,2,2,2,2,2,2,2,2,2,2,2,2,2,2,2,2,2,2,2,2,2,2,2,2,1,1,1
1,1,1,1,1,1,1,1,2,2,2,2,2,2,2,2,2,2,2,2,2,2,2,2,2,2,2,2,2,2,2,2,2,2,2,2,2,1,1,1,1
1,1,1,1,1,1,1,1,1,2,2,2,2,2,2,2,2,2,2,2,2,2,2,2,2,2,2,2,2,2,2,2,2,2,2,2,1,1,1,1,1
1,1,1,1,1,1,1,1,1,1,2,2,2,2,2,2,2,2,2,2,2,2,2,2,2,2,2,2,2,2,2,2,2,2,2,1,1,1,1,1,1
1,1,1,1,1,1,1,1,1,1,1,2,2,2,2,2,2,2,2,2,2,2,2,2,2,2,2,2,2,2,2,2,2,2,1,1,1,1,1,1,1
1,1,1,1,1,1,1,1,1,1,1,1,2,2,2,2,2,2,2,2,2,2,2,2,2,2,2,2,2,2,2,2,2,1,1,1,1,1,1,1,1
1,1,1,1,1,1,1,1,1,1,1,1,1,2,2,2,2,2,2,2,2,2,2,2,2,2,2,2,2,2,2,1,1,1,1,1,1,1,1,1,1
endlayer

layer
1,1,1,1,1,1,1,1,1,1,1,1,1,1,1,1,1,1,1,1,1,1,2,2,2,2,2,2,2,2,2,1,1,1,1,1,1,1,1,1,1
1,1,1,1,1,1,1,1,1,1,1,1,1,1,1,1,1,1,1,1,1,1,2,2,2,2,2,2,2,2,2,2,2,1,1,1,1,1,1,1,1
1,1,1,1,1,1,1,1,1,1,1,1,1,1,1,1,1,1,1,1,1,1,2,2,2,2,2,2,2,2,2,2,2,2,1,1,1,1,1,1,1
1,1,1,1,1,1,1,1,1,1,1,1,1,1,1,1,1,1,1,1,1,2,2,2,2,2,2,2,2,2,2,2,2,2,2,1,1,1,1,1,1
1,1,1,1,1,1,1,1,1,1,1,1,1,1,1,1,1,1,1,1,2,2,2,2,2,2,2,2,2,2,2,2,2,2,2,2,1,1,1,1,1
1,1,1,1,1,1,1,1,1,2,1,1,1,1,1,1,1,1,1,2,2,2,2,2,2,2,2,2,2,2,2,2,2,2,2,2,2,1,1,1,1
1,1,1,1,1,1,1,1,2,2,1,1,1,1,1,1,1,1,2,2,2,2,2,2,2,2,2,2,2,2,2,2,2,2,2,2,2,2,1,1,1
1,1,1,1,1,1,1,2,1,2,1,1,1,1,1,1,1,2,2,2,2,2,2,2,2,2,2,2,2,2,2,2,2,2,2,2,2,2,1,1,1
1,1,1,1,1,1,2,1,1,2,1,1,1,1,1,1,2,2,2,2,2,2,2,2,2,2,2,2,2,2,2,2,2,2,2,2,2,1,1,1,1
1,1,1,1,1,2,1,1,2,1,1,1,1,1,1,2,2,2,2,2,2,2,2,2,2,2,2,2,2,2,2,2,2,2,2,2,2,1,1,1,1
1,1,1,1,2,1,1,2,1,1,1,1,1,1,2,2,2,2,2,2,2,2,2,2,2,2,2,2,2,2,2,2,2,2,2,2,2,2,1,1,1
1,1,1,2,1,1,2,1,1,1,1,1,1,2,2,2,2,2,2,2,2,2,2,2,2,2,2,2,2,2,2,2,2,2,2,2,2,2,1,1,1
1,1,2,1,1,2,1,1,1,1,1,1,2,2,2,2,2,2,2,2,2,2,2,2,2,2,2,2,2,2,2,2,2,2,2,2,2,1,1,1,1
1,2,1,1,2,1,1,1,1,1,1,2,2,2,2,2,2,2,2,2,2,2,2,2,2,2,2,2,2,2,2,2,2,2,2,2,2,1,1,1,1
2,2,2,2,1,1,1,1,1,1,2,2,2,2,2,2,2,2,2,2,2,2,2,2,2,2,2,2,2,2,2,2,2,2,2,2,2,2,1,1,1
1,1,1,2,1,1,1,1,1,2,2,2,2,2,2,2,2,2,2,2,2,2,2,2,2,2,2,2,2,2,2,2,2,2,2,2,2,2,1,1,1
1,1,1,2,1,1,1,1,2,2,2,2,2,2,2,2,2,2,2,2,2,2,2,2,2,2,2,2,2,2,2,2,2,2,2,2,2,1,1,1,1
1,1,1,2,1,1,1,2,2,2,2,2,2,2,2,2,2,2,2,2,2,2,2,2,2,2,2,2,2,2,2,2,2,2,2,2,2,1,1,1,1
1,1,1,2,1,1,2,2,2,2,2,2,2,2,2,2,2,2,2,2,2,2,2,2,2,2,2,2,2,2,2,2,2,2,2,2,2,2,2,2,2
1,1,1,2,2,2,2,2,2,2,2,2,2,2,2,2,2,2,2,2,2,2,2,2,2,2,2,2,2,2,2,2,2,2,2,2,2,2,2,2,2
1,1,1,2,2,2,2,2,2,2,2,2,2,2,2,2,2,2,2,2,2,2,2,2,2,2,2,2,2,2,2,2,2,2,2,2,2,2,2,2,2
1,1,1,1,2,2,2,2,2,2,2,2,2,2,2,2,2,2,2,2,2,2,2,2,2,2,2,2,2,2,2,2,2,2,2,2,2,2,2,2,2
1,1,1,1,1,2,2,2,2,2,2,2,2,2,2,2,2,2,2,2,2,2,2,2,2,2,2,2,2,2,2,2,2,2,2,2,2,2,2,2,1
1,1,1,1,1,1,2,2,2,2,2,2,2,2,2,2,2,2,2,2,2,2,2,2,2,2,2,2,2,2,2,2,2,2,2,2,2,2,2,1,1
1,1,1,1,1,1,1,2,2,2,2,2,2,2,2,2,2,2,2,2,2,2,2,2,2,2,2,2,2,2,2,2,2,2,2,2,2,2,1,1,1
1,1,1,1,1,1,1,1,2,2,2,2,2,2,2,2,2,2,2,2,2,2,2,2,2,2,2,2,2,2,2,2,2,2,2,2,2,1,1,1,1
1,1,1,1,1,1,1,1,1,2,2,2,2,2,2,2,2,2,2,2,2,2,2,2,2,2,2,2,2,2,2,2,2,2,2,2,1,1,1,1,1
1,1,1,1,1,1,1,1,1,1,2,2,2,2,2,2,2,2,2,2,2,2,2,2,2,2,2,2,2,2,2,2,2,2,2,1,1,1,1,1,1
1,1,1,1,1,1,1,1,1,1,1,2,2,2,2,2,2,2,2,2,2,2,2,2,2,2,2,2,2,2,2,2,2,2,1,1,1,1,1,1,1
1,1,1,1,1,1,1,1,1,1,1,1,2,2,2,2,2,2,2,2,2,2,2,2,2,2,2,2,2,2,2,2,2,1,1,1,1,1,1,1,1
1,1,1,1,1,1,1,1,1,1,1,1,1,2,2,2,2,2,2,2,2,2,2,2,2,2,2,2,2,2,2,1,1,1,1,1,1,1,1,1,1
endlayer

layer
1,1,1,1,1,1,1,1,1,1,1,1,1,1,1,1,1,1,1,1,1,1,2,2,2,2,2,2,2,2,2,1,1,1,1,1,1,1,1,1,1
1,1,1,1,1,1,1,1,1,1,1,1,1,1,1,1,1,1,1,1,1,1,2,3,3,4,3,3,4,3,3,2,2,1,1,1,1,1,1,1,1
1,1,1,1,1,1,1,1,1,1,1,1,1,1,1,1,1,1,1,1,1,1,2,3,3,5,3,3,5,3,3,3,3,2,1,1,1,1,1,1,1
1,1,1,1,1,1,1,1,1,1,1,1,1,1,1,1,1,1,1,1,1,2,3,3,3,3,3,3,3,3,3,3,3,3,2,1,1,1,1,1,1
1,1,1,1,1,1,1,1,1,1,1,1,1,1,1,1,1,1,1,1,2,3,3,3,3,3,3,3,3,3,3,3,3,3,3,2,1,1,1,1,1
1,1,1,1,1,1,1,1,1,2,1,1,1,1,1,1,1,1,1,2,3,3,3,3,3,3,3,3,3,3,3,3,3,3,3,3,2,1,1,1,1
1,1,1,1,1,1,1,1,2,2,1,1,1,1,1,1,1,1,2,3,3,3,3,3,3,3,3,3,3,3,3,3,3,3,3,3,2,2,1,1,1
1,1,1,1,1,1,1,2,1,2,1,1,1,1,1,1,1,2,3,3,3,3,3,3,3,3,3,3,3,3,3,3,3,3,3,4,2,2,1,1,1
1,1,1,1,1,1,2,1,1,2,1,1,1,1,1,1,2,3,3,3,3,3,3,3,3,3,3,3,3,3,3,3,3,3,3,3,2,1,1,1,1
1,1,1,1,1,2,1,1,2,1,1,1,1,1,1,2,3,3,3,3,3,3,3,3,3,3,3,3,3,3,3,3,3,3,3,3,2,1,1,1,1
1,1,1,1,2,1,1,2,1,1,1,1,1,1,2,3,3,3,3,3,3,3,3,3,3,3,3,3,3,3,3,3,3,3,3,4,2,2,1,1,1
1,1,1,2,1,1,2,1,1,1,1,1,1,2,3,3,3,3,3,3,3,3,3,3,3,3,3,3,3,3,3,3,3,3,3,3,2,2,1,1,1
1,1,2,1,1,2,1,1,1,1,1,1,2,3,3,3,3,3,3,2,4,3,3,3,3,3,3,3,3,3,3,3,3,3,3,3,2,1,1,1,1
1,2,1,1,2,1,1,1,1,1,1,2,3,3,3,3,3,3,2,4,4,4,3,3,3,3,3,3,3,3,3,3,3,3,3,4,2,1,1,1,1
2,2,2,2,1,1,1,1,1,1,2,3,3,3,3,3,3,2,4,4,4,3,3,3,3,3,3,3,3,3,3,3,3,3,3,3,2,2,1,1,1
1,1,1,2,1,1,1,1,1,2,3,3,3,3,3,3,2,4,4,4,4,4,3,3,3,3,3,3,3,3,3,3,3,3,3,3,2,2,1,1,1
1,1,1,2,1,1,1,1,2,3,3,3,3,3,3,3,4,4,4,4,4,3,3,3,3,3,3,3,3,3,3,3,3,3,3,4,2,1,1,1,1
1,1,1,2,1,1,1,2,3,3,3,3,3,3,3,3,3,4,3,4,3,3,3,3,3,3,3,3,3,3,3,3,3,3,3,3,2,1,1,1,1
1,1,1,2,1,1,2,3,3,3,3,3,3,3,3,3,3,3,3,3,3,3,3,3,3,3,3,3,3,3,3,3,3,3,3,3,2,2,2,2,2
1,1,1,2,2,2,3,3,3,3,3,3,3,3,3,3,3,3,3,3,3,3,3,3,3,3,3,3,3,3,3,3,3,3,3,3,3,3,3,4,2
1,1,1,2,2,2,3,3,3,3,3,3,3,3,3,3,3,3,3,3,3,3,3,3,3,3,3,3,3,3,3,3,3,3,3,3,3,3,3,3,2
1,1,1,1,2,2,4,3,3,3,3,3,3,3,3,3,3,3,3,3,3,3,3,3,3,3,3,3,3,3,3,3,3,3,3,3,3,3,3,4,2
1,1,1,1,1,2,3,3,3,3,3,3,3,3,3,3,3,3,3,3,3,3,3,3,3,3,3,3,3,3,3,3,3,3,3,3,3,3,3,2,1
1,1,1,1,1,1,2,2,2,2,2,3,3,3,3,3,3,3,3,3,3,3,3,3,3,3,3,3,3,3,3,3,3,3,3,3,3,3,2,1,1
1,1,1,1,1,1,1,2,2,2,2,2,3,3,3,3,3,3,3,3,3,3,3,3,2,6,3,3,3,3,3,3,3,3,3,3,3,2,1,1,1
1,1,1,1,1,1,1,1,2,2,2,2,2,3,3,3,3,3,3,3,3,3,3,3,2,6,3,3,3,3,3,3,3,3,3,3,2,1,1,1,1
1,1,1,1,1,1,1,1,1,2,2,2,2,2,3,3,3,3,3,3,3,3,3,3,2,6,3,3,3,3,3,3,3,3,3,2,1,1,1,1,1
1,1,1,1,1,1,1,1,1,1,2,2,2,2,3,3,3,3,3,3,3,3,3,3,3,3,3,3,3,3,3,3,3,3,2,1,1,1,1,1,1
1,1,1,1,1,1,1,1,1,1,1,2,2,2,3,3,5,3,3,5,3,3,5,3,3,5,3,3,5,3,3,3,3,2,1,1,1,1,1,1,1
1,1,1,1,1,1,1,1,1,1,1,1,2,2,3,3,4,3,3,4,3,3,4,3,3,4,3,3,4,3,3,2,2,1,1,1,1,1,1,1,1
1,1,1,1,1,1,1,1,1,1,1,1,1,2,2,2,2,2,2,2,2,2,2,2,2,2,2,2,2,2,2,1,1,1,1,1,1,1,1,1,1
endlayer

layer
1,1,1,1,1,1,1,1,1,1,1,1,1,1,1,1,1,1,1,1,1,1,2,2,2,2,2,2,2,2,2,1,1,1,1,1,1,1,1,1,1
1,1,1,1,1,1,1,1,1,1,1,1,1,1,1,1,1,1,1,1,1,1,2,3,3,4,3,3,4,3,3,2,2,1,1,1,1,1,1,1,1
1,1,1,1,1,1,1,1,1,1,1,1,1,1,1,1,1,1,1,1,1,1,2,3,3,4,3,3,4,3,3,3,3,2,1,1,1,1,1,1,1
1,1,1,1,1,1,1,1,1,1,1,1,1,1,1,1,1,1,1,1,1,2,3,3,3,3,3,3,3,3,3,3,3,3,2,1,1,1,1,1,1
1,1,1,1,1,1,1,1,1,1,1,1,1,1,1,1,1,1,1,1,2,3,3,3,3,3,3,3,3,3,3,3,3,3,3,2,1,1,1,1,1
1,1,1,1,1,1,1,1,1,2,1,1,1,1,1,1,1,1,1,2,3,3,3,3,3,3,3,3,3,3,3,3,3,3,3,3,2,1,1,1,1
1,1,1,1,1,1,1,1,2,2,1,1,1,1,1,1,1,1,2,3,3,3,3,3,3,3,3,3,3,3,3,3,3,3,3,3,2,2,1,1,1
1,1,1,1,1,1,1,2,1,2,1,1,1,1,1,1,1,2,3,3,3,3,3,3,3,3,3,3,3,3,3,3,3,3,3,4,2,2,1,1,1
1,1,1,1,1,1,2,1,1,2,1,1,1,1,1,1,2,3,3,3,3,3,3,3,3,3,3,3,3,3,3,3,3,3,3,3,2,1,1,1,1
1,1,1,1,1,2,1,1,2,1,1,1,1,1,1,2,3,3,3,3,3,3,3,3,3,3,3,3,3,3,3,3,3,3,3,3,2,1,1,1,1
1,1,1,1,2,1,1,2,1,1,1,1,1,1,2,3,3,3,3,3,3,3,3,3,3,3,3,3,3,3,3,3,3,3,3,4,2,2,1,1,1
1,1,1,2,1,1,2,1,1,1,1,1,1,2,3,3,3,3,3,3,3,3,3,3,3,3,3,3,3,3,3,3,3,3,3,3,2,2,1,1,1
1,1,2,1,1,2,1,1,1,1,1,1,2,3,3,3,3,3,3,2,4,3,3,3,3,3,3,3,3,3,3,3,3,3,3,3,2,1,1,1,1
1,2,1,1,2,1,1,1,1,1,1,2,3,3,3,3,3,3,2,4,4,4,3,3,3,3,3,3,3,3,3,3,3,3,3,4,2,1,1,1,1
2,2,2,2,1,1,1,1,1,1,2,3,3,3,3,3,3,2,4,4,4,3,3,3,3,3,3,3,3,3,3,3,3,3,3,3,2,2,1,1,1
1,1,1,2,1,1,1,1,1,2,3,3,3,3,3,3,2,4,4,4,4,4,3,3,3,3,3,3,3,3,3,3,3,3,3,3,2,2,1,1,1
1,1,1,2,1,1,1,1,2,3,3,3,3,3,3,3,4,4,4,4,4,3,3,3,3,3,3,3,3,3,3,3,3,3,3,4,2,1,1,1,1
1,1,1,2,1,1,1,2,3,3,3,3,3,3,3,3,3,4,3,4,3,3,3,3,3,3,3,3,3,3,3,3,3,3,3,3,2,1,1,1,1
1,1,1,2,1,1,2,3,3,3,3,3,3,3,3,3,3,3,3,3,3,3,3,3,3,3,3,3,3,3,3,3,3,3,3,3,2,2,2,2,2
1,1,1,2,2,2,3,3,3,3,3,3,3,3,3,3,3,3,3,3,3,3,3,3,3,3,3,3,3,3,3,3,3,3,3,3,3,3,3,4,2
1,1,1,2,2,2,3,3,3,3,3,3,3,3,3,3,3,3,3,3,3,3,3,3,3,3,3,3,3,3,3,3,3,3,3,3,3,3,3,3,2
1,1,1,1,2,2,4,3,3,3,3,3,3,3,3,3,3,3,3,3,3,3,3,3,3,3,3,3,3,3,3,3,3,3,3,3,3,3,3,4,2
1,1,1,1,1,2,3,3,3,3,3,3,3,3,3,3,3,3,3,3,3,3,3,3,3,3,3,3,3,3,3,3,3,3,3,3,3,3,3,2,1
1,1,1,1,1,1,2,2,2,2,2,3,3,3,3,3,3,3,3,3,3,3,3,3,3,3,3,3,3,3,3,3,3,3,3,3,3,3,2,1,1
1,1,1,1,1,1,1,2,2,2,2,2,3,3,3,3,3,3,3,3,3,3,3,3,3,3,6,3,3,3,3,3,3,3,3,3,3,2,1,1,1
1,1,1,1,1,1,1,1,2,2,2,2,2,3,3,3,3,3,3,3,3,3,3,3,3,3,6,3,3,3,3,3,3,3,3,3,2,1,1,1,1
1,1,1,1,1,1,1,1,1,2,2,2,2,2,3,3,3,3,3,3,3,3,3,3,3,3,6,3,3,3,3,3,3,3,3,2,1,1,1,1,1
1,1,1,1,1,1,1,1,1,1,2,2,2,2,3,3,3,3,3,3,3,3,3,3,3,3,3,3,3,3,3,3,3,3,2,1,1,1,1,1,1
1,1,1,1,1,1,1,1,1,1,1,2,2,2,3,3,4,3,3,4,3,3,4,3,3,4,3,3,4,3,3,3,3,2,1,1,1,1,1,1,1
1,1,1,1,1,1,1,1,1,1,1,1,2,2,3,3,4,3,3,4,3,3,4,3,3,4,3,3,4,3,3,2,2,1,1,1,1,1,1,1,1
1,1,1,1,1,1,1,1,1,1,1,1,1,2,2,2,2,2,2,2,2,2,2,2,2,2,2,2,2,2,2,1,1,1,1,1,1,1,1,1,1
endlayer

layer
1,1,1,1,1,1,1,1,1,1,1,1,1,1,1,1,1,1,1,1,1,1,2,2,2,2,2,2,2,2,2,1,1,1,1,1,1,1,1,1,1
1,1,1,1,1,1,1,1,1,1,1,1,1,1,1,1,1,1,1,1,1,1,2,3,3,7,3,3,7,3,3,2,2,1,1,1,1,1,1,1,1
1,1,1,1,1,1,1,1,1,1,1,1,1,1,1,1,1,1,1,1,1,1,2,3,3,4,3,3,4,3,3,3,3,2,1,1,1,1,1,1,1
1,1,1,1,1,1,1,1,1,1,1,1,1,1,1,1,1,1,1,1,1,2,3,3,3,3,3,3,3,3,3,3,3,3,2,1,1,1,1,1,1
1,1,1,1,1,1,1,1,1,1,1,1,1,1,1,1,1,1,1,1,2,3,3,3,3,3,3,3,3,3,3,3,3,3,3,2,1,1,1,1,1
1,1,1,1,1,1,1,1,1,2,1,1,1,1,1,1,1,1,1,2,3,3,3,3,3,3,3,3,3,3,3,3,3,3,3,3,2,1,1,1,1
1,1,1,1,1,1,1,1,2,2,1,1,1,1,1,1,1,1,2,3,3,3,3,3,3,3,3,3,3,3,3,3,3,3,3,3,2,2,1,1,1
1,1,1,1,1,1,1,2,1,2,1,1,1,1,1,1,1,2,3,3,3,3,3,3,3,3,3,3,3,3,3,3,3,3,4,4,2,2,1,1,1
1,1,1,1,1,1,2,1,1,2,1,1,1,1,1,1,2,3,3,3,3,3,3,3,3,3,3,3,3,3,3,3,3,3,3,3,2,1,1,1,1
1,1,1,1,1,2,1,1,2,1,1,1,1,1,1,2,3,3,3,3,3,3,3,3,3,3,3,3,3,3,3,3,3,3,3,3,2,1,1,1,1
1,1,1,1,2,1,1,2,1,1,1,1,1,1,2,3,3,3,3,3,3,3,3,3,3,3,3,3,3,3,3,3,3,3,4,4,2,2,1,1,1
1,1,1,2,1,1,2,1,1,1,1,1,1,2,3,3,3,3,3,3,3,3,3,3,3,3,3,3,3,3,3,3,3,3,3,3,2,2,1,1,1
1,1,2,1,1,2,1,1,1,1,1,1,2,3,3,3,3,3,3,2,4,3,3,3,3,3,3,3,3,3,3,3,3,3,3,3,2,1,1,1,1
1,2,1,1,2,1,1,1,1,1,1,2,3,3,3,3,3,3,2,4,4,4,3,3,3,3,3,3,3,3,3,3,3,3,4,4,2,1,1,1,1
2,2,2,2,1,1,1,1,1,1,2,3,3,3,3,3,3,2,4,4,4,3,3,3,3,3,3,3,3,3,3,3,3,3,3,3,2,2,1,1,1
1,1,1,2,1,1,1,1,1,2,3,3,3,3,3,3,2,4,4,4,4,4,3,3,3,3,3,3,3,3,3,3,3,3,3,3,2,2,1,1,1
1,1,1,2,1,1,1,1,2,3,3,3,3,3,3,3,4,4,4,4,4,3,3,3,3,3,3,3,3,3,3,3,3,3,4,4,2,1,1,1,1
1,1,1,2,1,1,1,2,3,3,3,3,3,3,3,3,3,4,3,4,3,3,3,3,3,3,3,3,3,3,3,3,3,3,3,3,2,1,1,1,1
1,1,1,2,1,1,2,3,3,3,3,3,3,3,3,3,3,3,3,3,3,3,3,3,3,3,3,3,3,3,3,3,3,3,3,3,2,2,2,2,2
1,1,1,2,2,2,3,3,3,3,3,3,3,3,3,3,3,3,3,3,3,3,3,3,3,3,3,3,3,3,3,3,3,3,3,3,3,3,3,4,2
1,1,1,2,2,2,3,3,3,3,3,3,3,3,3,3,3,3,3,3,3,3,3,3,3,3,3,3,3,3,3,3,3,3,3,3,3,3,3,3,2
1,1,1,1,2,2,4,3,3,3,3,3,3,3,3,3,3,3,3,3,3,3,3,3,3,3,3,3,3,3,3,3,3,3,3,3,3,3,3,4,2
1,1,1,1,1,2,3,3,3,3,3,3,3,3,3,3,3,3,3,3,3,3,3,3,3,3,3,3,3,3,3,3,3,3,3,3,3,3,3,2,1
1,1,1,1,1,1,2,2,2,2,3,3,3,3,3,3,3,3,3,3,3,3,3,3,3,3,3,3,3,3,3,3,3,3,3,3,3,3,2,1,1
1,1,1,1,1,1,1,2,2,2,2,3,3,3,3,3,3,3,3,3,3,3,3,3,3,3,3,6,3,3,3,3,3,3,3,3,3,2,1,1,1
1,1,1,1,1,1,1,1,2,2,2,2,3,3,3,3,3,3,3,3,3,3,3,3,3,3,3,6,3,3,3,3,3,3,3,3,2,1,1,1,1
1,1,1,1,1,1,1,1,1,2,2,2,2,3,3,3,3,3,3,3,3,3,3,3,3,3,3,6,3,3,3,3,3,3,3,2,1,1,1,1,1
1,1,1,1,1,1,1,1,1,1,2,2,2,2,3,3,3,3,3,3,3,3,3,3,3,3,3,3,3,3,3,3,3,3,2,1,1,1,1,1,1
1,1,1,1,1,1,1,1,1,1,1,2,2,2,3,3,4,3,3,4,3,3,4,3,3,4,3,3,4,3,3,3,3,2,1,1,1,1,1,1,1
1,1,1,1,1,1,1,1,1,1,1,1,2,2,3,3,7,3,3,7,3,3,7,3,3,7,3,3,7,3,3,2,2,1,1,1,1,1,1,1,1
1,1,1,1,1,1,1,1,1,1,1,1,1,2,2,2,2,2,2,2,2,2,2,2,2,2,2,2,2,2,2,1,1,1,1,1,1,1,1,1,1
endlayer

layer
1,1,1,1,1,1,1,1,1,1,1,1,1,1,1,1,1,1,1,1,1,1,2,2,2,2,2,2,2,2,2,4,4,4,1,1,1,1,1,1,1
1,1,1,1,1,1,1,1,1,1,1,1,1,1,1,1,1,1,1,1,1,1,2,3,3,4,3,3,4,3,3,2,2,4,4,4,1,1,1,1,1
1,1,1,1,1,1,1,1,1,1,1,1,1,1,1,1,1,1,1,1,1,1,2,3,3,4,3,3,4,3,3,3,3,2,4,4,4,1,1,1,1
1,1,1,1,1,1,1,1,1,1,1,1,1,1,1,1,1,1,1,1,1,2,3,3,3,3,3,3,3,3,3,3,3,3,2,4,4,4,1,1,1
1,1,1,1,1,1,1,1,1,1,1,1,1,1,1,1,1,1,1,1,2,3,3,3,3,3,3,3,3,3,3,3,3,3,3,2,4,4,4,1,1
1,1,1,1,1,1,1,1,1,2,1,1,1,1,1,1,1,1,1,2,3,3,3,3,3,3,3,3,3,3,3,3,3,3,3,3,2,4,4,4,1
1,1,1,1,1,1,1,1,2,2,1,1,1,1,1,1,1,1,2,3,3,3,3,3,3,3,3,3,3,3,3,3,3,3,3,3,2,2,4,4,1
1,1,1,1,1,1,1,2,1,2,1,1,1,1,1,1,1,2,3,3,3,3,3,3,3,3,3,3,3,3,3,3,3,3,4,4,2,2,4,4,1
1,1,1,1,1,1,2,1,1,2,1,1,1,1,1,1,2,3,3,3,3,3,3,3,3,3,3,3,3,3,3,3,3,3,3,3,2,4,4,4,1
1,1,1,1,1,2,1,1,2,1,1,1,1,1,1,2,3,3,3,3,3,3,3,3,3,3,3,3,3,3,3,3,3,3,3,3,2,4,4,4,1
1,1,1,1,2,1,1,2,1,1,1,1,1,1,2,3,3,3,3,3,3,3,3,3,3,3,3,3,3,3,3,3,3,3,4,4,2,2,4,4,1
1,1,1,2,1,1,2,1,1,1,1,1,1,2,3,3,3,3,3,3,3,3,3,3,3,3,3,3,3,3,3,3,3,3,3,3,2,2,4,4,1
1,1,2,1,1,2,1,1,1,1,1,1,2,3,3,3,3,3,3,3,4,3,3,3,3,3,3,3,3,3,3,3,3,3,3,3,2,4,4,4,1
1,2,1,1,2,1,1,1,1,1,1,2,3,3,3,3,3,3,3,4,4,3,3,3,3,3,3,3,3,3,3,3,3,3,4,4,2,4,4,4,1
2,2,2,2,1,1,1,1,1,1,2,3,3,3,3,3,3,3,4,4,4,3,3,3,3,3,3,3,3,3,3,3,3,3,3,3,2,2,4,4,1
1,1,1,2,1,1,1,1,1,2,3,3,3,3,3,3,3,4,4,4,4,3,3,3,3,3,3,3,3,3,3,3,3,3,3,3,2,2,4,4,1
1,1,1,2,1,1,1,1,2,3,3,3,3,3,3,3,4,4,4,4,4,3,3,3,3,3,3,3,3,3,3,3,3,3,4,4,2,4,4,4,1
1,1,1,2,1,1,1,2,3,3,3,3,3,3,3,3,3,3,3,3,3,3,3,3,3,3,3,3,3,3,3,3,3,3,3,3,2,4,4,4,1
1,1,1,2,1,1,2,3,3,3,3,3,3,3,3,3,3,3,3,3,3,3,3,3,3,3,3,3,3,3,3,3,3,3,3,3,2,2,2,2,2
1,1,1,2,2,2,3,3,3,3,3,3,3,3,3,3,3,3,3,3,3,3,3,3,3,3,3,3,3,3,3,3,3,3,3,3,3,3,3,4,2
1,1,1,2,2,2,3,3,3,3,3,3,3,3,3,3,3,3,3,3,3,3,3,3,3,3,3,3,3,3,3,3,3,3,3,3,3,3,3,3,2
1,1,1,1,2,2,4,3,3,3,3,3,3,3,3,3,3,3,3,3,3,3,3,3,3,3,3,3,3,3,3,3,3,3,3,3,3,3,3,4,2
1,1,1,1,1,2,3,3,3,3,3,3,3,3,3,3,3,3,3,3,3,3,3,3,3,3,3,3,3,3,3,3,3,3,3,3,3,3,3,2,1
1,1,1,1,1,1,2,2,2,2,3,3,3,3,3,3,3,3,3,3,3,3,3,3,3,3,3,3,3,3,3,3,3,3,3,3,3,3,2,1,1
1,1,1,1,1,1,1,2,2,2,2,3,3,3,3,3,3,3,3,3,3,3,3,3,3,3,3,3,6,3,3,3,3,3,3,3,3,2,1,1,1
1,1,1,1,1,1,1,1,2,2,2,2,3,3,3,3,3,3,3,3,3,3,3,3,3,3,3,3,6,3,3,3,3,3,3,3,2,1,1,1,1
1,1,1,1,1,1,1,1,1,2,2,2,2,3,3,3,3,3,3,3,3,3,3,3,3,3,3,3,6,3,3,3,3,3,3,2,1,1,1,1,1
1,1,1,1,1,1,1,1,1,1,2,2,2,2,3,3,3,3,3,3,3,3,3,3,3,3,3,3,3,3,3,3,3,3,2,1,1,1,1,1,1
1,1,1,1,1,1,1,1,1,1,1,2,2,2,3,3,4,3,3,4,3,3,4,3,3,4,3,3,4,3,3,3,3,2,1,1,1,1,1,1,1
1,1,1,1,1,1,1,1,1,1,1,1,2,2,3,3,4,3,3,4,3,3,4,3,3,4,3,3,4,3,3,2,2,1,1,1,1,1,1,1,1
1,1,1,1,1,1,1,1,1,1,1,1,1,2,2,2,2,2,2,2,2,2,2,2,2,2,2,2,2,2,2,1,1,1,1,1,1,1,1,1,1
endlayer

layer
1,1,1,1,1,1,1,1,1,1,1,1,1,1,1,1,1,1,1,1,1,1,2,2,2,2,2,2,2,2,2,4,4,4,1,1,1,1,1,1,1
1,1,1,1,1,1,1,1,1,1,1,1,1,1,1,1,1,1,1,1,1,1,2,3,3,4,3,3,4,3,3,2,2,4,4,1,1,1,1,1,1
1,1,1,1,1,1,1,1,1,1,1,1,1,1,1,1,1,1,1,1,1,1,2,3,3,5,3,3,5,3,3,3,3,2,4,1,1,1,1,1,1
1,1,1,1,1,1,1,1,1,1,1,1,1,1,1,1,1,1,1,1,1,2,3,3,3,3,3,3,3,3,3,3,3,3,2,4,4,1,1,1,1
1,1,1,1,1,1,1,1,1,1,1,1,1,1,1,1,1,1,1,1,2,3,3,3,3,3,3,3,3,3,3,3,3,3,3,2,4,4,1,1,1
1,1,1,1,1,1,1,1,1,2,1,1,1,1,1,1,1,1,1,2,3,3,3,3,3,3,3,3,3,3,3,3,3,3,3,3,2,4,4,1,1
1,1,1,1,1,1,1,1,2,2,1,1,1,1,1,1,1,1,2,3,3,3,3,3,3,3,3,3,3,3,3,3,3,3,3,3,2,2,4,1,1
1,1,1,1,1,1,1,2,1,2,1,1,1,1,1,1,1,2,3,3,3,3,3,3,3,3,3,3,3,3,3,3,3,3,4,4,2,2,4,1,1
1,1,1,1,1,1,2,1,1,2,1,1,1,1,1,1,2,3,3,3,3,3,3,3,3,3,3,3,3,3,3,3,3,3,3,3,2,4,4,1,1
1,1,1,1,1,2,1,1,2,1,1,1,1,1,1,2,3,3,3,3,3,3,3,3,3,3,3,3,3,3,3,3,3,3,3,3,2,4,4,1,1
1,1,1,1,2,1,1,2,1,1,1,1,1,1,2,3,3,3,3,3,3,3,3,3,3,3,3,3,3,3,3,3,3,3,4,4,2,2,4,1,1
1,1,1,2,1,1,2,1,1,1,1,1,1,2,3,3,3,3,3,3,3,3,3,3,3,3,3,3,3,3,3,3,3,3,3,3,2,2,4,1,1
1,1,2,1,1,2,1,1,1,1,1,1,2,3,3,3,3,3,3,3,4,3,3,3,3,3,3,3,3,3,3,3,3,3,3,3,2,4,4,1,1
1,2,1,1,2,1,1,1,1,1,1,2,3,3,3,3,3,3,3,4,4,3,3,3,3,3,3,3,3,3,3,3,3,3,4,4,2,4,4,1,1
2,2,2,2,1,1,1,1,1,1,2,3,3,3,3,3,3,3,4,4,4,3,3,3,3,3,3,3,3,3,3,3,3,3,3,3,2,2,4,1,1
1,1,1,2,1,1,1,1,1,2,3,3,3,3,3,3,3,4,4,4,4,3,3,3,3,3,3,3,3,3,3,3,3,3,3,3,2,2,4,1,1
1,1,1,2,1,1,1,1,2,3,3,3,3,3,3,3,4,4,4,4,4,3,3,3,3,3,3,3,3,3,3,3,3,3,4,4,2,4,4,1,1
1,1,1,2,1,1,1,2,3,3,3,3,3,3,3,3,3,3,3,3,3,3,3,3,3,3,3,3,3,3,3,3,3,3,3,3,2,4,4,1,1
1,1,1,2,1,1,2,3,3,3,3,3,3,3,3,3,3,3,3,3,3,3,3,3,3,3,3,3,3,3,3,3,3,3,3,3,2,2,2,2,2
1,1,1,2,2,2,3,3,3,3,3,3,3,3,3,3,3,3,3,3,3,3,3,3,3,3,3,3,3,3,3,3,3,3,3,3,3,3,4,4,2
1,1,1,2,2,2,3,3,3,3,3,3,3,3,3,3,3,3,3,3,3,3,3,3,3,3,3,3,3,3,3,3,3,3,3,3,3,3,3,3,2
1,1,1,1,2,2,4,4,3,3,3,3,3,3,3,3,3,3,3,3,3,3,3,3,3,3,3,3,3,3,3,3,3,3,3,3,3,3,4,4,2
1,1,1,1,1,2,3,3,3,3,3,3,3,3,3,3,3,3,3,3,3,3,3,3,3,3,3,3,3,3,3,3,3,3,3,3,3,3,3,2,1
1,1,1,1,1,1,2,2,2,3,3,3,3,3,3,3,3,3,3,3,3,3,3,3,3,3,3,3,3,3,3,3,3,3,3,3,3,3,2,1,1
1,1,1,1,1,1,1,2,2,2,3,3,3,3,3,3,3,3,3,3,3,3,3,3,3,3,3,3,3,6,3,3,3,3,3,3,3,2,1,1,1
1,1,1,1,1,1,1,1,2,2,2,3,3,3,3,3,3,3,3,3,3,3,3,3,3,3,3,3,3,6,3,3,3,3,3,3,2,1,1,1,1
1,1,1,1,1,1,1,1,1,2,2,2,3,3,3,3,3,3,3,3,3,3,3,3,3,3,3,3,3,6,3,3,3,3,3,2,1,1,1,1,1
1,1,1,1,1,1,1,1,1,1,2,2,2,3,3,3,3,3,3,3,3,3,3,3,3,3,3,3,3,3,3,3,3,3,2,1,1,1,1,1,1
1,1,1,1,1,1,1,1,1,1,1,2,2,2,3,3,5,3,3,5,3,3,5,3,3,5,3,3,5,3,3,3,3,2,1,1,1,1,1,1,1
1,1,1,1,1,1,1,1,1,1,1,1,2,2,3,3,4,3,3,4,3,3,4,3,3,4,3,3,4,3,3,2,2,1,1,1,1,1,1,1,1
1,1,1,1,1,1,1,1,1,1,1,1,1,2,2,2,2,2,2,2,2,2,2,2,2,2,2,2,2,2,2,1,1,1,1,1,1,1,1,1,1
endlayer

layer
1,1,1,1,1,1,1,1,1,1,1,1,1,1,1,1,1,1,1,1,1,1,2,2,2,2,2,2,2,2,2,1,1,1,1,1,1,1,1,1,1
1,1,1,1,1,1,1,1,1,1,1,1,1,1,1,1,1,1,1,1,1,1,2,3,3,4,3,3,4,3,3,2,2,1,1,1,1,1,1,1,1
1,1,1,1,1,1,1,1,1,1,1,1,1,1,1,1,1,1,1,1,1,1,2,3,3,5,3,3,5,3,3,3,3,2,1,1,1,1,1,1,1
1,1,1,1,1,1,1,1,1,1,1,1,1,1,1,1,1,1,1,1,1,2,3,3,3,3,3,3,3,3,3,3,3,3,2,1,1,1,1,1,1
1,1,1,1,1,1,1,1,1,1,1,1,1,1,1,1,1,1,1,1,2,3,3,3,3,3,3,3,3,3,3,3,3,3,3,2,1,1,1,1,1
1,1,1,1,1,1,1,1,1,2,1,1,1,1,1,1,1,1,1,2,3,3,3,3,3,3,3,3,3,3,3,3,3,3,3,3,2,1,1,1,1
1,1,1,1,1,1,1,1,2,2,1,1,1,1,1,1,1,1,2,3,3,3,3,3,3,3,3,3,3,3,3,3,3,3,3,3,2,2,1,1,1
1,1,1,1,1,1,1,2,1,2,1,1,1,1,1,1,1,2,3,3,3,3,3,3,3,3,3,3,3,3,3,3,3,4,4,4,2,2,1,1,1
1,1,1,1,1,1,2,1,1,2,1,1,1,1,1,1,2,3,3,3,3,3,3,3,3,3,3,3,3,3,3,3,3,3,3,4,2,1,1,1,1
1,1,1,1,1,2,1,1,2,1,1,1,1,1,1,2,3,3,3,3,3,3,3,3,3,3,3,3,3,3,3,3,3,3,3,3,2,1,1,1,1
1,1,1,1,2,1,1,2,1,1,1,1,1,1,2,3,3,3,3,3,3,3,3,3,3,3,3,3,3,3,3,3,3,4,4,4,2,2,1,1,1
1,1,1,2,1,1,2,1,1,1,1,1,1,2,3,3,3,3,3,3,3,3,3,3,3,3,3,3,3,3,3,3,3,3,3,4,2,2,1,1,1
1,1,2,1,1,2,1,1,1,1,1,1,2,3,3,3,3,3,3,3,4,3,3,3,3,3,3,3,3,3,3,3,3,3,3,3,2,1,1,1,1
1,2,1,1,2,1,1,1,1,1,1,2,3,3,3,3,3,3,3,4,4,3,3,3,3,3,3,3,3,3,3,3,3,4,4,4,2,1,1,1,1
2,2,2,2,1,1,1,1,1,1,2,3,3,3,3,3,3,3,7,4,4,3,3,3,3,3,3,3,3,3,3,3,3,3,3,4,2,2,1,1,1
1,1,1,2,1,1,1,1,1,2,3,3,3,3,3,3,3,4,4,4,4,3,3,3,3,3,3,3,3,3,3,3,3,3,3,3,2,2,1,1,1
1,1,1,2,1,1,1,1,2,3,3,3,3,3,3,3,4,4,4,4,4,3,3,3,3,3,3,3,3,3,3,3,3,4,4,4,2,1,1,1,1
1,1,1,2,1,1,1,2,3,3,3,3,3,3,3,3,3,3,3,3,3,3,3,3,3,3,3,3,3,3,3,3,3,3,3,4,2,1,1,1,1
1,1,1,2,1,1,2,3,3,3,3,3,3,3,3,3,3,3,3,3,3,3,3,3,3,3,3,3,3,3,3,3,3,3,3,3,2,2,2,2,2
1,1,1,2,2,2,3,3,3,3,3,3,3,3,3,3,3,3,3,3,3,3,3,3,3,3,3,3,3,3,3,3,3,3,3,3,3,3,4,4,2
1,1,1,2,2,2,3,3,3,3,3,3,3,3,3,3,3,3,3,3,3,3,3,3,3,3,3,3,3,3,3,3,3,3,3,3,3,3,3,3,2
1,1,1,1,2,2,4,4,3,3,3,3,3,3,3,3,3,3,3,3,3,3,3,3,3,3,3,3,3,3,3,3,3,3,3,3,3,3,4,4,2
1,1,1,1,1,2,3,3,3,3,3,3,3,3,3,3,3,3,3,3,3,3,3,3,3,3,3,3,3,3,3,3,3,3,3,3,3,3,3,2,1
1,1,1,1,1,1,2,2,2,3,3,3,3,3,3,3,3,3,3,3,3,3,3,3,3,3,3,3,3,3,3,3,3,3,3,3,3,3,2,1,1
1,1,1,1,1,1,1,2,2,2,3,3,3,3,3,3,3,3,3,3,3,3,3,3,3,3,3,3,3,3,6,3,3,3,3,3,2,2,1,1,1
1,1,1,1,1,1,1,1,2,2,2,3,3,3,3,3,3,3,3,3,3,3,3,3,3,3,3,3,3,3,6,3,3,3,3,2,2,1,1,1,1
1,1,1,1,1,1,1,1,1,2,2,2,3,3,3,3,3,3,3,3,3,3,3,3,3,3,3,3,3,3,6,3,3,3,2,2,1,1,1,1,1
1,1,1,1,1,1,1,1,1,1,2,2,2,3,3,3,3,3,3,3,3,3,3,3,3,3,3,3,3,3,3,3,3,2,2,1,1,1,1,1,1
1,1,1,1,1,1,1,1,1,1,1,2,2,2,3,3,5,3,3,5,3,3,5,3,3,5,3,3,5,3,3,3,3,2,1,1,1,1,1,1,1
1,1,1,1,1,1,1,1,1,1,1,1,2,2,3,3,4,3,3,4,3,3,4,3,3,4,3,3,4,3,3,2,2,1,1,1,1,1,1,1,1
1,1,1,1,1,1,1,1,1,1,1,1,1,2,2,2,2,2,2,2,2,2,2,2,2,2,2,2,2,2,2,1,1,1,1,1,1,1,1,1,1
endlayer

layer
1,1,1,1,1,1,1,1,1,1,1,1,1,1,1,1,1,1,1,1,1,1,2,2,2,2,2,2,2,2,2,1,1,1,1,1,1,1,1,1,1
1,1,1,1,1,1,1,1,1,1,1,1,1,1,1,1,1,1,1,1,1,1,2,3,3,4,3,3,4,3,3,2,2,1,1,1,1,1,1,1,1
1,1,1,1,1,1,1,1,1,1,1,1,1,1,1,1,1,1,1,1,1,1,2,3,3,5,3,3,5,3,3,3,3,2,1,1,1,1,1,1,1
1,1,1,1,1,1,1,1,1,1,1,1,1,1,1,1,1,1,1,1,1,2,3,3,3,3,3,3,3,3,3,3,3,3,2,1,1,1,1,1,1
1,1,1,1,1,1,1,1,1,1,1,1,1,1,1,1,1,1,1,1,2,3,3,3,3,3,3,3,3,3,3,3,3,3,3,2,1,1,1,1,1
1,1,1,1,1,1,1,1,1,2,1,1,1,1,1,1,1,1,1,2,3,3,3,3,3,3,3,3,3,3,3,3,3,3,3,3,2,1,1,1,1
1,1,1,1,1,1,1,1,2,2,1,1,1,1,1,1,1,1,2,3,3,3,3,3,3,3,3,3,3,3,3,3,3,3,3,3,2,2,1,1,1
1,1,1,1,1,1,1,2,1,2,1,1,1,1,1,1,1,2,3,3,3,3,3,3,3,3,3,3,3,3,3,3,3,4,4,4,2,2,1,1,1
1,1,1,1,1,1,2,1,1,2,1,1,1,1,1,1,2,3,3,3,3,3,3,3,3,3,3,3,3,3,3,3,3,3,3,4,2,1,1,1,1
1,1,1,1,1,2,1,1,2,1,1,1,1,1,1,2,3,3,3,3,3,3,3,3,3,3,3,3,3,3,3,3,3,3,3,3,2,1,1,1,1
1,1,1,1,2,1,1,2,1,1,1,1,1,1,2,3,3,3,3,3,3,3,3,3,3,3,3,3,3,3,3,3,3,4,4,4,2,2,1,1,1
1,1,1,2,1,1,2,1,1,1,1,1,1,2,3,3,3,3,3,3,3,3,3,3,3,3,3,3,3,3,3,3,3,3,3,4,2,2,1,1,1
1,1,2,1,1,2,1,1,1,1,1,1,2,3,3,3,3,3,3,3,4,3,3,3,3,3,3,3,3,3,3,3,3,3,3,3,2,1,1,1,1
1,2,1,1,2,1,1,1,1,1,1,2,3,3,3,3,3,3,3,4,4,3,3,3,3,3,3,3,3,3,3,3,3,4,4,4,2,1,1,1,1
2,2,2,2,1,1,1,1,1,1,2,3,3,3,3,3,3,3,4,4,4,3,3,3,3,3,3,3,3,3,3,3,3,3,3,4,2,2,1,1,1
1,1,1,2,1,1,1,1,1,2,3,3,3,3,3,3,3,4,4,4,4,3,3,3,3,3,3,3,3,3,3,3,3,3,3,3,2,2,1,1,1
1,1,1,2,1,1,1,1,2,3,3,3,3,3,3,3,4,4,4,4,4,3,3,3,3,3,3,3,3,3,3,3,3,4,4,4,2,1,1,1,1
1,1,1,2,1,1,1,2,3,3,3,3,3,3,3,3,3,3,3,3,3,3,3,3,3,3,3,3,3,3,3,3,3,3,3,4,2,1,1,1,1
1,1,1,2,1,1,2,3,3,3,3,3,3,3,3,3,3,3,3,3,3,3,3,3,3,3,3,3,3,3,3,3,3,3,3,3,2,2,2,2,2
1,1,1,2,2,2,3,3,3,3,3,3,3,3,3,3,3,3,3,3,3,3,3,3,3,3,3,3,3,3,3,3,3,3,3,3,3,3,4,4,2
1,1,1,2,2,2,3,3,3,3,3,3,3,3,3,3,3,3,3,3,3,3,3,3,3,3,3,3,3,3,3,3,3,3,3,3,3,3,3,3,2
1,1,1,1,2,2,4,4,3,3,3,3,3,3,3,3,3,3,3,3,3,3,3,3,3,3,3,3,3,3,3,3,3,3,3,3,3,3,4,4,2
1,1,1,1,1,2,3,3,3,3,3,3,3,3,3,3,3,3,3,3,3,3,3,3,3,3,3,3,3,3,3,3,3,3,3,3,3,3,3,2,1
1,1,1,1,1,1,2,2,3,3,3,3,3,3,3,3,3,3,3,3,3,3,3,3,3,3,3,3,3,3,3,3,3,3,3,3,3,3,2,1,1
1,1,1,1,1,1,1,2,2,3,3,3,3,3,3,3,3,3,3,3,3,3,3,3,3,3,3,3,3,3,3,6,3,3,3,2,2,2,1,1,1
1,1,1,1,1,1,1,1,2,2,3,3,3,3,3,3,3,3,3,3,3,3,3,3,3,3,3,3,3,3,3,6,3,3,2,2,2,1,1,1,1
1,1,1,1,1,1,1,1,1,2,2,3,3,3,3,3,3,3,3,3,3,3,3,3,3,3,3,3,3,3,3,6,3,2,2,2,1,1,1,1,1
1,1,1,1,1,1,1,1,1,1,2,2,3,3,3,3,3,3,3,3,3,3,3,3,3,3,3,3,3,3,3,3,3,2,2,1,1,1,1,1,1
1,1,1,1,1,1,1,1,1,1,1,2,2,3,3,3,5,3,3,5,3,3,5,3,3,5,3,3,5,3,3,3,3,2,1,1,1,1,1,1,1
1,1,1,1,1,1,1,1,1,1,1,1,2,2,3,3,4,3,3,4,3,3,4,3,3,4,3,3,4,3,3,2,2,1,1,1,1,1,1,1,1
1,1,1,1,1,1,1,1,1,1,1,1,1,2,2,2,2,2,2,2,2,2,2,2,2,2,2,2,2,2,2,1,1,1,1,1,1,1,1,1,1
endlayer

layer
1,1,1,1,1,1,1,1,1,1,1,1,1,1,1,1,1,1,1,1,1,1,2,2,2,2,2,2,2,2,2,1,1,1,1,1,1,1,1,1,1
1,1,1,1,1,1,1,1,1,1,1,1,1,1,1,1,1,1,1,1,1,1,2,3,3,4,3,3,4,3,3,2,2,1,1,1,1,1,1,1,1
1,1,1,1,1,1,1,1,1,1,1,1,1,1,1,1,1,1,1,1,1,1,2,3,3,5,3,3,5,3,3,3,3,2,1,1,1,1,1,1,1
1,1,1,1,1,1,1,1,1,1,1,1,1,1,1,1,1,1,1,1,1,2,3,3,3,3,3,3,3,3,3,3,3,3,2,1,1,1,1,1,1
1,1,1,1,1,1,1,1,1,1,1,1,1,1,1,1,1,1,1,1,2,3,3,3,3,3,3,3,3,3,3,3,3,3,3,2,1,1,1,1,1
1,1,1,1,1,1,1,1,1,2,1,1,1,1,1,1,1,1,1,2,3,3,3,3,3,3,3,3,3,3,3,3,3,3,3,3,2,1,1,1,1
1,1,1,1,1,1,1,1,2,2,1,1,1,1,1,1,1,1,2,3,3,3,3,3,3,3,3,3,3,3,3,3,3,3,3,3,2,2,1,1,1
1,1,1,1,1,1,1,2,1,2,1,1,1,1,1,1,1,2,3,3,3,3,3,3,3,3,3,3,3,3,3,3,3,4,4,4,2,2,1,1,1
1,1,1,1,1,1,2,1,1,2,1,1,1,1,1,1,2,3,3,3,3,3,3,3,3,3,3,3,3,3,3,3,3,3,3,4,2,1,1,1,1
1,1,1,1,1,2,1,1,2,1,1,1,1,1,1,2,3,3,3,3,3,3,3,3,3,3,3,3,3,3,3,3,3,3,3,3,2,1,1,1,1
1,1,1,1,2,1,1,2,1,1,1,1,1,1,2,3,3,3,3,3,3,3,3,3,3,3,3,3,3,3,3,3,3,4,4,4,2,2,1,1,1
1,1,1,2,1,1,2,1,1,1,1,1,1,2,3,3,3,3,3,3,3,3,3,3,3,3,3,3,3,3,3,3,3,3,3,4,2,2,1,1,1
1,1,2,1,1,2,1,1,1,1,1,1,2,3,3,3,3,3,3,3,4,3,3,3,3,3,3,3,3,3,3,3,3,3,3,3,2,1,1,1,1
1,2,1,1,2,1,1,1,1,1,1,2,3,3,3,3,3,3,3,4,4,3,3,3,3,3,3,3,3,3,3,3,3,4,4,4,2,1,1,1,1
2,2,2,2,1,1,1,1,1,1,2,3,3,3,3,3,3,3,4,4,4,3,3,3,3,3,3,3,3,3,3,3,3,3,3,4,2,2,1,1,1
1,1,1,2,1,1,1,1,1,2,3,3,3,3,3,3,3,4,4,4,4,3,3,3,3,3,3,3,3,3,3,3,3,3,3,3,2,2,1,1,1
1,1,1,2,1,1,1,1,2,3,3,3,3,3,3,3,4,4,4,4,4,3,3,3,3,3,3,3,3,3,3,3,3,4,4,4,2,1,1,1,1
1,1,1,2,1,1,1,2,3,3,3,3,3,3,3,3,3,3,3,3,3,3,3,3,3,3,3,3,3,3,3,3,3,3,3,4,2,1,1,1,1
1,1,1,2,1,1,2,3,3,3,3,3,3,3,3,3,3,3,3,3,3,3,3,3,3,3,3,3,3,3,3,3,3,3,3,3,2,2,2,2,2
1,1,1,2,2,2,3,3,3,3,3,3,3,3,3,3,3,3,3,3,3,3,3,3,3,3,3,3,3,3,3,3,3,3,3,3,3,3,4,4,2
1,1,1,2,2,2,3,3,3,3,3,3,3,3,3,3,3,3,3,3,3,3,3,3,3,3,3,3,3,3,3,3,3,3,3,3,3,3,3,3,2
1,1,1,1,2,2,4,4,3,3,3,3,3,3,3,3,3,3,3,3,3,3,3,3,3,3,3,3,3,3,3,3,3,3,3,3,3,3,4,4,2
1,1,1,1,1,2,3,3,3,3,3,3,3,3,3,3,3,3,3,3,3,3,3,3,3,3,3,3,3,3,3,3,3,3,3,3,3,3,3,2,1
1,1,1,1,1,1,2,2,3,3,3,3,3,3,3,3,3,3,3,3,3,3,3,3,3,3,3,3,3,3,3,3,3,6,6,6,3,3,2,1,1
1,1,1,1,1,1,1,2,2,3,3,3,3,3,3,3,3,3,3,3,3,3,3,3,3,3,3,3,3,3,3,3,6,2,2,2,2,2,1,1,1
1,1,1,1,1,1,1,1,2,2,3,3,3,3,3,3,3,3,3,3,3,3,3,3,3,3,3,3,3,3,3,3,6,2,2,2,2,1,1,1,1
1,1,1,1,1,1,1,1,1,2,2,3,3,3,3,3,3,3,3,3,3,3,3,3,3,3,3,3,3,3,3,3,6,2,2,2,1,1,1,1,1
1,1,1,1,1,1,1,1,1,1,2,2,3,3,3,3,3,3,3,3,3,3,3,3,3,3,3,3,3,3,3,3,3,2,2,1,1,1,1,1,1
1,1,1,1,1,1,1,1,1,1,1,2,2,3,3,3,5,3,3,5,3,3,5,3,3,5,3,3,5,3,3,3,3,2,1,1,1,1,1,1,1
1,1,1,1,1,1,1,1,1,1,1,1,2,2,3,3,4,3,3,4,3,3,4,3,3,4,3,3,4,3,3,2,2,1,1,1,1,1,1,1,1
1,1,1,1,1,1,1,1,1,1,1,1,1,2,2,2,2,2,2,2,2,2,2,2,2,2,2,2,2,2,2,1,1,1,1,1,1,1,1,1,1
endlayer

layer
1,1,1,1,1,1,1,1,1,1,1,1,1,1,1,1,1,1,1,1,1,1,2,2,2,2,2,2,2,2,2,4,4,4,1,1,1,1,1,1,1
1,1,1,1,1,1,1,1,1,1,1,1,1,1,1,1,1,1,1,1,1,1,2,3,3,4,3,3,4,3,3,2,2,4,4,4,1,1,1,1,1
1,1,1,1,1,1,1,1,1,1,1,1,1,1,1,1,1,1,1,1,1,1,2,3,3,5,3,3,5,3,3,3,3,2,4,4,4,1,1,1,1
1,1,1,1,1,1,1,1,1,1,1,1,1,1,1,1,1,1,1,1,1,2,3,3,3,3,3,3,3,3,3,3,3,3,2,4,4,4,1,1,1
1,1,1,1,1,1,1,1,1,1,1,1,1,1,1,1,1,1,1,1,2,3,3,3,3,3,3,3,3,3,3,3,3,3,3,2,4,4,4,1,1
1,1,1,1,1,1,1,1,1,2,1,1,1,1,1,1,1,1,1,2,3,3,3,3,3,3,3,3,3,3,3,3,3,3,3,3,2,4,4,4,1
1,1,1,1,1,1,1,1,2,2,1,1,1,1,1,1,1,1,2,3,3,3,3,3,3,3,3,3,3,3,3,3,3,3,3,3,2,2,4,4,1
1,1,1,1,1,1,1,2,1,2,1,1,1,1,1,1,1,2,3,3,3,3,3,3,3,3,3,3,3,3,3,3,3,4,4,4,2,2,4,4,1
1,1,1,1,1,1,2,1,1,2,1,1,1,1,1,1,2,3,3,3,3,3,3,3,3,3,3,3,3,3,3,3,3,3,3,4,2,4,4,4,1
1,1,1,1,1,2,1,1,2,1,1,1,1,1,1,2,3,3,3,3,3,3,3,3,3,3,3,3,3,3,3,3,3,3,3,3,2,4,4,4,1
1,1,1,1,2,1,1,2,1,1,1,1,1,1,2,3,3,3,3,3,3,3,3,3,3,3,3,3,3,3,3,3,3,4,4,4,2,2,4,4,1
1,1,1,2,1,1,2,1,1,1,1,1,1,2,3,3,3,3,3,3,3,3,3,3,3,3,3,3,3,3,3,3,3,3,3,4,2,2,4,4,1
1,1,2,1,1,2,1,1,1,1,1,1,2,3,3,3,3,3,3,3,4,3,3,3,3,3,3,3,3,3,3,3,3,3,3,3,2,4,4,4,1
1,2,1,1,2,1,1,1,1,1,1,2,3,3,3,3,3,3,3,4,4,3,3,3,3,3,3,3,3,3,3,3,3,4,4,4,2,4,4,4,1
2,2,2,2,1,1,1,1,1,1,2,3,3,3,3,3,3,3,4,4,4,3,3,3,3,3,3,3,3,3,3,3,3,3,3,4,2,2,4,4,1
1,1,1,2,1,1,1,1,1,2,3,3,3,3,3,3,3,4,4,4,4,3,3,3,3,3,3,3,3,3,3,3,3,3,3,3,2,2,4,4,1
1,1,1,2,1,1,1,1,2,3,3,3,3,3,3,3,4,4,4,4,4,3,3,3,3,3,3,3,3,3,3,3,3,4,4,4,2,4,4,4,1
1,1,1,2,1,1,1,2,3,3,3,3,3,3,3,3,3,3,3,3,3,3,3,3,3,3,3,3,3,3,3,3,3,3,3,4,2,4,4,4,1
1,1,1,2,1,1,2,3,3,3,3,3,3,3,3,3,3,3,3,3,3,3,3,3,3,3,3,3,3,3,3,3,3,3,3,3,2,2,2,2,2
1,1,1,2,2,2,3,3,3,3,3,3,3,3,3,3,3,3,3,3,3,3,3,3,3,3,3,3,3,3,3,3,3,3,3,3,3,4,4,4,2
1,1,1,2,2,2,3,3,3,3,3,3,3,3,3,3,3,3,3,3,3,3,3,3,3,3,3,3,3,3,3,3,3,3,3,3,3,3,3,3,2
1,1,1,1,2,2,4,4,4,3,3,3,3,3,3,3,3,3,3,3,3,3,3,3,3,3,3,3,3,3,3,3,3,3,3,3,3,4,4,4,2
1,1,1,1,1,2,3,3,3,3,3,3,3,3,3,3,3,3,3,3,3,3,3,3,3,3,3,3,3,3,3,3,3,6,6,6,3,3,3,2,1
1,1,1,1,1,1,2,3,3,3,3,3,3,3,3,3,3,3,3,3,3,3,3,3,3,3,3,3,3,3,3,3,3,3,3,3,3,3,2,1,1
1,1,1,1,1,1,1,2,3,3,3,3,3,3,3,3,3,3,3,3,3,3,3,3,3,3,3,3,3,3,3,3,3,3,3,3,3,2,1,1,1
1,1,1,1,1,1,1,1,2,3,3,3,3,3,3,3,3,3,3,3,3,3,3,3,3,3,3,3,3,3,3,3,3,3,3,3,2,1,1,1,1
1,1,1,1,1,1,1,1,1,2,3,3,3,3,3,3,3,3,3,3,3,3,3,3,3,3,3,3,3,3,3,3,3,3,3,2,1,1,1,1,1
1,1,1,1,1,1,1,1,1,1,2,3,3,3,3,3,3,3,3,3,3,3,3,3,3,3,3,3,3,3,3,3,3,3,2,1,1,1,1,1,1
1,1,1,1,1,1,1,1,1,1,1,2,3,3,3,3,5,3,3,5,3,3,5,3,3,5,3,3,5,3,3,3,3,2,1,1,1,1,1,1,1
1,1,1,1,1,1,1,1,1,1,1,1,2,2,3,3,4,3,3,4,3,3,4,3,3,4,3,3,4,3,3,2,2,1,1,1,1,1,1,1,1
1,1,1,1,1,1,1,1,1,1,1,1,1,2,2,2,2,2,2,2,2,2,2,2,2,2,2,2,2,2,2,1,1,1,1,1,1,1,1,1,1
endlayer

layer
1,1,1,1,1,1,1,1,1,1,1,1,1,1,1,1,1,1,1,1,1,1,2,2,2,2,2,2,2,2,2,4,4,4,1,1,1,1,1,1,1
1,1,1,1,1,1,1,1,1,1,1,1,1,1,1,1,1,1,1,1,1,1,2,3,3,4,3,3,4,3,3,2,2,4,4,1,1,1,1,1,1
1,1,1,1,1,1,1,1,1,1,1,1,1,1,1,1,1,1,1,1,1,1,2,3,3,5,3,3,5,3,3,4,3,2,4,1,1,1,1,1,1
1,1,1,1,1,1,1,1,1,1,1,1,1,1,1,1,1,1,1,1,1,2,3,3,3,3,3,3,3,3,3,4,3,3,2,4,4,1,1,1,1
1,1,1,1,1,1,1,1,1,1,1,1,1,1,1,1,1,1,1,1,2,3,3,3,3,3,3,3,3,3,3,4,3,3,3,2,4,1,1,1,1
1,1,1,1,1,1,1,1,1,2,1,1,1,1,1,1,1,1,1,2,3,3,3,3,3,3,3,3,3,3,3,4,3,3,3,3,2,4,4,1,1
1,1,1,1,1,1,1,1,2,2,1,1,1,1,1,1,1,1,2,3,3,3,3,3,3,3,3,3,3,3,3,4,3,3,3,3,2,2,4,1,1
1,1,1,1,1,1,1,2,1,2,1,1,1,1,1,1,1,2,3,3,3,3,3,3,3,3,3,3,3,3,3,4,3,4,4,7,2,2,4,1,1
1,1,1,1,1,1,2,1,1,2,1,1,1,1,1,1,2,3,3,3,3,3,3,3,3,3,3,3,3,3,3,4,3,3,4,4,2,4,4,1,1
1,1,1,1,1,2,1,1,2,1,1,1,1,1,1,2,3,3,3,3,3,3,3,3,3,3,3,3,3,3,3,4,3,3,3,3,2,4,4,1,1
1,1,1,1,2,1,1,2,1,1,1,1,1,1,2,3,3,3,3,3,3,3,3,3,3,3,3,3,3,3,3,4,3,4,4,7,2,2,4,1,1
1,1,1,2,1,1,2,1,1,1,1,1,1,2,3,3,3,3,3,3,3,3,3,3,3,3,3,3,3,3,3,4,3,3,4,4,2,2,4,1,1
1,1,2,1,1,2,1,1,1,1,1,1,2,3,3,3,3,3,3,3,4,3,3,3,3,3,3,3,3,3,3,4,3,3,3,3,2,4,4,1,1
1,2,1,1,2,1,1,1,1,1,1,2,3,3,3,3,3,3,3,4,4,3,3,3,3,3,3,3,3,3,3,4,3,4,4,7,2,4,4,1,1
2,2,2,2,1,1,1,1,1,1,2,3,3,3,3,3,3,3,7,4,4,3,3,3,3,3,3,3,3,3,3,4,3,3,4,4,2,2,4,1,1
1,1,1,2,1,1,1,1,1,2,3,3,3,3,3,3,3,4,4,4,4,3,3,3,3,3,3,3,3,3,3,4,3,3,3,3,2,2,4,1,1
1,1,1,2,1,1,1,1,2,3,3,3,3,3,3,3,4,4,4,4,4,3,3,3,3,3,3,3,3,3,3,4,3,4,4,7,2,4,4,1,1
1,1,1,2,1,1,1,2,3,3,3,3,3,3,3,3,3,3,3,3,3,3,3,3,3,3,3,3,3,3,3,4,3,3,4,4,2,4,4,1,1
1,1,1,2,1,1,2,3,3,3,3,3,3,3,3,3,3,3,3,3,3,3,3,3,3,3,3,3,3,3,3,4,3,3,3,3,2,2,2,2,2
1,1,1,2,2,2,3,3,3,3,3,3,3,3,3,3,3,3,3,3,3,3,3,3,3,3,3,3,3,3,3,7,4,4,4,4,4,4,4,4,2
1,1,1,2,2,2,3,3,3,3,3,3,3,3,3,3,3,3,3,3,3,3,3,3,3,3,3,3,3,3,3,3,3,3,3,3,3,3,3,3,2
1,1,1,1,2,2,4,4,4,3,3,3,3,3,3,3,3,3,3,3,3,3,3,3,3,3,3,3,3,3,3,3,3,6,6,6,3,4,4,4,2
1,1,1,1,1,2,3,3,3,3,3,3,3,3,3,3,3,3,3,3,3,3,3,3,3,3,3,3,3,3,3,3,3,3,3,3,3,3,3,2,1
1,1,1,1,1,1,2,3,3,3,3,3,3,3,3,3,3,3,3,3,3,3,3,3,3,3,3,3,3,3,3,3,3,3,3,3,3,3,2,1,1
1,1,1,1,1,1,1,2,3,3,3,3,3,3,3,3,3,3,3,3,3,3,3,3,3,3,3,3,3,3,3,3,3,3,3,3,3,2,1,1,1
1,1,1,1,1,1,1,1,2,3,3,3,3,3,3,3,3,3,3,3,3,3,3,3,3,3,3,3,3,3,3,3,3,3,3,3,2,1,1,1,1
1,1,1,1,1,1,1,1,1,2,3,3,3,3,3,3,3,3,3,3,3,3,3,3,3,3,3,3,3,3,3,3,3,3,3,2,1,1,1,1,1
1,1,1,1,1,1,1,1,1,1,2,3,3,3,3,3,3,3,3,3,3,3,3,3,3,3,3,3,3,3,3,3,3,3,2,1,1,1,1,1,1
1,1,1,1,1,1,1,1,1,1,1,2,3,3,3,3,5,3,3,5,3,3,5,3,3,5,3,3,5,3,3,3,3,2,1,1,1,1,1,1,1
1,1,1,1,1,1,1,1,1,1,1,1,2,2,3,3,4,3,3,4,3,3,4,3,3,4,3,3,4,3,3,2,2,1,1,1,1,1,1,1,1
1,1,1,1,1,1,1,1,1,1,1,1,1,2,2,2,2,2,2,2,2,2,2,2,2,2,2,2,2,2,2,1,1,1,1,1,1,1,1,1,1
endlayer

layer
1,1,1,1,1,1,1,1,1,1,1,1,1,1,1,1,1,1,1,1,1,1,2,2,2,2,2,2,2,2,2,1,1,1,1,1,1,1,1,1,1
1,1,1,1,1,1,1,1,1,1,1,1,1,1,1,1,1,1,1,1,1,1,2,3,3,4,3,3,4,3,3,2,2,1,1,1,1,1,1,1,1
1,1,1,1,1,1,1,1,1,1,1,1,1,1,1,1,1,1,1,1,1,1,2,3,3,4,3,3,4,3,3,3,2,2,1,1,1,1,1,1,1
1,1,1,1,1,1,1,1,1,1,1,1,1,1,1,1,1,1,1,1,1,2,3,3,3,3,3,3,3,3,3,3,2,2,2,1,1,1,1,1,1
1,1,1,1,1,1,1,1,1,1,1,1,1,1,1,1,1,1,1,1,2,3,3,3,3,3,3,3,3,3,3,3,2,2,2,2,1,1,1,1,1
1,1,1,1,1,1,1,1,1,2,1,1,1,1,1,1,1,1,1,2,3,3,3,3,3,3,3,3,3,3,3,3,2,2,2,2,2,1,1,1,1
1,1,1,1,1,1,1,1,2,2,1,1,1,1,1,1,1,1,2,3,3,3,3,3,3,3,3,3,3,3,3,3,2,2,2,2,2,2,1,1,1
1,1,1,1,1,1,1,2,1,2,1,1,1,1,1,1,1,2,3,3,3,3,3,3,3,3,3,3,3,3,3,3,2,2,2,2,2,2,1,1,1
1,1,1,1,1,1,2,1,1,2,1,1,1,1,1,1,2,3,3,3,3,3,3,3,3,3,3,3,3,3,3,3,2,2,2,2,2,1,1,1,1
1,1,1,1,1,2,1,1,2,1,1,1,1,1,1,2,3,3,3,3,3,3,3,3,3,3,3,3,3,3,3,3,2,2,2,2,2,1,1,1,1
1,1,1,1,2,1,1,2,1,1,1,1,1,1,2,3,3,3,3,3,3,3,3,3,3,3,3,3,3,3,3,3,2,2,2,2,2,2,1,1,1
1,1,1,2,1,1,2,1,1,1,1,1,1,2,3,3,3,3,3,3,3,3,3,3,3,3,3,3,3,3,3,3,2,2,2,2,2,2,1,1,1
1,1,2,1,1,2,1,1,1,1,1,1,2,3,3,3,3,3,3,3,4,3,3,3,3,3,3,3,3,3,3,3,2,2,2,2,2,1,1,1,1
1,2,1,1,2,1,1,1,1,1,1,2,3,3,3,3,3,3,3,4,4,3,3,3,3,3,3,3,3,3,3,3,2,2,2,2,2,1,1,1,1
2,2,2,2,1,1,1,1,1,1,2,3,3,3,3,3,3,3,4,4,4,3,3,3,3,3,3,3,3,3,3,3,2,2,2,2,2,2,1,1,1
1,1,1,2,1,1,1,1,1,2,3,3,3,3,3,3,3,4,4,4,4,3,3,3,3,3,3,3,3,3,3,3,2,2,2,2,2,2,1,1,1
1,1,1,2,1,1,1,1,2,3,3,3,3,3,3,3,4,4,4,4,4,3,3,3,3,3,3,3,3,3,3,3,2,2,2,2,2,1,1,1,1
1,1,1,2,1,1,1,2,3,3,3,3,3,3,3,3,3,3,3,3,3,3,3,3,3,3,3,3,3,3,3,3,2,2,2,2,2,1,1,1,1
1,1,1,2,1,1,2,3,3,3,3,3,3,3,3,3,3,3,3,3,3,3,3,3,3,3,3,3,3,3,3,3,2,2,2,2,2,2,2,2,2
1,1,1,2,2,2,3,3,3,3,3,3,3,3,3,3,3,3,3,3,3,3,3,3,3,3,3,3,3,3,3,4,5,2,2,2,5,4,4,4,2
1,1,1,2,2,2,3,3,3,3,3,3,3,3,3,3,3,3,3,3,3,3,3,3,3,3,3,3,3,3,3,3,3,6,6,6,3,3,3,3,2
1,1,1,1,2,2,4,4,4,3,3,3,3,3,3,3,3,3,3,3,3,3,3,3,3,3,3,3,3,3,3,3,3,3,3,3,3,4,4,4,2
1,1,1,1,1,2,3,3,3,3,3,3,3,3,3,3,3,3,3,3,3,3,3,3,3,3,3,3,3,3,3,3,3,3,3,3,3,3,3,2,1
1,1,1,1,1,1,2,3,3,3,3,3,3,3,3,3,3,3,3,3,3,3,3,3,3,3,3,3,3,3,3,3,3,3,3,3,3,3,2,1,1
1,1,1,1,1,1,1,2,3,3,3,3,3,3,3,3,3,3,3,3,3,3,3,3,3,3,3,3,3,3,3,3,3,3,3,3,3,2,1,1,1
1,1,1,1,1,1,1,1,2,3,3,3,3,3,3,3,3,3,3,3,3,3,3,3,3,3,3,3,3,3,3,3,3,3,3,3,2,1,1,1,1
1,1,1,1,1,1,1,1,1,2,3,3,3,3,3,3,3,3,3,3,3,3,3,3,3,3,3,3,3,3,3,3,3,3,3,2,1,1,1,1,1
1,1,1,1,1,1,1,1,1,1,2,3,3,3,3,3,3,3,3,3,3,3,3,3,3,3,3,3,3,3,3,3,3,3,2,1,1,1,1,1,1
1,1,1,1,1,1,1,1,1,1,1,2,3,3,3,3,4,3,3,4,3,3,4,3,3,4,3,3,4,3,3,3,3,2,1,1,1,1,1,1,1
1,1,1,1,1,1,1,1,1,1,1,1,2,2,3,3,4,3,3,4,3,3,4,3,3,4,3,3,4,3,3,2,2,1,1,1,1,1,1,1,1
1,1,1,1,1,1,1,1,1,1,1,1,1,2,2,2,2,2,2,2,2,2,2,2,2,2,2,2,2,2,2,1,1,1,1,1,1,1,1,1,1
endlayer

layer
1,1,1,1,1,1,1,1,1,1,1,1,1,1,1,1,1,1,1,1,1,1,2,2,2,2,2,2,2,2,2,1,1,1,1,1,1,1,1,1,1
1,1,1,1,1,1,1,1,1,1,1,1,1,1,1,1,1,1,1,1,1,1,2,3,3,7,3,3,7,3,3,2,2,1,1,1,1,1,1,1,1
1,1,1,1,1,1,1,1,1,1,1,1,1,1,1,1,1,1,1,1,1,1,2,3,3,4,3,3,4,3,3,3,2,2,1,1,1,1,1,1,1
1,1,1,1,1,1,1,1,1,1,1,1,1,1,1,1,1,1,1,1,1,2,3,3,3,3,3,3,3,3,3,3,2,2,2,1,1,1,1,1,1
1,1,1,1,1,1,1,1,1,1,1,1,1,1,1,1,1,1,1,1,2,3,3,3,3,3,3,3,3,3,3,3,8,3,3,2,1,1,1,1,1
1,1,1,1,1,1,1,1,1,2,1,1,1,1,1,1,1,1,1,2,3,3,3,3,3,3,3,3,3,3,3,3,8,3,3,3,2,1,1,1,1
1,1,1,1,1,1,1,1,2,2,1,1,1,1,1,1,1,1,2,3,3,3,3,3,3,3,3,3,3,3,3,3,2,3,6,6,2,2,1,1,1
1,1,1,1,1,1,1,2,1,2,1,1,1,1,1,1,1,2,3,3,3,3,3,3,3,3,3,3,3,3,3,3,8,3,3,3,2,2,1,1,1
1,1,1,1,1,1,2,1,1,2,1,1,1,1,1,1,2,3,3,3,3,3,3,3,3,3,3,3,3,3,3,3,8,3,3,3,2,1,1,1,1
1,1,1,1,1,2,1,1,2,1,1,1,1,1,1,2,3,3,3,3,3,3,3,3,3,3,3,3,3,3,3,3,2,3,3,3,2,1,1,1,1
1,1,1,1,2,1,1,2,1,1,1,1,1,1,2,3,3,3,3,3,3,3,3,3,3,3,3,3,3,3,3,3,8,3,3,3,2,2,1,1,1
1,1,1,2,1,1,2,1,1,1,1,1,1,2,3,3,3,3,3,3,3,3,3,3,3,3,3,3,3,3,3,3,8,3,3,3,2,2,1,1,1
1,1,2,1,1,2,1,1,1,1,1,1,2,3,3,3,3,3,3,3,4,3,3,3,3,3,3,3,3,3,3,3,2,3,3,3,2,1,1,1,1
1,2,1,1,2,1,1,1,1,1,1,2,3,3,3,3,3,3,3,4,4,3,3,3,3,3,3,3,3,3,3,3,2,3,3,3,2,1,1,1,1
2,2,2,2,1,1,1,1,1,1,2,3,3,3,3,3,3,3,4,4,4,3,3,3,3,3,3,3,3,3,3,3,2,3,3,3,2,2,1,1,1
1,1,1,2,1,1,1,1,1,2,3,3,3,3,3,3,3,4,4,4,4,3,3,3,3,3,3,3,3,3,3,3,2,3,3,3,2,2,1,1,1
1,1,1,2,1,1,1,1,2,3,3,3,3,3,3,3,4,4,4,4,4,3,3,3,3,3,3,3,3,3,3,3,2,3,3,3,2,1,1,1,1
1,1,1,2,1,1,1,2,3,3,3,3,3,3,3,3,3,3,3,3,3,3,3,3,3,3,3,3,3,3,3,3,2,3,3,3,2,1,1,1,1
1,1,1,2,1,1,2,3,3,3,3,3,3,3,3,3,3,3,3,3,3,3,3,3,3,3,3,3,3,3,3,3,2,3,3,3,2,2,2,2,2
1,1,1,2,2,2,3,3,3,3,3,3,3,3,3,3,3,3,3,3,3,3,3,3,3,3,3,3,3,3,3,4,3,3,3,3,3,4,4,4,2
1,1,1,2,2,2,3,3,3,3,3,3,3,3,3,3,3,3,3,3,3,3,3,3,3,3,3,3,3,3,3,3,3,3,3,3,3,3,3,3,2
1,1,1,1,2,2,4,4,4,3,3,3,3,3,3,3,3,3,3,3,3,3,3,3,3,3,3,3,3,3,3,3,3,3,3,3,3,4,4,4,2
1,1,1,1,1,2,3,3,3,3,3,3,3,3,3,3,3,3,3,3,3,3,3,3,3,3,3,3,3,3,3,3,3,3,3,3,3,3,3,2,1
1,1,1,1,1,1,2,3,3,3,3,3,3,3,3,3,3,3,3,3,3,3,3,3,3,3,3,3,3,3,3,3,3,3,3,3,3,3,2,1,1
1,1,1,1,1,1,1,2,3,3,3,3,3,3,3,3,3,3,3,3,3,3,3,3,3,3,3,3,3,3,3,3,3,3,3,3,3,2,1,1,1
1,1,1,1,1,1,1,1,2,3,3,3,3,3,3,3,3,3,3,3,3,3,3,3,3,3,3,3,3,3,3,3,3,3,3,3,2,1,1,1,1
1,1,1,1,1,1,1,1,1,2,3,3,3,3,3,3,3,3,3,3,3,3,3,3,3,3,3,3,3,3,3,3,3,3,3,2,1,1,1,1,1
1,1,1,1,1,1,1,1,1,1,2,3,3,3,3,3,3,3,3,3,3,3,3,3,3,3,3,3,3,3,3,3,3,3,2,1,1,1,1,1,1
1,1,1,1,1,1,1,1,1,1,1,2,3,3,3,3,4,3,3,4,3,3,4,3,3,4,3,3,4,3,3,3,3,2,1,1,1,1,1,1,1
1,1,1,1,1,1,1,1,1,1,1,1,2,2,3,3,7,3,3,7,3,3,7,3,3,7,3,3,7,3,3,2,2,1,1,1,1,1,1,1,1
1,1,1,1,1,1,1,1,1,1,1,1,1,2,2,2,2,2,2,2,2,2,2,2,2,2,2,2,2,2,2,1,1,1,1,1,1,1,1,1,1
endlayer

layer
1,1,1,1,1,1,1,1,1,1,1,1,1,1,1,1,1,1,1,1,1,1,2,2,2,2,2,2,2,2,2,1,1,1,1,1,1,1,1,1,1
1,1,1,1,1,1,1,1,1,1,1,1,1,1,1,1,1,1,1,1,1,1,2,3,3,4,3,3,4,3,3,2,2,1,1,1,1,1,1,1,1
1,1,1,1,1,1,1,1,1,1,1,1,1,1,1,1,1,1,1,1,1,1,2,3,3,4,3,3,4,3,3,3,2,2,1,1,1,1,1,1,1
1,1,1,1,1,1,1,1,1,1,1,1,1,1,1,1,1,1,1,1,1,2,3,3,3,3,3,3,3,3,3,3,2,2,2,1,1,1,1,1,1
1,1,1,1,1,1,1,1,1,1,1,1,1,1,1,1,1,1,1,1,2,3,3,3,3,3,3,3,3,3,3,3,8,3,3,2,1,1,1,1,1
1,1,1,1,1,1,1,1,1,2,1,1,1,1,1,1,1,1,1,2,3,3,3,3,3,3,3,3,3,3,3,3,8,3,3,3,2,1,1,1,1
1,1,1,1,1,1,1,1,2,2,1,1,1,1,1,1,1,1,2,3,3,3,3,3,3,3,3,3,3,3,3,3,2,3,3,3,2,2,1,1,1
1,1,1,1,1,1,1,2,1,2,1,1,1,1,1,1,1,2,3,3,3,3,3,3,3,3,3,3,3,3,3,3,8,3,6,6,2,2,1,1,1
1,1,1,1,1,1,2,1,1,2,1,1,1,1,1,1,2,3,3,3,3,3,3,3,3,3,3,3,3,3,3,3,8,3,3,3,2,1,1,1,1
1,1,1,1,1,2,1,1,2,1,1,1,1,1,1,2,3,3,3,3,3,3,3,3,3,3,3,3,3,3,3,3,2,3,3,3,2,1,1,1,1
1,1,1,1,2,1,1,2,1,1,1,1,1,1,2,3,3,3,3,3,3,3,3,3,3,3,3,3,3,3,3,3,8,3,3,3,2,2,1,1,1
1,1,1,2,1,1,2,1,1,1,1,1,1,2,3,3,3,3,3,3,3,3,3,3,3,3,3,3,3,3,3,3,8,3,3,3,2,2,1,1,1
1,1,2,1,1,2,1,1,1,1,1,1,2,3,3,3,3,3,3,3,4,3,3,3,3,3,3,3,3,3,3,3,2,3,3,3,2,1,1,1,1
1,2,1,1,2,1,1,1,1,1,1,2,3,3,3,3,3,3,3,4,4,3,3,3,3,3,3,3,3,3,3,3,2,3,3,3,2,1,1,1,1
2,2,2,2,1,1,1,1,1,1,2,3,3,3,3,3,3,3,4,4,4,3,3,3,3,3,3,3,3,3,3,3,2,3,3,3,2,2,1,1,1
1,1,1,2,1,1,1,1,1,2,3,3,3,3,3,3,3,4,4,4,4,3,3,3,3,3,3,3,3,3,3,3,2,3,3,3,2,2,1,1,1
1,1,1,2,1,1,1,1,2,3,3,3,3,3,3,3,4,4,4,4,4,3,3,3,3,3,3,3,3,3,3,3,2,3,3,3,2,1,1,1,1
1,1,1,2,1,1,1,2,3,3,3,3,3,3,3,3,3,3,3,3,3,3,3,3,3,3,3,3,3,3,3,3,2,3,3,3,2,1,1,1,1
1,1,1,2,1,1,2,3,3,3,3,3,3,3,3,3,3,3,3,3,3,3,3,3,3,3,3,3,3,3,3,3,2,3,3,3,2,2,2,2,2
1,1,1,2,2,2,3,3,3,3,3,3,3,3,3,3,3,3,3,3,3,3,3,3,3,3,3,3,3,3,3,4,3,3,3,3,3,4,4,4,2
1,1,1,2,2,2,3,3,3,3,3,3,3,3,3,3,3,3,3,3,3,3,3,3,3,3,3,3,3,3,3,3,3,3,3,3,3,3,3,3,2
1,1,1,1,2,2,4,4,4,3,3,3,3,3,3,3,3,3,3,3,3,3,3,3,3,3,3,3,3,3,3,3,3,3,3,3,3,4,4,4,2
1,1,1,1,1,2,3,3,3,3,3,3,3,3,3,3,3,3,3,3,3,3,3,3,3,3,3,3,3,3,3,3,3,3,3,3,3,3,3,2,1
1,1,1,1,1,1,2,3,3,3,3,3,3,3,3,3,3,3,3,3,3,3,3,3,3,3,3,3,3,3,3,3,3,3,3,3,3,3,2,1,1
1,1,1,1,1,1,1,2,3,3,3,3,3,3,3,3,3,3,3,3,3,3,3,3,3,3,3,3,3,3,3,3,3,3,3,3,3,2,1,1,1
1,1,1,1,1,1,1,1,2,3,3,3,3,3,3,3,3,3,3,3,3,3,3,3,3,3,3,3,3,3,3,3,3,3,3,3,2,1,1,1,1
1,1,1,1,1,1,1,1,1,2,3,3,3,3,3,3,3,3,3,3,3,3,3,3,3,3,3,3,3,3,3,3,3,3,3,2,1,1,1,1,1
1,1,1,1,1,1,1,1,1,1,2,3,3,3,3,3,3,3,3,3,3,3,3,3,3,3,3,3,3,3,3,3,3,3,2,1,1,1,1,1,1
1,1,1,1,1,1,1,1,1,1,1,2,3,3,3,3,4,3,3,4,3,3,4,3,3,4,3,3,4,3,3,3,3,2,1,1,1,1,1,1,1
1,1,1,1,1,1,1,1,1,1,1,1,2,2,3,3,4,3,3,4,3,3,4,3,3,4,3,3,4,3,3,2,2,1,1,1,1,1,1,1,1
1,1,1,1,1,1,1,1,1,1,1,1,1,2,2,2,2,2,2,2,2,2,2,2,2,2,2,2,2,2,2,1,1,1,1,1,1,1,1,1,1
endlayer

layer
1,1,1,1,1,1,1,1,1,1,1,1,1,1,1,1,1,1,1,1,1,1,2,2,2,2,2,2,2,2,2,4,4,1,1,1,1,1,1,1,1
1,1,1,1,1,1,1,1,1,1,1,1,1,1,1,1,1,1,1,1,1,1,2,3,3,4,3,3,4,3,3,2,2,4,4,4,1,1,1,1,1
1,1,1,1,1,1,1,1,1,1,1,1,1,1,1,1,1,1,1,1,1,1,2,3,3,5,3,3,5,3,3,3,2,2,4,4,4,1,1,1,1
1,1,1,1,1,1,1,1,1,1,1,1,1,1,1,1,1,1,1,1,1,2,3,3,3,3,3,3,3,3,3,3,2,2,2,4,4,4,1,1,1
1,1,1,1,1,1,1,1,1,1,1,1,1,1,1,1,1,1,1,1,2,3,3,3,3,3,3,3,3,3,3,3,8,3,3,2,4,4,4,1,1
1,1,1,1,1,1,1,1,1,2,1,1,1,1,1,1,1,1,1,2,3,3,3,3,3,3,3,3,3,3,3,3,8,3,3,3,2,4,4,4,1
1,1,1,1,1,1,1,1,2,2,1,1,1,1,1,1,1,1,2,3,3,3,3,3,3,3,3,3,3,3,3,3,2,3,3,3,2,2,4,4,1
1,1,1,1,1,1,1,2,1,2,1,1,1,1,1,1,1,2,3,3,3,3,3,3,3,3,3,3,3,3,3,3,8,3,3,3,2,2,4,4,1
1,1,1,1,1,1,2,1,1,2,1,1,1,1,1,1,2,3,3,3,3,3,3,3,3,3,3,3,3,3,3,3,8,3,6,6,2,4,4,4,1
1,1,1,1,1,2,1,1,2,1,1,1,1,1,1,2,3,3,3,3,3,3,3,3,3,3,3,3,3,3,3,3,2,3,3,3,2,4,4,4,1
1,1,1,1,2,1,1,2,1,1,1,1,1,1,2,3,3,3,3,3,3,3,3,3,3,3,3,3,3,3,3,3,8,3,3,3,2,2,4,4,1
1,1,1,2,1,1,2,1,1,1,1,1,1,2,3,3,3,3,3,3,3,3,3,3,3,3,3,3,3,3,3,3,8,3,3,3,2,2,4,4,1
1,1,2,1,1,2,1,1,1,1,1,1,2,3,3,3,3,3,3,3,4,3,3,3,3,3,3,3,3,3,3,3,2,3,3,3,2,4,4,4,1
1,2,1,1,2,1,1,1,1,1,1,2,3,3,3,3,3,3,3,4,4,3,3,3,3,3,3,3,3,3,3,3,2,3,3,3,2,4,4,4,1
2,2,2,2,1,1,1,1,1,1,2,3,3,3,3,3,3,3,7,4,4,3,3,3,3,3,3,3,3,3,3,3,2,3,3,3,2,2,4,4,1
1,1,1,2,1,1,1,1,1,2,3,3,3,3,3,3,3,4,4,4,4,3,3,3,3,3,3,3,3,3,3,3,2,3,3,3,2,2,4,4,1
1,1,1,2,1,1,1,1,2,3,3,3,3,3,3,3,4,4,4,4,4,3,3,3,3,3,3,3,3,3,3,3,2,3,3,3,2,4,4,4,1
1,1,1,2,1,1,1,2,3,3,3,3,3,3,3,3,3,3,3,3,3,3,3,3,3,3,3,3,3,3,3,3,2,3,3,3,2,4,4,4,1
1,1,1,2,1,1,2,3,3,3,3,3,3,3,3,3,3,3,3,3,3,3,3,3,3,3,3,3,3,3,3,3,2,3,3,3,2,2,2,2,2
1,1,1,2,2,2,3,3,3,3,3,3,3,3,3,3,3,3,3,3,3,3,3,3,3,3,3,3,3,3,3,4,3,3,3,3,3,4,4,4,2
1,1,1,2,2,2,3,3,3,3,3,3,3,3,3,3,3,3,3,3,3,3,3,3,3,3,3,3,3,3,3,3,3,3,3,3,3,3,3,3,2
1,1,1,1,2,2,4,4,4,3,3,3,3,3,3,3,3,3,3,3,3,3,3,3,3,3,3,3,3,3,3,3,3,3,3,3,3,4,4,4,2
1,1,1,1,1,2,3,3,3,3,3,3,3,3,3,3,3,3,3,3,3,3,3,3,3,3,3,3,3,3,3,3,3,3,3,3,3,3,3,2,1
1,1,1,1,1,1,2,3,3,3,3,3,3,3,3,3,3,3,3,3,3,3,3,3,3,3,3,3,3,3,3,3,3,3,3,3,3,3,2,1,1
1,1,1,1,1,1,1,2,3,3,3,3,3,3,3,3,3,3,3,3,3,3,3,3,3,3,3,3,3,3,3,3,3,3,3,3,3,2,1,1,1
1,1,1,1,1,1,1,1,2,3,3,3,3,3,3,3,3,3,3,3,3,3,3,3,3,3,3,3,3,3,3,3,3,3,3,3,2,1,1,1,1
1,1,1,1,1,1,1,1,1,2,3,3,3,3,3,3,3,3,3,3,3,3,3,3,3,3,3,3,3,3,3,3,3,3,3,2,1,1,1,1,1
1,1,1,1,1,1,1,1,1,1,2,3,3,3,3,3,3,3,3,3,3,3,3,3,3,3,3,3,3,3,3,3,3,3,2,1,1,1,1,1,1
1,1,1,1,1,1,1,1,1,1,1,2,3,3,3,3,5,3,3,5,3,3,5,3,3,5,3,3,5,3,3,3,3,2,1,1,1,1,1,1,1
1,1,1,1,1,1,1,1,1,1,1,1,2,2,3,3,4,3,3,4,3,3,4,3,3,4,3,3,4,3,3,2,2,1,1,1,1,1,1,1,1
1,1,1,1,1,1,1,1,1,1,1,1,1,2,2,2,2,2,2,2,2,2,2,2,2,2,2,2,2,2,2,1,1,1,1,1,1,1,1,1,1
endlayer

layer
1,1,1,1,1,1,1,1,1,1,1,1,1,1,1,1,1,1,1,1,1,1,2,2,2,2,2,2,2,2,2,4,4,1,1,1,1,1,1,1,1
1,1,1,1,1,1,1,1,1,1,1,1,1,1,1,1,1,1,1,1,1,1,2,3,3,4,3,3,4,3,3,2,2,4,4,1,1,1,1,1,1
1,1,1,1,1,1,1,1,1,1,1,1,1,1,1,1,1,1,1,1,1,1,2,3,3,5,3,3,5,3,3,3,2,2,4,1,1,1,1,1,1
1,1,1,1,1,1,1,1,1,1,1,1,1,1,1,1,1,1,1,1,1,2,3,3,3,3,3,3,3,3,3,3,2,2,2,4,4,1,1,1,1
1,1,1,1,1,1,1,1,1,1,1,1,1,1,1,1,1,1,1,1,2,3,3,3,3,3,3,3,3,3,3,3,8,3,3,2,4,1,1,1,1
1,1,1,1,1,1,1,1,1,2,1,1,1,1,1,1,1,1,1,2,3,3,3,3,3,3,3,3,3,3,3,3,8,3,3,3,2,4,4,1,1
1,1,1,1,1,1,1,1,2,2,1,1,1,1,1,1,1,1,2,3,3,3,3,3,3,3,3,3,3,3,3,3,2,3,3,3,2,2,4,1,1
1,1,1,1,1,1,1,2,1,2,1,1,1,1,1,1,1,2,3,3,3,3,3,3,3,3,3,3,3,3,3,3,8,3,3,3,2,2,4,1,1
1,1,1,1,1,1,2,1,1,2,1,1,1,1,1,1,2,3,3,3,3,3,3,3,3,3,3,3,3,3,3,3,8,3,3,3,2,4,4,1,1
1,1,1,1,1,2,1,1,2,1,1,1,1,1,1,2,3,3,3,3,3,3,3,3,3,3,3,3,3,3,3,3,2,3,6,6,2,4,4,1,1
1,1,1,1,2,1,1,2,1,1,1,1,1,1,2,3,3,3,3,3,3,3,3,3,3,3,3,3,3,3,3,3,8,3,3,3,2,2,4,1,1
1,1,1,2,1,1,2,1,1,1,1,1,1,2,3,3,3,3,3,3,3,3,3,3,3,3,3,3,3,3,3,3,8,3,3,3,2,2,4,1,1
1,1,2,1,1,2,1,1,1,1,1,1,2,3,3,3,3,3,3,3,4,3,3,3,3,3,3,3,3,3,3,3,2,3,3,3,2,4,4,1,1
1,2,1,1,2,1,1,1,1,1,1,2,3,3,3,3,3,3,3,4,4,3,3,3,3,3,3,3,3,3,3,3,2,3,3,3,2,4,4,1,1
2,2,2,2,1,1,1,1,1,1,2,3,3,3,3,3,3,3,4,4,4,3,3,3,3,3,3,3,3,3,3,3,2,3,3,3,2,2,4,1,1
1,1,1,2,1,1,1,1,1,2,3,3,3,3,3,3,3,4,4,4,4,3,3,3,3,3,3,3,3,3,3,3,2,3,3,3,2,2,4,1,1
1,1,1,2,1,1,1,1,2,3,3,3,3,3,3,3,4,4,4,4,4,3,3,3,3,3,3,3,3,3,3,3,2,3,3,3,2,4,4,1,1
1,1,1,2,1,1,1,2,3,3,3,3,3,3,3,3,3,3,3,3,3,3,3,3,3,3,3,3,3,3,3,3,2,3,3,3,2,4,4,1,1
1,1,1,2,1,1,2,3,3,3,3,3,3,3,3,3,3,3,3,3,3,3,3,3,3,3,3,3,3,3,3,3,2,3,3,3,2,2,2,2,2
1,1,1,2,2,2,3,3,3,3,3,3,3,3,3,3,3,3,3,3,3,3,3,3,3,3,3,3,3,3,3,4,3,3,3,3,3,4,4,4,2
1,1,1,2,2,2,3,3,3,3,3,3,3,3,3,3,3,3,3,3,3,3,3,3,3,3,3,3,3,3,3,3,3,3,3,3,3,3,3,3,2
1,1,1,1,2,2,4,4,4,3,3,3,3,3,3,3,3,3,3,3,3,3,3,3,3,3,3,3,3,3,3,3,3,3,3,3,3,4,4,4,2
1,1,1,1,1,2,3,3,3,3,3,3,3,3,3,3,3,3,3,3,3,3,3,3,3,3,3,3,3,3,3,3,3,3,3,3,3,3,3,2,1
1,1,1,1,1,1,2,3,3,3,3,3,3,3,3,3,3,3,3,3,3,3,3,3,3,3,3,3,3,3,3,3,3,3,3,3,3,3,2,1,1
1,1,1,1,1,1,1,2,3,3,3,3,3,3,3,3,3,3,3,3,3,3,3,3,3,3,3,3,3,3,3,3,3,3,3,3,3,2,1,1,1
1,1,1,1,1,1,1,1,2,3,3,3,3,3,3,3,3,3,3,3,3,3,3,3,3,3,3,3,3,3,3,3,3,3,3,3,2,1,1,1,1
1,1,1,1,1,1,1,1,1,2,3,3,3,3,3,3,3,3,3,3,3,3,3,3,3,3,3,3,3,3,3,3,3,3,3,2,1,1,1,1,1
1,1,1,1,1,1,1,1,1,1,2,3,3,3,3,3,3,3,3,3,3,3,3,3,3,3,3,3,3,3,3,3,3,3,2,1,1,1,1,1,1
1,1,1,1,1,1,1,1,1,1,1,2,3,3,3,3,5,3,3,5,3,3,5,3,3,5,3,3,5,3,3,3,3,2,1,1,1,1,1,1,1
1,1,1,1,1,1,1,1,1,1,1,1,2,2,3,3,4,3,3,4,3,3,4,3,3,4,3,3,4,3,3,2,2,1,1,1,1,1,1,1,1
1,1,1,1,1,1,1,1,1,1,1,1,1,2,2,2,2,2,2,2,2,2,2,2,2,2,2,2,2,2,2,1,1,1,1,1,1,1,1,1,1
endlayer

layer
1,1,1,1,1,1,1,1,1,1,1,1,1,1,1,1,1,1,1,1,1,1,2,2,2,2,2,2,2,2,2,1,1,1,1,1,1,1,1,1,1
1,1,1,1,1,1,1,1,1,1,1,1,1,1,1,1,1,1,1,1,1,1,2,3,3,4,3,3,4,3,3,2,2,1,1,1,1,1,1,1,1
1,1,1,1,1,1,1,1,1,1,1,1,1,1,1,1,1,1,1,1,1,1,2,3,3,5,3,3,5,3,3,3,2,2,1,1,1,1,1,1,1
1,1,1,1,1,1,1,1,1,1,1,1,1,1,1,1,1,1,1,1,1,2,3,3,3,3,3,3,3,3,3,3,2,2,2,1,1,1,1,1,1
1,1,1,1,1,1,1,1,1,1,1,1,1,1,1,1,1,1,1,1,2,3,3,3,3,3,3,3,3,3,3,3,2,2,2,2,1,1,1,1,1
1,1,1,1,1,1,1,1,1,2,1,1,1,1,1,1,1,1,1,2,3,3,3,3,3,3,3,3,3,3,3,3,2,2,3,3,2,1,1,1,1
1,1,1,1,1,1,1,1,2,2,1,1,1,1,1,1,1,1,2,3,3,3,3,3,3,3,3,3,3,3,3,3,2,2,3,3,2,2,1,1,1
1,1,1,1,1,1,1,2,1,2,1,1,1,1,1,1,1,2,3,3,3,3,3,3,3,3,3,3,3,3,3,3,2,2,3,3,2,2,1,1,1
1,1,1,1,1,1,2,1,1,2,1,1,1,1,1,1,2,3,3,3,3,3,3,3,3,3,3,3,3,3,3,3,2,2,3,3,2,1,1,1,1
1,1,1,1,1,2,1,1,2,1,1,1,1,1,1,2,3,3,3,3,3,3,3,3,3,3,3,3,3,3,3,3,2,2,3,3,2,1,1,1,1
1,1,1,1,2,1,1,2,1,1,1,1,1,1,2,3,3,3,3,3,3,3,3,3,3,3,3,3,3,3,3,3,2,2,6,6,2,2,1,1,1
1,1,1,2,1,1,2,1,1,1,1,1,1,2,3,3,3,3,3,3,3,3,3,3,3,3,3,3,3,3,3,3,2,2,2,2,2,2,1,1,1
1,1,2,1,1,2,1,1,1,1,1,1,2,3,3,3,3,3,3,3,4,3,3,3,3,3,3,3,3,3,3,5,2,2,2,2,2,1,1,1,1
1,2,1,1,2,1,1,1,1,1,1,2,3,3,3,3,3,3,3,4,4,3,3,3,3,3,3,3,3,3,6,2,2,2,2,2,2,1,1,1,1
2,2,2,2,1,1,1,1,1,1,2,3,3,3,3,3,3,3,4,4,4,3,3,3,3,3,3,3,3,3,6,2,2,2,2,2,2,2,1,1,1
1,1,1,2,1,1,1,1,1,2,3,3,3,3,3,3,3,4,4,4,4,3,3,3,3,3,3,3,3,3,6,2,2,2,2,2,2,2,1,1,1
1,1,1,2,1,1,1,1,2,3,3,3,3,3,3,3,4,4,4,4,4,3,3,3,3,3,3,3,3,3,3,5,2,2,2,2,2,1,1,1,1
1,1,1,2,1,1,1,2,3,3,3,3,3,3,3,3,3,3,3,3,3,3,3,3,3,3,3,3,3,3,3,3,2,2,2,2,2,1,1,1,1
1,1,1,2,1,1,2,3,3,3,3,3,3,3,3,3,3,3,3,3,3,3,3,3,3,3,3,3,3,3,3,3,2,2,2,2,2,2,2,2,2
1,1,1,2,2,2,3,3,3,3,3,3,3,3,3,3,3,3,3,3,3,3,3,3,3,3,3,3,3,3,3,4,3,3,3,3,3,3,4,4,2
1,1,1,2,2,2,3,3,3,3,3,3,3,3,3,3,3,3,3,3,3,3,3,3,3,3,3,3,3,3,3,3,3,3,3,3,3,3,3,3,2
1,1,1,1,2,2,4,4,3,3,3,3,3,3,3,3,3,3,3,3,3,3,3,3,3,3,3,3,3,3,3,3,3,3,3,3,3,3,4,4,2
1,1,1,1,1,2,3,3,3,3,3,3,3,3,3,3,3,3,3,3,3,3,3,3,3,3,3,3,3,3,3,3,3,3,3,3,3,3,3,2,1
1,1,1,1,1,1,2,3,3,3,3,3,3,3,3,3,3,3,3,3,3,3,3,3,3,3,3,3,3,3,3,3,3,3,3,3,3,3,2,1,1
1,1,1,1,1,1,1,2,3,3,3,3,3,3,3,3,3,3,3,3,3,3,3,3,3,3,3,3,3,3,3,3,3,3,3,3,3,2,1,1,1
1,1,1,1,1,1,1,1,2,3,3,3,3,3,3,3,3,3,3,3,3,3,3,3,3,3,3,3,3,3,3,3,3,3,3,3,2,1,1,1,1
1,1,1,1,1,1,1,1,1,2,3,3,3,3,3,3,3,3,3,3,3,3,3,3,3,3,3,3,3,3,3,3,3,3,3,2,1,1,1,1,1
1,1,1,1,1,1,1,1,1,1,2,3,3,3,3,3,3,3,3,3,3,3,3,3,3,3,3,3,3,3,3,3,3,3,2,1,1,1,1,1,1
1,1,1,1,1,1,1,1,1,1,1,2,3,3,3,3,5,3,3,5,3,3,5,3,3,5,3,3,5,3,3,3,3,2,1,1,1,1,1,1,1
1,1,1,1,1,1,1,1,1,1,1,1,2,2,3,3,4,3,3,4,3,3,4,3,3,4,3,3,4,3,3,2,2,1,1,1,1,1,1,1,1
1,1,1,1,1,1,1,1,1,1,1,1,1,2,2,2,2,2,2,2,2,2,2,2,2,2,2,2,2,2,2,1,1,1,1,1,1,1,1,1,1
endlayer

layer
1,1,1,1,1,1,1,1,1,1,1,1,1,1,1,1,1,1,1,1,1,1,2,2,2,2,2,2,2,2,2,1,1,1,1,1,1,1,1,1,1
1,1,1,1,1,1,1,1,1,1,1,1,1,1,1,1,1,1,1,1,1,1,2,3,3,4,3,3,4,3,3,2,2,1,1,1,1,1,1,1,1
1,1,1,1,1,1,1,1,1,1,1,1,1,1,1,1,1,1,1,1,1,1,2,3,3,5,3,3,5,3,3,3,2,2,1,1,1,1,1,1,1
1,1,1,1,1,1,1,1,1,1,1,1,1,1,1,1,1,1,1,1,1,2,3,3,3,3,3,3,3,3,3,3,2,2,2,1,1,1,1,1,1
1,1,1,1,1,1,1,1,1,1,1,1,1,1,1,1,1,1,1,1,2,3,3,3,3,3,3,3,3,3,3,3,8,3,9,2,1,1,1,1,1
1,1,1,1,1,1,1,1,1,2,1,1,1,1,1,1,1,1,1,2,3,3,3,3,3,3,3,3,3,3,3,3,8,3,3,3,2,1,1,1,1
1,1,1,1,1,1,1,1,2,2,1,1,1,1,1,1,1,1,2,3,3,3,3,3,3,3,3,3,3,3,3,3,2,3,3,3,2,2,1,1,1
1,1,1,1,1,1,1,2,1,2,1,1,1,1,1,1,1,2,3,3,3,3,3,3,3,3,3,3,3,3,3,3,8,3,3,3,2,2,1,1,1
1,1,1,1,1,1,2,1,1,2,1,1,1,1,1,1,2,3,3,3,3,3,3,3,3,3,3,3,3,3,3,3,8,3,3,3,2,1,1,1,1
1,1,1,1,1,2,1,1,2,1,1,1,1,1,1,2,3,3,3,3,3,3,3,3,3,3,3,3,3,3,3,3,2,3,3,3,2,1,1,1,1
1,1,1,1,2,1,1,2,1,1,1,1,1,1,2,3,3,3,3,3,3,3,3,3,3,3,3,3,3,3,3,3,8,3,3,3,2,2,1,1,1
1,1,1,2,1,1,2,1,1,1,1,1,1,2,3,3,3,3,3,3,3,3,3,3,3,3,3,3,3,3,3,3,8,3,3,3,2,2,1,1,1
1,1,2,1,1,2,1,1,1,1,1,1,2,3,3,3,3,3,3,3,4,3,3,3,3,3,3,3,3,3,3,3,2,3,3,3,2,1,1,1,1
1,2,1,1,2,1,1,1,1,1,1,2,3,3,3,3,3,3,3,4,4,3,3,3,3,3,3,3,3,6,3,3,3,3,3,3,2,1,1,1,1
2,2,2,2,1,1,1,1,1,1,2,3,3,3,3,3,3,3,4,4,4,3,3,3,3,3,3,3,3,6,3,3,3,3,3,3,2,2,1,1,1
1,1,1,2,1,1,1,1,1,2,3,3,3,3,3,3,3,4,4,4,4,3,3,3,3,3,3,3,3,6,3,3,3,3,3,3,2,2,1,1,1
1,1,1,2,1,1,1,1,2,3,3,3,3,3,3,3,4,4,4,4,4,3,3,3,3,3,3,3,3,3,3,3,2,3,3,3,2,1,1,1,1
1,1,1,2,1,1,1,2,3,3,3,3,3,3,3,3,3,3,3,3,3,3,3,3,3,3,3,3,3,3,3,3,2,3,3,3,2,1,1,1,1
1,1,1,2,1,1,2,3,3,3,3,3,3,3,3,3,3,3,3,3,3,3,3,3,3,3,3,3,3,3,3,3,2,8,8,8,2,2,2,2,2
1,1,1,2,2,2,3,3,3,3,3,3,3,3,3,3,3,3,3,3,3,3,3,3,3,3,3,3,3,3,3,4,3,3,3,3,3,3,4,4,2
1,1,1,2,2,2,3,3,3,3,3,3,3,3,3,3,3,3,3,3,3,3,3,3,3,3,3,3,3,3,3,3,3,3,3,3,3,3,3,3,2
1,1,1,1,2,2,4,4,3,3,3,3,3,3,3,3,3,3,3,3,3,3,3,3,3,3,3,3,3,3,3,3,3,3,3,3,3,3,4,4,2
1,1,1,1,1,2,3,3,3,3,3,3,3,3,3,3,3,3,3,3,3,3,3,3,3,3,3,3,3,3,3,3,3,3,3,3,3,3,3,2,1
1,1,1,1,1,1,2,3,3,3,3,3,3,3,3,3,3,3,3,3,3,3,3,3,3,3,3,3,3,3,3,3,3,3,3,3,3,3,2,1,1
1,1,1,1,1,1,1,2,3,3,3,3,3,3,3,3,3,3,3,3,3,3,3,3,3,3,3,3,3,3,3,3,3,3,3,3,3,2,1,1,1
1,1,1,1,1,1,1,1,2,3,3,3,3,3,3,3,3,3,3,3,3,3,3,3,3,3,3,3,3,3,3,3,3,3,3,3,2,1,1,1,1
1,1,1,1,1,1,1,1,1,2,3,3,3,3,3,3,3,3,3,3,3,3,3,3,3,3,3,3,3,3,3,3,3,3,3,2,1,1,1,1,1
1,1,1,1,1,1,1,1,1,1,2,3,3,3,3,3,3,3,3,3,3,3,3,3,3,3,3,3,3,3,3,3,3,3,2,1,1,1,1,1,1
1,1,1,1,1,1,1,1,1,1,1,2,3,3,3,3,5,3,3,5,3,3,5,3,3,5,3,3,5,3,3,3,3,2,1,1,1,1,1,1,1
1,1,1,1,1,1,1,1,1,1,1,1,2,2,3,3,4,3,3,4,3,3,4,3,3,4,3,3,4,3,3,2,2,1,1,1,1,1,1,1,1
1,1,1,1,1,1,1,1,1,1,1,1,1,2,2,2,2,2,2,2,2,2,2,2,2,2,2,2,2,2,2,1,1,1,1,1,1,1,1,1,1
endlayer

layer
1,1,1,1,1,1,1,1,1,1,1,1,1,1,1,1,1,1,1,1,1,1,2,2,2,2,2,2,2,2,2,1,1,1,1,1,1,1,1,1,1
1,1,1,1,1,1,1,1,1,1,1,1,1,1,1,1,1,1,1,1,1,1,2,3,3,4,3,3,4,3,3,2,2,1,1,1,1,1,1,1,1
1,1,1,1,1,1,1,1,1,1,1,1,1,1,1,1,1,1,1,1,1,1,2,3,3,5,3,3,5,3,3,3,2,2,1,1,1,1,1,1,1
1,1,1,1,1,1,1,1,1,1,1,1,1,1,1,1,1,1,1,1,1,2,3,3,3,3,3,3,3,3,3,3,2,2,2,1,1,1,1,1,1
1,1,1,1,1,1,1,1,1,1,1,1,1,1,1,1,1,1,1,1,2,3,3,3,3,3,3,3,3,3,3,3,8,3,3,2,1,1,1,1,1
1,1,1,1,1,1,1,1,1,2,1,1,1,1,1,1,1,1,1,2,3,3,3,3,3,3,3,3,3,3,3,3,8,3,3,3,2,1,1,1,1
1,1,1,1,1,1,1,1,2,2,1,1,1,1,1,1,1,1,2,3,3,3,3,3,3,3,3,3,3,3,3,3,2,3,3,3,2,2,1,1,1
1,1,1,1,1,1,1,2,1,2,1,1,1,1,1,1,1,2,3,3,3,3,3,3,3,3,3,3,3,3,3,3,8,3,3,3,2,2,1,1,1
1,1,1,1,1,1,2,1,1,2,1,1,1,1,1,1,2,3,3,3,3,3,3,3,3,3,3,3,3,3,3,3,8,3,3,3,2,1,1,1,1
1,1,1,1,1,2,1,1,2,1,1,1,1,1,1,2,3,3,3,3,3,3,3,3,3,3,3,3,3,3,3,3,2,3,3,3,2,1,1,1,1
1,1,1,1,2,1,1,2,1,1,1,1,1,1,2,3,3,3,3,3,3,3,3,3,3,3,3,3,3,3,3,3,8,3,3,3,2,2,1,1,1
1,1,1,2,1,1,2,1,1,1,1,1,1,2,3,3,3,3,3,3,3,3,3,3,3,3,3,3,3,3,3,3,8,3,3,3,2,2,1,1,1
1,1,2,1,1,2,1,1,1,1,1,1,2,3,3,3,3,3,3,3,4,3,3,3,3,3,3,3,3,3,3,3,2,3,3,3,2,1,1,1,1
1,2,1,1,2,1,1,1,1,1,1,2,3,3,3,3,3,3,3,4,4,3,3,3,3,3,3,3,6,3,3,3,3,3,3,3,2,1,1,1,1
2,2,2,2,1,1,1,1,1,1,2,3,3,3,3,3,3,3,7,4,4,3,3,3,3,3,3,3,6,3,3,3,3,3,10,3,2,2,1,1,1
1,1,1,2,1,1,1,1,1,2,3,3,3,3,3,3,3,4,4,4,4,3,3,3,3,3,3,3,6,3,3,3,3,3,3,3,2,2,1,1,1
1,1,1,2,1,1,1,1,2,3,3,3,3,3,3,3,4,4,4,4,4,3,3,3,3,3,3,3,3,3,3,3,2,3,3,3,2,1,1,1,1
1,1,1,2,1,1,1,2,3,3,3,3,3,3,3,3,3,3,3,3,3,3,3,3,3,3,3,3,3,3,3,3,2,3,3,3,2,1,1,1,1
1,1,1,2,1,1,2,3,3,3,3,3,3,3,3,3,3,3,3,3,3,3,3,3,3,3,3,3,3,3,3,3,2,8,8,8,2,2,2,2,2
1,1,1,2,2,2,3,3,3,3,3,3,3,3,3,3,3,3,3,3,3,3,3,3,3,3,3,3,3,3,3,4,3,3,3,3,3,3,4,4,2
1,1,1,2,2,2,3,3,3,3,3,3,3,3,3,3,3,3,3,3,3,3,3,3,3,3,3,3,3,3,3,3,3,3,3,3,3,3,3,3,2
1,1,1,1,2,2,4,4,3,3,3,3,3,3,3,3,3,3,3,3,3,3,3,3,3,3,3,3,3,3,3,3,3,3,3,3,3,3,4,4,2
1,1,1,1,1,2,3,3,3,3,3,3,3,3,3,3,3,3,3,3,3,3,3,3,3,3,3,3,3,3,3,3,3,3,3,3,3,3,3,2,1
1,1,1,1,1,1,2,3,3,3,3,3,3,3,3,3,3,3,3,3,3,3,3,3,3,3,3,3,3,3,3,3,3,3,3,3,3,3,2,1,1
1,1,1,1,1,1,1,2,3,3,3,3,3,3,3,3,3,3,3,3,3,3,3,3,3,3,3,3,3,3,3,3,3,3,3,3,3,2,1,1,1
1,1,1,1,1,1,1,1,2,3,3,3,3,3,3,3,3,3,3,3,3,3,3,3,3,3,3,3,3,3,3,3,3,3,3,3,2,1,1,1,1
1,1,1,1,1,1,1,1,1,2,3,3,3,3,3,3,3,3,3,3,3,3,3,3,3,3,3,3,3,3,3,3,3,3,3,2,1,1,1,1,1
1,1,1,1,1,1,1,1,1,1,2,3,3,3,3,3,3,3,3,3,3,3,3,3,3,3,3,3,3,3,3,3,3,3,2,1,1,1,1,1,1
1,1,1,1,1,1,1,1,1,1,1,2,3,3,3,3,5,3,3,5,3,3,5,3,3,5,3,3,5,3,3,3,3,2,1,1,1,1,1,1,1
1,1,1,1,1,1,1,1,1,1,1,1,2,2,3,3,4,3,3,4,3,3,4,3,3,4,3,3,4,3,3,2,2,1,1,1,1,1,1,1,1
1,1,1,1,1,1,1,1,1,1,1,1,1,2,2,2,2,2,2,2,2,2,2,2,2,2,2,2,2,2,2,1,1,1,1,1,1,1,1,1,1
endlayer

layer
1,1,1,1,1,1,1,1,1,1,1,1,1,1,1,1,1,1,1,1,1,1,2,2,2,2,2,2,2,2,2,4,4,1,1,1,1,1,1,1,1
1,1,1,1,1,1,1,1,1,1,1,1,1,1,1,1,1,1,1,1,1,1,2,3,3,4,3,3,4,3,3,2,2,4,4,4,1,1,1,1,1
1,1,1,1,1,1,1,1,1,1,1,1,1,1,1,1,1,1,1,1,1,1,2,3,3,5,3,3,5,3,3,3,2,2,4,4,4,1,1,1,1
1,1,1,1,1,1,1,1,1,1,1,1,1,1,1,1,1,1,1,1,1,2,3,3,3,3,3,3,3,3,3,3,2,2,2,4,4,4,1,1,1
1,1,1,1,1,1,1,1,1,1,1,1,1,1,1,1,1,1,1,1,2,3,3,3,3,3,3,3,3,3,3,3,8,3,3,2,4,4,4,1,1
1,1,1,1,1,1,1,1,1,2,1,1,1,1,1,1,1,1,1,2,3,3,3,3,3,3,3,3,3,3,3,3,8,3,3,3,2,4,4,4,1
1,1,1,1,1,1,1,1,2,2,1,1,1,1,1,1,1,1,2,3,3,3,3,3,3,3,3,3,3,3,3,3,2,3,3,3,2,2,4,4,1
1,1,1,1,1,1,1,2,1,2,1,1,1,1,1,1,1,2,3,3,3,3,3,3,3,3,3,3,3,3,3,3,8,3,3,3,2,2,4,4,1
1,1,1,1,1,1,2,1,1,2,1,1,1,1,1,1,2,3,3,3,3,3,3,3,3,3,3,3,3,3,3,3,8,3,3,3,2,4,4,4,1
1,1,1,1,1,2,1,1,2,1,1,1,1,1,1,2,3,3,3,3,3,3,3,3,3,3,3,3,3,3,3,3,2,3,3,3,2,4,4,4,1
1,1,1,1,2,1,1,2,1,1,1,1,1,1,2,3,3,3,3,3,3,3,3,3,3,3,3,3,3,3,3,3,8,3,3,3,2,2,4,4,1
1,1,1,2,1,1,2,1,1,1,1,1,1,2,3,3,3,3,3,3,3,3,3,3,3,3,3,3,3,3,3,3,8,3,3,3,2,2,4,4,1
1,1,2,1,1,2,1,1,1,1,1,1,2,3,3,3,3,3,3,3,4,3,3,3,3,3,3,3,3,3,3,3,2,3,3,3,2,4,4,4,1
1,2,1,1,2,1,1,1,1,1,1,2,3,3,3,3,3,3,3,4,4,3,3,3,3,3,3,6,3,3,3,3,3,3,3,3,2,4,4,4,1
2,2,2,2,1,1,1,1,1,1,2,3,3,3,3,3,3,3,4,4,4,3,3,3,3,3,3,6,3,3,3,3,3,3,3,3,2,2,4,4,1
1,1,1,2,1,1,1,1,1,2,3,3,3,3,3,3,3,4,4,4,4,3,3,3,3,3,3,6,3,3,3,3,3,3,3,3,2,2,4,4,1
1,1,1,2,1,1,1,1,2,3,3,3,3,3,3,3,4,4,4,4,4,3,3,3,3,3,3,3,3,3,3,3,2,3,3,3,2,4,4,4,1
1,1,1,2,1,1,1,2,3,3,3,3,3,3,3,3,3,3,3,3,3,3,3,3,3,3,3,3,3,3,3,3,2,3,3,3,2,4,4,4,1
1,1,1,2,1,1,2,3,3,3,3,3,3,3,3,3,3,3,3,3,3,3,3,3,3,3,3,3,3,3,3,3,2,8,8,8,2,2,2,2,2
1,1,1,2,2,2,3,3,3,3,3,3,3,3,3,3,3,3,3,3,3,3,3,3,3,3,3,3,3,3,3,4,3,3,3,3,3,3,4,4,2
1,1,1,2,2,2,3,3,3,3,3,3,3,3,3,3,3,3,3,3,3,3,3,3,3,3,3,3,3,3,3,3,3,3,3,3,3,3,3,3,2
1,1,1,1,2,2,4,4,3,3,3,3,3,3,3,3,3,3,3,3,3,3,3,3,3,3,3,3,3,3,3,3,3,3,3,3,3,3,4,4,2
1,1,1,1,1,2,3,3,3,3,3,3,3,3,3,3,3,3,3,3,3,3,3,3,3,3,3,3,3,3,3,3,3,3,3,3,3,3,3,2,1
1,1,1,1,1,1,2,3,3,3,3,3,3,3,3,3,3,3,3,3,3,3,3,3,3,3,3,3,3,3,3,3,3,3,3,3,3,3,2,1,1
1,1,1,1,1,1,1,2,3,3,3,3,3,3,3,3,3,3,3,3,3,3,3,3,3,3,3,3,3,3,3,3,3,3,3,3,3,2,1,1,1
1,1,1,1,1,1,1,1,2,3,3,3,3,3,3,3,3,3,3,3,3,3,3,3,3,3,3,3,3,3,3,3,3,3,3,3,2,1,1,1,1
1,1,1,1,1,1,1,1,1,2,3,3,3,3,3,3,3,3,3,3,3,3,3,3,3,3,3,3,3,3,3,3,3,3,3,2,1,1,1,1,1
1,1,1,1,1,1,1,1,1,1,2,3,3,3,3,3,3,3,3,3,3,3,3,3,3,3,3,3,3,3,3,3,3,3,2,1,1,1,1,1,1
1,1,1,1,1,1,1,1,1,1,1,2,3,3,3,3,5,3,3,5,3,3,5,3,3,5,3,3,5,3,3,3,3,2,1,1,1,1,1,1,1
1,1,1,1,1,1,1,1,1,1,1,1,2,2,3,3,4,3,3,4,3,3,4,3,3,4,3,3,4,3,3,2,2,1,1,1,1,1,1,1,1
1,1,1,1,1,1,1,1,1,1,1,1,1,2,2,2,2,2,2,2,2,2,2,2,2,2,2,2,2,2,2,1,1,1,1,1,1,1,1,1,1
endlayer

layer
1,1,1,1,1,1,1,1,1,1,1,1,1,1,1,1,1,1,1,1,1,1,2,2,2,2,2,2,2,2,2,4,4,1,1,1,1,1,1,1,1
1,1,1,1,1,1,1,1,1,1,1,1,1,1,1,1,1,1,1,1,1,1,2,3,3,4,3,3,4,3,3,2,2,4,4,1,1,1,1,1,1
1,1,1,1,1,1,1,1,1,1,1,1,1,1,1,1,1,1,1,1,1,1,2,3,3,4,3,3,4,3,3,3,2,2,4,1,1,1,1,1,1
1,1,1,1,1,1,1,1,1,1,1,1,1,1,1,1,1,1,1,1,1,2,3,3,3,3,3,3,3,3,3,3,2,2,2,4,4,1,1,1,1
1,1,1,1,1,1,1,1,1,1,1,1,1,1,1,1,1,1,1,1,2,3,3,3,3,3,3,3,3,3,3,3,8,3,3,2,4,1,1,1,1
1,1,1,1,1,1,1,1,1,2,1,1,1,1,1,1,1,1,1,2,3,3,3,3,3,3,3,3,3,3,3,3,8,3,3,3,2,4,4,1,1
1,1,1,1,1,1,1,1,2,2,1,1,1,1,1,1,1,1,2,3,3,3,3,3,3,3,3,3,3,3,3,3,2,3,3,3,2,2,4,1,1
1,1,1,1,1,1,1,2,1,2,1,1,1,1,1,1,1,2,3,3,3,3,3,3,3,3,3,3,3,3,3,3,8,3,3,3,2,2,4,1,1
1,1,1,1,1,1,2,1,1,2,1,1,1,1,1,1,2,3,3,3,3,3,3,3,3,3,3,3,3,3,3,3,8,3,3,3,2,4,4,1,1
1,1,1,1,1,2,1,1,2,1,1,1,1,1,1,2,3,3,3,3,3,3,3,3,3,3,3,3,3,3,3,3,2,3,3,3,2,4,4,1,1
1,1,1,1,2,1,1,2,1,1,1,1,1,1,2,3,3,3,3,3,3,3,3,3,3,3,3,3,3,3,3,3,8,3,3,3,2,2,4,1,1
1,1,1,2,1,1,2,1,1,1,1,1,1,2,3,3,3,3,3,3,3,3,3,3,3,3,3,3,3,3,3,3,8,3,3,3,2,2,4,1,1
1,1,2,1,1,2,1,1,1,1,1,1,2,3,3,3,3,3,3,3,4,3,3,3,3,3,3,3,3,3,3,3,2,3,3,3,2,4,4,1,1
1,2,1,1,2,1,1,1,1,1,1,2,3,3,3,3,3,3,3,4,4,4,3,3,3,3,6,3,3,3,3,3,2,3,3,3,2,4,4,1,1
2,2,2,2,1,1,1,1,1,1,2,3,3,3,3,3,3,3,4,4,4,3,3,3,3,3,6,3,3,3,3,3,2,3,3,3,2,2,4,1,1
1,1,1,2,1,1,1,1,1,2,3,3,3,3,3,3,3,4,4,4,4,4,3,3,3,3,6,3,3,3,3,3,2,3,3,3,2,2,4,1,1
1,1,1,2,1,1,1,1,2,3,3,3,3,3,3,3,4,4,4,4,4,3,3,3,3,3,3,3,3,3,3,3,2,3,3,3,2,4,4,1,1
1,1,1,2,1,1,1,2,3,3,3,3,3,3,3,3,3,4,3,4,3,3,3,3,3,3,3,3,3,3,3,3,2,3,3,3,2,4,4,1,1
1,1,1,2,1,1,2,3,3,3,3,3,3,3,3,3,3,3,3,3,3,3,3,3,3,3,3,3,3,3,3,3,2,8,8,8,2,2,2,2,2
1,1,1,2,2,2,3,3,3,3,3,3,3,3,3,3,3,3,3,3,3,3,3,3,3,3,3,3,3,3,3,4,3,3,3,3,3,3,3,4,2
1,1,1,2,2,2,3,3,3,3,3,3,3,3,3,3,3,3,3,3,3,3,3,3,3,3,3,3,3,3,3,3,3,3,3,3,3,3,3,3,2
1,1,1,1,2,2,4,3,3,3,3,3,3,3,3,3,3,3,3,3,3,3,3,3,3,3,3,3,3,3,3,3,3,3,3,3,3,3,3,4,2
1,1,1,1,1,2,3,3,3,3,3,3,3,3,3,3,3,3,3,3,3,3,3,3,3,3,3,3,3,3,3,3,3,3,3,3,3,3,3,2,1
1,1,1,1,1,1,2,3,3,3,3,3,3,3,3,3,3,3,3,3,3,3,3,3,3,3,3,3,3,3,3,3,3,3,3,3,3,3,2,1,1
1,1,1,1,1,1,1,2,3,3,3,3,3,3,3,3,3,3,3,3,3,3,3,3,3,3,3,3,3,3,3,3,3,3,3,3,3,2,1,1,1
1,1,1,1,1,1,1,1,2,3,3,3,3,3,3,3,3,3,3,3,3,3,3,3,3,3,3,3,3,3,3,3,3,3,3,3,2,1,1,1,1
1,1,1,1,1,1,1,1,1,2,3,3,3,3,3,3,3,3,3,3,3,3,3,3,3,3,3,3,3,3,3,3,3,3,3,2,1,1,1,1,1
1,1,1,1,1,1,1,1,1,1,2,3,3,3,3,3,3,3,3,3,3,3,3,3,3,3,3,3,3,3,3,3,3,3,2,1,1,1,1,1,1
1,1,1,1,1,1,1,1,1,1,1,2,3,3,3,3,4,3,3,4,3,3,4,3,3,4,3,3,4,3,3,3,3,2,1,1,1,1,1,1,1
1,1,1,1,1,1,1,1,1,1,1,1,2,2,3,3,4,3,3,4,3,3,4,3,3,4,3,3,4,3,3,2,2,1,1,1,1,1,1,1,1
1,1,1,1,1,1,1,1,1,1,1,1,1,2,2,2,2,2,2,2,2,2,2,2,2,2,2,2,2,2,2,1,1,1,1,1,1,1,1,1,1
endlayer

layer
0,0,0,0,0,0,0,0,0,0,0,0,0,0,0,0,0,0,0,0,0,0,2,2,2,2,2,2,2,2,2,0,0,0,0,0,0,0,0,0,0
0,0,0,0,0,0,0,0,0,0,0,0,0,0,0,0,0,0,0,0,0,0,2,4,3,7,3,3,7,3,3,2,2,0,0,0,0,0,0,0,0
0,0,0,0,0,0,0,0,0,0,0,0,0,0,0,0,0,0,0,0,0,0,2,4,3,4,3,3,4,3,3,3,2,2,0,0,0,0,0,0,0
0,0,0,0,0,0,0,0,0,0,0,0,0,0,0,0,0,0,0,0,0,2,3,4,3,3,3,3,3,3,3,3,2,2,2,0,0,0,0,0,0
0,0,0,0,0,0,0,0,0,0,0,0,0,0,0,0,0,0,0,0,2,4,3,4,3,3,3,3,3,3,3,3,2,2,2,2,0,0,0,0,0
0,0,0,0,0,0,0,0,0,2,0,0,0,0,0,0,0,0,0,2,4,4,3,4,3,3,3,3,3,3,3,3,2,2,2,2,2,0,0,0,0
0,0,0,0,0,0,0,0,2,2,0,0,0,0,0,0,0,0,2,4,4,4,3,4,3,3,3,3,3,3,3,3,2,2,2,2,2,2,0,0,0
0,0,0,0,0,0,0,2,0,2,0,0,0,0,0,0,0,2,4,4,4,4,3,4,3,3,3,3,3,3,3,3,2,2,2,2,2,2,0,0,0
0,0,0,0,0,0,2,0,0,2,0,0,0,0,0,0,2,4,4,4,4,4,3,4,3,3,3,3,3,3,3,3,2,2,2,2,2,0,0,0,0
0,0,0,0,0,2,0,0,2,0,0,0,0,0,0,2,4,4,4,4,4,4,3,4,3,3,3,3,3,3,3,3,2,2,2,2,2,0,0,0,0
0,0,0,0,2,0,0,2,0,0,0,0,0,0,2,4,4,4,4,4,4,4,3,4,3,3,3,3,3,3,3,3,2,2,2,2,2,2,0,0,0
0,0,0,2,0,0,2,0,0,0,0,0,0,2,4,4,4,4,4,4,4,4,3,4,3,3,3,3,3,3,3,3,2,2,2,2,2,2,0,0,0
0,0,2,0,0,2,0,0,0,0,0,0,2,4,4,4,4,4,4,4,4,4,3,4,3,3,3,3,3,3,3,3,2,2,2,2,2,0,0,0,0
0,2,0,0,2,0,0,0,0,0,0,2,4,4,4,4,4,4,4,4,4,4,3,4,3,6,3,3,3,3,3,3,2,2,2,2,2,0,0,0,0
2,2,2,2,0,0,0,0,0,0,2,4,4,4,4,4,4,4,4,4,4,4,3,4,3,6,3,3,3,3,3,3,2,2,2,2,2,2,0,0,0
0,0,0,2,0,0,0,0,0,2,4,4,4,4,4,4,4,4,4,4,4,4,3,4,3,6,3,3,3,3,3,3,2,2,2,2,2,2,0,0,0
0,0,0,2,0,0,0,0,2,4,4,4,4,4,4,4,4,4,4,4,4,4,3,4,3,3,3,3,3,3,3,3,2,2,2,2,2,0,0,0,0
0,0,0,2,0,0,0,2,4,4,4,4,4,4,4,4,4,4,4,4,4,4,3,4,3,3,3,3,3,3,3,3,2,2,2,2,2,0,0,0,0
0,0,0,2,0,0,2,3,3,3,3,3,3,3,3,3,3,3,3,3,3,3,3,4,3,3,3,3,3,3,3,3,2,2,2,2,2,2,2,2,2
0,0,0,2,2,2,4,4,4,4,4,4,4,4,4,4,4,4,4,4,4,4,4,7,3,3,3,3,3,3,3,4,3,3,3,3,3,3,3,4,2
0,0,0,2,2,2,3,3,3,3,3,3,3,3,3,3,3,3,3,3,3,3,3,3,3,3,3,3,3,3,3,3,3,3,3,3,3,3,3,3,2
0,0,0,0,2,2,4,3,3,3,3,3,3,3,3,3,3,3,3,3,3,3,3,3,3,3,3,3,3,3,3,3,3,3,3,3,3,3,3,4,2
0,0,0,0,0,2,3,3,3,3,3,3,3,3,3,3,3,3,3,3,3,3,3,3,3,3,3,3,3,3,3,3,3,3,3,3,3,3,3,2,0
0,0,0,0,0,0,2,3,3,3,3,3,3,3,3,3,3,3,3,3,3,3,3,3,3,3,3,3,3,3,3,3,3,3,3,3,3,3,2,0,0
0,0,0,0,0,0,0,2,3,3,3,3,3,3,3,3,3,3,3,3,3,3,3,3,3,3,3,3,3,3,3,3,3,3,3,3,3,2,0,0,0
0,0,0,0,0,0,0,0,2,3,3,3,3,3,3,3,3,3,3,3,3,3,3,3,3,3,3,3,3,3,3,3,3,3,3,3,2,0,0,0,0
0,0,0,0,0,0,0,0,0,2,3,3,3,3,3,3,3,3,3,3,3,3,3,3,3,3,3,3,3,3,3,3,3,3,3,2,0,0,0,0,0
0,0,0,0,0,0,0,0,0,0,2,3,3,3,3,3,3,3,3,3,3,3,3,3,3,3,3,3,3,3,3,3,3,3,2,0,0,0,0,0,0
0,0,0,0,0,0,0,0,0,0,0,2,3,3,3,3,4,3,3,4,3,3,4,3,3,4,3,3,4,3,3,3,3,2,0,0,0,0,0,0,0
0,0,0,0,0,0,0,0,0,0,0,0,2,2,3,3,7,3,3,7,3,3,7,3,3,7,3,3,7,3,3,2,2,0,0,0,0,0,0,0,0
0,0,0,0,0,0,0,0,0,0,0,0,0,2,2,2,2,2,2,2,2,2,2,2,2,2,2,2,2,2,2,0,0,0,0,0,0,0,0,0,0
endlayer

layer
0,0,0,0,0,0,0,0,0,0,0,0,0,0,0,0,0,0,0,0,0,0,2,2,2,2,2,2,2,2,2,0,0,0,0,0,0,0,0,0,0
0,0,0,0,0,0,0,0,0,0,0,0,0,0,0,0,0,0,0,0,0,0,2,3,3,4,3,3,4,3,3,2,2,0,0,0,0,0,0,0,0
0,0,0,0,0,0,0,0,0,0,0,0,0,0,0,0,0,0,0,0,0,0,2,3,3,4,3,3,4,3,3,4,3,2,0,0,0,0,0,0,0
0,0,0,0,0,0,0,0,0,0,0,0,0,0,0,0,0,0,0,0,0,2,2,3,3,3,3,3,3,3,3,4,3,3,2,0,0,0,0,0,0
0,0,0,0,0,0,0,0,0,0,0,0,0,0,0,0,0,0,0,0,2,2,2,3,3,3,3,3,3,3,3,4,3,3,3,2,0,0,0,0,0
0,0,0,0,0,0,0,0,0,2,0,0,0,0,0,0,0,0,0,2,2,2,2,3,3,3,3,3,3,3,3,4,3,3,3,3,2,0,0,0,0
0,0,0,0,0,0,0,0,2,2,0,0,0,0,0,0,0,0,2,2,2,2,2,3,3,3,3,3,3,3,3,4,3,3,3,3,2,2,0,0,0
0,0,0,0,0,0,0,2,0,2,0,0,0,0,0,0,0,2,2,2,2,2,2,3,3,3,3,3,3,3,3,4,3,3,4,7,2,2,0,0,0
0,0,0,0,0,0,2,0,0,2,0,0,0,0,0,0,2,2,2,2,2,2,2,3,3,3,3,3,3,3,3,4,3,3,3,4,2,0,0,0,0
0,0,0,0,0,2,0,0,2,0,0,0,0,0,0,2,2,2,2,2,2,2,2,3,3,3,3,3,3,3,3,4,3,3,3,3,2,0,0,0,0
0,0,0,0,2,0,0,2,0,0,0,0,0,0,2,2,2,2,2,2,2,2,2,3,3,3,3,3,3,3,3,4,3,3,4,7,2,2,0,0,0
0,0,0,2,0,0,2,0,0,0,0,0,0,2,2,2,2,2,2,2,2,2,2,3,3,3,3,3,3,3,3,4,3,3,3,4,2,2,0,0,0
0,0,2,0,0,2,0,0,0,0,0,0,2,2,2,2,2,2,2,2,2,2,2,5,3,3,3,3,3,3,3,4,3,3,3,3,2,0,0,0,0
0,2,0,0,2,0,0,0,0,0,0,2,2,2,2,2,2,2,2,2,2,2,2,2,6,3,3,3,3,3,3,4,3,3,4,7,2,0,0,0,0
2,2,2,2,0,0,0,0,0,0,2,2,2,2,2,2,2,2,2,2,2,2,2,2,6,3,3,3,3,3,3,4,3,3,3,4,2,2,0,0,0
0,0,0,2,0,0,0,0,0,2,2,2,2,2,2,2,2,2,2,2,2,2,2,2,6,3,3,3,3,3,3,4,3,3,3,3,2,2,0,0,0
0,0,0,2,0,0,0,0,2,2,2,2,2,2,2,2,2,2,2,2,2,2,2,5,3,3,3,3,3,3,3,4,3,3,4,7,2,0,0,0,0
0,0,0,2,0,0,0,2,2,2,2,2,2,2,2,2,2,2,2,2,2,2,2,3,3,3,3,3,3,3,3,4,3,3,3,4,2,0,0,0,0
0,0,0,2,0,0,2,2,2,2,2,2,2,2,2,2,2,2,2,2,2,2,2,3,3,3,3,3,3,3,3,4,3,3,3,3,2,2,2,2,2
0,0,0,2,2,2,3,3,3,5,2,2,2,5,3,3,3,3,3,3,3,3,3,4,3,3,3,3,3,3,3,7,4,4,4,4,4,4,4,4,2
0,0,0,2,2,2,3,3,3,3,6,6,6,3,3,3,3,3,3,3,3,3,3,3,3,3,3,3,3,3,3,3,3,3,3,3,3,3,3,3,2
0,0,0,0,2,2,4,3,3,3,3,3,3,3,3,3,3,3,3,3,3,3,3,3,3,3,3,3,3,3,3,3,3,3,3,3,3,3,3,4,2
0,0,0,0,0,2,3,3,3,3,3,3,3,3,3,3,3,3,3,3,3,3,3,3,3,3,3,3,3,3,3,3,3,3,3,3,3,3,3,2,0
0,0,0,0,0,0,2,3,3,3,3,3,3,3,3,3,3,3,3,3,3,3,3,3,3,3,3,3,3,3,3,3,3,3,3,3,3,3,2,0,0
0,0,0,0,0,0,0,2,3,3,3,3,3,3,3,3,3,3,3,3,3,3,3,3,3,3,3,3,3,3,3,3,3,3,3,3,3,2,0,0,0
0,0,0,0,0,0,0,0,2,3,3,3,3,3,3,3,3,3,3,3,3,3,3,3,3,3,3,3,3,3,3,3,3,3,3,3,2,0,0,0,0
0,0,0,0,0,0,0,0,0,2,3,3,3,3,3,3,3,3,3,3,3,3,3,3,3,3,3,3,3,3,3,3,3,3,3,2,0,0,0,0,0
0,0,0,0,0,0,0,0,0,0,2,3,3,3,3,3,3,3,3,3,3,3,3,3,3,3,3,3,3,3,3,3,3,3,2,0,0,0,0,0,0
0,0,0,0,0,0,0,0,0,0,0,2,3,3,3,3,4,3,3,4,3,3,4,3,3,4,3,3,4,3,3,3,3,2,0,0,0,0,0,0,0
0,0,0,0,0,0,0,0,0,0,0,0,2,2,3,3,4,3,3,4,3,3,4,3,3,4,3,3,4,3,3,2,2,0,0,0,0,0,0,0,0
0,0,0,0,0,0,0,0,0,0,0,0,0,2,2,2,2,2,2,2,2,2,2,2,2,2,2,2,2,2,2,0,0,0,0,0,0,0,0,0,0
endlayer

layer
0,0,0,0,0,0,0,0,0,0,0,0,0,0,0,0,0,0,0,0,0,0,2,2,2,2,2,2,2,2,2,0,0,0,0,0,0,0,0,0,0
0,0,0,0,0,0,0,0,0,0,0,0,0,0,0,0,0,0,0,0,0,0,2,3,3,4,3,3,4,3,3,2,2,0,0,0,0,0,0,0,0
0,0,0,0,0,0,0,0,0,0,0,0,0,0,0,0,0,0,0,0,0,0,2,3,3,5,3,3,5,3,3,3,3,2,0,0,0,0,0,0,0
0,0,0,0,0,0,0,0,0,0,0,0,0,0,0,0,0,0,0,0,0,2,2,3,3,3,3,3,3,3,3,3,3,3,2,0,0,0,0,0,0
0,0,0,0,0,0,0,0,0,0,0,0,0,0,0,0,0,0,0,0,2,3,8,3,3,3,3,3,3,3,3,3,3,3,3,2,0,0,0,0,0
0,0,0,0,0,0,0,0,0,2,0,0,0,0,0,0,0,0,0,2,3,3,8,3,3,3,3,3,3,3,3,3,3,3,3,3,2,0,0,0,0
0,0,0,0,0,0,0,0,2,2,0,0,0,0,0,0,0,0,2,3,3,3,2,3,3,3,3,3,3,3,3,3,3,3,3,3,2,2,0,0,0
0,0,0,0,0,0,0,2,0,2,0,0,0,0,0,0,0,2,3,3,3,3,8,3,3,3,3,3,3,3,3,3,3,3,4,4,2,2,0,0,0
0,0,0,0,0,0,2,0,0,2,0,0,0,0,0,0,2,3,3,3,3,3,8,3,3,3,3,3,3,3,3,3,3,3,3,3,2,0,0,0,0
0,0,0,0,0,2,0,0,2,0,0,0,0,0,0,2,3,3,3,3,3,3,2,3,3,3,3,3,3,3,3,3,3,3,3,3,2,0,0,0,0
0,0,0,0,2,0,0,2,0,0,0,0,0,0,2,3,3,3,3,3,3,3,8,3,3,3,3,3,3,3,3,3,3,3,4,4,2,2,0,0,0
0,0,0,2,0,0,2,0,0,0,0,0,0,2,3,3,3,3,3,3,3,3,8,3,3,3,3,3,3,3,3,3,3,3,3,3,2,2,0,0,0
0,0,2,0,0,2,0,0,0,0,0,0,2,3,3,3,3,3,3,3,3,3,2,3,3,3,3,3,3,3,3,3,3,3,3,3,2,0,0,0,0
0,2,0,0,2,0,0,0,0,0,0,2,3,3,3,3,3,3,3,3,3,3,3,3,3,3,3,3,3,3,3,3,3,3,4,4,2,0,0,0,0
2,2,2,2,0,0,0,0,0,0,2,3,3,3,3,3,3,3,3,3,3,3,3,3,3,3,3,3,3,3,3,3,3,3,3,3,2,2,0,0,0
0,0,0,2,0,0,0,0,0,2,3,3,3,3,3,3,3,3,3,3,3,3,3,3,3,3,3,3,3,3,3,3,3,3,3,3,2,2,0,0,0
0,0,0,2,0,0,0,0,2,3,3,3,3,3,3,3,3,3,3,3,3,3,2,3,3,3,3,3,3,3,3,3,3,3,4,4,2,0,0,0,0
0,0,0,2,0,0,0,2,2,3,3,3,3,3,3,3,3,3,3,3,3,3,2,3,3,3,3,3,3,3,3,3,3,3,3,3,2,0,0,0,0
0,0,0,2,0,0,2,2,2,2,3,3,3,2,8,8,2,8,8,2,2,2,2,3,3,3,3,3,3,3,3,3,3,3,3,3,2,2,2,2,2
0,0,0,2,2,2,3,3,3,3,3,3,3,3,3,3,3,3,3,3,3,3,3,4,3,3,3,3,3,3,3,3,3,3,3,3,3,3,3,4,2
0,0,0,2,2,2,3,3,3,3,3,3,3,3,3,3,3,3,3,3,3,3,3,3,3,3,3,3,3,3,3,3,3,3,3,3,3,3,3,3,2
0,0,0,0,2,2,4,3,3,3,6,6,6,3,3,3,3,3,3,3,3,3,3,3,3,3,3,3,3,3,3,3,3,3,3,3,3,3,3,4,2
0,0,0,0,0,2,2,2,3,3,3,3,3,3,3,3,3,3,3,3,3,3,3,3,3,3,3,3,3,3,3,3,3,3,3,3,3,3,3,2,0
0,0,0,0,0,0,2,2,2,3,3,3,3,3,3,3,3,3,3,3,3,3,3,3,3,3,3,3,3,3,3,3,3,3,3,3,3,3,2,0,0
0,0,0,0,0,0,0,2,2,2,3,3,3,3,3,3,3,3,3,3,3,3,3,3,3,3,3,3,3,3,3,3,3,3,3,3,3,2,0,0,0
0,0,0,0,0,0,0,0,2,2,2,3,3,3,3,3,3,3,3,3,3,3,3,3,3,3,3,3,3,3,3,3,3,3,3,3,2,0,0,0,0
0,0,0,0,0,0,0,0,0,2,2,2,3,3,3,3,3,3,3,3,3,3,3,3,3,3,3,3,3,3,3,3,3,3,3,2,0,0,0,0,0
0,0,0,0,0,0,0,0,0,0,2,2,2,3,3,3,3,3,3,3,3,3,3,3,3,3,3,3,3,3,3,3,3,3,2,0,0,0,0,0,0
0,0,0,0,0,0,0,0,0,0,0,2,2,2,2,3,5,3,3,5,3,3,5,3,3,5,3,3,5,3,3,3,3,2,0,0,0,0,0,0,0
0,0,0,0,0,0,0,0,0,0,0,0,2,2,2,3,4,3,3,4,3,3,4,3,3,4,3,3,4,3,3,2,2,0,0,0,0,0,0,0,0
0,0,0,0,0,0,0,0,0,0,0,0,0,2,2,2,2,2,2,2,2,2,2,2,2,2,2,2,2,2,2,0,0,0,0,0,0,0,0,0,0
endlayer

layer
0,0,0,0,0,0,0,0,0,0,0,0,0,0,0,0,0,0,0,0,0,0,2,2,2,2,2,2,2,2,2,0,0,0,0,0,0,0,0,0,0
0,0,0,0,0,0,0,0,0,0,0,0,0,0,0,0,0,0,0,0,0,0,2,3,3,4,3,3,4,3,2,2,2,0,0,0,0,0,0,0,0
0,0,0,0,0,0,0,0,0,0,0,0,0,0,0,0,0,0,0,0,0,0,2,3,3,4,3,3,4,3,2,2,2,2,0,0,0,0,0,0,0
0,0,0,0,0,0,0,0,0,0,0,0,0,0,0,0,0,0,0,0,0,2,2,3,3,3,3,3,3,3,3,3,2,2,2,0,0,0,0,0,0
0,0,0,0,0,0,0,0,0,0,0,0,0,0,0,0,0,0,0,0,2,3,8,3,3,3,3,3,3,3,3,3,3,2,2,2,0,0,0,0,0
0,0,0,0,0,0,0,0,0,2,0,0,0,0,0,0,0,0,0,2,3,3,8,3,3,3,3,3,3,3,3,3,3,3,2,2,2,0,0,0,0
0,0,0,0,0,0,0,0,2,2,0,0,0,0,0,0,0,0,2,3,3,3,2,3,3,3,3,3,3,3,3,3,3,3,3,3,2,2,0,0,0
0,0,0,0,0,0,0,2,0,2,0,0,0,0,0,0,0,2,3,3,3,3,8,3,3,3,3,3,3,3,3,3,3,3,3,4,2,2,0,0,0
0,0,0,0,0,0,2,0,0,2,0,0,0,0,0,0,2,3,3,3,3,3,8,3,3,3,3,3,3,3,3,3,3,3,3,3,2,0,0,0,0
0,0,0,0,0,2,0,0,2,0,0,0,0,0,0,2,3,3,3,11,3,3,2,3,3,3,3,3,3,3,3,3,3,3,3,3,2,0,0,0,0
0,0,0,0,2,0,0,2,0,0,0,0,0,0,2,3,3,3,3,3,3,3,8,3,3,3,3,3,3,3,3,3,3,3,3,4,2,2,0,0,0
0,0,0,2,0,0,2,0,0,0,0,0,0,2,3,3,3,3,3,3,3,3,8,3,3,3,3,3,3,3,3,3,3,3,3,3,2,2,0,0,0
0,0,2,0,0,2,0,0,0,0,0,0,2,3,3,3,3,3,3,3,3,3,2,3,3,3,3,3,3,3,3,3,3,3,3,3,2,0,0,0,0
0,2,0,0,2,0,0,0,0,0,0,2,3,3,3,3,3,3,3,3,3,3,3,3,3,3,3,3,3,3,3,3,3,3,3,4,2,0,0,0,0
2,2,2,2,0,0,0,0,0,0,2,3,3,3,3,3,3,3,3,3,3,3,3,3,3,3,3,3,3,3,3,3,3,3,3,3,2,2,0,0,0
0,0,0,2,0,0,0,0,0,2,3,3,3,3,3,3,3,3,3,3,3,3,3,3,3,3,3,3,3,3,3,3,3,3,3,3,2,2,0,0,0
0,0,0,2,0,0,0,0,2,3,3,3,3,3,3,3,3,3,3,3,3,3,2,3,3,3,3,3,3,3,3,3,3,3,3,4,2,0,0,0,0
0,0,0,2,0,0,0,2,2,3,3,3,3,3,3,3,3,3,3,3,3,3,2,3,3,3,3,3,3,3,3,3,3,3,3,3,2,0,0,0,0
0,0,0,2,0,0,2,2,2,2,3,3,3,2,8,8,2,8,8,2,2,2,2,3,3,3,3,3,3,3,3,3,3,3,3,3,2,2,2,2,2
0,0,0,2,2,2,0,3,3,3,3,3,3,3,3,3,3,3,3,3,3,3,3,4,3,3,3,3,3,3,3,3,3,3,3,3,3,3,3,2,2
0,0,0,2,2,2,3,3,3,3,3,3,3,3,3,3,3,3,3,3,3,3,3,3,3,3,3,3,3,3,3,3,3,3,3,3,3,3,3,2,2
0,0,0,0,2,2,4,3,3,3,3,3,3,3,3,3,3,3,3,3,3,3,3,3,3,3,3,3,3,3,3,3,3,3,3,3,3,3,2,2,2
0,0,0,0,0,2,2,2,3,3,6,6,6,3,3,3,3,3,3,3,3,3,3,3,3,3,3,3,3,3,3,3,3,3,3,3,3,2,2,2,0
0,0,0,0,0,0,2,2,2,3,3,3,3,3,3,3,3,3,3,3,3,3,3,3,3,3,3,3,3,3,3,3,3,3,3,3,2,2,2,0,0
0,0,0,0,0,0,0,2,2,2,2,3,3,3,3,3,3,3,3,3,3,3,3,3,3,3,3,3,3,3,3,3,3,3,3,2,2,2,0,0,0
0,0,0,0,0,0,0,0,2,2,2,2,3,3,3,3,3,3,3,3,3,3,3,3,3,3,3,3,3,3,3,3,3,3,2,2,2,0,0,0,0
0,0,0,0,0,0,0,0,0,2,2,2,2,3,3,3,3,3,3,3,3,3,3,3,3,3,3,3,3,3,3,3,3,2,2,2,0,0,0,0,0
0,0,0,0,0,0,0,0,0,0,2,2,2,3,3,3,3,3,3,3,3,3,3,3,3,3,3,3,3,3,3,3,2,2,2,0,0,0,0,0,0
0,0,0,0,0,0,0,0,0,0,0,2,2,2,2,3,4,3,3,4,3,3,4,3,3,4,3,3,4,3,2,2,2,2,0,0,0,0,0,0,0
0,0,0,0,0,0,0,0,0,0,0,0,2,2,2,3,4,3,3,4,3,3,4,3,3,4,3,3,4,3,2,2,2,0,0,0,0,0,0,0,0
0,0,0,0,0,0,0,0,0,0,0,0,0,2,2,2,2,2,2,2,2,2,2,2,2,2,2,2,2,2,2,0,0,0,0,0,0,0,0,0,0
endlayer

layer
0,0,0,0,0,0,0,0,0,0,0,0,0,0,0,0,0,0,0,0,0,0,0,0,0,0,0,0,0,0,0,0,0,0,0,0,0,0,0,0,0
0,0,0,0,0,0,0,0,0,0,0,0,0,0,0,0,0,0,0,0,0,0,0,2,2,2,2,2,2,2,0,0,0,0,0,0,0,0,0,0,0
0,0,0,0,0,0,0,0,0,0,0,0,0,0,0,0,0,0,0,0,0,0,2,3,3,4,3,3,4,3,2,2,0,0,0,0,0,0,0,0,0
0,0,0,0,0,0,0,0,0,0,0,0,0,0,0,0,0,0,0,0,0,2,2,3,3,3,3,3,3,3,3,3,2,0,0,0,0,0,0,0,0
0,0,0,0,0,0,0,0,0,0,0,0,0,0,0,0,0,0,0,0,2,3,8,3,3,3,3,3,3,3,3,3,3,2,0,0,0,0,0,0,0
0,0,0,0,0,0,0,0,0,2,0,0,0,0,0,0,0,0,0,2,3,3,8,3,3,3,3,3,3,3,3,3,3,3,2,0,0,0,0,0,0
0,0,0,0,0,0,0,0,2,2,0,0,0,0,0,0,0,0,2,3,3,3,2,3,3,3,3,3,3,3,3,3,3,3,3,2,4,0,0,0,0
0,0,0,0,0,0,0,2,0,2,0,0,0,0,0,0,0,2,3,3,3,3,8,3,3,3,3,3,3,3,3,3,3,3,3,2,4,0,0,0,0
0,0,0,0,0,0,2,0,0,2,0,0,0,0,0,0,2,3,3,3,3,3,8,3,3,3,3,3,3,3,3,3,3,3,3,2,0,0,0,0,0
0,0,0,0,0,2,0,0,2,0,0,0,0,0,0,2,3,3,3,3,3,3,2,3,3,3,3,3,3,3,3,3,3,3,3,2,0,0,0,0,0
0,0,0,0,2,0,0,2,0,0,0,0,0,0,2,3,3,3,3,3,3,3,8,3,3,3,3,3,3,3,3,3,3,3,3,2,4,0,0,0,0
0,0,0,2,0,0,2,0,0,0,0,0,0,2,3,3,3,3,3,3,3,3,8,3,3,3,3,3,3,3,3,3,3,3,3,2,4,0,0,0,0
0,0,2,0,0,2,0,0,0,0,0,0,2,3,3,3,3,3,3,3,3,3,2,3,3,3,3,3,3,3,3,3,3,3,3,2,0,0,0,0,0
0,2,0,0,2,0,0,0,0,0,0,2,3,3,3,3,3,3,3,3,3,3,3,3,3,3,3,3,3,3,3,3,3,3,3,2,0,0,0,0,0
2,2,2,2,0,0,0,0,0,0,2,3,3,3,3,3,3,3,3,3,3,3,3,3,3,3,3,3,3,3,3,3,3,3,3,2,4,0,0,0,0
0,0,0,2,0,0,0,0,0,2,3,3,3,3,3,3,3,3,3,3,3,3,3,3,3,3,3,3,3,3,3,3,3,3,3,2,4,0,0,0,0
0,0,0,2,0,0,0,0,2,3,3,3,3,3,3,3,3,3,3,3,3,3,2,3,3,3,3,3,3,3,3,3,3,3,3,2,0,0,0,0,0
0,0,0,2,0,0,0,2,2,3,3,3,3,3,3,3,3,3,3,3,3,3,2,3,3,3,3,3,3,3,3,3,3,3,3,2,0,0,0,0,0
0,0,0,2,0,0,2,2,2,2,3,3,3,2,8,8,2,8,8,2,2,2,2,3,3,3,3,3,3,3,3,3,3,3,3,2,0,0,0,0,0
0,0,0,2,2,2,2,3,3,3,3,3,3,3,3,3,3,3,3,3,3,3,3,4,3,3,3,3,3,3,3,3,3,3,3,2,2,2,2,4,0
0,0,0,0,2,2,2,3,3,3,3,3,3,3,3,3,3,3,3,3,3,3,3,3,3,3,3,3,3,3,3,3,3,3,3,3,3,3,2,4,0
0,0,0,0,0,2,2,3,3,3,3,3,3,3,3,3,3,3,3,3,3,3,3,3,3,3,3,3,3,3,3,3,3,3,3,3,3,3,2,0,0
0,0,0,0,0,0,2,2,3,3,3,3,3,3,3,3,3,3,3,3,3,3,3,3,3,3,3,3,3,3,3,3,3,3,3,3,3,2,0,0,0
0,0,0,0,0,0,0,2,2,3,6,6,6,3,3,3,3,3,3,3,3,3,3,3,3,3,3,3,3,3,3,3,3,3,3,3,2,0,0,0,0
0,0,0,0,0,0,0,0,2,2,2,2,2,6,3,3,3,3,3,3,3,3,3,3,3,3,3,3,3,3,3,3,3,3,3,2,0,0,0,0,0
0,0,0,0,0,0,0,0,0,2,2,2,2,6,3,3,3,3,3,3,3,3,3,3,3,3,3,3,3,3,3,3,3,3,2,0,0,0,0,0,0
0,0,0,0,0,0,0,0,0,0,2,2,2,6,3,3,3,3,3,3,3,3,3,3,3,3,3,3,3,3,3,3,3,2,0,0,0,0,0,0,0
0,0,0,0,0,0,0,0,0,0,0,2,2,3,3,3,3,3,3,3,3,3,3,3,3,3,3,3,3,3,3,3,2,0,0,0,0,0,0,0,0
0,0,0,0,0,0,0,0,0,0,0,0,2,2,2,3,4,3,3,4,3,3,4,3,3,4,3,3,4,3,2,2,0,0,0,0,0,0,0,0,0
0,0,0,0,0,0,0,0,0,0,0,0,0,2,2,2,2,2,2,2,2,2,2,2,2,2,2,2,2,2,0,0,0,0,0,0,0,0,0,0,0
0,0,0,0,0,0,0,0,0,0,0,0,0,0,0,0,0,0,0,0,0,0,0,0,0,0,0,0,0,0,0,0,0,0,0,0,0,0,0,0,0
endlayer

layer
0,0,0,0,0,0,0,0,0,0,0,0,0,0,0,0,0,0,0,0,0,0,0,0,0,0,0,0,0,0,0,0,0,0,0,0,0,0,0,0,0
0,0,0,0,0,0,0,0,0,0,0,0,0,0,0,0,0,0,0,0,0,0,0,2,2,2,2,2,2,2,0,0,0,0,0,0,0,0,0,0,0
0,0,0,0,0,0,0,0,0,0,0,0,0,0,0,0,0,0,0,0,0,0,2,3,3,4,3,3,4,3,2,2,0,0,0,0,0,0,0,0,0
0,0,0,0,0,0,0,0,0,0,0,0,0,0,0,0,0,0,0,0,0,2,2,3,3,3,3,3,3,3,3,3,2,0,0,0,0,0,0,0,0
0,0,0,0,0,0,0,0,0,0,0,0,0,0,0,0,0,0,0,0,2,3,8,3,3,3,3,3,3,3,3,3,3,2,0,0,0,0,0,0,0
0,0,0,0,0,0,0,0,0,2,0,0,0,0,0,0,0,0,0,2,3,3,8,3,3,3,3,3,3,3,3,3,3,3,2,0,0,0,0,0,0
0,0,0,0,0,0,0,0,2,2,0,0,0,0,0,0,0,0,2,3,3,3,2,3,3,3,3,3,3,3,3,3,3,3,3,2,4,0,0,0,0
0,0,0,0,0,0,0,2,0,2,0,0,0,0,0,0,0,2,3,3,3,3,8,3,3,3,3,3,3,3,3,3,3,3,3,2,4,0,0,0,0
0,0,0,0,0,0,2,0,0,2,0,0,0,0,0,0,2,3,3,3,3,3,8,3,3,3,3,3,3,3,3,3,3,3,3,2,0,0,0,0,0
0,0,0,0,0,2,0,0,2,0,0,0,0,0,0,2,3,3,3,3,3,3,2,3,3,3,3,3,3,3,3,3,3,3,3,2,0,0,0,0,0
0,0,0,0,2,0,0,2,0,0,0,0,0,0,2,3,3,3,3,3,3,3,8,3,3,3,3,3,3,3,3,3,3,3,3,2,4,0,0,0,0
0,0,0,2,0,0,2,0,0,0,0,0,0,2,3,3,3,3,3,3,3,3,8,3,3,3,3,3,3,3,3,3,3,3,3,2,4,0,0,0,0
0,0,2,0,0,2,0,0,0,0,0,0,2,3,3,3,3,3,3,3,3,3,2,3,3,3,3,3,3,3,3,3,3,3,3,2,0,0,0,0,0
0,2,0,0,2,0,0,0,0,0,0,2,3,3,3,3,3,3,3,3,3,3,3,3,3,3,3,3,3,3,3,3,3,3,3,2,0,0,0,0,0
2,2,2,2,0,0,0,0,0,0,2,3,3,3,3,3,3,3,3,3,3,3,3,3,3,3,3,3,3,3,3,3,3,3,3,2,4,0,0,0,0
0,0,0,2,0,0,0,0,0,2,3,3,3,3,3,3,3,3,3,3,3,3,3,3,3,3,3,3,3,3,3,3,3,3,3,2,4,0,0,0,0
0,0,0,2,0,0,0,0,2,3,3,3,3,3,3,3,3,3,3,3,3,3,2,3,3,3,3,3,3,3,3,3,3,3,3,2,0,0,0,0,0
0,0,0,2,0,0,0,2,2,3,3,3,3,3,3,3,3,3,3,3,3,3,2,3,3,3,3,3,3,3,3,3,3,3,3,2,0,0,0,0,0
0,0,0,2,0,0,2,2,2,2,3,3,3,2,8,8,2,8,8,2,2,2,2,3,3,3,3,3,3,3,3,3,3,3,3,2,0,0,0,0,0
0,0,0,2,2,2,2,3,3,3,3,3,3,3,3,3,3,3,3,3,3,3,3,4,3,3,3,3,3,3,3,3,3,3,3,2,2,2,2,4,0
0,0,0,0,2,2,2,3,3,3,3,3,3,3,3,3,3,3,3,3,3,3,3,3,3,3,3,3,3,3,3,3,3,3,3,3,3,3,2,4,0
0,0,0,0,0,2,2,3,3,3,3,3,3,3,3,3,3,3,3,3,3,3,3,3,3,3,3,3,3,3,3,3,3,3,3,3,3,3,2,0,0
0,0,0,0,0,0,2,2,3,3,3,3,3,3,3,3,3,3,3,3,3,3,3,3,3,3,3,3,3,3,3,3,3,3,3,3,3,2,0,0,0
0,0,0,0,0,0,0,2,2,3,3,3,3,3,3,3,3,3,3,3,3,3,3,3,3,3,3,3,3,3,3,3,3,3,3,3,2,0,0,0,0
0,0,0,0,0,0,0,0,2,3,3,3,3,3,6,3,3,3,3,3,3,3,3,3,3,3,3,3,3,3,3,3,3,3,3,2,0,0,0,0,0
0,0,0,0,0,0,0,0,0,2,3,3,3,3,6,3,3,3,3,3,3,3,3,3,3,3,3,3,3,3,3,3,3,3,2,0,0,0,0,0,0
0,0,0,0,0,0,0,0,0,0,2,3,3,3,6,3,3,3,3,3,3,3,3,3,3,3,3,3,3,3,3,3,3,2,0,0,0,0,0,0,0
0,0,0,0,0,0,0,0,0,0,0,2,3,3,3,3,3,3,3,3,3,3,3,3,3,3,3,3,3,3,3,3,2,0,0,0,0,0,0,0,0
0,0,0,0,0,0,0,0,0,0,0,0,2,2,2,3,4,3,3,4,0,3,4,3,3,4,3,3,4,3,2,2,0,0,0,0,0,0,0,0,0
0,0,0,0,0,0,0,0,0,0,0,0,0,2,2,2,2,2,2,2,2,2,2,2,2,2,2,2,2,2,0,0,0,0,0,0,0,0,0,0,0
0,0,0,0,0,0,0,0,0,0,0,0,0,0,0,0,0,0,0,0,0,0,0,0,0,0,0,0,0,0,0,0,0,0,0,0,0,0,0,0,0
endlayer

layer
0,0,0,0,0,0,0,0,0,0,0,0,0,0,0,0,0,0,0,0,0,0,2,2,2,2,2,2,2,2,2,0,0,0,0,0,0,0,0,0,0
0,0,0,0,0,0,0,0,0,0,0,0,0,0,0,0,0,0,0,0,0,0,2,3,3,4,3,3,4,3,2,2,2,0,0,0,0,0,0,0,0
0,0,0,0,0,0,0,0,0,0,0,0,0,0,0,0,0,0,0,0,0,0,2,3,3,4,3,3,4,3,2,2,2,2,0,0,0,0,0,0,0
0,0,0,0,0,0,0,0,0,0,0,0,0,0,0,0,0,0,0,0,0,2,2,3,3,3,3,3,3,3,3,3,2,2,2,0,0,0,0,0,0
0,0,0,0,0,0,0,0,0,0,0,0,0,0,0,0,0,0,0,0,2,3,8,3,3,3,3,3,3,3,3,3,3,2,2,2,0,0,0,0,0
0,0,0,0,0,0,0,0,0,2,0,0,0,0,0,0,0,0,0,2,3,3,8,3,3,3,3,3,3,3,3,3,3,3,2,2,2,0,0,0,0
0,0,0,0,0,0,0,0,2,2,0,0,0,0,0,0,0,0,2,3,3,3,2,3,3,3,3,3,3,3,3,3,3,3,3,3,2,2,0,0,0
0,0,0,0,0,0,0,2,0,2,0,0,0,0,0,0,0,2,3,3,3,3,8,3,3,3,3,3,3,3,3,3,3,3,3,3,2,2,0,0,0
0,0,0,0,0,0,2,0,0,2,0,0,0,0,0,0,2,3,3,3,3,3,8,3,3,3,3,3,3,3,3,3,3,3,3,3,2,0,0,0,0
0,0,0,0,0,2,0,0,2,0,0,0,0,0,0,2,3,3,3,3,3,3,2,3,3,3,3,3,3,3,3,3,3,3,3,3,2,0,0,0,0
0,0,0,0,2,0,0,2,0,0,0,0,0,0,2,3,3,3,3,3,3,3,8,3,3,3,3,3,3,3,3,3,3,3,3,3,2,2,0,0,0
0,0,0,2,0,0,2,0,0,0,0,0,0,2,3,3,3,3,3,3,3,3,8,3,3,3,3,3,3,3,3,3,3,3,3,3,2,2,0,0,0
0,0,2,0,0,2,0,0,0,0,0,0,2,3,3,3,3,3,3,3,3,3,2,3,3,3,3,3,3,3,3,3,3,3,3,3,2,0,0,0,0
0,2,0,0,2,0,0,0,0,0,0,2,3,3,3,3,3,3,3,3,3,3,3,3,3,3,3,3,3,3,3,3,3,3,3,3,2,0,0,0,0
2,2,2,2,0,0,0,0,0,0,2,3,3,3,3,3,3,3,3,3,3,3,3,3,3,3,3,3,3,3,3,3,3,3,3,3,2,2,0,0,0
0,0,0,2,0,0,0,0,0,2,3,3,3,3,3,3,3,3,3,3,3,3,3,3,3,3,3,3,3,3,3,3,3,3,3,3,2,2,0,0,0
0,0,0,2,0,0,0,0,2,3,3,3,3,3,3,3,3,3,3,3,3,3,2,3,3,3,3,3,3,3,3,3,3,3,3,3,2,0,0,0,0
0,0,0,2,0,0,0,2,2,3,3,3,3,3,3,3,3,3,3,3,3,3,2,3,3,3,3,3,3,3,3,3,3,3,3,3,2,0,0,0,0
0,0,0,2,0,0,2,2,2,2,3,3,3,2,8,8,2,8,8,2,2,2,2,3,3,3,3,3,3,3,3,3,3,3,3,3,2,2,2,2,2
0,0,0,2,2,2,3,3,3,3,3,3,3,3,3,3,3,3,3,3,3,3,3,4,3,3,3,3,3,3,3,3,3,3,3,3,3,3,3,2,2
0,0,0,2,2,2,3,3,3,3,3,3,3,3,3,3,3,3,3,3,3,3,3,3,3,3,3,3,3,3,3,3,3,3,3,3,3,3,3,2,2
0,0,0,0,2,2,4,3,3,3,3,3,3,3,3,3,3,3,3,3,3,3,3,3,3,3,3,3,3,3,3,3,3,3,3,3,3,3,2,2,2
0,0,0,0,0,2,2,2,3,3,3,3,3,3,3,3,3,3,3,3,3,3,3,3,3,3,3,3,3,3,3,3,3,3,3,3,3,2,2,2,0
0,0,0,0,0,0,2,2,2,3,3,3,3,3,3,3,3,3,3,3,3,3,3,3,3,3,3,3,3,3,3,3,3,3,3,3,2,2,2,0,0
0,0,0,0,0,0,0,2,2,3,3,3,3,3,3,6,3,3,3,3,3,3,3,3,3,3,3,3,3,3,3,3,3,3,3,2,2,2,0,0,0
0,0,0,0,0,0,0,0,2,2,3,3,3,3,3,6,3,3,3,3,3,3,3,3,3,3,3,3,3,3,3,3,3,3,2,2,2,0,0,0,0
0,0,0,0,0,0,0,0,0,2,2,3,3,3,3,6,3,3,3,3,3,3,3,3,3,3,3,3,3,3,3,3,3,2,2,2,0,0,0,0,0
0,0,0,0,0,0,0,0,0,0,2,2,3,3,3,3,3,3,3,3,3,3,3,3,3,3,3,3,3,3,3,3,2,2,2,0,0,0,0,0,0
0,0,0,0,0,0,0,0,0,0,0,2,2,2,2,3,4,3,3,4,3,3,4,3,3,4,3,3,4,3,2,2,2,2,0,0,0,0,0,0,0
0,0,0,0,0,0,0,0,0,0,0,0,2,2,2,3,4,3,3,4,3,3,4,3,3,4,3,3,4,3,2,2,2,0,0,0,0,0,0,0,0
0,0,0,0,0,0,0,0,0,0,0,0,0,2,2,2,2,2,2,2,2,2,2,2,2,2,2,2,2,2,2,0,0,0,0,0,0,0,0,0,0
endlayer

layer
0,0,0,0,0,0,0,0,0,0,0,0,0,0,0,0,0,0,0,0,0,0,2,2,2,2,2,2,2,2,2,0,0,0,0,0,0,0,0,0,0
0,0,0,0,0,0,0,0,0,0,0,0,0,0,0,0,0,0,0,0,0,0,2,3,0,4,0,0,4,0,0,2,2,0,0,0,0,0,0,0,0
0,0,0,0,0,0,0,0,0,0,0,0,0,0,0,0,0,0,0,0,0,0,2,3,0,5,0,0,5,0,0,0,0,2,0,0,0,0,0,0,0
0,0,0,0,0,0,0,0,0,0,0,0,0,0,0,0,0,0,0,0,0,2,2,3,0,0,0,0,0,0,0,0,0,0,2,0,0,0,0,0,0
0,0,0,0,0,0,0,0,0,0,0,0,0,0,0,0,0,0,0,0,2,3,8,3,0,0,0,0,0,0,0,0,0,0,0,2,0,0,0,0,0
0,0,0,0,0,0,0,0,0,2,0,0,0,0,0,0,0,0,0,2,3,3,8,3,0,0,0,0,0,0,0,0,0,0,0,0,2,0,0,0,0
0,0,0,0,0,0,0,0,2,2,0,0,0,0,0,0,0,0,2,3,3,3,2,3,0,0,0,0,0,0,0,0,0,0,0,0,2,2,0,0,0
0,0,0,0,0,0,0,2,0,2,0,0,0,0,0,0,0,2,3,3,3,3,8,3,0,0,0,0,0,0,0,0,0,0,0,0,2,2,0,0,0
0,0,0,0,0,0,2,0,0,2,0,0,0,0,0,0,2,3,3,3,3,3,8,3,0,0,0,0,0,0,0,0,0,0,0,0,2,0,0,0,0
0,0,0,0,0,2,0,0,2,0,0,0,0,0,0,2,3,3,3,3,3,3,2,3,0,0,0,0,0,0,0,0,0,0,0,0,2,0,0,0,0
0,0,0,0,2,0,0,2,0,0,0,0,0,0,2,3,3,3,3,3,3,3,8,3,0,0,0,0,0,0,0,0,0,0,0,0,2,2,0,0,0
0,0,0,2,0,0,2,0,0,0,0,0,0,2,3,3,3,3,3,3,3,3,8,3,0,0,0,0,0,0,0,0,0,0,0,0,2,2,0,0,0
0,0,2,0,0,2,0,0,0,0,0,0,2,3,3,3,3,3,3,3,3,3,2,3,0,0,0,0,0,0,0,0,0,0,0,0,2,0,0,0,0
0,2,0,0,2,0,0,0,0,0,0,2,3,3,3,3,3,3,3,3,3,3,3,3,0,0,0,0,0,0,0,0,0,0,0,0,2,0,0,0,0
2,2,2,2,0,0,0,0,0,0,2,3,3,3,3,3,3,3,3,3,3,3,3,3,0,0,0,0,0,0,0,0,0,0,0,0,2,2,0,0,0
0,0,0,2,0,0,0,0,0,2,3,3,3,3,3,3,3,3,3,3,3,3,3,3,0,0,0,0,0,0,0,0,0,0,0,0,2,2,0,0,0
0,0,0,2,0,0,0,0,2,3,3,3,3,3,3,3,3,3,3,3,3,3,2,3,0,0,0,0,0,0,0,0,0,0,0,0,2,0,0,0,0
0,0,0,2,0,0,0,2,2,3,3,3,3,3,3,3,3,3,3,3,3,3,2,3,0,0,0,0,0,0,0,0,0,0,0,0,2,0,0,0,0
0,0,0,2,0,0,2,2,2,2,3,3,3,2,8,8,2,8,8,2,2,2,2,3,0,0,0,0,0,0,0,0,0,0,0,0,2,2,2,2,2
0,0,0,2,2,2,3,3,3,3,3,3,3,3,3,3,3,3,3,3,3,3,3,4,0,0,0,0,0,0,0,0,0,0,0,0,0,0,0,4,2
0,0,0,2,2,2,3,3,3,3,0,0,0,0,0,0,0,0,0,0,0,0,0,0,0,0,0,0,0,0,0,0,0,0,0,0,0,0,0,0,2
0,0,0,0,2,2,4,3,3,3,0,0,0,0,0,0,0,0,0,0,0,0,0,0,0,0,0,0,0,0,0,0,0,0,0,0,0,0,0,0,2
0,0,0,0,0,2,2,2,3,0,0,0,0,0,0,0,0,0,0,0,0,0,0,0,0,0,0,0,0,0,0,0,0,0,0,0,0,0,0,2,0
0,0,0,0,0,0,2,2,2,0,0,0,0,0,0,0,0,0,0,0,0,0,0,0,0,0,0,0,0,0,0,0,0,0,0,0,0,4,2,0,0
0,0,0,0,0,0,0,2,2,0,0,0,0,0,0,0,6,6,6,6,6,6,6,6,6,6,6,6,0,0,0,0,0,0,4,0,0,2,0,0,0
0,0,0,0,0,0,0,0,2,2,0,0,0,0,0,0,6,6,6,6,6,6,6,6,6,6,6,6,0,0,0,0,0,0,0,4,2,0,0,0,0
0,0,0,0,0,0,0,0,0,2,2,0,0,0,0,0,6,6,6,6,6,6,6,6,6,6,6,6,0,0,0,0,0,0,0,2,0,0,0,0,0
0,0,0,0,0,0,0,0,0,0,2,2,0,0,0,0,0,0,0,0,0,0,0,0,0,0,0,0,0,0,0,0,0,4,2,0,0,0,0,0,0
0,0,0,0,0,0,0,0,0,0,0,2,2,2,2,0,5,0,0,5,0,0,5,0,0,5,0,0,5,0,0,0,0,2,0,0,0,0,0,0,0
0,0,0,0,0,0,0,0,0,0,0,0,2,2,2,0,4,0,0,4,0,0,4,0,0,4,0,0,4,0,0,2,2,0,0,0,0,0,0,0,0
0,0,0,0,0,0,0,0,0,0,0,0,0,2,2,2,2,2,2,2,2,2,2,2,2,2,2,2,2,2,2,0,0,0,0,0,0,0,0,0,0
endlayer

layer
0,0,0,0,0,0,0,0,0,0,0,0,0,0,0,0,0,0,0,0,0,0,2,2,2,2,2,2,2,2,2,4,4,4,0,0,0,0,0,0,0
0,0,0,0,0,0,0,0,0,0,0,0,0,0,0,0,0,0,0,0,0,0,2,3,0,4,0,0,4,0,0,2,2,4,4,4,0,0,0,0,0
0,0,0,0,0,0,0,0,0,0,0,0,0,0,0,0,0,0,0,0,0,0,2,3,0,4,0,0,4,0,0,0,0,2,4,4,4,0,0,0,0
0,0,0,0,0,0,0,0,0,0,0,0,0,0,0,0,0,0,0,0,0,2,2,3,0,0,0,0,0,0,0,0,0,0,2,4,4,4,0,0,0
0,0,0,0,0,0,0,0,0,0,0,0,0,0,0,0,0,0,0,0,2,2,2,3,0,0,0,0,0,0,0,0,0,0,0,2,4,4,4,0,0
0,0,0,0,0,0,0,0,0,2,0,0,0,0,0,0,0,0,0,2,2,2,2,3,0,0,0,0,0,0,0,0,0,0,0,4,2,4,4,4,0
0,0,0,0,0,0,0,0,2,2,0,0,0,0,0,0,0,0,2,2,2,2,2,3,0,0,0,0,0,0,0,0,0,0,0,0,2,2,4,4,0
0,0,0,0,0,0,0,2,0,2,0,0,0,0,0,0,0,2,2,2,2,2,2,3,0,0,0,0,0,0,0,0,0,0,0,0,2,2,4,4,0
0,0,0,0,0,0,2,0,0,2,0,0,0,0,0,0,2,2,2,2,2,2,2,3,0,0,0,0,0,0,0,0,0,0,0,0,2,4,4,4,0
0,0,0,0,0,2,0,0,2,0,0,0,0,0,0,2,2,2,2,2,2,2,2,3,0,0,0,0,0,0,0,0,0,0,0,4,2,4,4,4,0
0,0,0,0,2,0,0,2,0,0,0,0,0,0,2,2,2,2,2,2,2,2,2,3,0,0,0,0,0,0,0,0,0,0,0,0,2,2,4,4,0
0,0,0,2,0,0,2,0,0,0,0,0,0,2,2,2,2,2,2,2,2,2,2,3,0,0,0,0,0,0,0,0,0,0,0,0,2,2,4,4,0
0,0,2,0,0,2,0,0,0,0,0,0,2,2,2,2,2,2,2,2,2,2,2,3,0,0,0,0,0,0,0,0,0,0,0,0,2,4,4,4,0
0,2,0,0,2,0,0,0,0,0,0,2,2,2,2,2,2,2,2,2,2,2,2,3,0,0,0,0,0,0,0,0,0,0,0,4,2,4,4,4,0
2,2,2,2,0,0,0,0,0,0,2,2,2,2,2,2,2,2,2,2,2,2,2,3,0,0,0,0,0,0,0,0,0,0,0,0,2,2,4,4,0
0,0,0,2,0,0,0,0,0,2,2,2,2,2,2,2,2,2,2,2,2,2,2,3,0,0,0,0,0,0,0,0,0,0,0,0,2,2,4,4,0
0,0,0,2,0,0,0,0,2,2,2,2,2,2,2,2,2,2,2,2,2,2,2,3,0,0,0,0,0,0,0,0,0,0,0,0,2,4,4,4,4
0,0,0,2,0,0,0,2,2,2,2,2,2,2,2,2,2,2,2,2,2,2,2,3,0,0,0,0,0,0,0,0,0,0,0,0,2,4,4,4,4
0,0,0,2,0,0,2,2,2,2,2,2,2,2,2,2,2,2,2,2,2,2,2,3,0,0,0,0,0,0,0,0,0,0,0,0,2,2,2,2,2
0,0,0,2,2,2,3,3,3,3,3,3,3,3,3,3,3,3,3,3,3,3,3,4,0,0,0,0,0,0,0,0,0,0,0,0,0,0,0,4,2
0,0,0,2,2,2,3,3,3,3,0,0,0,0,0,0,0,0,0,0,0,0,0,0,0,0,0,0,0,0,0,0,0,0,0,0,0,0,0,0,2
0,0,0,0,2,2,4,3,3,3,0,0,0,0,0,0,0,0,0,0,0,0,0,0,0,0,0,0,0,0,0,0,0,0,0,0,0,0,0,0,2
0,0,0,0,0,2,0,0,0,0,0,0,0,0,0,0,0,0,0,0,0,0,0,0,0,0,0,0,0,0,0,0,0,0,0,0,4,0,0,2,4
0,0,0,0,0,0,2,0,0,0,0,0,0,0,0,0,0,0,0,0,0,0,0,0,0,0,0,0,0,0,0,0,0,4,0,0,0,4,2,4,4
0,0,0,0,0,0,0,2,0,0,0,0,0,0,0,0,0,0,0,0,0,0,0,0,0,0,0,0,6,0,0,0,0,0,4,0,0,2,4,4,4
0,0,0,0,0,0,0,0,2,0,0,0,0,0,0,0,0,0,0,0,0,0,0,0,0,0,0,0,6,0,0,0,0,0,0,4,2,4,4,4,0
0,0,0,0,0,0,0,0,0,2,0,0,0,0,0,0,0,0,0,0,0,0,0,0,0,0,0,0,6,0,0,0,4,0,0,2,4,4,4,0,0
0,0,0,0,0,0,0,0,0,0,2,0,0,0,0,0,0,0,0,0,0,0,0,0,0,0,0,0,0,0,0,0,0,4,2,4,4,4,0,0,0
0,0,0,0,0,0,0,0,0,0,0,2,0,0,0,0,4,0,0,4,0,0,4,0,0,4,0,0,4,0,0,0,0,2,4,4,4,0,0,0,0
0,0,0,0,0,0,0,0,0,0,0,0,2,2,0,0,4,0,0,4,0,0,4,0,0,4,0,0,4,0,0,2,2,4,4,4,0,0,0,0,0
0,0,0,0,0,0,0,0,0,0,0,0,0,2,2,2,2,2,2,2,2,2,2,2,2,2,2,2,2,2,2,4,4,4,4,0,0,0,0,0,0
endlayer

layer
0,0,0,0,0,0,0,0,0,0,0,0,0,0,0,0,0,0,0,0,0,0,2,2,2,2,2,2,2,2,2,4,4,0,0,0,0,0,0,0,0
0,0,0,0,0,0,0,0,0,0,0,0,0,0,0,0,0,0,0,0,0,0,2,4,0,7,0,0,7,0,0,2,2,4,4,0,0,0,0,0,0
0,0,0,0,0,0,0,0,0,0,0,0,0,0,0,0,0,0,0,0,0,0,2,4,0,4,0,0,4,0,0,0,0,2,4,0,0,0,0,0,0
0,0,0,0,0,0,0,0,0,0,0,0,0,0,0,0,0,0,0,0,0,2,0,4,0,0,0,0,0,0,0,0,0,0,2,4,4,0,0,0,0
0,0,0,0,0,0,0,0,0,0,0,0,0,0,0,0,0,0,0,0,2,0,0,4,0,0,0,0,0,0,0,0,0,0,0,2,4,0,0,0,0
0,0,0,0,0,0,0,0,0,2,0,0,0,0,0,0,0,0,0,2,0,0,0,4,0,0,0,0,0,0,0,0,0,0,4,4,2,4,4,0,0
0,0,0,0,0,0,0,0,2,2,0,0,0,0,0,0,0,0,2,0,0,0,0,4,0,0,0,0,0,0,0,0,0,0,0,0,2,2,4,0,0
0,0,0,0,0,0,0,2,0,2,0,0,0,0,0,0,0,2,0,0,0,0,0,4,0,0,0,0,0,0,0,0,0,0,0,0,2,2,4,0,0
0,0,0,0,0,0,2,0,0,2,0,0,0,0,0,0,2,0,0,0,0,0,0,4,0,0,0,0,0,0,0,0,0,0,0,0,2,4,4,0,0
0,0,0,0,0,2,0,0,2,0,0,0,0,0,0,2,0,0,0,0,0,0,0,4,0,0,0,0,0,0,0,0,0,0,4,4,2,4,4,0,0
0,0,0,0,2,0,0,2,0,0,0,0,0,0,2,0,0,0,0,0,0,0,0,4,0,0,0,0,0,0,0,0,0,0,0,0,2,2,4,0,0
0,0,0,2,0,0,2,0,0,0,0,0,0,2,0,0,0,0,0,0,0,0,0,4,0,0,0,0,0,0,0,0,0,0,0,0,2,2,4,0,0
0,0,2,0,0,2,0,0,0,0,0,0,2,0,0,0,0,0,0,0,0,0,0,4,0,0,0,0,0,0,0,0,0,0,0,0,2,4,4,0,0
0,2,0,0,2,0,0,0,0,0,0,2,0,0,0,0,0,0,0,0,0,0,0,4,0,0,0,0,0,0,0,0,0,0,4,4,2,4,4,0,0
2,2,2,2,0,0,0,0,0,0,2,0,0,0,0,0,0,0,0,0,0,0,0,4,0,0,0,0,0,0,0,0,0,0,0,0,2,2,4,0,0
0,0,0,2,0,0,0,0,0,2,2,2,2,2,2,2,2,2,0,0,0,0,0,4,0,0,0,0,0,0,0,0,0,0,0,0,2,2,4,0,0
0,0,0,2,0,0,0,0,2,2,2,2,2,2,2,2,2,2,2,2,2,2,0,4,0,0,0,0,0,0,0,0,0,0,0,0,2,4,4,0,0
0,0,0,2,0,0,0,2,2,2,2,2,2,2,2,2,2,2,0,0,0,0,0,4,0,0,0,0,0,0,0,0,0,0,0,0,2,4,4,4,4
0,0,0,2,0,0,2,0,0,0,0,0,0,0,0,0,0,0,0,0,0,0,0,4,0,0,0,0,0,0,0,0,0,0,0,0,2,2,2,2,2
0,0,0,2,2,2,4,4,4,4,4,4,4,4,4,4,4,4,4,4,4,4,4,7,0,0,0,0,0,0,0,0,0,0,0,0,0,0,0,4,2
0,0,0,2,2,2,0,0,0,0,0,0,0,0,0,0,0,0,0,0,0,0,0,0,0,0,0,0,0,0,0,0,0,0,0,0,0,0,0,0,2
0,0,0,0,2,2,4,0,0,0,0,0,0,0,0,0,0,0,0,0,0,0,0,0,0,0,0,0,0,0,0,7,4,4,4,4,4,4,4,4,2
0,0,0,0,0,2,0,0,0,0,0,0,0,0,0,0,0,0,0,0,0,0,0,0,0,0,0,0,0,0,0,4,4,0,0,0,4,0,0,2,4
0,0,0,0,0,0,2,0,0,0,0,0,0,0,0,0,0,0,0,0,0,0,0,0,0,0,0,0,0,0,0,4,0,4,4,0,0,4,2,4,4
0,0,0,0,0,0,0,2,0,0,0,0,0,0,0,0,0,0,0,0,0,0,0,0,0,0,0,0,0,6,0,4,0,4,4,4,0,2,4,4,0
0,0,0,0,0,0,0,0,2,0,0,0,0,0,0,0,0,0,0,0,0,0,0,0,0,0,0,0,0,6,0,4,0,0,4,4,2,4,4,0,0
0,0,0,0,0,0,0,0,0,2,0,0,0,0,0,0,0,0,0,0,0,0,0,0,0,0,0,0,0,6,0,4,4,0,0,2,4,4,0,0,0
0,0,0,0,0,0,0,0,0,0,2,0,0,0,0,0,0,0,0,0,0,0,0,0,0,0,0,0,0,0,0,4,0,4,2,4,4,0,0,0,0
0,0,0,0,0,0,0,0,0,0,0,2,0,0,0,0,4,0,0,4,0,0,4,0,0,4,0,0,4,0,0,4,0,2,4,4,0,0,0,0,0
0,0,0,0,0,0,0,0,0,0,0,0,2,2,0,0,7,0,0,7,0,0,7,0,0,7,0,0,7,0,0,2,2,4,4,0,0,0,0,0,0
0,0,0,0,0,0,0,0,0,0,0,0,0,2,2,2,2,2,2,2,2,2,2,2,2,2,2,2,2,2,2,4,4,4,0,0,0,0,0,0,0
endlayer

layer
0,0,0,0,0,0,0,0,0,0,0,0,0,0,0,0,0,0,0,0,0,0,2,2,2,2,2,2,2,2,2,0,0,0,0,0,0,0,0,0,0
0,0,0,0,0,0,0,0,0,0,0,0,0,0,0,0,0,0,0,0,0,0,2,0,0,4,0,0,4,0,0,2,2,0,0,0,0,0,0,0,0
0,0,0,0,0,0,0,0,0,0,0,0,0,0,0,0,0,0,0,0,0,0,2,0,0,4,0,0,4,0,0,0,0,2,0,0,0,0,0,0,0
0,0,0,0,0,0,0,0,0,0,0,0,0,0,0,0,0,0,0,0,0,2,0,0,0,0,0,0,0,0,0,0,0,0,2,0,0,0,0,0,0
0,0,0,0,0,0,0,0,0,0,0,0,0,0,0,0,0,0,0,0,2,0,0,0,0,0,0,0,0,0,0,0,0,0,0,2,0,0,0,0,0
0,0,0,0,0,0,0,0,0,2,0,0,0,0,0,0,0,0,0,2,0,0,0,0,0,0,0,0,0,0,0,0,0,0,4,4,2,0,0,0,0
0,0,0,0,0,0,0,0,2,2,0,0,0,0,0,0,0,0,2,0,0,0,0,0,0,0,0,0,0,0,0,0,0,0,0,0,2,2,0,0,0
0,0,0,0,0,0,0,2,0,2,0,0,0,0,0,0,0,2,0,0,0,0,0,0,0,0,0,0,0,0,0,0,0,0,0,0,2,2,0,0,0
0,0,0,0,0,0,2,0,0,2,0,0,0,0,0,0,2,0,0,0,0,0,0,0,0,0,0,0,0,0,0,0,0,0,0,0,2,0,0,0,0
0,0,0,0,0,2,0,0,2,0,0,0,0,0,0,2,0,0,0,0,0,0,0,0,0,0,0,0,0,0,0,0,0,0,4,4,2,0,0,0,0
0,0,0,0,2,0,0,2,0,0,0,0,0,0,2,0,0,0,0,0,0,0,0,0,0,0,0,0,0,0,0,0,0,0,0,0,2,2,0,0,0
0,0,0,2,0,0,2,0,0,0,0,0,0,2,0,0,0,0,0,0,0,0,0,0,0,0,0,0,0,0,0,0,0,0,0,0,2,2,0,0,0
0,0,2,0,0,2,0,0,0,0,0,0,2,0,0,0,0,0,0,0,0,0,0,0,0,0,0,0,0,0,0,0,0,0,0,0,2,0,0,0,0
0,2,0,0,2,0,0,0,0,0,0,2,0,0,0,0,0,0,0,0,0,0,0,0,0,0,0,0,0,0,0,0,0,0,4,4,2,0,0,0,0
2,2,2,2,0,0,0,0,0,0,2,0,0,0,0,0,0,0,0,0,0,0,0,0,0,0,0,0,0,0,0,0,0,0,0,0,2,2,0,0,0
0,0,0,2,0,0,0,0,0,2,2,2,2,2,2,2,2,2,0,0,0,0,0,0,0,0,0,0,0,0,0,0,0,0,0,0,2,2,0,0,0
0,0,0,2,0,0,0,0,2,2,2,2,2,2,2,2,2,2,2,2,2,2,0,0,0,0,0,0,0,0,0,0,0,0,0,0,2,0,0,0,0
0,0,0,2,0,0,0,2,2,2,2,2,2,2,2,2,2,2,0,0,0,0,0,0,0,0,0,0,0,0,0,0,0,0,0,0,2,0,0,0,0
0,0,0,2,0,0,2,0,0,0,0,0,0,0,0,0,0,0,0,0,0,0,0,0,0,0,0,0,0,0,0,0,0,0,0,0,2,2,2,2,2
0,0,0,2,2,2,0,0,0,0,0,0,0,0,0,0,0,0,0,0,0,0,0,0,0,0,0,0,0,0,0,0,0,0,0,0,0,0,0,4,2
0,0,0,2,2,2,0,0,0,0,0,0,0,0,0,0,0,0,0,0,0,0,0,0,0,0,0,0,0,0,0,0,0,0,0,0,0,0,0,0,2
0,0,0,0,2,2,4,0,0,0,0,0,0,0,0,0,0,0,0,0,0,0,0,0,0,0,0,0,0,0,0,4,5,2,2,2,5,0,0,0,2
0,0,0,0,0,2,0,0,0,0,0,0,0,0,0,0,0,0,0,0,0,0,0,0,0,0,0,0,0,0,0,0,2,2,2,2,2,2,2,2,0
0,0,0,0,0,0,2,0,0,0,0,0,0,0,0,0,0,0,0,0,0,0,0,0,0,0,0,0,0,0,0,5,2,2,2,2,2,2,2,0,0
0,0,0,0,0,0,0,2,0,0,0,0,0,0,0,0,0,0,0,0,0,0,0,0,0,0,0,0,0,0,6,2,2,2,2,2,2,2,0,0,0
0,0,0,0,0,0,0,0,2,0,0,0,0,0,0,0,0,0,0,0,0,0,0,0,0,0,0,0,0,0,6,2,2,2,2,2,2,0,0,0,0
0,0,0,0,0,0,0,0,0,2,0,0,0,0,0,0,0,0,0,0,0,0,0,0,0,0,0,0,0,0,6,2,2,2,2,2,0,0,0,0,0
0,0,0,0,0,0,0,0,0,0,2,0,0,0,0,0,0,0,0,0,0,0,0,0,0,0,0,0,0,0,0,5,2,2,2,0,0,0,0,0,0
0,0,0,0,0,0,0,0,0,0,0,2,0,0,0,0,4,0,0,4,0,0,4,0,0,4,0,0,4,0,0,0,2,2,0,0,0,0,0,0,0
0,0,0,0,0,0,0,0,0,0,0,0,2,2,0,0,4,0,0,4,0,0,4,0,0,4,0,0,4,0,0,2,2,0,0,0,0,0,0,0,0
0,0,0,0,0,0,0,0,0,0,0,0,0,2,2,2,2,2,2,2,2,2,2,2,2,2,2,2,2,2,2,0,0,0,0,0,0,0,0,0,0
endlayer

layer
0,0,0,0,0,0,0,0,0,0,0,0,0,0,0,0,0,0,0,0,0,0,2,2,2,2,2,2,2,2,2,0,0,0,0,0,0,0,0,0,0
0,0,0,0,0,0,0,0,0,0,0,0,0,0,0,0,0,0,0,0,0,0,2,0,0,4,0,0,4,0,0,2,2,0,0,0,0,0,0,0,0
0,0,0,0,0,0,0,0,0,0,0,0,0,0,0,0,0,0,0,0,0,0,2,0,0,5,0,0,5,0,0,0,0,2,0,0,0,0,0,0,0
0,0,0,0,0,0,0,0,0,0,0,0,0,0,0,0,0,0,0,0,0,2,0,0,0,0,0,0,0,0,0,0,0,0,2,0,0,0,0,0,0
0,0,0,0,0,0,0,0,0,0,0,0,0,0,0,0,0,0,0,0,2,0,0,0,0,0,0,0,0,0,0,0,0,0,0,2,0,0,0,0,0
0,0,0,0,0,0,0,0,0,2,0,0,0,0,0,0,0,0,0,2,0,0,0,0,0,0,0,0,0,0,0,0,0,4,4,4,2,0,0,0,0
0,0,0,0,0,0,0,0,2,2,0,0,0,0,0,0,0,0,2,0,0,0,0,0,0,0,0,0,0,0,0,0,0,0,0,4,2,2,0,0,0
0,0,0,0,0,0,0,2,0,2,0,0,0,0,0,0,0,2,0,0,0,0,0,0,0,0,0,0,0,0,0,0,0,0,0,0,2,2,0,0,0
0,0,0,0,0,0,2,0,0,2,0,0,0,0,0,0,2,0,0,0,0,0,0,0,0,0,0,0,0,0,0,0,0,0,0,0,2,0,0,0,0
0,0,0,0,0,2,0,0,2,0,0,0,0,0,0,2,0,0,0,0,0,0,0,0,0,0,0,0,0,0,0,0,0,4,4,4,2,0,0,0,0
0,0,0,0,2,0,0,2,0,0,0,0,0,0,2,0,0,0,0,0,0,0,0,0,0,0,0,0,0,0,0,0,0,0,0,4,2,2,0,0,0
0,0,0,2,0,0,2,0,0,0,0,0,0,2,0,0,0,0,0,0,0,0,0,0,0,0,0,0,0,0,0,0,0,0,0,0,2,2,0,0,0
0,0,2,0,0,2,0,0,0,0,0,0,2,0,0,0,0,0,0,0,0,0,0,0,0,0,0,0,0,0,0,0,0,0,0,0,2,0,0,0,0
0,2,0,0,2,0,0,0,0,0,0,2,0,0,0,0,0,0,0,0,0,0,0,0,0,0,0,0,0,0,0,0,0,4,4,4,2,0,0,0,0
2,2,2,2,0,0,0,0,0,0,2,0,0,0,0,0,0,0,0,0,0,0,0,0,0,0,0,0,0,0,0,0,0,0,0,4,2,2,0,0,0
0,0,0,2,0,0,0,0,0,2,2,2,2,2,2,2,2,2,2,0,0,0,0,0,0,0,0,0,0,0,0,0,0,0,0,0,2,2,0,0,0
0,0,0,2,0,0,0,0,2,2,2,2,2,2,2,2,2,2,2,2,2,2,2,0,0,0,0,0,0,0,0,0,0,0,0,0,2,0,0,0,0
0,0,0,2,0,0,0,2,2,2,2,2,2,2,2,2,2,2,2,0,0,0,0,0,0,0,0,0,0,0,0,0,0,0,0,0,2,0,0,0,0
0,0,0,2,0,0,2,0,0,0,0,0,0,0,0,0,0,0,0,0,0,0,0,0,0,0,0,0,0,0,0,0,0,0,0,0,2,2,2,2,2
0,0,0,2,2,2,0,0,0,0,0,0,0,0,0,0,0,0,0,0,0,0,0,0,0,0,0,0,0,0,0,0,0,0,0,0,0,0,4,4,2
0,0,0,2,2,2,0,0,0,0,0,0,0,0,0,0,0,0,0,0,0,0,0,0,0,0,0,0,0,0,0,0,0,6,6,6,0,0,0,0,2
0,0,0,0,2,2,4,4,0,0,0,0,0,0,0,0,0,0,0,0,0,0,0,0,0,0,0,0,0,0,0,4,0,0,0,0,0,0,0,0,2
0,0,0,0,0,2,0,0,0,0,0,0,0,0,0,0,0,0,0,0,0,0,0,0,0,0,0,0,0,0,0,0,2,0,0,0,0,0,2,2,0
0,0,0,0,0,0,2,0,0,0,0,0,0,0,0,0,0,0,0,0,0,0,0,0,0,0,0,0,0,0,0,0,0,0,0,0,0,0,2,0,0
0,0,0,0,0,0,0,2,0,0,0,0,0,0,0,0,0,0,0,0,0,0,0,0,0,0,0,0,0,0,0,0,0,0,0,0,0,2,0,0,0
0,0,0,0,0,0,0,0,2,0,0,0,0,0,0,0,0,0,0,0,0,0,0,0,0,0,0,0,0,0,0,0,0,0,0,0,2,0,0,0,0
0,0,0,0,0,0,0,0,0,2,0,0,0,0,0,0,0,0,0,0,0,0,0,0,0,0,0,0,0,0,0,0,0,0,0,2,0,0,0,0,0
0,0,0,0,0,0,0,0,0,0,2,0,0,0,0,0,0,0,0,0,0,0,0,0,0,0,0,0,0,0,0,0,0,0,2,0,0,0,0,0,0
0,0,0,0,0,0,0,0,0,0,0,2,0,0,0,0,5,0,0,5,0,0,5,0,0,5,0,0,5,0,0,0,2,2,0,0,0,0,0,0,0
0,0,0,0,0,0,0,0,0,0,0,0,2,2,0,0,4,0,0,4,0,0,4,0,0,4,0,0,4,0,0,2,2,0,0,0,0,0,0,0,0
0,0,0,0,0,0,0,0,0,0,0,0,0,2,2,2,2,2,2,2,2,2,2,2,2,2,2,2,2,2,2,0,0,0,0,0,0,0,0,0,0
endlayer

layer
0,0,0,0,0,0,0,0,0,0,0,0,0,0,0,0,0,0,0,0,0,0,2,2,2,2,2,2,2,2,2,4,4,4,0,0,0,0,0,0,0
0,0,0,0,0,0,0,0,0,0,0,0,0,0,0,0,0,0,0,0,0,0,2,0,0,4,0,0,4,0,0,2,2,4,4,4,0,0,0,0,0
0,0,0,0,0,0,0,0,0,0,0,0,0,0,0,0,0,0,0,0,0,0,2,0,0,5,0,0,5,0,0,0,0,2,4,4,4,0,0,0,0
0,0,0,0,0,0,0,0,0,0,0,0,0,0,0,0,0,0,0,0,0,2,0,0,0,0,0,0,0,0,0,0,0,0,2,4,4,4,0,0,0
0,0,0,0,0,0,0,0,0,0,0,0,0,0,0,0,0,0,0,0,2,0,0,0,0,0,0,0,0,0,0,0,0,0,0,2,4,4,4,0,0
0,0,0,0,0,0,0,0,0,2,0,0,0,0,0,0,0,0,0,2,0,0,0,0,0,0,0,0,0,0,0,0,0,4,4,4,2,4,4,4,0
0,0,0,0,0,0,0,0,2,2,0,0,0,0,0,0,0,0,2,0,0,0,0,0,0,0,0,0,0,0,0,0,0,0,0,4,2,2,4,4,0
0,0,0,0,0,0,0,2,0,2,0,0,0,0,0,0,0,2,0,0,0,0,0,0,0,0,0,0,0,0,0,0,0,0,0,0,2,2,4,4,0
0,0,0,0,0,0,2,0,0,2,0,0,0,0,0,0,2,0,0,0,0,0,0,0,0,0,0,0,0,0,0,0,0,0,0,0,2,4,4,4,0
0,0,0,0,0,2,0,0,2,0,0,0,0,0,0,2,0,0,0,0,0,0,0,0,0,0,0,0,0,0,0,0,0,4,4,4,2,4,4,4,0
0,0,0,0,2,0,0,2,0,0,0,0,0,0,2,0,0,0,0,0,0,0,0,0,0,0,0,0,0,0,0,0,0,0,0,4,2,2,4,4,0
0,0,0,2,0,0,2,0,0,0,0,0,0,2,0,0,0,0,0,0,0,0,0,0,0,0,0,0,0,0,0,0,0,0,0,0,2,2,4,4,0
0,0,2,0,0,2,0,0,0,0,0,0,2,0,0,0,0,0,0,0,0,0,0,0,0,0,0,0,0,0,0,0,0,0,0,0,2,4,4,4,0
0,2,0,0,2,0,0,0,0,0,0,2,0,0,0,0,0,0,0,0,0,0,0,0,0,0,0,0,0,0,0,0,0,4,4,4,2,4,4,4,0
2,2,2,2,0,0,0,0,0,0,2,0,0,0,0,0,0,0,0,0,0,0,0,0,0,0,0,0,0,0,0,0,0,0,0,4,2,2,4,4,0
0,0,0,2,0,0,0,0,0,2,2,2,2,2,2,2,2,2,2,0,0,0,0,0,0,0,0,0,0,0,0,0,0,0,0,0,2,2,4,4,0
0,0,0,2,0,0,0,0,2,2,2,2,2,2,2,2,2,2,2,2,2,2,2,0,0,0,0,0,0,0,0,0,0,0,0,0,2,4,4,4,4
0,0,0,2,0,0,0,2,2,2,2,2,2,2,2,2,2,2,2,0,0,0,0,0,0,0,0,0,0,0,0,0,0,0,0,0,2,4,4,4,4
0,0,0,2,0,0,2,0,0,0,0,0,0,0,0,0,0,0,0,0,0,0,0,0,0,0,0,0,0,0,0,0,0,0,0,0,2,2,2,2,2
0,0,0,2,2,2,0,0,0,0,0,0,0,0,0,0,0,0,0,0,0,0,0,0,0,0,0,0,0,0,0,0,0,6,6,6,0,0,4,4,2
0,0,0,2,2,2,0,0,0,0,0,0,0,0,0,0,0,0,0,0,0,0,0,0,0,0,0,0,0,0,0,0,0,0,0,0,0,0,0,0,2
0,0,0,0,2,2,4,4,0,0,0,0,0,0,0,0,0,0,0,0,0,0,0,0,0,0,0,0,0,0,0,4,0,0,0,0,0,0,0,0,2
0,0,0,0,0,2,0,0,0,0,0,0,0,0,0,0,0,0,0,0,0,0,0,0,0,0,0,0,0,0,0,0,2,0,0,0,0,0,2,2,4
0,0,0,0,0,0,2,0,0,0,0,0,0,0,0,0,0,0,0,0,0,0,0,0,0,0,0,0,0,0,0,0,0,0,0,0,0,0,2,4,4
0,0,0,0,0,0,0,2,0,0,0,0,0,0,0,0,0,0,0,0,0,0,0,0,0,0,0,0,0,0,0,0,0,0,0,0,0,2,4,4,4
0,0,0,0,0,0,0,0,2,0,0,0,0,0,0,0,0,0,0,0,0,0,0,0,0,0,0,0,0,0,0,0,0,0,0,0,2,4,4,4,0
0,0,0,0,0,0,0,0,0,2,0,0,0,0,0,0,0,0,0,0,0,0,0,0,0,0,0,0,0,0,0,0,0,0,0,2,4,4,4,0,0
0,0,0,0,0,0,0,0,0,0,2,0,0,0,0,0,0,0,0,0,0,0,0,0,0,0,0,0,0,0,0,0,0,0,2,4,4,4,0,0,0
0,0,0,0,0,0,0,0,0,0,0,2,0,0,0,0,5,0,0,5,0,0,5,0,0,5,0,0,5,0,0,0,2,2,4,4,4,0,0,0,0
0,0,0,0,0,0,0,0,0,0,0,0,2,2,0,0,4,0,0,4,0,0,4,0,0,4,0,0,4,0,0,2,2,4,4,4,0,0,0,0,0
0,0,0,0,0,0,0,0,0,0,0,0,0,2,2,2,2,2,2,2,2,2,2,2,2,2,2,2,2,2,2,4,4,4,4,0,0,0,0,0,0
endlayer

layer
0,0,0,0,0,0,0,0,0,0,0,0,0,0,0,0,0,0,0,0,0,0,2,2,2,2,2,2,2,2,2,4,4,0,0,0,0,0,0,0,0
0,0,0,0,0,0,0,0,0,0,0,0,0,0,0,0,0,0,0,0,0,0,2,0,0,4,0,0,4,0,0,2,2,4,4,0,0,0,0,0,0
0,0,0,0,0,0,0,0,0,0,0,0,0,0,0,0,0,0,0,0,0,0,2,0,0,5,0,0,5,0,0,4,0,2,4,0,0,0,0,0,0
0,0,0,0,0,0,0,0,0,0,0,0,0,0,0,0,0,0,0,0,0,2,0,0,0,0,0,0,0,0,0,4,0,0,2,4,4,0,0,0,0
0,0,0,0,0,0,0,0,0,0,0,0,0,0,0,0,0,0,0,0,2,0,0,0,0,0,0,0,0,0,0,4,0,0,0,2,4,0,0,0,0
0,0,0,0,0,0,0,0,0,2,0,0,0,0,0,0,0,0,0,2,0,0,0,0,0,0,0,0,0,0,0,4,0,4,7,4,2,4,4,0,0
0,0,0,0,0,0,0,0,2,2,0,0,0,0,0,0,0,0,2,0,0,0,0,0,0,0,0,0,0,0,0,4,0,0,4,4,2,2,4,0,0
0,0,0,0,0,0,0,2,0,2,0,0,0,0,0,0,0,2,0,0,0,0,0,0,0,0,0,0,0,0,0,4,0,0,0,0,2,2,4,0,0
0,0,0,0,0,0,2,0,0,2,0,0,0,0,0,0,2,0,0,0,0,0,0,0,0,0,0,0,0,0,0,4,0,0,0,0,2,4,4,0,0
0,0,0,0,0,2,0,0,2,0,0,0,0,0,0,2,0,0,0,0,0,0,0,0,0,0,0,0,0,0,0,4,0,4,4,7,2,4,4,0,0
0,0,0,0,2,0,0,2,0,0,0,0,0,0,2,0,0,0,0,0,0,0,0,0,0,0,0,0,0,0,0,4,0,0,4,4,2,2,4,0,0
0,0,0,2,0,0,2,0,0,0,0,0,0,2,0,0,0,0,0,0,0,0,0,0,0,0,0,0,0,0,0,4,0,0,0,0,2,2,4,0,0
0,0,2,0,0,2,0,0,0,0,0,0,2,0,0,0,0,0,0,0,0,0,0,0,0,0,0,0,0,0,0,4,0,0,0,0,2,4,4,0,0
0,2,0,0,2,0,0,0,0,0,0,2,0,0,0,0,0,0,0,0,0,0,0,0,0,0,0,0,0,0,0,4,0,4,4,7,2,4,4,0,0
2,2,2,2,0,0,0,0,0,0,2,0,0,0,0,0,0,0,0,0,0,0,0,0,0,0,0,0,0,0,0,4,0,0,4,4,2,2,4,0,0
0,0,0,2,0,0,0,0,0,2,2,2,2,2,2,2,2,2,2,2,0,0,0,0,0,0,0,0,0,0,0,4,0,0,0,0,2,2,4,0,0
0,0,0,0,0,0,0,0,2,2,2,2,2,2,2,2,2,2,2,2,2,2,2,2,0,0,0,0,0,0,0,7,4,4,4,4,2,4,4,0,0
0,0,0,0,0,0,0,2,2,2,2,2,2,2,2,2,2,2,2,2,0,0,0,0,0,0,0,0,0,0,0,0,0,0,0,0,2,4,4,4,4
0,0,0,2,0,0,2,2,0,0,0,0,0,0,0,0,0,0,0,0,0,0,0,0,0,0,0,0,0,0,0,0,0,6,6,6,2,2,2,2,2
0,0,0,2,2,2,0,0,0,0,0,0,0,0,0,0,0,0,0,0,0,0,0,0,0,0,0,0,0,0,0,0,0,0,0,0,0,0,4,4,2
0,0,0,2,2,2,0,0,0,0,0,0,0,0,0,0,0,0,0,0,0,0,0,0,0,0,0,0,0,0,0,0,0,0,0,0,0,0,0,0,2
0,0,0,0,2,2,4,4,0,0,0,0,0,0,0,0,0,0,0,0,0,0,0,0,0,0,0,0,0,0,0,4,0,0,0,0,0,0,0,0,2
0,0,0,0,0,2,0,0,0,0,0,0,0,0,0,0,0,0,0,0,0,0,0,0,0,0,0,0,0,0,0,0,2,0,0,0,0,0,2,2,4
0,0,0,0,0,0,2,0,0,0,0,0,0,0,0,0,0,0,0,0,0,0,0,0,0,0,0,0,0,0,0,0,0,0,0,0,0,0,2,4,4
0,0,0,0,0,0,0,2,0,0,0,0,0,0,0,0,0,0,0,0,0,0,0,0,0,0,0,0,0,0,0,0,0,0,0,0,0,2,4,4,0
0,0,0,0,0,0,0,0,2,0,0,0,0,0,0,0,0,0,0,0,0,0,0,0,0,0,0,0,0,0,0,0,0,0,0,0,2,4,4,0,0
0,0,0,0,0,0,0,0,0,2,0,0,0,0,0,0,0,0,0,0,0,0,0,0,0,0,0,0,0,0,0,0,0,0,0,2,4,4,0,0,0
0,0,0,0,0,0,0,0,0,0,2,0,0,0,0,0,0,0,0,0,0,0,0,0,0,0,0,0,0,0,0,0,0,0,2,4,4,0,0,0,0
0,0,0,0,0,0,0,0,0,0,0,2,0,0,0,0,5,0,0,5,0,0,5,0,0,5,0,0,5,0,0,0,2,2,4,4,0,0,0,0,0
0,0,0,0,0,0,0,0,0,0,0,0,2,2,0,0,4,0,0,4,0,0,4,0,0,4,0,0,4,0,0,2,2,4,4,0,0,0,0,0,0
0,0,0,0,0,0,0,0,0,0,0,0,0,2,2,2,2,2,2,2,2,2,2,2,2,2,2,2,2,2,2,4,4,4,0,0,0,0,0,0,0
endlayer

layer
0,0,0,0,0,0,0,0,0,0,0,0,0,0,0,0,0,0,0,0,0,0,2,2,2,2,2,2,2,2,2,0,0,0,0,0,0,0,0,0,0
0,0,0,0,0,0,0,0,0,0,0,0,0,0,0,0,0,0,0,0,0,0,2,0,0,4,0,0,4,0,0,2,2,0,0,0,0,0,0,0,0
0,0,0,0,0,0,0,0,0,0,0,0,0,0,0,0,0,0,0,0,0,0,2,0,0,5,0,0,5,0,0,0,2,2,0,0,0,0,0,0,0
0,0,0,0,0,0,0,0,0,0,0,0,0,0,0,0,0,0,0,0,0,2,0,0,0,0,0,0,0,0,0,0,2,2,2,0,0,0,0,0,0
0,0,0,0,0,0,0,0,0,0,0,0,0,0,0,0,0,0,0,0,2,0,0,0,0,0,0,0,0,0,0,0,2,2,2,2,0,0,0,0,0
0,0,0,0,0,0,0,0,0,2,0,0,0,0,0,0,0,0,0,2,0,0,0,0,0,0,0,0,0,0,0,0,2,2,2,2,2,0,0,0,0
0,0,0,0,0,0,0,0,2,2,0,0,0,0,0,0,0,0,2,0,0,0,0,0,0,0,0,0,0,0,0,5,2,2,2,2,2,2,0,0,0
0,0,0,0,0,0,0,2,0,2,0,0,0,0,0,0,0,2,0,0,0,0,0,0,0,0,0,0,0,0,0,2,2,2,2,2,2,2,0,0,0
0,0,0,0,0,0,2,0,0,2,0,0,0,0,0,0,2,0,0,0,0,0,0,0,0,0,0,0,0,0,0,2,2,2,2,2,2,0,0,0,0
0,0,0,0,0,2,0,0,2,0,0,0,0,0,0,2,0,0,0,0,0,0,0,0,0,0,0,0,0,0,0,2,2,2,2,2,2,0,0,0,0
0,0,0,0,2,0,0,2,0,0,0,0,0,0,2,0,0,0,0,0,0,0,0,0,0,0,0,0,0,0,0,5,2,2,2,2,2,2,0,0,0
0,0,0,2,0,0,2,0,0,0,0,0,0,2,0,0,0,0,0,0,0,0,0,0,0,0,0,0,0,0,0,0,2,2,2,2,2,2,0,0,0
0,0,2,0,0,2,0,0,0,0,0,0,2,0,0,0,0,0,0,0,0,0,0,0,0,0,0,0,0,0,0,0,2,2,2,2,2,0,0,0,0
0,2,0,0,2,0,0,0,0,0,0,2,0,0,0,0,0,0,0,0,0,0,0,0,0,0,0,0,0,0,0,0,2,2,2,2,2,0,0,0,0
2,2,2,2,0,0,0,0,0,0,2,0,0,0,0,0,0,0,0,0,0,0,0,0,0,0,0,0,0,0,0,0,2,2,2,2,2,2,0,0,0
0,0,0,0,0,0,0,0,0,2,2,2,2,2,2,2,2,2,2,2,0,0,0,0,0,0,0,0,0,0,0,0,2,2,2,2,2,2,0,0,0
0,0,0,0,0,0,0,0,2,2,2,2,2,2,2,2,2,2,2,2,2,2,2,2,0,0,0,0,0,0,0,4,5,2,2,2,2,0,0,0,0
0,0,0,0,0,0,0,2,2,2,2,2,2,2,2,2,2,2,2,2,0,0,0,0,0,0,0,0,0,0,0,0,0,6,6,6,2,0,0,0,0
0,0,0,0,0,0,2,2,0,0,0,0,0,0,0,0,0,0,0,0,0,0,0,0,0,0,0,0,0,0,0,0,0,0,0,0,2,2,2,2,2
0,0,0,2,2,2,0,0,0,0,0,0,0,0,0,0,0,0,0,0,0,0,0,0,0,0,0,0,0,0,0,0,0,0,0,0,0,0,4,4,2
0,0,0,2,2,2,0,0,0,0,0,0,0,0,0,0,0,0,0,0,0,0,0,0,0,0,0,0,0,0,0,0,0,0,0,0,0,0,0,0,2
0,0,0,0,2,2,4,4,0,0,0,0,0,0,0,0,0,0,0,0,0,0,0,0,0,0,0,0,0,0,0,4,0,0,0,0,0,0,0,0,2
0,0,0,0,0,2,0,0,0,0,0,0,0,0,0,0,0,0,0,0,0,0,0,0,0,0,0,0,0,0,0,0,2,2,2,2,2,2,2,2,0
0,0,0,0,0,0,2,0,0,0,0,0,0,0,0,0,0,0,0,0,0,0,0,0,0,0,0,0,0,0,0,0,2,2,2,2,2,2,2,0,0
0,0,0,0,0,0,0,2,0,0,0,0,0,0,0,0,0,0,0,0,0,0,0,0,0,0,0,0,0,0,0,0,2,2,2,2,2,2,0,0,0
0,0,0,0,0,0,0,0,2,0,0,0,0,0,0,0,0,0,0,0,0,0,0,0,0,0,0,0,0,0,0,0,2,2,2,2,2,0,0,0,0
0,0,0,0,0,0,0,0,0,2,0,0,0,0,0,0,0,0,0,0,0,0,0,0,0,0,0,0,0,0,0,0,2,2,2,2,0,0,0,0,0
0,0,0,0,0,0,0,0,0,0,2,0,0,0,0,0,0,0,0,0,0,0,0,0,0,0,0,0,0,0,0,0,2,2,2,0,0,0,0,0,0
0,0,0,0,0,0,0,0,0,0,0,2,0,0,0,0,5,0,0,5,0,0,5,0,0,5,0,0,5,0,0,0,2,2,0,0,0,0,0,0,0
0,0,0,0,0,0,0,0,0,0,0,0,2,2,0,0,4,0,0,4,0,0,4,0,0,4,0,0,4,0,0,2,2,0,0,0,0,0,0,0,0
0,0,0,0,0,0,0,0,0,0,0,0,0,2,2,2,2,2,2,2,2,2,2,2,2,2,2,2,2,2,2,0,0,0,0,0,0,0,0,0,0
endlayer

layer
0,0,0,0,0,0,0,0,0,0,0,0,0,0,0,0,0,0,0,0,0,0,2,2,2,2,2,2,2,2,2,0,0,0,0,0,0,0,0,0,0
0,0,0,0,0,0,0,0,0,0,0,0,0,0,0,0,0,0,0,0,0,0,2,0,0,4,0,0,4,0,0,2,2,0,0,0,0,0,0,0,0
0,0,0,0,0,0,0,0,0,0,0,0,0,0,0,0,0,0,0,0,0,0,2,0,0,5,0,0,5,0,0,0,2,2,0,0,0,0,0,0,0
0,0,0,0,0,0,0,0,0,0,0,0,0,0,0,0,0,0,0,0,0,2,0,0,0,0,0,0,0,0,0,0,2,2,2,0,0,0,0,0,0
0,0,0,0,0,0,0,0,0,0,0,0,0,0,0,0,0,0,0,0,2,0,0,0,0,0,0,0,0,0,0,0,8,0,12,2,0,0,0,0,0
0,0,0,0,0,0,0,0,0,2,0,0,0,0,0,0,0,0,0,2,0,0,0,0,0,0,0,0,0,0,0,0,8,0,0,0,2,0,0,0,0
0,0,0,0,0,0,0,0,2,2,0,0,0,0,0,0,0,0,2,0,0,0,0,0,0,0,0,0,0,0,0,0,2,0,0,0,2,2,0,0,0
0,0,0,0,0,0,0,2,2,2,0,0,0,0,0,0,0,2,0,0,0,0,0,0,0,0,0,0,0,0,6,0,0,0,0,0,2,2,0,0,0
0,0,0,0,0,0,2,0,0,2,0,0,0,0,0,0,2,0,0,0,0,0,0,0,0,0,0,0,0,0,6,0,0,0,0,0,2,0,0,0,0
0,0,0,0,0,2,0,0,2,0,0,0,0,0,0,2,0,0,0,0,0,0,0,0,0,0,0,0,0,0,6,0,0,0,0,0,2,0,0,0,0
0,0,0,0,2,0,0,2,0,0,0,0,0,0,2,0,0,0,0,0,0,0,0,0,0,0,0,0,0,0,0,0,2,0,0,0,2,2,0,0,0
0,0,0,2,0,0,2,0,0,0,0,0,0,2,0,0,0,0,0,0,0,0,0,0,0,0,0,0,0,0,0,0,8,0,0,0,2,2,0,0,0
0,0,2,0,0,2,0,0,0,0,0,0,2,0,0,0,0,0,0,0,0,0,0,0,0,0,0,0,0,0,0,0,8,0,0,0,2,0,0,0,0
0,2,0,0,2,0,0,0,0,0,0,2,0,0,0,0,0,0,0,0,0,0,0,0,0,0,0,0,0,0,0,0,2,0,0,0,2,0,0,0,0
2,2,2,2,0,0,0,0,0,0,2,0,0,0,0,0,0,0,0,0,0,0,0,0,0,0,0,0,0,0,0,0,2,0,0,0,2,2,0,0,0
0,0,0,0,0,0,0,0,0,2,2,2,2,2,2,2,2,2,2,2,2,0,0,0,0,0,0,0,0,0,0,0,2,0,0,0,2,2,0,0,0
0,0,0,0,0,0,0,0,2,2,2,2,2,2,2,2,2,2,2,2,2,2,2,2,2,0,0,0,0,0,0,4,0,0,0,0,2,0,0,0,0
0,0,0,0,0,0,0,2,2,2,2,2,2,2,2,2,2,2,2,2,2,0,0,0,0,0,0,0,0,0,0,0,0,0,0,0,2,0,0,0,0
0,0,0,0,0,0,2,2,2,0,0,0,0,0,0,0,0,0,0,0,0,0,0,0,0,0,0,0,0,0,0,0,0,0,0,0,2,2,2,2,2
0,0,0,2,2,2,0,0,0,0,0,0,0,0,0,0,0,0,0,0,0,0,0,0,0,0,0,0,0,0,0,0,0,0,0,0,0,4,4,4,2
0,0,0,2,2,2,0,0,0,0,0,0,0,0,0,0,0,0,0,0,0,0,0,0,0,0,0,0,0,0,0,0,0,0,0,0,0,0,0,0,2
0,0,0,0,2,2,4,4,4,0,0,0,0,0,0,0,0,0,0,0,0,0,0,0,0,0,0,0,0,0,0,7,4,4,4,4,4,4,4,4,2
0,0,0,0,0,2,0,0,0,0,0,0,0,0,0,0,0,0,0,0,0,0,0,0,0,0,0,0,0,0,0,4,0,0,0,0,0,0,0,2,0
0,0,0,0,0,0,2,0,0,0,0,0,0,0,0,0,0,0,0,0,0,0,0,0,0,0,0,0,0,0,0,4,0,0,0,0,0,0,2,0,0
0,0,0,0,0,0,0,2,0,0,0,0,0,0,0,0,0,0,0,0,0,0,0,0,0,0,0,0,0,0,0,4,0,0,0,0,0,2,0,0,0
0,0,0,0,0,0,0,0,2,0,0,0,0,0,0,0,0,0,0,0,0,0,0,0,0,0,0,0,0,0,0,4,0,0,0,0,2,0,0,0,0
0,0,0,0,0,0,0,0,0,2,0,0,0,0,0,0,0,0,0,0,0,0,0,0,0,0,0,0,0,0,0,4,0,0,0,2,0,0,0,0,0
0,0,0,0,0,0,0,0,0,0,2,0,0,0,0,0,0,0,0,0,0,0,0,0,0,0,0,0,0,0,0,4,0,0,2,0,0,0,0,0,0
0,0,0,0,0,0,0,0,0,0,0,2,0,0,0,0,5,0,0,5,0,0,5,0,0,5,0,0,5,0,0,4,0,2,0,0,0,0,0,0,0
0,0,0,0,0,0,0,0,0,0,0,0,2,2,0,0,4,0,0,4,0,0,4,0,0,4,0,0,4,0,0,2,2,0,0,0,0,0,0,0,0
0,0,0,0,0,0,0,0,0,0,0,0,0,2,2,2,2,2,2,2,2,2,2,2,2,2,2,2,2,2,2,0,0,0,0,0,0,0,0,0,0
endlayer

layer
0,0,0,0,0,0,0,0,0,0,0,0,0,0,0,0,0,0,0,0,0,0,2,2,2,2,2,2,2,2,2,0,0,0,0,0,0,0,0,0,0
0,0,0,0,0,0,0,0,0,0,0,0,0,0,0,0,0,0,0,0,0,0,2,0,0,4,0,0,4,0,0,2,2,0,0,0,0,0,0,0,0
0,0,0,0,0,0,0,0,0,0,0,0,0,0,0,0,0,0,0,0,0,0,2,0,0,5,0,0,5,0,0,0,2,2,0,0,0,0,0,0,0
