
# Campsite
# Created 9 Mar 2014
# Created by Ruins mod version 12.3 Ingame Parser
# authoring Player: Jordan_Greywolf

# Updated to MC 1.7.10: 9 Oct 2014
# Updated to MC 1.8: 29 Oct 2015
# Updated to MC 1.9: 16 Apr 2016
# Updated to MC 1.11: 13 Jan 2017
# Verified for MC 1.12: 23 Jun 2017
# Updated to MC 1.12.1: 10 Sep 2017

biomesToSpawnIn=autumn hills,autumn woods,bamboo forest,birch forest,birch_forest,boreal forest,brushland,chaparral,cherry blossom grove,coniferous forest,deciduous forest,extreme hills edge,flower forest,forest,forested field,forest_hills,forested hills,forested island,garden,grove,highland,lush redwoods,magical forest,mangrove,maplewoods,meadow forest,mountain taiga,mutated_forest,mutated_plains,mystic grove,orchard,pine forest,plains,redwood forest,redwood_taiga,rwg_plains,seasonal forest,seasonal spruce forest,spruce woods,roofed forest,roofed_forest,savanna,taiga,sunflower plains,thinned mystic grove,thinned timber,timber,wonderous woods,woodland,woodlands,xeric shrubland,mining biome

weight=1
embed_into_distance=3

unacceptable_target_blocks=lava,flowing_lava,water,flowing_water,cloud,Natura:Cloud,slime_congealed,slime_dirt,slime_grass,command_block

dimensions=8,14,15
allowable_overhang=0
max_cut_in=0
cut_in_buffer=0
max_leveling=2
leveling_buffer=-1
preserve_water=0
preserve_lava=0
preserve_plants=1

rule1=0,100,minecraft:grass-0
rule2=0,100,minecraft:dirt-0
rule3=0,100,preserveBlock
rule4=0,100,air,air,air
rule5=0,100,minecraft:cobblestone-0
rule6=0,100,minecraft:netherrack-0
rule7=0,75,minecraft:tallgrass-1,minecraft:tallgrass-1,minecraft:tallgrass-1,minecraft:tallgrass-2,minecraft:red_flower,minecraft:yellow_flower
rule8=0,100,minecraft:log-8
rule9=0,100,minecraft:wool-8
rule10=0,100,minecraft:log-4
rule11=0,100,minecraft:cobblestone_wall-0
rule12=0,75,minecraft:fire-15
rule13=0,100,minecraft:bed-0
rule14=0,100,minecraft:bed-8
rule15=0,100,minecraft:bed-3
rule16=0,100,minecraft:bed-11
rule17=0,75,minecraft:cauldron-3,minecraft:cauldron-0

layer
3,1,2,2,2,2,2,2,2,2,2,1,1,1,1
1,2,2,2,0,0,2,2,2,2,2,2,2,1,1
2,2,2,2,2,2,2,2,2,2,2,2,2,2,1
2,2,2,2,2,0,2,2,2,2,2,2,2,2,1
2,2,2,2,2,2,2,2,2,2,2,2,2,2,1
2,2,2,2,2,2,2,2,2,2,2,2,2,2,2
2,2,2,2,2,2,2,2,2,2,2,2,2,2,2
2,2,2,2,2,2,2,2,2,2,2,2,2,2,1
2,2,2,2,2,2,2,2,2,2,2,2,2,2,1
3,2,2,2,2,2,2,2,2,2,2,2,2,2,1
3,1,2,2,2,2,2,2,2,2,2,2,2,2,2
3,3,1,2,2,2,2,2,2,2,2,2,2,2,1
3,3,3,1,2,2,2,2,2,2,2,2,2,1,1
3,3,3,3,3,1,1,1,2,2,2,1,1,1,3
endlayer

layer
3,3,1,1,2,2,2,2,2,2,1,3,3,3,3
3,2,2,2,2,2,2,2,2,2,2,1,1,3,3
2,2,2,2,2,2,2,2,2,2,2,2,1,1,3
2,2,2,2,2,2,2,2,2,2,2,2,2,1,3
2,2,4,2,2,2,2,2,2,2,2,2,2,1,3
2,2,2,2,2,2,2,2,2,2,2,2,2,1,1
2,2,2,2,2,2,2,2,2,2,2,2,2,1,1
1,2,2,2,2,2,2,2,2,2,2,2,2,1,3
1,2,2,2,2,2,2,2,2,2,2,2,1,1,3
3,1,2,2,2,2,2,2,2,2,2,2,1,1,3
3,3,1,1,2,2,2,2,4,2,2,2,2,1,1
3,3,3,1,2,2,2,2,2,2,2,2,1,1,3
3,3,3,3,1,2,1,2,2,2,2,1,1,3,3
3,3,3,3,3,3,3,3,1,1,1,3,3,3,3
endlayer

layer
3,3,3,3,1,1,1,1,1,1,3,3,3,3,3
3,1,1,1,1,1,1,2,2,2,1,3,3,3,3
1,2,2,2,2,1,1,1,1,1,1,1,3,3,3
1,2,1,1,2,1,1,5,5,5,1,2,1,3,3
1,2,1,1,1,1,1,5,6,5,1,2,1,3,3
1,2,1,1,2,1,1,5,5,5,1,2,1,3,3
1,2,2,2,2,1,1,1,1,1,1,1,1,3,3
3,1,1,1,1,1,1,1,1,1,1,1,1,3,3
3,1,1,1,1,1,2,2,1,2,2,1,3,3,3
3,3,1,1,1,1,2,1,1,1,2,1,3,3,3
3,3,3,3,1,1,2,1,1,1,2,1,1,3,3
3,3,3,3,1,1,2,2,2,2,2,1,3,3,3
3,3,3,3,3,1,3,1,1,1,1,3,3,3,3
3,3,3,3,3,3,3,3,3,3,3,3,3,3,3
endlayer

layer
3,3,3,3,7,7,7,7,7,7,3,3,3,3,3
3,7,7,7,7,7,7,8,8,8,7,3,3,3,3
7,9,9,9,9,7,0,0,0,0,0,7,3,3,3
7,9,0,0,9,0,0,0,11,0,0,10,7,3,3
7,9,14,13,0,0,0,0,12,0,0,10,7,3,3
7,9,0,0,9,0,0,0,11,0,0,10,7,3,3
7,9,9,9,9,0,0,0,0,0,0,7,7,3,3
3,7,7,7,7,7,0,0,0,0,7,7,7,3,3
3,7,7,7,7,7,9,9,7,9,9,7,3,3,3
3,3,7,7,7,7,9,0,15,0,9,7,3,3,3
3,3,3,3,7,7,9,0,16,0,9,7,7,3,3
3,3,3,3,7,7,9,9,9,9,9,7,3,3,3
3,3,3,3,3,7,3,7,7,7,7,3,3,3,3
3,3,3,3,3,3,3,3,3,3,3,3,3,3,3
endlayer

layer
3,3,0,0,0,0,0,0,0,0,0,3,3,3,3
0,0,0,0,0,0,0,0,0,0,0,0,3,3,3
0,0,0,0,0,0,0,0,0,0,0,0,0,3,3
0,9,9,9,9,0,0,0,11,0,0,0,0,0,3
0,9,0,0,0,0,0,0,17,0,0,0,0,0,3
0,9,9,9,9,0,0,0,11,0,0,0,0,0,3
0,0,0,0,0,0,0,0,0,0,0,0,0,0,3
0,0,0,0,0,0,0,0,0,0,0,0,0,0,3
0,0,0,0,0,0,0,9,0,9,0,0,0,3,3
3,0,0,0,0,0,0,9,0,9,0,0,0,3,3
3,3,0,0,0,0,0,9,0,9,0,0,0,0,3
3,3,3,0,0,0,0,9,9,9,0,0,0,3,3
3,3,3,0,0,0,0,0,0,0,0,0,3,3,3
3,3,3,3,3,0,3,0,0,0,0,3,3,3,3
endlayer

layer
3,0,0,0,0,0,0,0,0,0,0,0,3,3,3
0,0,0,0,0,0,0,0,0,0,0,0,0,3,3
0,0,0,0,0,0,0,0,0,0,0,0,0,0,3
0,0,0,0,0,0,0,0,0,0,0,0,0,0,3
0,9,9,9,9,0,0,0,0,0,0,0,0,0,0
0,0,0,0,0,0,0,0,0,0,0,0,0,0,0
0,0,0,0,0,0,0,0,0,0,0,0,0,0,0
0,0,0,0,0,0,0,0,0,0,0,0,0,0,3
0,0,0,0,0,0,0,0,9,0,0,0,0,0,3
0,0,0,0,0,0,0,0,9,0,0,0,0,0,3
3,0,0,0,0,0,0,0,9,0,0,0,0,0,0
3,3,0,0,0,0,0,0,9,0,0,0,0,0,3
3,3,0,0,0,0,0,0,0,0,0,0,0,3,3
3,3,3,0,0,0,0,0,0,0,0,0,3,3,3
endlayer

layer
0,0,0,0,0,0,0,0,0,0,0,0,0,3,3
0,0,0,0,0,0,0,0,0,0,0,0,0,0,3
0,0,0,0,0,0,0,0,0,0,0,0,0,0,0
0,0,0,0,0,0,0,0,0,0,0,0,0,0,0
0,0,0,0,0,0,0,0,0,0,0,0,0,0,0
0,0,0,0,0,0,0,0,0,0,0,0,0,0,0
0,0,0,0,0,0,0,0,0,0,0,0,0,0,0
0,0,0,0,0,0,0,0,0,0,0,0,0,0,0
0,0,0,0,0,0,0,0,0,0,0,0,0,0,3
0,0,0,0,0,0,0,0,0,0,0,0,0,0,0
0,0,0,0,0,0,0,0,0,0,0,0,0,0,0
0,0,0,0,0,0,0,0,0,0,0,0,0,0,0
3,0,0,0,0,0,0,0,0,0,0,0,0,0,3
3,3,0,0,0,0,0,0,0,0,0,0,0,3,3
endlayer

layer
0,0,0,0,0,0,0,0,0,0,0,0,0,0,3
0,0,0,0,0,0,0,0,0,0,0,0,0,0,0
0,0,0,0,0,0,0,0,0,0,0,0,0,0,0
0,0,0,0,0,0,0,0,0,0,0,0,0,0,0
0,0,0,0,0,0,0,0,0,0,0,0,0,0,0
0,0,0,0,0,0,0,0,0,0,0,0,0,0,0
0,0,0,0,0,0,0,0,0,0,0,0,0,0,0
0,0,0,0,0,0,0,0,0,0,0,0,0,0,0
0,0,0,0,0,0,0,0,0,0,0,0,0,0,0
0,0,0,0,0,0,0,0,0,0,0,0,0,0,0
0,0,0,0,0,0,0,0,0,0,0,0,0,0,0
0,0,0,0,0,0,0,0,0,0,0,0,0,0,0
0,0,0,0,0,0,0,0,0,0,0,0,0,0,0
3,0,0,0,0,0,0,0,0,0,0,0,0,0,3
endlayer

