# Caravan_Wagon_1-r (ruined caravan wagon)
# 6 Mar 2014; updated to MC 1.7.10, 11 Oct 2014
# Created by Ruins mod version 12.3 Ingame Parser
# authoring Player: Jordan_Greywolf
# Last Updated: 27 Apr 2015
# Updated to MC 1.10: 13 Sep 2016
# Updated for MC 1.11: 13 Jan 2017
# Verified for MC 1.12: 23 Jun 2017
# Updated to MC 1.12.1: 10 Sep 2017

biomesToSpawnIn=clearing,eerie,eldritch,field,grove,lavender fields,magical forest,meadow,ominous woods,orchard,pasture,plains,prairie,rwg_coldplains,rwg_plains,savanna,sunflower plains,tainted land,wasteland,mining biome,mutated_plains

weight=1
embed_into_distance=1

unacceptable_target_blocks=water,flowing_water,lava,flowing_lava,cloud,Natura:Cloud,slime_congealed,slime_dirt,slime_grass,command_block

dimensions=7,7,13
allowable_overhang=5
max_cut_in=0
cut_in_buffer=0
max_leveling=4
leveling_buffer=-1
preserve_water=0
preserve_lava=0
preserve_plants=1

rule1=0,100,preserveBlock
rule2=0,75,minecraft:spruce_stairs-6
rule3=0,75,minecraft:spruce_stairs-7
rule4=0,75,minecraft:spruce_stairs-2
rule5=0,75,minecraft:spruce_stairs-3
rule6=0,100,minecraft:planks-0
rule7=0,75,minecraft:oak_stairs-2
rule8=0,75,minecraft:fence-0
rule9=0,75,minecraft:oak_stairs-4
rule10=0,50,minecraft:planks-0
rule11=0,50,IInventory;minecraft:stone;minecraft:coal#1#1#1-5
rule12=0,75,minecraft:oak_stairs-3
rule13=0,75,minecraft:oak_stairs-5
rule14=0,100,minecraft:log-1
rule15=1,75,minecraft:cobblestone_wall-0
rule16=0,75,minecraft:wooden_slab-9
rule17=1,50,minecraft:wool-11,minecraft:wool-3,minecraft:wool-9
rule18=0,50,minecraft:wooden_slab-1
rule19=0,75,minecraft:spruce_stairs-0
rule20=0,100,minecraft:planks-1
rule21=0,75,minecraft:spruce_stairs-1

layer
1,1,1,1,1,1,1,1,1,1,1,1,1
1,1,1,1,3,2,1,1,1,3,2,1,1
1,1,1,1,1,1,1,1,1,1,0,1,1
1,1,1,1,1,1,1,1,1,1,1,1,1
1,1,1,1,1,1,1,1,1,1,1,1,1
1,1,1,1,3,2,1,1,1,3,2,1,1
1,1,1,1,1,1,1,1,1,1,1,1,1
endlayer

layer
1,1,1,1,1,1,1,1,1,1,1,1,1
1,1,1,1,5,4,1,6,1,5,4,1,1
1,1,6,6,6,6,6,6,6,6,6,6,1
8,8,6,6,6,6,6,6,6,6,6,7,0
1,1,6,6,6,6,6,6,6,6,6,6,1
1,1,1,1,5,4,1,6,1,5,4,1,1
1,1,1,1,1,1,1,1,1,1,1,1,1
endlayer

layer
1,1,1,8,8,8,8,8,8,8,8,8,1
1,8,8,8,9,9,6,6,6,9,9,8,1
1,8,12,8,6,1,1,1,11,10,6,8,1
1,8,1,1,1,1,1,1,1,1,1,1,1
1,8,12,8,6,1,1,1,1,1,6,8,1
1,8,8,8,13,13,6,6,6,13,13,8,1
1,1,1,8,8,8,8,8,8,8,8,8,1
endlayer

layer
1,1,1,1,1,1,1,1,1,1,1,1,1
1,1,1,1,14,8,14,8,14,8,14,1,1
1,1,1,1,6,1,1,1,15,1,6,1,1
1,1,1,1,1,1,1,1,1,1,1,1,1
1,1,1,1,6,1,1,1,1,1,6,1,1
1,1,1,1,14,8,14,8,14,8,14,1,1
1,1,1,1,1,1,1,1,1,1,1,1,1
endlayer

layer
1,1,1,16,16,16,16,16,16,16,16,16,1
1,1,1,1,14,17,14,17,14,17,14,1,1
1,1,1,1,6,1,1,1,15,1,6,1,1
1,1,1,1,6,1,1,1,1,1,6,1,1
1,1,1,1,6,1,1,1,1,1,6,1,1
1,1,1,1,14,17,14,17,14,17,14,1,1
1,1,1,16,16,16,16,16,16,16,16,16,1
endlayer

layer
1,1,1,1,1,1,1,1,1,1,1,1,1
1,1,1,18,18,18,18,18,18,18,18,18,1
1,1,1,19,19,19,19,19,20,19,19,19,1
1,1,1,1,20,1,16,1,16,1,20,1,1
1,1,1,21,21,21,21,21,21,21,21,21,1
1,1,1,18,18,18,18,18,18,18,18,18,1
1,1,1,1,1,1,1,1,1,1,1,1,1
endlayer

layer
1,1,1,1,1,1,1,1,1,1,1,1,1
1,1,1,1,1,1,1,1,1,1,1,1,1
1,1,1,1,1,1,1,1,15,1,1,1,1
1,1,1,1,1,1,1,1,1,1,1,1,1
1,1,1,1,1,1,1,1,1,1,1,1,1
1,1,1,1,1,1,1,1,1,1,1,1,1
1,1,1,1,1,1,1,1,1,1,1,1,1
endlayer



